Workbook

Sheet Início
E2: HIPÓTESE DE NICHO
B4: Objetivo
C6: Definir a solução de ataque, definir os nichos que possuem maior potencial de resultado, verificar a viabilidade de prospecção e definir a tese de ataque
B10: Acessos Importantes de Consulta
C12: PPT Conceitual (N/A) | I12: Vídeo Explicativo - Extrapolação de Empresas (N/A)
C15: Exemplo do Template Preenchido (N/A) | I15: Vídeo Explicativo - Booleana (N/A)
C18: Vídeo Explicativo - Análise de Empresas (N/A) | I18: Vídeo Explicativo - Análise de Viabilidade (N/A)
C22: PPT Conceitual: Apresentação com uma introdução ao assunto
C23: Exemplo do Template Preenchido: Exemplo para ser utilizado em caso de dúvidas na construção desse template
C24: Vídeo explicativo - Análise de empresa: Como preencher o template
C25: Vídeo Explicativo - Extrapolação de Empresa: Como preencher, utilizar o template para construir a lógica booleana e análise de viabilidade
C26: Vídeo Explicativo - Booleana: Como preencher/construir a lógica booleana baseado no cargo + departamento mapeado
C27: Vídeo Explicativo - Análise de Viabilidade: Como definir a viabilidade do nicho a prospectar
C30: Obs> Quando tiver o N/A ao lado de algum acesso, é porque não se faz necessário o material de consulta para este template

Sheet Definição de Solução para Ataqu
C2: DEFINIÇÃO DE SOLUÇÃO PARA ATAQUE
B4: =IF(COUNTIF(5:5,"Sim")>1,"ATENÇÃO: ESCOLHER APENAS 1 SOLUÇÃO PARA ATAQUE","")
B5: Solução Escolhida?
B6: Score | C6: =IF(COUNTA(C7:C19)<10,"Preencha todos os critérios", IFERROR(VLOOKUP(C10,'Apoio Geral'!$B:$C,2,FALSE)*'Apoio Geral'!$C$32+ VLOOKUP(C11,'Apoio Geral'!$B:$C,2,FALSE)*'Apoio Geral'!$C$39+ VLOOKUP(C12,'Apoio Geral'!$B:$C,2,FALSE)*'Apoio Geral'!$C$46+ (LARGE($C$16:$L$16,1)/C16)*0.1+ VLOOKUP(C19,'Apoio Validação'!$D:$F,3,FALSE), "Preencha todos os critérios")) -> Preencha todos os critérios | D6: =IF(COUNTA(D7:D19)<10,"Preencha todos os critérios", IFERROR(VLOOKUP(D10,'Apoio Geral'!$B:$C,2,FALSE)*'Apoio Geral'!$C$32+ VLOOKUP(D11,'Apoio Geral'!$B:$C,2,FALSE)*'Apoio Geral'!$C$39+ VLOOKUP(D12,'Apoio Geral'!$B:$C,2,FALSE)*'Apoio Geral'!$C$46+ (LARGE($C$16:$L$16,1)/D16)*0.1+ VLOOKUP(D19,'Apoio Validação'!$D:$F,3,FALSE), "Preencha todos os critérios")) -> Preencha todos os critérios | E6: =IF(COUNTA(E7:E19)<10,"Preencha todos os critérios", IFERROR(VLOOKUP(E10,'Apoio Geral'!$B:$C,2,FALSE)*'Apoio Geral'!$C$32+ VLOOKUP(E11,'Apoio Geral'!$B:$C,2,FALSE)*'Apoio Geral'!$C$39+ VLOOKUP(E12,'Apoio Geral'!$B:$C,2,FALSE)*'Apoio Geral'!$C$46+ (LARGE($C$16:$L$16,1)/E16)*0.1+ VLOOKUP(E19,'Apoio Validação'!$D:$F,3,FALSE), "Preencha todos os critérios")) -> Preencha todos os critérios | F6: =IF(COUNTA(F7:F19)<10,"Preencha todos os critérios", IFERROR(VLOOKUP(F10,'Apoio Geral'!$B:$C,2,FALSE)*'Apoio Geral'!$C$32+ VLOOKUP(F11,'Apoio Geral'!$B:$C,2,FALSE)*'Apoio Geral'!$C$39+ VLOOKUP(F12,'Apoio Geral'!$B:$C,2,FALSE)*'Apoio Geral'!$C$46+ (LARGE($C$16:$L$16,1)/F16)*0.1+ VLOOKUP(F19,'Apoio Validação'!$D:$F,3,FALSE), "Preencha todos os critérios")) -> Preencha todos os critérios | G6: =IF(COUNTA(G7:G19)<10,"Preencha todos os critérios", IFERROR(VLOOKUP(G10,'Apoio Geral'!$B:$C,2,FALSE)*'Apoio Geral'!$C$32+ VLOOKUP(G11,'Apoio Geral'!$B:$C,2,FALSE)*'Apoio Geral'!$C$39+ VLOOKUP(G12,'Apoio Geral'!$B:$C,2,FALSE)*'Apoio Geral'!$C$46+ (LARGE($C$16:$L$16,1)/G16)*0.1+ VLOOKUP(G19,'Apoio Validação'!$D:$F,3,FALSE), "Preencha todos os critérios")) -> Preencha todos os critérios | H6: =IF(COUNTA(H7:H19)<10,"Preencha todos os critérios", IFERROR(VLOOKUP(H10,'Apoio Geral'!$B:$C,2,FALSE)*'Apoio Geral'!$C$32+ VLOOKUP(H11,'Apoio Geral'!$B:$C,2,FALSE)*'Apoio Geral'!$C$39+ VLOOKUP(H12,'Apoio Geral'!$B:$C,2,FALSE)*'Apoio Geral'!$C$46+ (LARGE($C$16:$L$16,1)/H16)*0.1+ VLOOKUP(H19,'Apoio Validação'!$D:$F,3,FALSE), "Preencha todos os critérios")) -> Preencha todos os critérios | I6: =IF(COUNTA(I7:I19)<10,"Preencha todos os critérios", IFERROR(VLOOKUP(I10,'Apoio Geral'!$B:$C,2,FALSE)*'Apoio Geral'!$C$32+ VLOOKUP(I11,'Apoio Geral'!$B:$C,2,FALSE)*'Apoio Geral'!$C$39+ VLOOKUP(I12,'Apoio Geral'!$B:$C,2,FALSE)*'Apoio Geral'!$C$46+ (LARGE($C$16:$L$16,1)/I16)*0.1+ VLOOKUP(I19,'Apoio Validação'!$D:$F,3,FALSE), "Preencha todos os critérios")) -> Preencha todos os critérios | J6: =IF(COUNTA(J7:J19)<10,"Preencha todos os critérios", IFERROR(VLOOKUP(J10,'Apoio Geral'!$B:$C,2,FALSE)*'Apoio Geral'!$C$32+ VLOOKUP(J11,'Apoio Geral'!$B:$C,2,FALSE)*'Apoio Geral'!$C$39+ VLOOKUP(J12,'Apoio Geral'!$B:$C,2,FALSE)*'Apoio Geral'!$C$46+ (LARGE($C$16:$L$16,1)/J16)*0.1+ VLOOKUP(J19,'Apoio Validação'!$D:$F,3,FALSE), "Preencha todos os critérios")) -> Preencha todos os critérios | ... L6: =IF(COUNTA(L7:L19)<10,"Preencha todos os critérios", IFERROR(VLOOKUP(L10,'Apoio Geral'!$B:$C,2,FALSE)*'Apoio Geral'!$C$32+ VLOOKUP(L11,'Apoio Geral'!$B:$C,2,FALSE)*'Apoio Geral'!$C$39+ VLOOKUP(L12,'Apoio Geral'!$B:$C,2,FALSE)*'Apoio Geral'!$C$46+ (LARGE($C$16:$L$16,1)/L16)*0.1+ VLOOKUP(L19,'Apoio Validação'!$D:$F,3,FALSE), "Preencha todos os critérios")) -> Preencha todos os critérios
B7: Nome da solução
B8: Descrição da Solução
B9: Análise Absoluta Posicione a solução frente aos critérios analisados (Duas soluções podem possuir a mesma nota em um critério)
B10: Product Market Fit (A solução já foi validada pelo mercado ou é uma nova solução?)
B11: É vendida como solução de ataque? (É vendida como uma solução de ataque ou é vendida como um upsell/crossell de outras soluções?)
B12: Qual o ciclo de vendas?
B13: Ticket Médio
B14: CLT - Customer Lifetime
B15: Margem Bruta
B16: LTV | C16: =IF(AND(C13<>"",C14<>"",C15<>""),(IF(C15="Acima de 70%",0.7,IF(C15="Entre 30% e 70%",0.5,IF(C15="Abaixo de 30%",0.15))))*C14*C13,"") | D16: =IF(AND(D13<>"",D14<>"",D15<>""),(IF(D15="Acima de 70%",0.7,IF(D15="Entre 30% e 70%",0.5,IF(D15="Abaixo de 30%",0.15))))*D14*D13,"") | E16: =IF(AND(E13<>"",E14<>"",E15<>""),(IF(E15="Acima de 70%",0.7,IF(E15="Entre 30% e 70%",0.5,IF(E15="Abaixo de 30%",0.15))))*E14*E13,"") | F16: =IF(AND(F13<>"",F14<>"",F15<>""),(IF(F15="Acima de 70%",0.7,IF(F15="Entre 30% e 70%",0.5,IF(F15="Abaixo de 30%",0.15))))*F14*F13,"") | G16: =IF(AND(G13<>"",G14<>"",G15<>""),(IF(G15="Acima de 70%",0.7,IF(G15="Entre 30% e 70%",0.5,IF(G15="Abaixo de 30%",0.15))))*G14*G13,"") | H16: =IF(AND(H13<>"",H14<>"",H15<>""),(IF(H15="Acima de 70%",0.7,IF(H15="Entre 30% e 70%",0.5,IF(H15="Abaixo de 30%",0.15))))*H14*H13,"") | I16: =IF(AND(I13<>"",I14<>"",I15<>""),(IF(I15="Acima de 70%",0.7,IF(I15="Entre 30% e 70%",0.5,IF(I15="Abaixo de 30%",0.15))))*I14*I13,"") | J16: =IF(AND(J13<>"",J14<>"",J15<>""),(IF(J15="Acima de 70%",0.7,IF(J15="Entre 30% e 70%",0.5,IF(J15="Abaixo de 30%",0.15))))*J14*J13,"") | ... L16: =IF(AND(L13<>"",L14<>"",L15<>""),(IF(L15="Acima de 70%",0.7,IF(L15="Entre 30% e 70%",0.5,IF(L15="Abaixo de 30%",0.15))))*L14*L13,"")
B17: Análise de Riscos Posicione a solução frente aos critérios analisados (Duas soluções podem possuir a mesma nota em um critério)
B18: Quais são os riscos, dificuldades de implantação e/ou de uso percebidos pelas personas na contratação da sua solução? (ex: a implantação da minha solução é complexa e envolve muitas áreas e pessoas para funcionar)
B19: O quão crítico são os riscos e dificuldades acima abordados? Ou seja, qual é a classificação destes riscos e dificuldades?

Sheet Análise de Empresas
C1: =IFERROR(IF(C8="Sim",COUNTA($A$1:B1)-COUNTBLANK($A$1:B1)+3,""),"") | D1: =IFERROR(IF(D8="Sim",COUNTA($A$1:C1)-COUNTBLANK($A$1:C1)+3,""),"") | E1: =IFERROR(IF(E8="Sim",COUNTA($A$1:D1)-COUNTBLANK($A$1:D1)+3,""),"") | F1: =IFERROR(IF(F8="Sim",COUNTA($A$1:E1)-COUNTBLANK($A$1:E1)+3,""),"") | G1: =IFERROR(IF(G8="Sim",COUNTA($A$1:F1)-COUNTBLANK($A$1:F1)+3,""),"") | H1: =IFERROR(IF(H8="Sim",COUNTA($A$1:G1)-COUNTBLANK($A$1:G1)+3,""),"") | I1: =IFERROR(IF(I8="Sim",COUNTA($A$1:H1)-COUNTBLANK($A$1:H1)+3,""),"") | J1: =IFERROR(IF(J8="Sim",COUNTA($A$1:I1)-COUNTBLANK($A$1:I1)+3,""),"") | ... L1: =IFERROR(IF(L8="Sim",COUNTA($A$1:K1)-COUNTBLANK($A$1:K1)+3,""),"")
C2: ANÁLISE DE EMPRESAS
C5: Legenda: | D5: Editável | E5: O que está em branco já foi preenchido | G5: =IF(COUNTIF(8:8,"Sim")>3,"Erro: Selecione até 3 empresas","")
B7: Score | C7: {=IF(COUNTA(C10:C22)<13,"Finalize o Preenchimento", IFERROR(ROUND((C18/LARGE($C$18:$L$18,1)) + VLOOKUP(C20,'Apoio Validação'!$D$48:$E$51,2,FALSE)+ INDEX('Apoio Validação'!$D$34:$F$38,MATCH(C14,'Apoio Validação'!$D$34:$D$38,0),3)+ INDEX('Apoio Validação'!$D$61:$F$65,MATCH(C19,'Apoio Validação'!$D$61:$D$65,0),3)+ (LARGE($C$21:$L$21,1)/C21)*0.1,2),"Finalize o Preenchimento"))} -> Finalize o Preenchimento | D7: {=IF(COUNTA(D10:D22)<13,"Finalize o Preenchimento", IFERROR(ROUND((D18/LARGE($C$18:$L$18,1)) + VLOOKUP(D20,'Apoio Validação'!$D$48:$E$51,2,FALSE)+ INDEX('Apoio Validação'!$D$34:$F$38,MATCH(D14,'Apoio Validação'!$D$34:$D$38,0),3)+ INDEX('Apoio Validação'!$D$61:$F$65,MATCH(D19,'Apoio Validação'!$D$61:$D$65,0),3)+ (LARGE($C$21:$L$21,1)/D21)*0.1,2),"Finalize o Preenchimento"))} -> Finalize o Preenchimento | E7: {=IF(COUNTA(E10:E22)<13,"Finalize o Preenchimento", IFERROR(ROUND((E18/LARGE($C$18:$L$18,1)) + VLOOKUP(E20,'Apoio Validação'!$D$48:$E$51,2,FALSE)+ INDEX('Apoio Validação'!$D$34:$F$38,MATCH(E14,'Apoio Validação'!$D$34:$D$38,0),3)+ INDEX('Apoio Validação'!$D$61:$F$65,MATCH(E19,'Apoio Validação'!$D$61:$D$65,0),3)+ (LARGE($C$21:$L$21,1)/E21)*0.1,2),"Finalize o Preenchimento"))} -> Finalize o Preenchimento | F7: {=IF(COUNTA(F10:F22)<13,"Finalize o Preenchimento", IFERROR(ROUND((F18/LARGE($C$18:$L$18,1)) + VLOOKUP(F20,'Apoio Validação'!$D$48:$E$51,2,FALSE)+ INDEX('Apoio Validação'!$D$34:$F$38,MATCH(F14,'Apoio Validação'!$D$34:$D$38,0),3)+ INDEX('Apoio Validação'!$D$61:$F$65,MATCH(F19,'Apoio Validação'!$D$61:$D$65,0),3)+ (LARGE($C$21:$L$21,1)/F21)*0.1,2),"Finalize o Preenchimento"))} -> Finalize o Preenchimento | G7: {=IF(COUNTA(G10:G22)<13,"Finalize o Preenchimento", IFERROR(ROUND((G18/LARGE($C$18:$L$18,1)) + VLOOKUP(G20,'Apoio Validação'!$D$48:$E$51,2,FALSE)+ INDEX('Apoio Validação'!$D$34:$F$38,MATCH(G14,'Apoio Validação'!$D$34:$D$38,0),3)+ INDEX('Apoio Validação'!$D$61:$F$65,MATCH(G19,'Apoio Validação'!$D$61:$D$65,0),3)+ (LARGE($C$21:$L$21,1)/G21)*0.1,2),"Finalize o Preenchimento"))} -> Finalize o Preenchimento | H7: {=IF(COUNTA(H10:H22)<13,"Finalize o Preenchimento", IFERROR(ROUND((H18/LARGE($C$18:$L$18,1)) + VLOOKUP(H20,'Apoio Validação'!$D$48:$E$51,2,FALSE)+ INDEX('Apoio Validação'!$D$34:$F$38,MATCH(H14,'Apoio Validação'!$D$34:$D$38,0),3)+ INDEX('Apoio Validação'!$D$61:$F$65,MATCH(H19,'Apoio Validação'!$D$61:$D$65,0),3)+ (LARGE($C$21:$L$21,1)/H21)*0.1,2),"Finalize o Preenchimento"))} -> Finalize o Preenchimento | I7: {=IF(COUNTA(I10:I22)<13,"Finalize o Preenchimento", IFERROR(ROUND((I18/LARGE($C$18:$L$18,1)) + VLOOKUP(I20,'Apoio Validação'!$D$48:$E$51,2,FALSE)+ INDEX('Apoio Validação'!$D$34:$F$38,MATCH(I14,'Apoio Validação'!$D$34:$D$38,0),3)+ INDEX('Apoio Validação'!$D$61:$F$65,MATCH(I19,'Apoio Validação'!$D$61:$D$65,0),3)+ (LARGE($C$21:$L$21,1)/I21)*0.1,2),"Finalize o Preenchimento"))} -> Finalize o Preenchimento | J7: {=IF(COUNTA(J10:J22)<13,"Finalize o Preenchimento", IFERROR(ROUND((J18/LARGE($C$18:$L$18,1)) + VLOOKUP(J20,'Apoio Validação'!$D$48:$E$51,2,FALSE)+ INDEX('Apoio Validação'!$D$34:$F$38,MATCH(J14,'Apoio Validação'!$D$34:$D$38,0),3)+ INDEX('Apoio Validação'!$D$61:$F$65,MATCH(J19,'Apoio Validação'!$D$61:$D$65,0),3)+ (LARGE($C$21:$L$21,1)/J21)*0.1,2),"Finalize o Preenchimento"))} -> Finalize o Preenchimento | ... L7: {=IF(COUNTA(L10:L22)<13,"Finalize o Preenchimento", IFERROR(ROUND((L18/LARGE($C$18:$L$18,1)) + VLOOKUP(L20,'Apoio Validação'!$D$48:$E$51,2,FALSE)+ INDEX('Apoio Validação'!$D$34:$F$38,MATCH(L14,'Apoio Validação'!$D$34:$D$38,0),3)+ INDEX('Apoio Validação'!$D$61:$F$65,MATCH(L19,'Apoio Validação'!$D$61:$D$65,0),3)+ (LARGE($C$21:$L$21,1)/L21)*0.1,2),"Finalize o Preenchimento"))} -> Finalize o Preenchimento
B8: Empresas Selecionadas
B9: Critérios de análise de empresas | C9: Cliente 1 | D9: Cliente 2 | E9: Cliente 3 | F9: Cliente 4 | G9: Cliente 5 | H9: Cliente 6 | I9: Cliente 7 | J9: Cliente 8 | K9: Cliente 9 | L9: Cliente 10
B10: Principais clientes/empresas (em termos de lucratividade, alinhamento de dores aos benefícios do seu produto, necessidade, facilidade para fechar negócio, sucesso gerado e relacionamento no pós venda)
B11: Porte (Com base no número de funcionários)
B12: Setor de atuação da empresa (LinkedIn) (ex: serviços financeiros, contabilidade, consultoria de gerenciamento etc)
B13: CNAE Primário Vídeo: Como buscar o CNAE a partir da pesquisa pelo CNPJ no Google:https://bit.ly Link IBGE: https://cnae.ibge.gov.br/ Obs: Padrão de preenchimento XX.XX-X
B14: Qual era a intensidade da dor para a empresa do cliente?
B15: Ticket Médio
B16: CLT - Customer Lifetime
B17: Margem Bruta
B18: LTV - Lifetime Value | C18: =IF(COUNTA(C15:C17)<3,"",C15*C16*C17) | D18: =IF(COUNTA(D15:D17)<3,"",D15*D16*D17) | E18: =IF(COUNTA(E15:E17)<3,"",E15*E16*E17) | F18: =IF(COUNTA(F15:F17)<3,"",F15*F16*F17) | G18: =IF(COUNTA(G15:G17)<3,"",G15*G16*G17) | H18: =IF(COUNTA(H15:H17)<3,"",H15*H16*H17) | I18: =IF(COUNTA(I15:I17)<3,"",I15*I16*I17) | J18: =IF(COUNTA(J15:J17)<3,"",J15*J16*J17) | ... L18: =IF(COUNTA(L15:L17)<3,"",L15*L16*L17)
B19: Em uma pesquisa de satisfação com o cliente (NPS), qual nota ele daria para a sua empresa e para os resultados obtidos com a sua solução?
B20: Informe o canal de vendas
B21: Informe o ciclo de vendas deste cliente (em dias)
B22: Quem foram os decisores de compra dessa empresa?

Sheet Análise de Nichos
D2: ANÁLISE DE NICHOS
C6: SELECIONE O NICHO | D6: =IF(COUNTIF(D8:H8,"Sim")>1,"Erro: Selecione apenas 1 nicho","")
C7: Score | D7: =IF(COUNTA(D10:D26)<17,"Finalize o preenchimento",IFERROR( VLOOKUP(D15,'Apoio Validação'!$D:$F,3,FALSE)+ VLOOKUP(D16,'Apoio Validação'!$D:$F,3,FALSE)+ VLOOKUP(D17,'Apoio Validação'!$D:$F,3,FALSE)+ VLOOKUP(D18,'Apoio Validação'!$D:$F,3,FALSE)+ VLOOKUP(D19,'Apoio Validação'!$D:$F,3,FALSE)+ IF(D20=0,0,(D20/LARGE($D$20:$F$20,1)))+ VLOOKUP(D22,'Apoio Validação'!$D:$F,3,FALSE)+ VLOOKUP(D24,'Apoio Validação'!$D:$F,3,FALSE)+ VLOOKUP(D25,'Apoio Validação'!$D:$F,3,FALSE)+ VLOOKUP(D26,'Apoio Validação'!$D:$F,3,FALSE) ,"Finalize o preenchimento")) -> Finalize o preenchimento | E7: =IF(COUNTA(E10:E26)<17,"Finalize o preenchimento",IFERROR( VLOOKUP(E15,'Apoio Validação'!$D:$F,3,FALSE)+ VLOOKUP(E16,'Apoio Validação'!$D:$F,3,FALSE)+ VLOOKUP(E17,'Apoio Validação'!$D:$F,3,FALSE)+ VLOOKUP(E18,'Apoio Validação'!$D:$F,3,FALSE)+ VLOOKUP(E19,'Apoio Validação'!$D:$F,3,FALSE)+ IF(E20=0,0,(E20/LARGE($D$20:$F$20,1)))+ VLOOKUP(E22,'Apoio Validação'!$D:$F,3,FALSE)+ VLOOKUP(E24,'Apoio Validação'!$D:$F,3,FALSE)+ VLOOKUP(E25,'Apoio Validação'!$D:$F,3,FALSE)+ VLOOKUP(E26,'Apoio Validação'!$D:$F,3,FALSE) ,"Finalize o preenchimento")) -> Finalize o preenchimento | F7: =IF(COUNTA(F10:F26)<17,"Finalize o preenchimento",IFERROR( VLOOKUP(F15,'Apoio Validação'!$D:$F,3,FALSE)+ VLOOKUP(F16,'Apoio Validação'!$D:$F,3,FALSE)+ VLOOKUP(F17,'Apoio Validação'!$D:$F,3,FALSE)+ VLOOKUP(F18,'Apoio Validação'!$D:$F,3,FALSE)+ VLOOKUP(F19,'Apoio Validação'!$D:$F,3,FALSE)+ IF(F20=0,0,(F20/LARGE($D$20:$F$20,1)))+ VLOOKUP(F22,'Apoio Validação'!$D:$F,3,FALSE)+ VLOOKUP(F24,'Apoio Validação'!$D:$F,3,FALSE)+ VLOOKUP(F25,'Apoio Validação'!$D:$F,3,FALSE)+ VLOOKUP(F26,'Apoio Validação'!$D:$F,3,FALSE) ,"Finalize o preenchimento")) -> Finalize o preenchimento | G7: =IF(COUNTA(G10:G26)<17,"Finalize o preenchimento",IFERROR( VLOOKUP(G15,'Apoio Validação'!$D:$F,3,FALSE)+ VLOOKUP(G16,'Apoio Validação'!$D:$F,3,FALSE)+ VLOOKUP(G17,'Apoio Validação'!$D:$F,3,FALSE)+ VLOOKUP(G18,'Apoio Validação'!$D:$F,3,FALSE)+ VLOOKUP(G19,'Apoio Validação'!$D:$F,3,FALSE)+ (G20/LARGE($D$20:$F$20,1))+ VLOOKUP(G22,'Apoio Validação'!$D:$F,3,FALSE)+ VLOOKUP(G24,'Apoio Validação'!$D:$F,3,FALSE)+ VLOOKUP(G25,'Apoio Validação'!$D:$F,3,FALSE)+ VLOOKUP(G26,'Apoio Validação'!$D:$F,3,FALSE) ,"Finalize o preenchimento")) -> Finalize o preenchimento | H7: =IF(COUNTA(H10:H26)<17,"Finalize o preenchimento",IFERROR( VLOOKUP(H15,'Apoio Validação'!$D:$F,3,FALSE)+ VLOOKUP(H16,'Apoio Validação'!$D:$F,3,FALSE)+ VLOOKUP(H17,'Apoio Validação'!$D:$F,3,FALSE)+ VLOOKUP(H18,'Apoio Validação'!$D:$F,3,FALSE)+ VLOOKUP(H19,'Apoio Validação'!$D:$F,3,FALSE)+ (H20/LARGE($D$20:$F$20,1))+ VLOOKUP(H22,'Apoio Validação'!$D:$F,3,FALSE)+ VLOOKUP(H24,'Apoio Validação'!$D:$F,3,FALSE)+ VLOOKUP(H25,'Apoio Validação'!$D:$F,3,FALSE)+ VLOOKUP(H26,'Apoio Validação'!$D:$F,3,FALSE) ,"Finalize o preenchimento")) -> Finalize o preenchimento
C8: Nicho Selecionado | E8: Sim
C9: Critérios de análise de nichos | D9: Nicho 1 | E9: Nicho 2 | F9: Nicho 3 | G9: Nicho 4 | H9: Nicho 5
B10: Aspectos de um ótimo nicho | C10: Portes do nicho específico selecionado (ex: Médio, 51-200 funcionários)
C11: Segmentos de mercado do nicho específico selecionado (ex: serviços financeiros, contabilidade, consultoria de gerenciamento etc)
B12: Personas | C12: IPPs analisados | D12: [Insira manualmente] | E12: [Insira manualmente] | F12: [Insira manualmente] | G12: [Insira manualmente] | H12: [Insira manualmente]
C13: Defina o IPP a ser prospectado
C14: Justifique a escolha do IPP para tese de ataque
B15: Identificação de Alvos | C15: Qual é a dificuldade de se obter os dados de contato do decisor deste nicho?
C16: Qual é a dificuldade de se comunicar por telefone com o decisor deste nicho?
C17: Qual é a dificuldade de se comunicar por e-mail com o decisor deste nicho?
C18: Qual é a dificuldade de se comunicar pelo linkedin com o decisor deste nicho?
B19: Solução e resultados | C19: O quanto sua solução gera de resultados tangíveis em relação à expectativa do cliente?
B20: Provas Sociais | C20: Quantas provas sociais sua empresa possui que confirmam que a sua solução entrega os resultados tangíveis esperados? (ex de provas: cases de projeto, cases de sucesso, depoimentos - especialmente em vídeo etc)
C21: Descreva o resultado da principal prova social que você pode apresentar e que suporte o que você alega fazer (caso não possua nenhuma prova, escreva "sem prova")
C22: Você possui algum conteúdo que mostre que você de fato é um especialista nesse nicho? (Blogposts, publicações em redes sociais, artigos etc)
B23: Cliente | C23: Do ponto de vista do cliente, o que diferencia a sua solução do seu concorrente? Onde você se destaca? Quais são os seus diferenciais? (ex: possuo atendimento especializado 24h por dia para auxiliar as empresas na implantação da solução)
C24: O quão diferenciada é a sua solução frente a concorrência nesse nicho, com base no argumento de diferenciação acima?
B25: Atratividade | C25: Qual é o potencial de lucratividade do nicho analisado? (icp)
C26: Qual é a facilidade para se vender para o nicho analisado? (icp)

Sheet Conclusão
C2: CONCLUSÃO
B7: Tese de Ataque (Por onde iremos começar a prospecção?)
B8: Porte | C8: Setor | E8: IPP | F8: Localidade
B9: [Insira manualmente] | C9: [Insira manualmente] | E9: [Insira manualmente] | F9: [Insira manualmente]
B10: Justificativa | C10: Justificativa | E10: Justificativa | F10: Justificativa
B11: [Insira manualmente] | C11: [Insira manualmente] | E11: [Insira manualmente] | F11: [Insira manualmente]

Sheet Dicas
F2: DICAS
E4: Explicações e pontos de atenção do preenchimento da planilha
B6: Antes de começarmos, primeiramente você precisa entender qual é a lógica por trás do jogo. De forma sucinta: a ideia inicial é analisarmos empresas que foram clientes ideiais para o seu negócio, ou seja, aqueles que trouxeram o máximo de receita com o mínimo de esforço possível. Após o preenchimento inicial, verificaremos quais empresas possuem os maiores scores para que possamos fazer uma análise mais detalhada do nicho no qual estão inseridas para, assim, definir qual o melhor tipo de cliente para o seu negócio.
B9: Sobre a aba 'Análise de Empresas'
B10: Nessa aba avaliamos as 10 melhores empresas com as quais a sua empresa já negociou.
B12: Passo a passo
B13: 1) Definir até 10 empresas que foram seus clientes ideais em termos de lucratividade, facilidade para fechar negócio e sucesso com o uso da sua solução.
B14: 2) Buscar as mesmas empresas no Linkedin e preencher o porte e segmento das empresas de acordo com as informações disponíveis.
B15: 3) Preencher as informações solicitadas. Algumas informações são tangíveis e outras são percepções. É importante ser fidedigno as tangíveis e trazer uma percepção justa as demais.
B16: 4) Avalie a sua percepção quanto às 3 empresas com maior score para discussão posterior com o mentor responsável
B18: Após preenchimento dessa aba, você e o mentor debaterão juntos quais serão os nichos a serem analisados na próxima reunião
B20: Ponto de Atenção 1: | D20: As informações devem ser preenchidas da forma mais real possível, não extrapole os resultados obtidos ou a percepção do cliente quanto aos ganhos causados pela sua solução
B21: Ponto de Atenção 2: | D21: Todas as informações devem ser preenchidas para que o score seja calculado de forma correta. Caso não saiba/não tenha alguma informação, converse com o mentor responsável sobre a melhor forma de preenchê-la
B23: Sobre a aba 'Extrapolação de Empresa'
B24: Nessa aba trabalhamos com uma extrapolação dos nichos originários para nichos de comportamento semelhante. Feito a partir dos setores do Linkedin e também pelo CNAE.
B26: Passo a passo
B27: 1. Escolha quais os setores são compatíveis no Linkedin para fazer a Extrapolação de empresas;
B28: 2. Escolha quais os CNAE´s são compatíveis para fazer a Extrapolação de empresas;
B29: 3. Escolha quais são os portes compatíveis para fazer a Extrapolação de empresas e coloque o "Sim" no porte Ideal que está marcado com a cor verde;
B31: Ponto de Atenção 1: | D31: A cor vermelha está proibida de aparecer na planilha. Ela indica algum erro de preenchimento e deve ser indica para o mentor assim que possível.
B32: Ponto de Atenção 2: | D32: Se atentar ao preenchimento e extrapolação dos 3 nichos
B34: Sobre a aba 'Booleana'
B35: Nessa aba estaremos fazendo as boolenas para todos os IPP's selecionados. Assim, teremos uma mistura de todas as combinações possíveis de cargos e de setores para uma busca completa no Sales Navigator
B37: Passo a passo
B38: 1. Escolha o Nível do Cargo que deseja utilizar na Booleana (célula N10); Copiar para (célula D:E13);
B39: 2. Escolha o Departamento do IPP desejado (Célula P10); Copiar para célula B13);
B40: 3. Caso não queira algum cargo ou departamento específico, basta deletar, dessa forma, não aparecerá na Booleana construída;
B41: 4. Copie a Booleana que aparecerá na célula B11:F11 e cole como VALOR na coluna F no nicho e IPP desejado, assim como os Níveis Hierárquicos e os Departamentos.
B43: Ponto de Atenção 1: | D43: Validar que as palavras e cargos que vem automaticamente dos npiveis de departamentos selecionados fazem sentido para ajudar a encontrar a persona que estamos buscando.
B45: Sobre a aba 'Análise de Viabilidade'
B46: Nesta aba buscaremos entender qual o tamanho do mercado a ser prospectado e em quanto tempo conseguimos trabalhar uma lista de smart leads. Todo o processo é feito comparando a base da Receita Federal com a quantidade de empresas presentes no Linkedin
B48: Considerações:
B49: Esta análise tem como proposta trazer o comparativo entre:
B50: 1. O número de empresas cadastradas na base da Receita Federal do Brasil (Ferramenta Speedio)
B51: 2. O número de empresas presentes no LinkedIn para cada porte/setor;
B52: 3. O número de leads encontrados conforme a variação do porte/setor;
B53: 4. O número de leads encontrados conforme a variação do cargo/departamento;
B55: Ponto de Atenção 1: | D55: Todas as informações que constam no bloco da esquerda são referentes aos inputs que irão alimentar o bloco da direita, que é justamente o output e demais considerações quanto a viabilidade do mercado.
B57: Sobre a aba 'Análise de Nicho'
B58: Nessa aba filtramos as 3 melhores empresas analisadas e avaliamos os nichos nos quais estão inseridas em termos de porte e segmento. Nesse caso é importante não avaliarmos apenas a empresa escolhida e sim todas as empresas do seu nicho
...

Sheet Apoio Validação
H2: Pontos de atenção
H3: 3 - Dor esporádica que impacta diretamente e de forma muita intensa os resultados da empresa | I3: Gravidade do problema
H4: 2 - Dor constante que impacta diretamente e de forma leve os resultados da empresa | I4: Gravidade do problema
H5: 1 - Dor esporádica que impacta diretamente e de forma moderada os resultados da empresa | I5: Gravidade do problema
H7: 3 - O resultado gerado foi dentro do esperado/média | I7: Resultado gerado
H8: 2 - O resultado gerado foi abaixo do esperado/média | I8: Resultado gerado
H9: 1 - O resultado gerado foi extremamente abaixo do esperado/média | I9: Resultado gerado
H11: 5 - A venda teve um ciclo de venda médio e o preço da nossa solução não foi um problema | I11: Ciclo de venda e orçamento
H12: 5 - A venda teve um ciclo de venda curto e o preço da nossa solução não foi um problema | I12: Ciclo de venda e orçamento
H13: 5 - A venda teve um ciclo de venda curto e o preço da nossa solução não foi um problema | I13: Ciclo de venda e orçamento
H15: 7 ou 8 - É satisfeito com os resultados, porém não tem uma grande percepção de valor da solução | I15: NPS
H16: 5 ou 6 - É insatisfeito com os resultados obtidos e não vê muito valor na solução | I16: NPS
H17: 1 a 4 - É completamente insatisfeito com os resultados obtidos e não vê valor com a solução | I17: NPS
... H21: 1 - Dor esporádica que impacta diretamente e de forma moderada seus resultados e/ou sua vida pessoal | I21: Intensidade do problema para o decisor
B22: 1-10 | C22: Micro
B23: 11-50 | C23: Pequeno | H23: 3 - Minha solução gera parcialmente os resultados que o cliente espera | I23: Resultados tangíveis
B24: 51-200 | C24: Médio | H24: 2 - Minha solução gera poucos resultados esperados pelo cliente | I24: Resultados tangíveis
B25: 201-500 | C25: Médio | H25: 1 - Minha solução não gera nenhum dos resultados esperados pelo cliente | I25: Resultados tangíveis
B26: 501-1.000 | C26: Grande | D26: Porte (Com base no número de funcionários)
B27: 1.001-5.000 | C27: Grande | D27: Micro, (1-10 funcionários) | E27: 5 | H27: 3- Possuo poucos conteúdos produzidos para esse nicho | I27: Conteúdo gerado
B28: 5.001-10.000 | C28: Grande | D28: Pequeno, (11-50 funcionários) | E28: 4 | H28: 2- Não possuo conteúdos direcionados a esse nicho, mas possuo conteúdos que podem ser aplicáveis a esse nicho | I28: Conteúdo gerado
B29: + de 10.000 | C29: Grande | D29: Médio, (51-200 funcionários) | E29: 3 | H29: 1- Não possuo nenhum conteúdo para esse nicho | I29: Conteúdo gerado
D30: Médio-Grande, (201-500 funcionários) | E30: 2
D31: Grande, (Acima de 500 funcionários) | E31: 1 | H31: 3 - Os decisores deste nicho são ativos no linkedin, mas não possuem seus dados de contato abertos | I31: Dados de contato
H32: 2 - Os decisores deste nicho possuem linkedin, mas não são ativos na rede | I32: Dados de contato
D33: Qual é a gravidade desse problema para as empresas desse nicho? | H33: 1 - Os decisores deste nicho não estão no linkedin e nem possuem seus dados de contato abertos de forma pública | I33: Dados de contato
D34: 5 - Dor constante que impacta diretamente e de forma muito grave os resultados da empresa | E34: 7 | F34: =E34/$E$34 -> 1
D35: 4 - Dor constante que impacta diretamente e de forma moderada os resultados da empresa | E35: 5 | F35: =E35/$E$34 -> 0.71428571 | H35: 1 - Alto risco e alta dificuldade de implantação e/ou uso | I35: Riscos e dificuldades
D36: 3 - Dor esporádica que impacta diretamente e de forma muita intensa os resultados da empresa | E36: 3 | F36: =E36/$E$34 -> 0.42857143 | H36: 2 - Alto risco e média dificuldade de implantação e/ou uso | I36: Riscos e dificuldades
D37: 2 - Dor constante que impacta diretamente e de forma leve os resultados da empresa | E37: 2 | F37: =E37/$E$34 -> 0.28571429 | H37: 3 - Risco médio e alta dificuldade de implantação e/ou uso | I37: Riscos e dificuldades
D38: 1 - Dor esporádica que impacta diretamente e de forma moderada os resultados da empresa | E38: 1 | F38: =E38/$E$34 -> 0.14285714 | H38: 4 - Alto risco e baixa dificuldade de implantação e/ou uso | I38: Riscos e dificuldades
H39: 5 - Risco médio e média dificuldade de implantação e/ou uso | I39: Riscos e dificuldades
D40: Em uma escala de 1 a 5, o quanto esse resultado gerado foi incrível se comparado ao seu histórico?
D41: 5 - O resultado gerado foi extremamente acima do esperado/média | E41: 7 | F41: =E41/$E$41 -> 1 | H41: 1 - O tamanho do mercado não é suficiente para os meus objetivos | I41: Tamanho mercado
D42: 4 - O resultado gerado foi acima do esperado/média | E42: 5 | F42: =E42/$E$41 -> 0.71428571
D43: 3 - O resultado gerado foi dentro do esperado/média | E43: 3 | F43: =E43/$E$41 -> 0.42857143 | H43: 1 - Possuem gatekeepers | I43: Acessibilidade por telefone
D44: 2 - O resultado gerado foi abaixo do esperado/média | E44: 2 | F44: =E44/$E$41 -> 0.28571429 | H44: 2 - Apesar de não terem gatekeerpers, dificilmente alguém da empresa transfere uma ligação diretamente | I44: Acessibilidade por telefone
D45: 1 - O resultado gerado foi extremamente abaixo do esperado/média | E45: 1 | F45: =E45/$E$41 -> 0.14285714
H46: Qual é a dificuldade de se comunicar por e-mail com o decisor deste nicho?
D47: Qual foi o canal de prospecção utilizado para esta venda?
...

Sheet Apoio Geral
Q1: Empresas para analise de viabilidade
B2: Base para definição do ICP na planilha de posicionamento | O2: Setores Linkedin | P2: =COLUMN(P1) -> 16 | Q2: =IF(Q3="Sim",COUNTIF(B3:Q3,"Sim"),"") -> #N/A | R2: =IF(R3="Sim",COUNTIF(C3:R3,"Sim"),"") -> #N/A | S2: =IF(S3="Sim",COUNTIF(D3:S3,"Sim"),"") -> #N/A | T2: =IF(T3="Sim",COUNTIF(E3:T3,"Sim"),"") -> #N/A | U2: =IF(U3="Sim",COUNTIF(F3:U3,"Sim"),"") -> #N/A | V2: =IF(V3="Sim",COUNTIF(N3:V3,"Sim"),"") -> #N/A | W2: =IF(W3="Sim",COUNTIF(O3:W3,"Sim"),"") -> #N/A | X2: =IF(X3="Sim",COUNTIF(P3:X3,"Sim"),"") -> #N/A | Y2: =IF(Y3="Sim",COUNTIF(Q3:Y3,"Sim"),"") -> #N/A | Z2: =IF(Z3="Sim",COUNTIF(R3:Z3,"Sim"),"") -> #N/A
B3: =IF($B$4<>"","",_xlfn.RANK.EQ(B6,$B$6:$F$6,FALSE)) -> #VALUE! | C3: =IF($B$4<>"","",_xlfn.RANK.EQ(C6,$B$6:$F$6,FALSE)) -> #VALUE! | D3: =IF($B$4<>"","",_xlfn.RANK.EQ(D6,$B$6:$F$6,FALSE)) -> #VALUE! | E3: =IF($B$4<>"","",_xlfn.RANK.EQ(E6,$B$6:$F$6,FALSE)) -> #VALUE! | F3: =IF($B$4<>"","",_xlfn.RANK.EQ(F6,$B$6:$F$6,FALSE)) -> #VALUE! | O3: Agricultura, Pecuária, Silvicultura | Q3: =HLOOKUP(Q4,'Análise de Empresas'!$C$7:$L$10,2,FALSE) -> #N/A | R3: =HLOOKUP(R4,'Análise de Empresas'!$C$7:$L$10,2,FALSE) -> #N/A | S3: =HLOOKUP(S4,'Análise de Empresas'!$C$7:$L$10,2,FALSE) -> #N/A | T3: =HLOOKUP(T4,'Análise de Empresas'!$C$7:$L$10,2,FALSE) -> #N/A | U3: =HLOOKUP(U4,'Análise de Empresas'!$C$7:$L$10,2,FALSE) -> #N/A | V3: =HLOOKUP(V4,'Análise de Empresas'!$C$7:$L$10,2,FALSE) -> #N/A | W3: =HLOOKUP(W4,'Análise de Empresas'!$C$7:$L$10,2,FALSE) -> #N/A | X3: =HLOOKUP(X4,'Análise de Empresas'!$C$7:$L$10,2,FALSE) -> #N/A | ... Z3: =HLOOKUP(Z4,'Análise de Empresas'!$C$7:$L$10,2,FALSE) -> #N/A
B4: ='Análise de Nichos'!D5 | O4: Agricultura | Q4: =IFERROR(LARGE('Análise de Empresas'!$C$7:$L$7,COLUMN(A1)),"") | R4: =IFERROR(LARGE('Análise de Empresas'!$C$7:$L$7,COLUMN(B1)),"") | S4: =IFERROR(LARGE('Análise de Empresas'!$C$7:$L$7,COLUMN(C1)),"") | T4: =IFERROR(LARGE('Análise de Empresas'!$C$7:$L$7,COLUMN(D1)),"") | U4: =IFERROR(LARGE('Análise de Empresas'!$C$7:$L$7,COLUMN(E1)),"") | V4: =IFERROR(LARGE('Análise de Empresas'!$C$7:$L$7,COLUMN(F1)),"") | W4: =IFERROR(LARGE('Análise de Empresas'!$C$7:$L$7,COLUMN(N1)),"") | X4: =IFERROR(LARGE('Análise de Empresas'!$C$7:$L$7,COLUMN(O1)),"") | Y4: =IFERROR(LARGE('Análise de Empresas'!$C$7:$L$7,COLUMN(P1)),"") | Z4: =IFERROR(LARGE('Análise de Empresas'!$C$7:$L$7,COLUMN(Q1)),"")
O5: Horticultura | Q5: =HLOOKUP(Q4,'Análise de Empresas'!$C$7:$L$10,4,FALSE) -> #N/A | R5: =HLOOKUP(R4,'Análise de Empresas'!$C$7:$L$10,4,FALSE) -> #N/A | S5: =HLOOKUP(S4,'Análise de Empresas'!$C$7:$L$10,4,FALSE) -> #N/A | T5: =HLOOKUP(T4,'Análise de Empresas'!$C$7:$L$10,4,FALSE) -> #N/A | U5: =HLOOKUP(U4,'Análise de Empresas'!$C$7:$L$10,4,FALSE) -> #N/A | V5: =HLOOKUP(V4,'Análise de Empresas'!$C$7:$L$10,4,FALSE) -> #N/A | W5: =HLOOKUP(W4,'Análise de Empresas'!$C$7:$L$10,4,FALSE) -> #N/A | X5: =HLOOKUP(X4,'Análise de Empresas'!$C$7:$L$10,4,FALSE) -> #N/A | ... Z5: =HLOOKUP(Z4,'Análise de Empresas'!$C$7:$L$10,4,FALSE) -> #N/A
B6: ='Análise de Nichos'!D7 -> Finalize o preenchimento | C6: ='Análise de Nichos'!E7 -> Finalize o preenchimento | D6: ='Análise de Nichos'!F7 -> Finalize o preenchimento | E6: ='Análise de Nichos'!G7 -> Finalize o preenchimento | F6: ='Análise de Nichos'!H7 -> Finalize o preenchimento | O6: Pecuária e Pesca | Q6: =COUNTIF(Q3:Z3,"Sim") -> 0
B7: ='Análise de Nichos'!D9 -> Nicho 1 | C7: ='Análise de Nichos'!E9 -> Nicho 2 | D7: ='Análise de Nichos'!F9 -> Nicho 3 | E7: ='Análise de Nichos'!G9 -> Nicho 4 | F7: ='Análise de Nichos'!H9 -> Nicho 5 | O7: Pecuária | Q7: Organização
B8: ='Análise de Nichos'!D10 | C8: ='Análise de Nichos'!E10 | D8: ='Análise de Nichos'!F10 | E8: ='Análise de Nichos'!G10 | F8: ='Análise de Nichos'!H10 | O8: Pesca | Q8: =IF(COUNTIF(A8:P8,"Sim")<$Q$6,"Sim","") | R8: =IF(COUNTIF(B8:Q8,"Sim")<$Q$6,"Sim","") | S8: =IF(COUNTIF(C8:R8,"Sim")<$Q$6,"Sim","") | T8: =IF(COUNTIF(D8:S8,"Sim")<$Q$6,"Sim","") | U8: =IF(COUNTIF(E8:T8,"Sim")<$Q$6,"Sim","") | V8: =IF(COUNTIF(F8:U8,"Sim")<$Q$6,"Sim","") | W8: =IF(COUNTIF(N8:V8,"Sim")<$Q$6,"Sim","") | X8: =IF(COUNTIF(O8:W8,"Sim")<$Q$6,"Sim","") | Y8: =IF(COUNTIF(P8:X8,"Sim")<$Q$6,"Sim","") | Z8: =IF(COUNTIF(Q8:Y8,"Sim")<$Q$6,"Sim","")
B9: 1 | C9: 2 | D9: 3 | E9: 4 | F9: 5 | O9: Florestal e madeireira | Q9: =IF(Q8="Sim",COUNTIF(A8:Q8,"Sim"),"") | R9: =IF(R8="Sim",COUNTIF(B8:R8,"Sim"),"") | S9: =IF(S8="Sim",COUNTIF(C8:S8,"Sim"),"") | T9: =IF(T8="Sim",COUNTIF(D8:T8,"Sim"),"") | U9: =IF(U8="Sim",COUNTIF(E8:U8,"Sim"),"") | V9: =IF(V8="Sim",COUNTIF(F8:V8,"Sim"),"") | W9: =IF(W8="Sim",COUNTIF(N8:W8,"Sim"),"") | X9: =IF(X8="Sim",COUNTIF(O8:X8,"Sim"),"") | Y9: =IF(Y8="Sim",COUNTIF(P8:Y8,"Sim"),"") | Z9: =IF(Z8="Sim",COUNTIF(Q8:Z8,"Sim"),"")
O10: Petróleo, Gás e Mineração | Q10: =IFERROR(HLOOKUP(Q9,Q2:Z5,3,FALSE),"") | R10: =IFERROR(HLOOKUP(R9,R2:AA5,3,FALSE),"") | S10: =IFERROR(HLOOKUP(S9,S2:AB5,3,FALSE),"") | T10: =IFERROR(HLOOKUP(T9,T2:AC5,3,FALSE),"") | U10: =IFERROR(HLOOKUP(U9,U2:AD5,3,FALSE),"") | V10: =IFERROR(HLOOKUP(V9,V2:AE5,3,FALSE),"") | W10: =IFERROR(HLOOKUP(W9,W2:AF5,3,FALSE),"") | X10: =IFERROR(HLOOKUP(X9,X2:AG5,3,FALSE),"") | ... Z10: =IFERROR(HLOOKUP(Z9,Z2:AI5,3,FALSE),"")
B11: Base para viabilidade de prospecção | E11: Nicho escolhido | F11: =HLOOKUP('[A finalizar] Posicionamento'!D4,B3:F7,5,FALSE) -> #REF! | O11: Óleo e gás | Q11: =IFERROR(HLOOKUP(Q9,Q2:Z5,4,FALSE),"") | R11: =IFERROR(HLOOKUP(R9,R2:AA5,4,FALSE),"") | S11: =IFERROR(HLOOKUP(S9,S2:AB5,4,FALSE),"") | T11: =IFERROR(HLOOKUP(T9,T2:AC5,4,FALSE),"") | U11: =IFERROR(HLOOKUP(U9,U2:AD5,4,FALSE),"") | V11: =IFERROR(HLOOKUP(V9,V2:AE5,4,FALSE),"") | W11: =IFERROR(HLOOKUP(W9,W2:AF5,4,FALSE),"") | X11: =IFERROR(HLOOKUP(X9,X2:AG5,4,FALSE),"") | ... Z11: =IFERROR(HLOOKUP(Z9,Z2:AI5,4,FALSE),"")
B12: Até score | O12: Extração de petróleo | Q12: =IFERROR(HLOOKUP(Q10,'Análise de Empresas'!$C$7:$L$13,5,FALSE),"") | R12: =IFERROR(HLOOKUP(R10,'Análise de Empresas'!$C$7:$L$13,5,FALSE),"") | S12: =IFERROR(HLOOKUP(S10,'Análise de Empresas'!$C$7:$L$13,5,FALSE),"") | T12: =IFERROR(HLOOKUP(T10,'Análise de Empresas'!$C$7:$L$13,5,FALSE),"") | U12: =IFERROR(HLOOKUP(U10,'Análise de Empresas'!$C$7:$L$13,5,FALSE),"") | V12: =IFERROR(HLOOKUP(V10,'Análise de Empresas'!$C$7:$L$13,5,FALSE),"") | W12: =IFERROR(HLOOKUP(W10,'Análise de Empresas'!$C$7:$L$13,5,FALSE),"") | X12: =IFERROR(HLOOKUP(X10,'Análise de Empresas'!$C$7:$L$13,5,FALSE),"") | ... Z12: =IFERROR(HLOOKUP(Z10,'Análise de Empresas'!$C$7:$L$13,5,FALSE),"")
B13: =B14*0.8 -> 3.072 | C13: inviável | O13: Extração de Gás Natural | Q13: =IFERROR(HLOOKUP(Q10,'Análise de Empresas'!$C$7:$L$13,6,FALSE),"") | R13: =IFERROR(HLOOKUP(R10,'Análise de Empresas'!$C$7:$L$13,6,FALSE),"") | S13: =IFERROR(HLOOKUP(S10,'Análise de Empresas'!$C$7:$L$13,6,FALSE),"") | T13: =IFERROR(HLOOKUP(T10,'Análise de Empresas'!$C$7:$L$13,6,FALSE),"") | U13: =IFERROR(HLOOKUP(U10,'Análise de Empresas'!$C$7:$L$13,6,FALSE),"") | V13: =IFERROR(HLOOKUP(V10,'Análise de Empresas'!$C$7:$L$13,6,FALSE),"") | W13: =IFERROR(HLOOKUP(W10,'Análise de Empresas'!$C$7:$L$13,6,FALSE),"") | X13: =IFERROR(HLOOKUP(X10,'Análise de Empresas'!$C$7:$L$13,6,FALSE),"") | ... Z13: =IFERROR(HLOOKUP(Z10,'Análise de Empresas'!$C$7:$L$13,6,FALSE),"")
B14: =B15*0.8 -> 3.84 | C14: pouco viável | O14: Mineração | Q14: =IFERROR(HLOOKUP(Q10,'Análise de Empresas'!$C$7:$L$13,7,FALSE),"") | R14: =IFERROR(HLOOKUP(R10,'Análise de Empresas'!$C$7:$L$13,7,FALSE),"") | S14: =IFERROR(HLOOKUP(S10,'Análise de Empresas'!$C$7:$L$13,7,FALSE),"") | T14: =IFERROR(HLOOKUP(T10,'Análise de Empresas'!$C$7:$L$13,7,FALSE),"") | U14: =IFERROR(HLOOKUP(U10,'Análise de Empresas'!$C$7:$L$13,7,FALSE),"") | V14: =IFERROR(HLOOKUP(V10,'Análise de Empresas'!$C$7:$L$13,7,FALSE),"") | W14: =IFERROR(HLOOKUP(W10,'Análise de Empresas'!$C$7:$L$13,7,FALSE),"") | X14: =IFERROR(HLOOKUP(X10,'Análise de Empresas'!$C$7:$L$13,7,FALSE),"") | ... Z14: =IFERROR(HLOOKUP(Z10,'Análise de Empresas'!$C$7:$L$13,7,FALSE),"")
B15: =B16*0.8 -> 4.8 | C15: viável | O15: Mineração de carvão | Q15: =Q12&CHAR(10)&Q13&CHAR(10)&Q14 | R15: =R12&CHAR(10)&R13&CHAR(10)&R14 | S15: =S12&CHAR(10)&S13&CHAR(10)&S14 | T15: =T12&CHAR(10)&T13&CHAR(10)&T14
B16: 6 | C16: bastante viável | O16: Mineração de minério de metal
O17: Mineração de minerais não metálicos
B18: Base para persona ideal | O18: Serviços de utilidade pública
B19: Até score | O19: Transmissão, Controle e Distribuição de Energia Elétrica
B20: =B21*0.9 -> 3.78675 | C20: não poderá ser utilizada no | O20: Geração de Energia Elétrica
B21: =B22*0.9 -> 4.2075 | C21: não deve ser utilizada no | O21: Geração de Energia Hidrelétrica
B22: =B23*0.85 -> 4.675 | C22: pode ser utilizada no | O22: Geração de Energia Elétrica com Combustível Fóssil
B23: 5.5 | C23: é ideal para o | O23: Geração de Energia Elétrica Nuclear
O24: Geração de energia elétrica solar
O25: Geração de Energia Eólica
O26: Geração de Energia Elétrica Geotérmica
O27: Geração de Energia Elétrica de Biomassa
O28: Distribuição de Gás Natural
O29: Serviços de Água, Resíduos, Vapor e Ar Condicionado
O30: Sistemas de Abastecimento de Água e Irrigação
B31: Definição de solução para ataque | C31: Score | F31: Peso | O31: Fornecimento de vapor e ar condicionado
B32: Validação do mercado (A solução já foi validada pelo mercado ou é uma nova solução?) | C32: 5 | E32: Diferenciação frente a concorrência (Quais são as vantagens competitivas em relação aos concorrentes diretos e indiretos frente as outras soluções?) | F32: 5 | O32: Recolha de resíduos
B33: 1- Solução é nova e ainda não foi lançada no mercado | C33: 0 | E33: Potencial de tamanho de mercado (Qual o tamanho do mercado que possui fit com a sua solução frente as outras soluções? ) | F33: 3 | O33: Tratamento e Descarte de Resíduos
B34: 2- Solução foi lançada no mercado, mas ainda existem poucos feedbacks quanto a percepção de valor do cliente | C34: 0.6 | E34: Nível da dor atrelada a solução (Qual o impacto e frequência da dor resolvida pela sua solução em relação as outras soluções?) | F34: 4 | O34: Construção
B35: 3- Solução foi lançada no mercado e existem claros feedbacks (positivos e negativos) quanto a percepção de valor do cliente | C35: 1 | E35: Percepção de valor e Resultado obtido (Qual a percepção do seu cliente quanto a valor e resultados obtidos com esta solução frente as outras?) | F35: 3 | O35: Construção civil
O36: Construção de Edifícios Residenciais
O37: Construção de edifícios não residenciais
O38: Engenharia Civil
B39: É vendida como solução de ataque? (É vendida como uma solução de ataque ou é vendida como um upsell/crossell de outras soluções?) | C39: 3 | O39: Construção do Sistema de Utilidade
B40: 1- Solução sempre é vendida como upsell/crossell | C40: 0 | O40: Subdivisão de Terras
...

Sheet Apoio Base IC
A1: Departamento | C1: Setores | D1: Decisores | J1: Classe | M1: Subclasse | N1: Segmento no Linkedin | O1: Descrição | P1: Empresas
A2: Português | B2: Inglês | C2: Administração agrícola | D2: - Nível 1: vice | presidente | owner | propriet | socio (a)| advisor | board | fundador; | J2: Indústria | K2: 1 | L2: Agro indústria1 | M2: Agro indústria | N2: Administração agrícola | O2: Empresas voltadas para tecnologia e investimentos no agronegócio além de usinas e cooperativas | P2: GeSafra, AGRI. Usina Santa Adélia
A3: Contabilidade | B3: Accounting | C3: Administração de serviços | D3: - Nível 2: chief | diretor | head | superintendente | J3: Serviços | K3: 1 | L3: Serviço de tercerização1 | M3: Serviço de tercerização | N3: Administração de serviços | O3: Empresas de gestão de serviços como estacionamentos, infraestrutura etc | P3: Grupo Indigo, Estapar
A4: Contas a Pagar | B4: Accounts Payable | C4: Administração governamental | D4: - Nível 3: coordenador | gerente | J4: Geral | K4: 1 | L4: Instituições Públicas1 | M4: Instituições Públicas | N4: Administração governamental | O4: Empresas com função organizar as instituições públicas | P4: Correios, CAPES, ANEEL
A5: Contas a Receber | B5: Accounts Receivable | C5: Agricultura | D5: - Nível 4: Lider | supervisor | encarregado | J5: Indústria | K5: 2 | L5: Agro indústria2 | M5: Agro indústria | N5: Agricultura | O5: Produtos e serviços agrícolas | P5: Belagricola, Lavoro Agro, Zilor
A6: Administrativo | B6: Administration | C6: Alimentos e bebidas | D6: - Nível 5: analista | especialista | J6: Geral | K6: 1 | L6: Alimentos e bebidas1 | M6: Alimentos e bebidas | N6: Alimentos e bebidas | O6: Produtores e exportadores de alimentos | P6: Ambev, Cacau Show, Marilan
A7: Auditoria | B7: Audit | C7: Animação | J7: Comércio | K7: 1 | L7: Audiovisual1 | M7: Audiovisual | N7: Animação | O7: Produtoras especializadas em animação | P7: Mono Animation, Hype Animation
A8: Desenvolvimento de negócios | B8: Business Development | C8: Armazenagem | J8: Serviços | K8: 1 | L8: Logistica1 | M8: Logistica | N8: Armazenagem | O8: Empresas de inteligência em soluções logísticas para a cadeia de alimentos e agronegócios. | P8: Kepler, Comfrio
A9: Comercial | B9: Commercial | C9: Arquitetura e planejamento | J9: Geral | K9: 1 | L9: Arquitetura/Construção Civil/Imobiliária1 | M9: Arquitetura/Construção Civil/Imobiliária | N9: Arquitetura e planejamento | O9: Empresas especializadas no desenvolvimento de projetos e execução de trabalhos corporativos e comerciais | P9: Jacobsen Arquitetura, Casacor, Yuny Incorporadora
A10: Comunicação | B10: Communication | C10: Arrecadação de recursos | J10: Geral | K10: 1 | L10: ONG's e afins1 | M10: ONG's e afins | N10: Arrecadação de recursos | O10: Empresas de "vaquinhas" | P10: VOAA, Incentiv.me
A11: Controladoria | B11: Controlling | C11: Artes cênicas | J11: Comércio | K11: 2 | L11: Audiovisual2 | M11: Audiovisual | N11: Artes cênicas | O11: Empresas focadas em artes cênicas como grupos de teatros, teatros e escolas teatrais | P11: Cia de Teatro Paranafernália, Escola de Teatro Bolshoi no Brasil, Teatro Porto Seguro
A12: Credit | B12: Crédito | C12: Artes e artesanato | J12: Serviços | K12: 1 | L12: Artes 1 | M12: Artes | N12: Artes e artesanato | O12: Materias artístiscos, ateliers, galerias | P12: Acrilex (tintas) Cicero papelaria
A13: Atendimento ao cliente | B13: Customer Service | C13: Atacado | J13: Comércio | K13: 1 | L13: Comércio1 | M13: Comércio | N13: Atacado | O13: Empresas que vendem no modelo atacado | P13: Assaí Atacadista, Atacadão
A14: Exportação | B14: Exports | C14: Atendimento ao consumidor | J14: Serviços | K14: 1 | L14: Serviços para o público1 | M14: Serviços para o público | N14: Atendimento ao consumidor | O14: Empresas de monitoramento e gestão da satisfação de clientes. | P14: Reclame aqui, Track.co
A15: Financeiro | B15: Finance | C15: Atendimento médico e hospitalar | J15: Serviços | K15: 1 | L15: Saúde1 | M15: Saúde | N15: Atendimento médico e hospitalar | O15: Planos de saúde e hospitais | P15: Amil, Dasa, Hospital Sirio Libanes
A16: Planejamento Financeiro | B16: Financial Planning | C16: Atendimento médico psiquiátrico | J16: Serviços | K16: 2 | L16: Saúde2 | M16: Saúde | N16: Atendimento médico psiquiátrico | O16: Clinicas de psicologia e terapia sexual | P16: Formare Clinica de Psicologia
A17: Recursos Humanos | B17: Human Resources | C17: Atividades parlamentares | J17: Geral | K17: 2 | L17: Instituições Públicas2 | M17: Instituições Públicas | N17: Atividades parlamentares | O17: Organizações do poder legislativo | P17: Senado Federal, Câmara dos Deputados
A18: Importação | B18: Imports | C18: Automação industrial | J18: Indústria | K18: 1 | L18: Indústria de eletrônicos 1 | M18: Indústria de eletrônicos | N18: Automação industrial | O18: Empresas que oferecem soluções de sistemas de automação | P18: Forja Taurus, Lenze, Festo Brasil
... A44: Atacado | B44: Wholesale | C44: Engenharia civil | J44: Geral | K44: 4 | L44: Arquitetura/Construção Civil/Imobiliária4 | M44: Arquitetura/Construção Civil/Imobiliária | N44: Engenharia civil | O44: Construtoras | P44: MRV, Even Construtora
C45: Engenharia mecânica ou industrial | J45: Serviços | K45: 2 | L45: Serviços técnicos2 | M45: Serviços técnicos | N45: Engenharia mecânica ou industrial | O45: Empresas no segmento da construção, montagem e manutenção industrial. | P45: Embraco, Atlas Schindler
C46: Ensino fundamental/médio | J46: Serviços | K46: 3 | L46: Educação e pesquisa3 | M46: Educação e pesquisa | N46: Ensino fundamental/médio | O46: Escolas de ensino fundamental e médio | P46: SAS, Sistema Elite de Ensino
C47: Ensino superior | J47: Serviços | K47: 4 | L47: Educação e pesquisa4 | M47: Educação e pesquisa | N47: Ensino superior | O47: Faculdades públicas e particulares | P47: SENAI, Faculdade Souza Marques
C48: Entrega de encomendas e fretes | J48: Serviços | K48: 2 | L48: Logistica2 | M48: Logistica | N48: Entrega de encomendas e fretes | O48: Transportadoras e empresas de logística | P48: Mobi Logística, Transporte Generoso
C49: Entretenimento | J49: Serviços | K49: 3 | L49: Comunicação3 | M49: Comunicação | N49: Entretenimento | O49: Cinemas, tv a cabo e eventos | P49: HBO, Netflix, Cinemark
C50: Esportes | J50: Serviços | K50: 1 | L50: Bem estar e lazer1 | M50: Bem estar e lazer | N50: Esportes | O50: Comitês e times | P50: Rio 2016, Flamengo, CBF
C51: Execução da lei | J51: Geral | K51: 3 | L51: Instituições Públicas3 | M51: Instituições Públicas | N51: Execução da lei | O51: Orgãos públicos | P51: Polícia Federal, Ministério Público
C52: Filantropia | J52: Geral | K52: 2 | L52: ONG's e afins2 | M52: ONG's e afins | N52: Filantropia | O52: Entidades de assistência social | P52: CIEE, Fundação São Francisco Xavier
C53: Fotografia | J53: Serviços | K53: 5 | L53: Artes 5 | M53: Artes | N53: Fotografia | O53: Fotógrafos e empresas de fotografia e filmagem | P53: Produtora 7, eMania
C54: Gabinete presidencial | J54: Geral | K54: 4 | L54: Instituições Públicas4 | M54: Instituições Públicas | N54: Gabinete presidencial | O54: Assembleias legislativas | P54: G100, Assembleias
C55: Gestão de investimentos | J55: Serviços | K55: 4 | L55: Financeiro4 | M55: Financeiro | N55: Gestão de investimentos | O55: Gestoras de fundos de investimentos | P55: Odebrecht, Votorantim, Bradesco Asset Management
C56: Gestão de organização sem fins lucrativos | J56: Geral | K56: 3 | L56: ONG's e afins3 | M56: ONG's e afins | N56: Gestão de organização sem fins lucrativos | O56: Instituição sem fins lucrativos nas áreas de educação, saúde, cultura, lazer e assistência. | P56: Fundação Estudar, Endeavor, Sesc
... C148: Vinhos e destilados | J148: Indústria | K148: 5 | L148: Indústria pesada5 | M148: Indústria pesada | N148: Vidro, cerâmica e concreto | O148: Fabricantes de materiais de base de vidro, cerâmica e concreto | P148: Cebrace, Incepa, Saint Gobain
J149: Geral | K149: 3 | L149: Alimentos e bebidas3 | M149: Alimentos e bebidas | N149: Vinhos e destilados | O149: Importadoras e distribuidoraa especializadas em vinhos | P149: Wine.com.br , Vinícola Salton
