Workbook

Sheet 0- METAS DE CONVERSÕES
A1: ORÇAMENTO DO FUNIL 1 | D1: FATURAMENTO ACEITAVEL | J1: FATURAMENTO BASEADO NA ESTRATÉGIA AMERICANA
A2: Orçamento dia | B2: 66.7 | D2: Meta % aplicações | E2: 0.1 | J2: Meta % Qualificação | K2: 0.2
A3: orçamento total do seu próximo lançamento | B3: =B2*30 -> 2001 | D3: Meta Nº de aplicações | E3: =B5*E2 -> 63.043478 | J3: Meta Nº de Qualificação | K3: =B5*K2 -> 126.08696
A4: Meta de custo por lead | B4: 3.174
A5: Meta de leads prospectados | B5: =B3/B4 -> 630.43478 | D5: Meta % conversão | E5: 0.1 | J5: Meta % Calls | K5: 0.7
A6: Meta % respostas | B6: 0.3 | D6: Meta Nº de converções | E6: =ROUND(F6,0) -> 6 | F6: =E3*E5 -> 6.3043478 | J6: Meta de Calll's realizadas | K6: =ROUND(L6,0) -> 88 | L6: =K5*K3 -> 88.26087
A7: Meta Nº de respostas [ETAPA1] | B7: =B5*B6 -> 189.13043
A8: Meta % agendamentos | B8: 0.15 | D8: Preço do produto de entrada | E8: 3497 | J8: Meta % conversão | K8: 0.3
A9: Meta Nº de agendamentos | B9: =ROUND(C9,0) -> 28 | C9: =B7*B8 -> 28.369565 | D9: Meta faturamento | E9: =E6*E8 -> 20982 | J9: Meta Nº de converções | K9: =ROUND(L9,0) -> 26 | L9: =K6*K8 -> 26.4
A10: Meta % calls realizadas | B10: 0.5
A11: Meta Nº de calls realizadas | B11: =B9*B10 -> 14
A12: Meta % de converções | B12: 0.1 | D12: Meta faturamento + order bump + upsell | E12: =E9*1.2 -> 25178.4
A13: Meta Nº de converções | B13: =B11*B12 -> 1.4
A14: Preço do Produto de entrada | B14: 12000
A15: Meta faturamento aceitável | B15: =B13*B14 -> 16800 | D15: FATURAMENTO ÓTIMO | J15: Preço do produto de entrada | K15: 6000
A16: Meta faturamento + order bump + upsell | B16: =B15*1.2 -> 20160 | D16: Meta % aplicações | E16: 0.15 | J16: Meta faturamento | K16: =K9*K15 -> 156000
D17: Meta Nº de aplicações | E17: =B5*E16 -> 94.565217 | J17: Meta faturamento + order bump + upsell | K17: =K16*1.2 -> 187200
D19: Meta % conversão | E19: 0.1
D20: Meta Nº de converções | E20: =ROUND(F20,0) -> 9 | F20: =E17*E19 -> 9.4565217
H21: CRIAR ANÚNCIO - PROBLEMA/ ROTA/ SOLUÇÃO
D22: Preço do produto de entrada | E22: 3497 | H22: https://chat.openai.com/c/588b4f4f-5cb8-42c9-a210-fc446d7de038
A23: 1 ada 10% | D23: Meta faturamento | E23: =E20*E22 -> 31473
D24: Meta faturamento + order bump + upsell | E24: =E23*1.2 -> 37767.6
D26: FATURAMENTO EXCELENTE
D27: Meta % aplicações | E27: 0.2
D28: Meta Nº de aplicações | E28: =B5*E27 -> 126.08696
D30: Meta % conversão | E30: 0.1
D31: Meta Nº de converções | E31: =ROUND(F31,0) -> 13 | F31: =E28*E30 -> 12.608696
D33: Preço do produto de entrada | E33: 3497
D34: Meta faturamento | E34: =E31*E33 -> 45461
D35: Meta faturamento + order bump + upsell | E35: =E34*1.2 -> 54553.2

Sheet 1 - INÍCIO - PLANEJEMANTO VERBA
A1: ORÇAMENTO DO EVENTO | D1: FATURAMENTO ACEITAVEL | F1: PLANILHA 2
A2: orçamento total do seu próximo lançamento | B2: 1500 | D2: meta % comparecimento | E2: 1 | F2: Orçamento dia | G2: 50
A4: % de investimento em remarketing - Distribuilção | B4: 0.3 | D4: meta lista de comparecimento | E4: =B11*E2 -> 75 | F4: Orçamento total do seu perpétuo | G4: =G2*30 -> 1500
A5: % de investimento em lead no perpétuo - Captação | B5: 0.8 | F5: Meta de custo por lead | G5: 6
A6: % de investimento em raiz/nutella - Nutrição | B6: 0 | D6: meta % conversão | E6: 0.05 | F6: Meta de leads | G6: =G4/G5 -> 250
A7: % de investimento em remarketing - Captação | B7: 0.2 | D7: meta conversão | E7: =E4*E6 -> 3.75 | F7: Meta % aplicações | G7: 0.06
F8: Meta Nº de aplicações | G8: =G6*G7 -> 15
A9: total de investimento em lead | B9: =B2*B5 -> 1200 | D9: preço do produto principal | E9: 3497 | F9: Meta % conversão | G9: 0.3
A10: meta de custo por lead | B10: 20 | D10: meta faturamento | E10: =E7*E9 -> 13113.75 | F10: Meta Nº de converções | G10: =G8*G9 -> 4.5
A11: meta de leads | B11: 75 | D11: meta faturamento + order bump + upsell | E11: =E10*1.2 -> 15736.5 | F11: Preço do Produto de entrada | G11: 2497
F12: Meta faturamento aceitável | G12: =G10*G11 -> 11236.5
A13: total de investimento em raiz/nutella (até lançamento) | B13: =B2*B6 -> 0 | D13: FATURAMENTO ÓTIMO | F13: Meta faturamento + order bump + upsell | G13: =G12*1.2 -> 13483.8
A14: quantidade de raiz/nutella (até lançamento) | D14: meta % comparecimento | E14: 1
A15: quanto impulsionar por vídeo (durante 7 dias) | B15: 0 | D15: meta lista de comparecimento | E15: =B11*E14 -> 75
A17: total de investimento em remarketing | B17: =B2*B7 -> 300 | D17: meta % conversão | E17: 0.01
D18: meta conversão | E18: =E15*E17 -> 0.75
A19: ORÇAMENTO REMARKETING
A20: orçamento total do seu próximo lançamento | B20: =B17 -> 300 | D20: preço do produto principal | E20: 1997
D21: meta faturamento | E21: =E18*E20 -> 1497.75
A22: Aquecimento | B22: 0 | D22: meta faturamento + order bump + upsell | E22: =E21*1.2 -> 1797.3
A23: Antecipação | B23: 0
A24: Cpls/Lives | B24: 0 | D24: FATURAMENTO EXCELENTE
A25: Carrinho aberto | B25: 0 | D25: meta % comparecimento | E25: 1
D26: meta lista de comparecimento | E26: =B11*E25 -> 75
A27: Aquecimento | B27: =B20*B22 -> 0
A28: Antecipação | B28: =B23*B20 -> 0 | D28: meta % conversão | E28: 0.02
A29: Cpl | B29: =B20*B24 -> 0 | D29: meta conversão | E29: =E26*E28 -> 1.5
A30: Carrinho aberto | B30: =B20*B25 -> 0
D31: preço do produto principal | E31: 1997
A32: CPL | D32: meta faturamento | E32: =E29*E31 -> 2995.5
A33: orçamento total do Evento Principal | B33: =B29 -> 0 | D33: meta faturamento + order bump + upsell | E33: =E32*1.2 -> 3594.6
A35: CPL 01 | B35: 0
A36: CPL 02 | B36: 0
A37: CPL 03 | B37: 0
A38: CPL 04 | B38: 0
A40: CPL 01 | B40: =B33*B35 -> 0
A41: CPL 02 | B41: =B36*B33 -> 0
A42: CPL 03 | B42: =B33*B37 -> 0
A43: CPL 04 | B43: =B33*B38 -> 0

Sheet RESULTADOS DIRETOS
B3: LEADS CAPTADOS | D3: LEADS DENTRO | F3: VALOR GASTO
B4: DENTRO DAS BM's | D4: DO ACTIVE | F4: TOTAL
B5: ='RESULTADOS MACROS'!C17 -> 17 | D5: ='RESULTADOS MACROS'!C31 -> 17 | F5: =F9+F13 -> 265.67
B8: QUENTE | D8: ADS | F8: CAPTAÇÃO
B9: ='RESULTADOS MACROS'!C20 -> 0 | D9: =B5 -> 17 | F9: ='RESULTADOS MACROS'!E17 -> 265.67
B12: FRIO | D12: ORG TOTAL | F12: RMKT
B13: ='RESULTADOS MACROS'!C21 -> 17 | F13: ='RESULTADOS MACROS'!I17 -> 0

Sheet RESULTADOS MACROS
B2: CAPTAÇÃO | G2: REMARKETING
B7: FONTES | C7: LEADS | D7: CUSTO P/ LEAD (CPL) | E7: VALOR | G7: FONTES | H7: VALOR PRA GASTAR | I7: VALOR GASTO
B9: [AUTO] [QUENTE] | C9: ='AUTO - QUENTE'!G38 -> 0 | D9: =E9/C9 -> #DIV/0! | E9: ='AUTO - QUENTE'!J38 -> 0 | G9: AQUECIMENTO | H9: ='1 - INÍCIO - PLANEJEMANTO VERBA'!B27 -> 0 | I9: =AQUECIMENTOANTECIPACAO!B39 -> 0
B10: [AUTO] [FRIO] | C10: ='AUTO - FRIO'!G38 -> 0 | D10: =E10/C10 -> #DIV/0! | E10: ='AUTO - FRIO'!J38 -> 0
B11: [FACE] [QUENTE] | C11: ='FACE - QUENTE'!G38 -> 0 | D11: =E11/C11 -> #DIV/0! | E11: ='FACE - QUENTE'!J38 -> 0 | G11: ANTECIPAÇÃO | H11: ='1 - INÍCIO - PLANEJEMANTO VERBA'!B28 -> 0 | I11: =AQUECIMENTOANTECIPACAO!G39 -> 0
B12: [FACE] [FRIO] | C12: ='FACE - FRIO'!G38 -> 0 | D12: =E12/C12 -> #DIV/0! | E12: ='FACE - FRIO'!J38 -> 0
B13: [INSTA] [QUENTE] | C13: ='INSTA - QUENTE'!G38 -> 0 | D13: =E13/C13 -> #DIV/0! | E13: ='INSTA - QUENTE'!J38 -> 0 | G13: LIVES/CPLS | H13: ='1 - INÍCIO - PLANEJEMANTO VERBA'!B29 -> 0 | I13: 0
B14: [INSTA] [FRIO] | C14: ='INSTA - FRIO'!G38 -> 17 | D14: =E14/C14 -> 15.627647 | E14: ='INSTA - FRIO'!J38 -> 265.67
B15: GOOGLE - QUENTE | C15: ='GOOGLE - QUENTE'!G38 -> 0 | D15: =E15/C15 -> #DIV/0! | E15: ='GOOGLE - QUENTE'!J38 -> 0 | G15: ABERTURA DE CARRINHO | H15: ='1 - INÍCIO - PLANEJEMANTO VERBA'!B30 -> 0 | I15: 0
B16: GOOGLE - FRIO | C16: ='GOOGLE - FRIO'!G38 -> 0 | D16: =E16/C16 -> #DIV/0! | E16: ='GOOGLE - FRIO'!J38 -> 0
B17: TOTAL | C17: =SUM(C9:C16) -> 17 | D17: =E17/C17 -> 15.627647 | E17: =SUM(E9:E16) -> 265.67 | G17: TOTAL | H17: =SUM(H9:H16) -> 0 | I17: =SUM(I9:I16) -> 0
B19: LEADS CAPTADOS | D19: CUSTO POR LEAD | E19: GASTO
B20: QUENTE | C20: =C11+C13+C9+C15 -> 0 | D20: =E20/C20 -> #DIV/0! | E20: =E9+E10+E11+E16 -> 0 | G20: REMARKETING | H20: GASTO TOTAL
B21: FRIO | C21: =C10+C12+C16+C14 -> 17 | D21: =E21/C21 -> 15.627647 | E21: =E12+E13+E14+E15 -> 265.67 | G21: AQUECIMENTO FB | H21: =AQUECIMENTOANTECIPACAO!B38 -> 0
G22: AQUECIMENTO GOOGLE | H22: =AQUECIMENTOANTECIPACAO!D38 -> 0
B23: META | E23: CAPTADOS | G23: ANTECIPAÇÃO FB | H23: =AQUECIMENTOANTECIPACAO!G38 -> 0 | I23: VALOR PRA GASTAR: | J23: ='1 - INÍCIO - PLANEJEMANTO VERBA'!B40 -> 0 | K23: ='1 - INÍCIO - PLANEJEMANTO VERBA'!B41 -> 0 | L23: ='1 - INÍCIO - PLANEJEMANTO VERBA'!B42 -> 0 | M23: ='1 - INÍCIO - PLANEJEMANTO VERBA'!B43 -> 0
B24: QUENTE | C24: 0 | D24: QUENTES | E24: =C20 -> 0 | G24: ANTECIPAÇÃO GOOGLE | H24: =AQUECIMENTOANTECIPACAO!I38 -> 0 | J24: CPL 1 | K24: CPL 2 | L24: CPL 3 | M24: CPL 4
B25: FRIO | C25: 75 | D25: FRIOS | E25: =C21 -> 17 | G25: LIVES/CPLS FB | H25: =J25+K25+L25+M25 -> 0 | I25: GASTO FB
G26: LIVES/CPLS GOOGLE | H26: =J26+K26+L26+M26 -> 0 | I26: GASTO GG
B27: FALTA PARA A META QUENTE | C27: =C24-C20 -> 0 | G27: ABERTURA DE CARRINHO FB | I27: VALOR GASTO TOTAL: | J27: =J25+J26 -> 0 | K27: =K25+K26 -> 0 | L27: =L25+L26 -> 0 | M27: =M25+M26 -> 0
B28: FALTA PARA A META FRIO | C28: =C25-C21 -> 58 | G28: ABERTURA DE CARRINHO GOOGLE
G29: TOTAL RMKT | H29: =SUM(H21:H28) -> 0
B30: RESULTADOS REAIS
B31: LEADS CAPTADOS | C31: =C17 -> 17 | G31: TOTAL GASTO RMKT
B32: GASTO TOTAL | C32: =E17 -> 265.67
B33: % DA VERBA GASTA | C33: =C32/C42 -> 0.13276862
B34: % DOS LEADS ALCANÇADOS | C34: =C31/'0- METAS DE CONVERSÕES'!B5 -> 0.026965517
B35: % DIFERENÇA DA % | C35: =C33-C34 -> 0.1058031
B36: PREÇO POR LEAD GERAL | C36: =C32/C31 -> 15.627647
B37: DATA DE HOJE | C37: 45331
B38: DATA FINAL | C38: 45351
B39: QUANTOS DIAS FALTAM | C39: =C38-C37 -> 20
B40: QUANTO FALTA PARA A META? | C40: ='0- METAS DE CONVERSÕES'!B5-C31 -> 613.43478
B41: LEADS/DIA PARA A META | C41: =C40/C39 -> 30.671739
B42: VERBA TOTAL | C42: ='0- METAS DE CONVERSÕES'!B3 -> 2001
B43: VERBA RESTANTE | C43: =C42-C32 -> 1735.33
B44: GASTO DIARIO NECESSARIO | C44: =C43/C39 -> 86.7665
B45: CUSTO LEAD PARA A META | C45: =C43/C40 -> 2.8288745
B65: DATA INÍCIO | C65: 44229
B66: TOTAIS DE DIAS | C66: =C38-C65 -> 1122
...

Sheet GERALZÃO - CAPTACAO
A1: DIA | B1: IMPRESSÕES | C1: CTR % | D1: CLIQUE NO LINK | E1: VISUALIZAÇÃO DE PÁGINA | F1: PORCETAGEM DE VIEW PAGES | G1: NÚMERO DE LEADS | H1: CONVERSÃO EM LEADS | I1: CUSTO POR LEAD | J1: VALOR GASTO
A2: 44410 | B2: ='AUTO - QUENTE'!B2+'AUTO - FRIO'!B2+'FACE - QUENTE'!B2+'FACE - FRIO'!B2+'INSTA - QUENTE'!B2+'INSTA - FRIO'!B2+'GOOGLE - QUENTE'!B2+'GOOGLE - FRIO'!B2 -> 0 | C2: ='AUTO - QUENTE'!C2+'AUTO - FRIO'!C2+'FACE - QUENTE'!C2+'FACE - FRIO'!C2+'INSTA - QUENTE'!C2+'INSTA - FRIO'!C2+'GOOGLE - QUENTE'!C2+'GOOGLE - FRIO'!C2 -> 0 | D2: ='AUTO - QUENTE'!D2+'AUTO - FRIO'!D2+'FACE - QUENTE'!D2+'FACE - FRIO'!D2+'INSTA - QUENTE'!D2+'INSTA - FRIO'!D2+'GOOGLE - QUENTE'!D2+'GOOGLE - FRIO'!D2 -> 0 | E2: ='AUTO - QUENTE'!E2+'AUTO - FRIO'!E2+'FACE - QUENTE'!E2+'FACE - FRIO'!E2+'INSTA - QUENTE'!E2+'INSTA - FRIO'!E2+'GOOGLE - QUENTE'!E2+'GOOGLE - FRIO'!E2 -> 0 | F2: ='AUTO - QUENTE'!F2+'AUTO - FRIO'!F2+'FACE - QUENTE'!F2+'FACE - FRIO'!F2+'INSTA - QUENTE'!F2+'INSTA - FRIO'!F2+'GOOGLE - QUENTE'!F2+'GOOGLE - FRIO'!F2 -> #DIV/0! | G2: ='AUTO - QUENTE'!G2+'AUTO - FRIO'!G2+'FACE - QUENTE'!G2+'FACE - FRIO'!G2+'INSTA - QUENTE'!G2+'INSTA - FRIO'!G2+'GOOGLE - QUENTE'!G2+'GOOGLE - FRIO'!G2 -> 0 | H2: ='AUTO - QUENTE'!H2+'AUTO - FRIO'!H2+'FACE - QUENTE'!H2+'FACE - FRIO'!H2+'INSTA - QUENTE'!H2+'INSTA - FRIO'!H2+'GOOGLE - QUENTE'!H2+'GOOGLE - FRIO'!H2 -> #DIV/0! | I2: =J2/G2 -> #DIV/0! | J2: ='AUTO - QUENTE'!J2+'AUTO - FRIO'!J2+'FACE - QUENTE'!J2+'FACE - FRIO'!J2+'INSTA - QUENTE'!J2+'INSTA - FRIO'!J2+'GOOGLE - QUENTE'!J2+'GOOGLE - FRIO'!J2 -> 0
A3: 44411 | B3: ='AUTO - QUENTE'!B3+'AUTO - FRIO'!B3+'FACE - QUENTE'!B3+'FACE - FRIO'!B3+'INSTA - QUENTE'!B3+'INSTA - FRIO'!B3+'GOOGLE - QUENTE'!B3+'GOOGLE - FRIO'!B3 -> 0 | C3: ='AUTO - QUENTE'!C3+'[AUTO] - [FRIO]'!C3+'FACE - QUENTE'!C3+'FACE - FRIO'!C3+'INSTA - QUENTE'!C3+'INSTA - FRIO'!C3+'GOOGLE - QUENTE'!C3+'GOOGLE - FRIO'!C3 -> #REF! | D3: ='AUTO - QUENTE'!D3+'AUTO - FRIO'!D3+'FACE - QUENTE'!D3+'FACE - FRIO'!D3+'INSTA - QUENTE'!D3+'INSTA - FRIO'!D3+'GOOGLE - QUENTE'!D3+'GOOGLE - FRIO'!D3 -> 0 | E3: ='AUTO - [QUENTE]'!E3+'AUTO - QUENTE'!E3+'INSTA - [QUENTE]'!E3 -> #REF! | F3: =E3/D3 -> #REF! | G3: ='AUTO - QUENTE'!G3+'AUTO - FRIO'!G3+'FACE - QUENTE'!G3+'FACE - FRIO'!G3+'INSTA - QUENTE'!G3+'INSTA - FRIO'!G3+'GOOGLE - QUENTE'!G3+'GOOGLE - FRIO'!G3 -> 0 | H3: =G3/E3 -> #REF! | I3: =J3/G3 -> #DIV/0! | J3: ='AUTO - QUENTE'!J3+'AUTO - FRIO'!J3+'FACE - QUENTE'!J3+'FACE - FRIO'!J3+'INSTA - QUENTE'!J3+'INSTA - FRIO'!J3+'GOOGLE - QUENTE'!J3+'GOOGLE - FRIO'!J3 -> 0
A4: 44412 | B4: ='AUTO - QUENTE'!B4+'AUTO - FRIO'!B4+'FACE - QUENTE'!B4+'FACE - FRIO'!B4+'INSTA - QUENTE'!B4+'INSTA - FRIO'!B4+'GOOGLE - QUENTE'!B4+'GOOGLE - FRIO'!B4 -> 0 | C4: ='AUTO - QUENTE'!C4+'[AUTO] - [FRIO]'!C4+'FACE - QUENTE'!C4+'FACE - FRIO'!C4+'INSTA - QUENTE'!C4+'INSTA - FRIO'!C4+'GOOGLE - QUENTE'!C4+'GOOGLE - FRIO'!C4 -> #REF! | D4: ='AUTO - QUENTE'!D4+'AUTO - FRIO'!D4+'FACE - QUENTE'!D4+'FACE - FRIO'!D4+'INSTA - QUENTE'!D4+'INSTA - FRIO'!D4+'GOOGLE - QUENTE'!D4+'GOOGLE - FRIO'!D4 -> 0 | E4: ='AUTO - [QUENTE]'!E4+'AUTO - QUENTE'!E4+'INSTA - [QUENTE]'!E4 -> #REF! | F4: =E4/D4 -> #REF! | G4: ='AUTO - QUENTE'!G4+'AUTO - FRIO'!G4+'FACE - QUENTE'!G4+'FACE - FRIO'!G4+'INSTA - QUENTE'!G4+'INSTA - FRIO'!G4+'GOOGLE - QUENTE'!G4+'GOOGLE - FRIO'!G4 -> 0 | H4: =G4/E4 -> #REF! | I4: =J4/G4 -> #DIV/0! | J4: ='AUTO - QUENTE'!J4+'AUTO - FRIO'!J4+'FACE - QUENTE'!J4+'FACE - FRIO'!J4+'INSTA - QUENTE'!J4+'INSTA - FRIO'!J4+'GOOGLE - QUENTE'!J4+'GOOGLE - FRIO'!J4 -> 0
A5: 44413 | B5: ='AUTO - QUENTE'!B5+'AUTO - FRIO'!B5+'FACE - QUENTE'!B5+'FACE - FRIO'!B5+'INSTA - QUENTE'!B5+'INSTA - FRIO'!B5+'GOOGLE - QUENTE'!B5+'GOOGLE - FRIO'!B5 -> 5441 | C5: ='AUTO - QUENTE'!C5+'[AUTO] - [FRIO]'!C5+'FACE - QUENTE'!C5+'FACE - FRIO'!C5+'INSTA - QUENTE'!C5+'INSTA - FRIO'!C5+'GOOGLE - QUENTE'!C5+'GOOGLE - FRIO'!C5 -> #REF! | D5: ='AUTO - QUENTE'!D5+'AUTO - FRIO'!D5+'FACE - QUENTE'!D5+'FACE - FRIO'!D5+'INSTA - QUENTE'!D5+'INSTA - FRIO'!D5+'GOOGLE - QUENTE'!D5+'GOOGLE - FRIO'!D5 -> 11 | E5: ='AUTO - [QUENTE]'!E5+'AUTO - QUENTE'!E5+'INSTA - [QUENTE]'!E5 -> #REF! | F5: =E5/D5 -> #REF! | G5: ='AUTO - QUENTE'!G5+'AUTO - FRIO'!G5+'FACE - QUENTE'!G5+'FACE - FRIO'!G5+'INSTA - QUENTE'!G5+'INSTA - FRIO'!G5+'GOOGLE - QUENTE'!G5+'GOOGLE - FRIO'!G5 -> 2 | H5: =G5/E5 -> #REF! | I5: =J5/G5 -> 17.005 | J5: ='AUTO - QUENTE'!J5+'AUTO - FRIO'!J5+'FACE - QUENTE'!J5+'FACE - FRIO'!J5+'INSTA - QUENTE'!J5+'INSTA - FRIO'!J5+'GOOGLE - QUENTE'!J5+'GOOGLE - FRIO'!J5 -> 34.01
A6: 44414 | B6: ='AUTO - QUENTE'!B6+'AUTO - FRIO'!B6+'FACE - QUENTE'!B6+'FACE - FRIO'!B6+'INSTA - QUENTE'!B6+'INSTA - FRIO'!B6+'GOOGLE - QUENTE'!B6+'GOOGLE - FRIO'!B6 -> 4933 | C6: ='AUTO - QUENTE'!C6+'[AUTO] - [FRIO]'!C6+'FACE - QUENTE'!C6+'FACE - FRIO'!C6+'INSTA - QUENTE'!C6+'INSTA - FRIO'!C6+'GOOGLE - QUENTE'!C6+'GOOGLE - FRIO'!C6 -> #REF! | D6: ='AUTO - QUENTE'!D6+'AUTO - FRIO'!D6+'FACE - QUENTE'!D6+'FACE - FRIO'!D6+'INSTA - QUENTE'!D6+'INSTA - FRIO'!D6+'GOOGLE - QUENTE'!D6+'GOOGLE - FRIO'!D6 -> 11 | E6: ='AUTO - [QUENTE]'!E6+'AUTO - QUENTE'!E6+'INSTA - [QUENTE]'!E6 -> #REF! | F6: =E6/D6 -> #REF! | G6: ='AUTO - QUENTE'!G6+'AUTO - FRIO'!G6+'FACE - QUENTE'!G6+'FACE - FRIO'!G6+'INSTA - QUENTE'!G6+'INSTA - FRIO'!G6+'GOOGLE - QUENTE'!G6+'GOOGLE - FRIO'!G6 -> 5 | H6: =G6/E6 -> #REF! | I6: =J6/G6 -> 13.076 | J6: ='AUTO - QUENTE'!J6+'AUTO - FRIO'!J6+'FACE - QUENTE'!J6+'FACE - FRIO'!J6+'INSTA - QUENTE'!J6+'INSTA - FRIO'!J6+'GOOGLE - QUENTE'!J6+'GOOGLE - FRIO'!J6 -> 65.38
A7: 44415 | B7: ='AUTO - QUENTE'!B7+'AUTO - FRIO'!B7+'FACE - QUENTE'!B7+'FACE - FRIO'!B7+'INSTA - QUENTE'!B7+'INSTA - FRIO'!B7+'GOOGLE - QUENTE'!B7+'GOOGLE - FRIO'!B7 -> 6078 | C7: ='AUTO - QUENTE'!C7+'[AUTO] - [FRIO]'!C7+'FACE - QUENTE'!C7+'FACE - FRIO'!C7+'INSTA - QUENTE'!C7+'INSTA - FRIO'!C7+'GOOGLE - QUENTE'!C7+'GOOGLE - FRIO'!C7 -> #REF! | D7: ='AUTO - QUENTE'!D7+'AUTO - FRIO'!D7+'FACE - QUENTE'!D7+'FACE - FRIO'!D7+'INSTA - QUENTE'!D7+'INSTA - FRIO'!D7+'GOOGLE - QUENTE'!D7+'GOOGLE - FRIO'!D7 -> 29 | E7: ='AUTO - [QUENTE]'!E7+'AUTO - QUENTE'!E7+'INSTA - [QUENTE]'!E7 -> #REF! | F7: =E7/D7 -> #REF! | G7: ='AUTO - QUENTE'!G7+'AUTO - FRIO'!G7+'FACE - QUENTE'!G7+'FACE - FRIO'!G7+'INSTA - QUENTE'!G7+'INSTA - FRIO'!G7+'GOOGLE - QUENTE'!G7+'GOOGLE - FRIO'!G7 -> 4 | H7: =G7/E7 -> #REF! | I7: =J7/G7 -> 17.1925 | J7: ='AUTO - QUENTE'!J7+'AUTO - FRIO'!J7+'FACE - QUENTE'!J7+'FACE - FRIO'!J7+'INSTA - QUENTE'!J7+'INSTA - FRIO'!J7+'GOOGLE - QUENTE'!J7+'GOOGLE - FRIO'!J7 -> 68.77
A8: 44416 | B8: ='AUTO - QUENTE'!B8+'AUTO - FRIO'!B8+'FACE - QUENTE'!B8+'FACE - FRIO'!B8+'INSTA - QUENTE'!B8+'INSTA - FRIO'!B8+'GOOGLE - QUENTE'!B8+'GOOGLE - FRIO'!B8 -> 3151 | C8: ='AUTO - QUENTE'!C8+'[AUTO] - [FRIO]'!C8+'FACE - QUENTE'!C8+'FACE - FRIO'!C8+'INSTA - QUENTE'!C8+'INSTA - FRIO'!C8+'GOOGLE - QUENTE'!C8+'GOOGLE - FRIO'!C8 -> #REF! | D8: ='AUTO - QUENTE'!D8+'AUTO - FRIO'!D8+'FACE - QUENTE'!D8+'FACE - FRIO'!D8+'INSTA - QUENTE'!D8+'INSTA - FRIO'!D8+'GOOGLE - QUENTE'!D8+'GOOGLE - FRIO'!D8 -> 13 | E8: ='AUTO - [QUENTE]'!E8+'AUTO - QUENTE'!E8+'INSTA - [QUENTE]'!E8 -> #REF! | F8: =E8/D8 -> #REF! | G8: ='AUTO - QUENTE'!G8+'AUTO - FRIO'!G8+'FACE - QUENTE'!G8+'FACE - FRIO'!G8+'INSTA - QUENTE'!G8+'INSTA - FRIO'!G8+'GOOGLE - QUENTE'!G8+'GOOGLE - FRIO'!G8 -> 4 | H8: =G8/E8 -> #REF! | I8: =J8/G8 -> 17.12 | J8: ='AUTO - QUENTE'!J8+'AUTO - FRIO'!J8+'FACE - QUENTE'!J8+'FACE - FRIO'!J8+'INSTA - QUENTE'!J8+'INSTA - FRIO'!J8+'GOOGLE - QUENTE'!J8+'GOOGLE - FRIO'!J8 -> 68.48
A9: 44417 | B9: ='AUTO - QUENTE'!B9+'AUTO - FRIO'!B9+'FACE - QUENTE'!B9+'FACE - FRIO'!B9+'INSTA - QUENTE'!B9+'INSTA - FRIO'!B9+'GOOGLE - QUENTE'!B9+'GOOGLE - FRIO'!B9 -> 566 | C9: ='AUTO - QUENTE'!C9+'[AUTO] - [FRIO]'!C9+'FACE - QUENTE'!C9+'FACE - FRIO'!C9+'INSTA - QUENTE'!C9+'INSTA - FRIO'!C9+'GOOGLE - QUENTE'!C9+'GOOGLE - FRIO'!C9 -> #REF! | D9: ='AUTO - QUENTE'!D9+'AUTO - FRIO'!D9+'FACE - QUENTE'!D9+'FACE - FRIO'!D9+'INSTA - QUENTE'!D9+'INSTA - FRIO'!D9+'GOOGLE - QUENTE'!D9+'GOOGLE - FRIO'!D9 -> 11 | E9: ='AUTO - [QUENTE]'!E9+'AUTO - QUENTE'!E9+'INSTA - [QUENTE]'!E9 -> #REF! | F9: =E9/D9 -> #REF! | G9: ='AUTO - QUENTE'!G9+'AUTO - FRIO'!G9+'FACE - QUENTE'!G9+'FACE - FRIO'!G9+'INSTA - QUENTE'!G9+'INSTA - FRIO'!G9+'GOOGLE - QUENTE'!G9+'GOOGLE - FRIO'!G9 -> 2 | H9: =G9/E9 -> #REF! | I9: =J9/G9 -> 14.515 | J9: ='AUTO - QUENTE'!J9+'AUTO - FRIO'!J9+'FACE - QUENTE'!J9+'FACE - FRIO'!J9+'INSTA - QUENTE'!J9+'INSTA - FRIO'!J9+'GOOGLE - QUENTE'!J9+'GOOGLE - FRIO'!J9 -> 29.03
A10: 44418 | B10: ='AUTO - QUENTE'!B10+'AUTO - FRIO'!B10+'FACE - QUENTE'!B10+'FACE - FRIO'!B10+'INSTA - QUENTE'!B10+'INSTA - FRIO'!B10+'GOOGLE - QUENTE'!B10+'GOOGLE - FRIO'!B10 -> 0 | D10: ='AUTO - QUENTE'!D10+'AUTO - FRIO'!D10+'FACE - QUENTE'!D10+'FACE - FRIO'!D10+'INSTA - QUENTE'!D10+'INSTA - FRIO'!D10+'GOOGLE - QUENTE'!D10+'GOOGLE - FRIO'!D10 -> 0 | G10: ='AUTO - QUENTE'!G10+'AUTO - FRIO'!G10+'FACE - QUENTE'!G10+'FACE - FRIO'!G10+'INSTA - QUENTE'!G10+'INSTA - FRIO'!G10+'GOOGLE - QUENTE'!G10+'GOOGLE - FRIO'!G10 -> 0 | I10: =J10/G10 -> #DIV/0! | J10: ='AUTO - QUENTE'!J10+'AUTO - FRIO'!J10+'FACE - QUENTE'!J10+'FACE - FRIO'!J10+'INSTA - QUENTE'!J10+'INSTA - FRIO'!J10+'GOOGLE - QUENTE'!J10+'GOOGLE - FRIO'!J10 -> 0
A11: 44419 | B11: ='AUTO - QUENTE'!B11+'AUTO - FRIO'!B11+'FACE - QUENTE'!B11+'FACE - FRIO'!B11+'INSTA - QUENTE'!B11+'INSTA - FRIO'!B11+'GOOGLE - QUENTE'!B11+'GOOGLE - FRIO'!B11 -> 0 | D11: ='AUTO - QUENTE'!D11+'AUTO - FRIO'!D11+'FACE - QUENTE'!D11+'FACE - FRIO'!D11+'INSTA - QUENTE'!D11+'INSTA - FRIO'!D11+'GOOGLE - QUENTE'!D11+'GOOGLE - FRIO'!D11 -> 0 | G11: ='AUTO - QUENTE'!G11+'AUTO - FRIO'!G11+'FACE - QUENTE'!G11+'FACE - FRIO'!G11+'INSTA - QUENTE'!G11+'INSTA - FRIO'!G11+'GOOGLE - QUENTE'!G11+'GOOGLE - FRIO'!G11 -> 0 | I11: =J11/G11 -> #DIV/0! | J11: ='AUTO - QUENTE'!J11+'AUTO - FRIO'!J11+'FACE - QUENTE'!J11+'FACE - FRIO'!J11+'INSTA - QUENTE'!J11+'INSTA - FRIO'!J11+'GOOGLE - QUENTE'!J11+'GOOGLE - FRIO'!J11 -> 0
A12: 44420 | B12: ='AUTO - QUENTE'!B12+'AUTO - FRIO'!B12+'FACE - QUENTE'!B12+'FACE - FRIO'!B12+'INSTA - QUENTE'!B12+'INSTA - FRIO'!B12+'GOOGLE - QUENTE'!B12+'GOOGLE - FRIO'!B12 -> 0 | D12: ='AUTO - QUENTE'!D12+'AUTO - FRIO'!D12+'FACE - QUENTE'!D12+'FACE - FRIO'!D12+'INSTA - QUENTE'!D12+'INSTA - FRIO'!D12+'GOOGLE - QUENTE'!D12+'GOOGLE - FRIO'!D12 -> 0 | G12: ='AUTO - QUENTE'!G12+'AUTO - FRIO'!G12+'FACE - QUENTE'!G12+'FACE - FRIO'!G12+'INSTA - QUENTE'!G12+'INSTA - FRIO'!G12+'GOOGLE - QUENTE'!G12+'GOOGLE - FRIO'!G12 -> 0 | I12: =J12/G12 -> #DIV/0! | J12: ='AUTO - QUENTE'!J12+'AUTO - FRIO'!J12+'FACE - QUENTE'!J12+'FACE - FRIO'!J12+'INSTA - QUENTE'!J12+'INSTA - FRIO'!J12+'GOOGLE - QUENTE'!J12+'GOOGLE - FRIO'!J12 -> 0
A13: 44421 | B13: ='AUTO - QUENTE'!B13+'AUTO - FRIO'!B13+'FACE - QUENTE'!B13+'FACE - FRIO'!B13+'INSTA - QUENTE'!B13+'INSTA - FRIO'!B13+'GOOGLE - QUENTE'!B13+'GOOGLE - FRIO'!B13 -> 0 | D13: ='AUTO - QUENTE'!D13+'AUTO - FRIO'!D13+'FACE - QUENTE'!D13+'FACE - FRIO'!D13+'INSTA - QUENTE'!D13+'INSTA - FRIO'!D13+'GOOGLE - QUENTE'!D13+'GOOGLE - FRIO'!D13 -> 0 | G13: ='AUTO - QUENTE'!G13+'AUTO - FRIO'!G13+'FACE - QUENTE'!G13+'FACE - FRIO'!G13+'INSTA - QUENTE'!G13+'INSTA - FRIO'!G13+'GOOGLE - QUENTE'!G13+'GOOGLE - FRIO'!G13 -> 0 | I13: =J13/G13 -> #DIV/0! | J13: ='AUTO - QUENTE'!J13+'AUTO - FRIO'!J13+'FACE - QUENTE'!J13+'FACE - FRIO'!J13+'INSTA - QUENTE'!J13+'INSTA - FRIO'!J13+'GOOGLE - QUENTE'!J13+'GOOGLE - FRIO'!J13 -> 0
A14: 44422 | B14: ='AUTO - QUENTE'!B14+'AUTO - FRIO'!B14+'FACE - QUENTE'!B14+'FACE - FRIO'!B14+'INSTA - QUENTE'!B14+'INSTA - FRIO'!B14+'GOOGLE - QUENTE'!B14+'GOOGLE - FRIO'!B14 -> 0 | D14: ='AUTO - QUENTE'!D14+'AUTO - FRIO'!D14+'FACE - QUENTE'!D14+'FACE - FRIO'!D14+'INSTA - QUENTE'!D14+'INSTA - FRIO'!D14+'GOOGLE - QUENTE'!D14+'GOOGLE - FRIO'!D14 -> 0 | G14: ='AUTO - QUENTE'!G14+'AUTO - FRIO'!G14+'FACE - QUENTE'!G14+'FACE - FRIO'!G14+'INSTA - QUENTE'!G14+'INSTA - FRIO'!G14+'GOOGLE - QUENTE'!G14+'GOOGLE - FRIO'!G14 -> 0 | I14: =J14/G14 -> #DIV/0! | J14: ='AUTO - QUENTE'!J14+'AUTO - FRIO'!J14+'FACE - QUENTE'!J14+'FACE - FRIO'!J14+'INSTA - QUENTE'!J14+'INSTA - FRIO'!J14+'GOOGLE - QUENTE'!J14+'GOOGLE - FRIO'!J14 -> 0
A15: 44423 | B15: ='AUTO - QUENTE'!B15+'AUTO - FRIO'!B15+'FACE - QUENTE'!B15+'FACE - FRIO'!B15+'INSTA - QUENTE'!B15+'INSTA - FRIO'!B15+'GOOGLE - QUENTE'!B15+'GOOGLE - FRIO'!B15 -> 0 | D15: ='AUTO - QUENTE'!D15+'AUTO - FRIO'!D15+'FACE - QUENTE'!D15+'FACE - FRIO'!D15+'INSTA - QUENTE'!D15+'INSTA - FRIO'!D15+'GOOGLE - QUENTE'!D15+'GOOGLE - FRIO'!D15 -> 0 | G15: ='AUTO - QUENTE'!G15+'AUTO - FRIO'!G15+'FACE - QUENTE'!G15+'FACE - FRIO'!G15+'INSTA - QUENTE'!G15+'INSTA - FRIO'!G15+'GOOGLE - QUENTE'!G15+'GOOGLE - FRIO'!G15 -> 0 | I15: =J15/G15 -> #DIV/0! | J15: ='AUTO - QUENTE'!J15+'AUTO - FRIO'!J15+'FACE - QUENTE'!J15+'FACE - FRIO'!J15+'INSTA - QUENTE'!J15+'INSTA - FRIO'!J15+'GOOGLE - QUENTE'!J15+'GOOGLE - FRIO'!J15 -> 0
A16: 44424 | B16: ='AUTO - QUENTE'!B16+'AUTO - FRIO'!B16+'FACE - QUENTE'!B16+'FACE - FRIO'!B16+'INSTA - QUENTE'!B16+'INSTA - FRIO'!B16+'GOOGLE - QUENTE'!B16+'GOOGLE - FRIO'!B16 -> 0 | D16: ='AUTO - QUENTE'!D16+'AUTO - FRIO'!D16+'FACE - QUENTE'!D16+'FACE - FRIO'!D16+'INSTA - QUENTE'!D16+'INSTA - FRIO'!D16+'GOOGLE - QUENTE'!D16+'GOOGLE - FRIO'!D16 -> 0 | G16: ='AUTO - QUENTE'!G16+'AUTO - FRIO'!G16+'FACE - QUENTE'!G16+'FACE - FRIO'!G16+'INSTA - QUENTE'!G16+'INSTA - FRIO'!G16+'GOOGLE - QUENTE'!G16+'GOOGLE - FRIO'!G16 -> 0 | I16: =J16/G16 -> #DIV/0! | J16: ='AUTO - QUENTE'!J16+'AUTO - FRIO'!J16+'FACE - QUENTE'!J16+'FACE - FRIO'!J16+'INSTA - QUENTE'!J16+'INSTA - FRIO'!J16+'GOOGLE - QUENTE'!J16+'GOOGLE - FRIO'!J16 -> 0
A17: 44425 | B17: ='AUTO - QUENTE'!B17+'AUTO - FRIO'!B17+'FACE - QUENTE'!B17+'FACE - FRIO'!B17+'INSTA - QUENTE'!B17+'INSTA - FRIO'!B17+'GOOGLE - QUENTE'!B17+'GOOGLE - FRIO'!B17 -> 0 | D17: ='AUTO - QUENTE'!D17+'AUTO - FRIO'!D17+'FACE - QUENTE'!D17+'FACE - FRIO'!D17+'INSTA - QUENTE'!D17+'INSTA - FRIO'!D17+'GOOGLE - QUENTE'!D17+'GOOGLE - FRIO'!D17 -> 0 | G17: ='AUTO - QUENTE'!G17+'AUTO - FRIO'!G17+'FACE - QUENTE'!G17+'FACE - FRIO'!G17+'INSTA - QUENTE'!G17+'INSTA - FRIO'!G17+'GOOGLE - QUENTE'!G17+'GOOGLE - FRIO'!G17 -> 0 | I17: =J17/G17 -> #DIV/0! | J17: ='AUTO - QUENTE'!J17+'AUTO - FRIO'!J17+'FACE - QUENTE'!J17+'FACE - FRIO'!J17+'INSTA - QUENTE'!J17+'INSTA - FRIO'!J17+'GOOGLE - QUENTE'!J17+'GOOGLE - FRIO'!J17 -> 0
A18: 44426 | B18: ='AUTO - QUENTE'!B18+'AUTO - FRIO'!B18+'FACE - QUENTE'!B18+'FACE - FRIO'!B18+'INSTA - QUENTE'!B18+'INSTA - FRIO'!B18+'GOOGLE - QUENTE'!B18+'GOOGLE - FRIO'!B18 -> 0 | D18: ='AUTO - QUENTE'!D18+'AUTO - FRIO'!D18+'FACE - QUENTE'!D18+'FACE - FRIO'!D18+'INSTA - QUENTE'!D18+'INSTA - FRIO'!D18+'GOOGLE - QUENTE'!D18+'GOOGLE - FRIO'!D18 -> 0 | G18: ='AUTO - QUENTE'!G18+'AUTO - FRIO'!G18+'FACE - QUENTE'!G18+'FACE - FRIO'!G18+'INSTA - QUENTE'!G18+'INSTA - FRIO'!G18+'GOOGLE - QUENTE'!G18+'GOOGLE - FRIO'!G18 -> 0 | I18: =J18/G18 -> #DIV/0! | J18: ='AUTO - QUENTE'!J18+'AUTO - FRIO'!J18+'FACE - QUENTE'!J18+'FACE - FRIO'!J18+'INSTA - QUENTE'!J18+'INSTA - FRIO'!J18+'GOOGLE - QUENTE'!J18+'GOOGLE - FRIO'!J18 -> 0
A19: 44427 | B19: ='AUTO - QUENTE'!B19+'AUTO - FRIO'!B19+'FACE - QUENTE'!B19+'FACE - FRIO'!B19+'INSTA - QUENTE'!B19+'INSTA - FRIO'!B19+'GOOGLE - QUENTE'!B19+'GOOGLE - FRIO'!B19 -> 0 | D19: ='AUTO - QUENTE'!D19+'AUTO - FRIO'!D19+'FACE - QUENTE'!D19+'FACE - FRIO'!D19+'INSTA - QUENTE'!D19+'INSTA - FRIO'!D19+'GOOGLE - QUENTE'!D19+'GOOGLE - FRIO'!D19 -> 0 | G19: ='AUTO - QUENTE'!G19+'AUTO - FRIO'!G19+'FACE - QUENTE'!G19+'FACE - FRIO'!G19+'INSTA - QUENTE'!G19+'INSTA - FRIO'!G19+'GOOGLE - QUENTE'!G19+'GOOGLE - FRIO'!G19 -> 0 | I19: =J19/G19 -> #DIV/0! | J19: ='AUTO - QUENTE'!J19+'AUTO - FRIO'!J19+'FACE - QUENTE'!J19+'FACE - FRIO'!J19+'INSTA - QUENTE'!J19+'INSTA - FRIO'!J19+'GOOGLE - QUENTE'!J19+'GOOGLE - FRIO'!J19 -> 0
A20: 44428 | B20: ='AUTO - QUENTE'!B20+'AUTO - FRIO'!B20+'FACE - QUENTE'!B20+'FACE - FRIO'!B20+'INSTA - QUENTE'!B20+'INSTA - FRIO'!B20+'GOOGLE - QUENTE'!B20+'GOOGLE - FRIO'!B20 -> 0 | D20: ='AUTO - QUENTE'!D20+'AUTO - FRIO'!D20+'FACE - QUENTE'!D20+'FACE - FRIO'!D20+'INSTA - QUENTE'!D20+'INSTA - FRIO'!D20+'GOOGLE - QUENTE'!D20+'GOOGLE - FRIO'!D20 -> 0 | G20: ='AUTO - QUENTE'!G20+'AUTO - FRIO'!G20+'FACE - QUENTE'!G20+'FACE - FRIO'!G20+'INSTA - QUENTE'!G20+'INSTA - FRIO'!G20+'GOOGLE - QUENTE'!G20+'GOOGLE - FRIO'!G20 -> 0 | I20: =J20/G20 -> #DIV/0! | J20: ='AUTO - QUENTE'!J20+'AUTO - FRIO'!J20+'FACE - QUENTE'!J20+'FACE - FRIO'!J20+'INSTA - QUENTE'!J20+'INSTA - FRIO'!J20+'GOOGLE - QUENTE'!J20+'GOOGLE - FRIO'!J20 -> 0
A21: 44429 | B21: ='AUTO - QUENTE'!B21+'AUTO - FRIO'!B21+'FACE - QUENTE'!B21+'FACE - FRIO'!B21+'INSTA - QUENTE'!B21+'INSTA - FRIO'!B21+'GOOGLE - QUENTE'!B21+'GOOGLE - FRIO'!B21 -> 0 | D21: ='AUTO - QUENTE'!D21+'AUTO - FRIO'!D21+'FACE - QUENTE'!D21+'FACE - FRIO'!D21+'INSTA - QUENTE'!D21+'INSTA - FRIO'!D21+'GOOGLE - QUENTE'!D21+'GOOGLE - FRIO'!D21 -> 0 | G21: ='AUTO - QUENTE'!G21+'AUTO - FRIO'!G21+'FACE - QUENTE'!G21+'FACE - FRIO'!G21+'INSTA - QUENTE'!G21+'INSTA - FRIO'!G21+'GOOGLE - QUENTE'!G21+'GOOGLE - FRIO'!G21 -> 0 | I21: =J21/G21 -> #DIV/0! | J21: ='AUTO - QUENTE'!J21+'AUTO - FRIO'!J21+'FACE - QUENTE'!J21+'FACE - FRIO'!J21+'INSTA - QUENTE'!J21+'INSTA - FRIO'!J21+'GOOGLE - QUENTE'!J21+'GOOGLE - FRIO'!J21 -> 0
... A36: 44444 | B36: ='AUTO - QUENTE'!B36+'AUTO - FRIO'!B36+'FACE - QUENTE'!B36+'FACE - FRIO'!B36+'INSTA - QUENTE'!B36+'INSTA - FRIO'!B36+'GOOGLE - QUENTE'!B36+'GOOGLE - FRIO'!B36 -> 0 | D36: ='AUTO - QUENTE'!D36+'AUTO - FRIO'!D36+'FACE - QUENTE'!D36+'FACE - FRIO'!D36+'INSTA - QUENTE'!D36+'INSTA - FRIO'!D36+'GOOGLE - QUENTE'!D36+'GOOGLE - FRIO'!D36 -> 0 | G36: ='AUTO - QUENTE'!G36+'AUTO - FRIO'!G36+'FACE - QUENTE'!G36+'FACE - FRIO'!G36+'INSTA - QUENTE'!G36+'INSTA - FRIO'!G36+'GOOGLE - QUENTE'!G36+'GOOGLE - FRIO'!G36 -> 0 | I36: =J36/G36 -> #DIV/0! | J36: ='AUTO - QUENTE'!J36+'AUTO - FRIO'!J36+'FACE - QUENTE'!J36+'FACE - FRIO'!J36+'INSTA - QUENTE'!J36+'INSTA - FRIO'!J36+'GOOGLE - QUENTE'!J36+'GOOGLE - FRIO'!J36 -> 0
A37: MÉDIA | B37: =AVERAGE(B2:B36) -> 576.25714 | D37: =AVERAGE(D2:D36) -> 2.1428571 | G37: =AVERAGE(G2:G36) -> 0.48571429 | J37: =AVERAGE(J2:J36) -> 7.5905714
A38: TOTAL | B38: =SUM(B2:B36) -> 20169 | D38: =SUM(D2:D36) -> 75 | G38: =SUM(G2:G36) -> 17 | I38: =J38/G38 -> 15.627647 | J38: =SUM(J2:J36) -> 265.67

Sheet AQUECIMENTOANTECIPACAO
A1: DIA | B1: AQUECIMENTO GASTO | F1: DIA | G1: ANTECIPACAO GASTO
B2: AQC - FB | D2: AQC - GOOGLE | G2: ANT - FB | I2: ANT - GOOGLE
A3: 44410 | F3: 44410
A4: 44411 | F4: 44411
A5: 44412 | F5: 44412
A6: 44413 | F6: 44413
A7: 44414 | F7: 44414
A8: 44415 | F8: 44415
A9: 44416 | F9: 44416
A10: 44417 | F10: 44417
A11: 44418 | F11: 44418
A12: 44419 | F12: 44419
A13: 44420 | F13: 44420
A14: 44421 | F14: 44421
... A18: 44425 | F18: 44425
A19: 44426 | F19: 44426 | J19: -
A20: 44427 | F20: 44427
A21: 44428 | F21: 44428
A22: 44429 | F22: 44429
A23: 44430 | F23: 44430
A24: 44431 | F24: 44431
A25: 44432 | F25: 44432
A26: 44433 | F26: 44433
A27: 44434 | F27: 44434
A28: 44435 | F28: 44435
A29: 44436 | F29: 44436
A30: 44437 | F30: 44437
A31: 44438 | F31: 44438
... A37: 44444 | F37: 44444
A38: SOMA | B38: =SUM(B3:C37) -> 0 | D38: =SUM(D3:D37) -> 0 | F38: SOMA | G38: =SUM(G3:H37) -> 0 | I38: =SUM(I3:J37) -> 0
A39: TOTAL | B39: =B38+D38 -> 0 | F39: TOTAL | G39: =G38+I38 -> 0

Sheet PLANILHAMENTO ADS
C1: YOUTUBE | F1: FACEBOOK | K1: LINKS ADS
A2: ANUNCIO | B2: LEADS | C2: CPL | D2: VALOR GASTO | F2: ANUNCIO | G2: LEADS | H2: CPL | I2: VALOR GASTO
A3: AD 01 | C3: =D3/B3 -> #DIV/0! | F3: AD 01 | G3: 9 | H3: =I3/G3 -> 14.003333 | I3: 126.03 | K3: AD 01
A4: AD 02 | C4: =D4/B4 -> #DIV/0! | F4: AD 02 | G4: 4 | H4: =I4/G4 -> 16.7475 | I4: 66.99 | K4: AD 02 | L4: https://fb.me/1S3DCpJkY3qbyUM
A5: AD 03 | C5: =D5/B5 -> #DIV/0! | F5: AD 03 | G5: 1 | H5: =I5/G5 -> 16.87 | I5: 16.87 | K5: AD 03
A6: AD 04 | C6: =D6/B6 -> #DIV/0! | F6: AD 04 | H6: =I6/G6 -> #DIV/0! | K6: AD 04
A7: AD 05 | C7: =D7/B7 -> #DIV/0! | F7: AD 05 | H7: =I7/G7 -> #DIV/0! | K7: AD 05
A8: AD 06 | C8: =D8/B8 -> #DIV/0! | F8: AD 06 | H8: =I8/G8 -> #DIV/0! | K8: AD 06
A9: AD 07 | C9: =D9/B9 -> #DIV/0! | F9: AD 07 | H9: =I9/G9 -> #DIV/0! | K9: AD 07
A10: AD 08 | C10: =D10/B10 -> #DIV/0! | F10: AD 08 | H10: =I10/G10 -> #DIV/0! | K10: AD 08
A11: AD 09 | C11: =D11/B11 -> #DIV/0! | F11: AD 09 | H11: =I11/G11 -> #DIV/0! | K11: AD 09
A12: AD 10 | C12: =D12/B12 -> #DIV/0! | F12: AD 10 | H12: =I12/G12 -> #DIV/0! | K12: AD 10
A13: AD 11 | C13: =D13/B13 -> #DIV/0! | F13: AD 11 | H13: =I13/G13 -> #DIV/0! | K13: AD 11
A14: AD 12 | C14: =D14/B14 -> #DIV/0! | F14: AD 12 | H14: =I14/G14 -> #DIV/0! | K14: AD 12
A15: AD 13 | C15: =D15/B15 -> #DIV/0! | F15: AD 13 | H15: =I15/G15 -> #DIV/0! | K15: AD 13
A16: AD 14 | C16: =D16/B16 -> #DIV/0! | F16: AD 14 | H16: =I16/G16 -> #DIV/0! | K16: AD 14
A17: AD 15 | C17: =D17/B17 -> #DIV/0! | F17: AD 15 | H17: =I17/G17 -> #DIV/0! | K17: AD 15
A18: AD 16 | C18: =D18/B18 -> #DIV/0! | F18: AD 16 | H18: =I18/G18 -> #DIV/0! | K18: AD 16
A19: AD 17 | C19: =D19/B19 -> #DIV/0! | F19: AD 17 | H19: =I19/G19 -> #DIV/0! | J19: - | K19: AD 17
A20: AD 18 | C20: =D20/B20 -> #DIV/0! | F20: AD 18 | H20: =I20/G20 -> #DIV/0! | K20: AD 18
A21: AD 19 | C21: =D21/B21 -> #DIV/0! | F21: AD 19 | H21: =SUM(I21/G21) -> #DIV/0! | K21: AD 19
A22: AD 20 | C22: =D22/B22 -> #DIV/0! | F22: AD 20 | H22: =SUM(I22/G22) -> #DIV/0! | K22: AD 20
A23: AD 21 | C23: =D23/B23 -> #DIV/0! | F23: AD 21 | H23: =SUM(I23/G23) -> #DIV/0! | K23: AD 21
A24: AD 22 | C24: =D24/B24 -> #DIV/0! | F24: AD 22 | H24: =SUM(I24/G24) -> #DIV/0! | K24: AD 22
A25: AD 23 | C25: =D25/B25 -> #DIV/0! | F25: AD 23 | H25: =I25/G25 -> #DIV/0! | K25: AD 23
A26: AD 24 | C26: =D26/B26 -> #DIV/0! | F26: AD 24 | H26: =I26/G26 -> #DIV/0! | K26: AD 24
A27: AD 25 | C27: =D27/B27 -> #DIV/0! | F27: AD 25 | H27: =I27/G27 -> #DIV/0! | K27: AD 25
A28: AD 26 | C28: =D28/B28 -> #DIV/0! | F28: AD 26 | H28: =I28/G28 -> #DIV/0! | K28: AD 26
A29: AD 27 | C29: =D29/B29 -> #DIV/0! | F29: AD 27 | H29: =I29/G29 -> #DIV/0! | K29: AD 27
A30: AD 28 | C30: =D30/B30 -> #DIV/0! | F30: AD 28 | H30: =I30/G30 -> #DIV/0! | K30: AD 28
A31: AD 29 | C31: =D31/B31 -> #DIV/0! | F31: AD 29 | H31: =I31/G31 -> #DIV/0! | K31: AD 29
A32: AD 30 | C32: =D32/B32 -> #DIV/0! | F32: AD 30 | H32: =I32/G32 -> #DIV/0! | K32: AD 30
A33: AD 31 | C33: =D33/B33 -> #DIV/0! | F33: AD 31 | H33: =I33/G33 -> #DIV/0! | K33: AD 31
A34: AD 32 | C34: =D34/B34 -> #DIV/0! | F34: AD 32 | H34: =I34/G34 -> #DIV/0! | K34: AD 32
A35: AD 33 | C35: =D35/B35 -> #DIV/0! | F35: AD 33 | H35: =I35/G35 -> #DIV/0! | K35: AD 33
A36: AD 34 | C36: =D36/B36 -> #DIV/0! | F36: AD 34 | H36: =I36/G36 -> #DIV/0! | K36: AD 34
... A41: AD 39 | C41: =D41/B41 -> #DIV/0! | F41: AD 39 | H41: =I41/G41 -> #DIV/0! | K41: AD 39
A42: AD 40 | C42: =D42/B42 -> #DIV/0! | F42: AD 40 | H42: =SUM(I42/G42) -> #DIV/0! | K42: AD 40
A43: AD 41 | C43: =D43/B43 -> #DIV/0! | F43: AD 41 | H43: =I43/G43 -> #DIV/0! | K43: AD 41
A44: AD 42 | C44: =D44/B44 -> #DIV/0! | F44: AD 42 | H44: =I44/G44 -> #DIV/0! | K44: AD 42
...

Sheet AUTO - QUENTE
A1: DIA | B1: IMPRESSÕES | C1: CTR % | D1: CLIQUE NO LINK | E1: VISUALIZAÇÃO DE PÁGINA | F1: % DE VIEW PAGES/CLIQUE | G1: NÚMERO DE LEADS | H1: CONV DA PÁGINA % | I1: CUSTO POR LEAD | J1: VALOR GASTO
A2: 44410 | F2: =E2/D2 -> #DIV/0! | H2: =G2/E2 -> #DIV/0! | I2: =J2/G2 -> #DIV/0!
A3: 44411 | F3: =E3/D3 -> #DIV/0! | H3: =G3/E3 -> #DIV/0! | I3: =J3/G3 -> #DIV/0!
A4: 44412 | F4: =E4/D4 -> #DIV/0! | H4: =G4/E4 -> #DIV/0! | I4: =J4/G4 -> #DIV/0!
A5: 44413 | F5: =E5/D5 -> #DIV/0! | H5: =G5/E5 -> #DIV/0! | I5: =J5/G5 -> #DIV/0!
A6: 44414 | F6: =E6/D6 -> #DIV/0! | H6: =G6/E6 -> #DIV/0! | I6: =J6/G6 -> #DIV/0!
A7: 44415 | F7: =E7/D7 -> #DIV/0! | H7: =G7/E7 -> #DIV/0! | I7: =J7/G7 -> #DIV/0!
A8: 44416 | F8: =E8/D8 -> #DIV/0! | H8: =G8/E8 -> #DIV/0! | I8: =J8/G8 -> #DIV/0!
A9: 44417 | F9: =E9/D9 -> #DIV/0! | H9: =G9/E9 -> #DIV/0! | I9: =J9/G9 -> #DIV/0!
A10: 44418 | F10: =E10/D10 -> #DIV/0! | H10: =G10/E10 -> #DIV/0! | I10: =J10/G10 -> #DIV/0!
A11: 44419 | F11: =E11/D11 -> #DIV/0! | H11: =G11/E11 -> #DIV/0! | I11: =J11/G11 -> #DIV/0!
A12: 44420 | F12: =E12/D12 -> #DIV/0! | H12: =G12/E12 -> #DIV/0! | I12: =J12/G12 -> #DIV/0!
A13: 44421 | F13: =E13/D13 -> #DIV/0! | H13: =G13/E13 -> #DIV/0! | I13: =J13/G13 -> #DIV/0!
... A36: 44444 | F36: =E36/D36 -> #DIV/0! | H36: =G36/E36 -> #DIV/0! | I36: =J36/G36 -> #DIV/0!
A37: MÉDIA | B37: =MEDIAN(B2:B36) -> #NUM! | C37: =MEDIAN(C2:C36) -> #NUM! | D37: =MEDIAN(D2:D36) -> #NUM! | E37: =MEDIAN(E2:E36) -> #NUM! | F37: =MEDIAN(F2:F36) -> #DIV/0! | G37: =MEDIAN(G2:G36) -> #NUM! | H37: =MEDIAN(H2:H36) -> #DIV/0! | J37: =MEDIAN(J2:J36) -> #NUM!
A38: TOTAL | B38: =SUM(B2:B36) -> 0 | D38: =SUM(D2:D36) -> 0 | E38: =SUM(E2:E36) -> 0 | F38: =E38/D38 -> #DIV/0! | G38: =SUM(G2:G36) -> 0 | H38: =G38/E38 -> #DIV/0! | I38: =J38/G38 -> #DIV/0! | J38: =SUM(J2:J36) -> 0

Sheet AUTO - FRIO
A1: DIA | B1: IMPRESSÕES | C1: CTR % | D1: CLIQUE NO LINK | E1: VISUALIZAÇÃO DE PÁGINA | F1: % DE VIEW PAGES/CLIQUE | G1: NÚMERO DE LEADS | H1: CONV DA PÁGINA % | I1: CUSTO POR LEAD | J1: VALOR GASTO
A2: 44410 | F2: =E2/D2 -> #DIV/0! | H2: =G2/E2 -> #DIV/0! | I2: =J2/G2 -> #DIV/0!
A3: 44411 | F3: =E3/D3 -> #DIV/0! | H3: =G3/E3 -> #DIV/0! | I3: =J3/G3 -> #DIV/0!
A4: 44412 | F4: =E4/D4 -> #DIV/0! | H4: =G4/E4 -> #DIV/0! | I4: =J4/G4 -> #DIV/0!
A5: 44413 | F5: =E5/D5 -> #DIV/0! | H5: =G5/E5 -> #DIV/0! | I5: =J5/G5 -> #DIV/0!
A6: 44414 | F6: =E6/D6 -> #DIV/0! | H6: =G6/E6 -> #DIV/0! | I6: =J6/G6 -> #DIV/0!
A7: 44415 | F7: =E7/D7 -> #DIV/0! | H7: =G7/E7 -> #DIV/0! | I7: =J7/G7 -> #DIV/0!
A8: 44416 | F8: =E8/D8 -> #DIV/0! | H8: =G8/E8 -> #DIV/0! | I8: =J8/G8 -> #DIV/0!
A9: 44417 | F9: =E9/D9 -> #DIV/0! | H9: =G9/E9 -> #DIV/0! | I9: =J9/G9 -> #DIV/0!
A10: 44418 | F10: =E10/D10 -> #DIV/0! | H10: =G10/E10 -> #DIV/0! | I10: =J10/G10 -> #DIV/0!
A11: 44419 | F11: =E11/D11 -> #DIV/0! | H11: =G11/E11 -> #DIV/0! | I11: =J11/G11 -> #DIV/0!
A12: 44420 | F12: =E12/D12 -> #DIV/0! | H12: =G12/E12 -> #DIV/0! | I12: =J12/G12 -> #DIV/0!
A13: 44421 | F13: =E13/D13 -> #DIV/0! | H13: =G13/E13 -> #DIV/0! | I13: =J13/G13 -> #DIV/0!
... A36: 44444 | F36: =E36/D36 -> #DIV/0! | H36: =G36/E36 -> #DIV/0! | I36: =J36/G36 -> #DIV/0!
A37: MÉDIA | B37: =MEDIAN(B2:B36) -> #NUM! | C37: =MEDIAN(C2:C36) -> #NUM! | D37: =MEDIAN(D2:D36) -> #NUM! | E37: =MEDIAN(E2:E36) -> #NUM! | F37: =MEDIAN(F2:F36) -> #DIV/0! | G37: =MEDIAN(G2:G36) -> #NUM! | H37: =MEDIAN(H2:H36) -> #DIV/0! | J37: =MEDIAN(J2:J36) -> #NUM!
A38: TOTAL | B38: =SUM(B2:B36) -> 0 | D38: =SUM(D2:D36) -> 0 | E38: =SUM(E2:E36) -> 0 | F38: =E38/D38 -> #DIV/0! | G38: =SUM(G2:G36) -> 0 | H38: =G38/E38 -> #DIV/0! | I38: =J38/G38 -> #DIV/0! | J38: =SUM(J2:J36) -> 0

Sheet FACE - QUENTE
A1: DIA | B1: IMPRESSÕES | C1: CTR % | D1: CLIQUE NO LINK | E1: VISUALIZAÇÃO DE PÁGINA | F1: % DE VIEW PAGES/CLIQUE | G1: NÚMERO DE LEADS | H1: CONV DA PÁGINA % | I1: CUSTO POR LEAD | J1: VALOR GASTO
A2: 44410 | F2: =E2/D2 -> #DIV/0! | H2: =G2/E2 -> #DIV/0! | I2: =J2/G2 -> #DIV/0!
A3: 44411 | F3: =E3/D3 -> #DIV/0! | H3: =G3/E3 -> #DIV/0! | I3: =J3/G3 -> #DIV/0!
A4: 44412 | F4: =E4/D4 -> #DIV/0! | H4: =G4/E4 -> #DIV/0! | I4: =J4/G4 -> #DIV/0!
A5: 44413 | F5: =E5/D5 -> #DIV/0! | H5: =G5/E5 -> #DIV/0! | I5: =J5/G5 -> #DIV/0!
A6: 44414 | F6: =E6/D6 -> #DIV/0! | H6: =G6/E6 -> #DIV/0! | I6: =J6/G6 -> #DIV/0!
A7: 44415 | F7: =E7/D7 -> #DIV/0! | H7: =G7/E7 -> #DIV/0! | I7: =J7/G7 -> #DIV/0!
A8: 44416 | F8: =E8/D8 -> #DIV/0! | H8: =G8/E8 -> #DIV/0! | I8: =J8/G8 -> #DIV/0!
A9: 44417 | F9: =E9/D9 -> #DIV/0! | H9: =G9/E9 -> #DIV/0! | I9: =J9/G9 -> #DIV/0!
A10: 44418 | F10: =E10/D10 -> #DIV/0! | H10: =G10/E10 -> #DIV/0! | I10: =J10/G10 -> #DIV/0!
A11: 44419 | F11: =E11/D11 -> #DIV/0! | H11: =G11/E11 -> #DIV/0! | I11: =J11/G11 -> #DIV/0!
A12: 44420 | F12: =E12/D12 -> #DIV/0! | H12: =G12/E12 -> #DIV/0! | I12: =J12/G12 -> #DIV/0!
A13: 44421 | F13: =E13/D13 -> #DIV/0! | H13: =G13/E13 -> #DIV/0! | I13: =J13/G13 -> #DIV/0!
... A36: 44444 | F36: =E36/D36 -> #DIV/0! | H36: =G36/E36 -> #DIV/0! | I36: =J36/G36 -> #DIV/0!
A37: MÉDIA | B37: =MEDIAN(B2:B36) -> #NUM! | C37: =MEDIAN(C2:C36) -> #NUM! | D37: =MEDIAN(D2:D36) -> #NUM! | E37: =MEDIAN(E2:E36) -> #NUM! | F37: =MEDIAN(F2:F36) -> #DIV/0! | G37: =MEDIAN(G2:G36) -> #NUM! | H37: =MEDIAN(H2:H36) -> #DIV/0! | J37: =MEDIAN(J2:J36) -> #NUM!
A38: TOTAL | B38: =SUM(B2:B36) -> 0 | D38: =SUM(D2:D36) -> 0 | E38: =SUM(E2:E36) -> 0 | F38: =E38/D38 -> #DIV/0! | G38: =SUM(G2:G36) -> 0 | H38: =G38/E38 -> #DIV/0! | I38: =J38/G38 -> #DIV/0! | J38: =SUM(J2:J36) -> 0

Sheet FACE - FRIO
A1: DIA | B1: IMPRESSÕES | C1: CTR % | D1: CLIQUE NO LINK | E1: VISUALIZAÇÃO DE PÁGINA | F1: % DE VIEW PAGES/CLIQUE | G1: NÚMERO DE LEADS | H1: CONV DA PÁGINA % | I1: CUSTO POR LEAD | J1: VALOR GASTO
A2: 44410 | F2: =E2/D2 -> #DIV/0! | H2: =G2/E2 -> #DIV/0! | I2: =J2/G2 -> #DIV/0!
A3: 44411 | F3: =E3/D3 -> #DIV/0! | H3: =G3/E3 -> #DIV/0! | I3: =J3/G3 -> #DIV/0!
A4: 44412 | F4: =E4/D4 -> #DIV/0! | H4: =G4/E4 -> #DIV/0! | I4: =J4/G4 -> #DIV/0!
A5: 44413 | F5: =E5/D5 -> #DIV/0! | H5: =G5/E5 -> #DIV/0! | I5: =J5/G5 -> #DIV/0!
A6: 44414 | F6: =E6/D6 -> #DIV/0! | H6: =G6/E6 -> #DIV/0! | I6: =J6/G6 -> #DIV/0!
A7: 44415 | F7: =E7/D7 -> #DIV/0! | H7: =G7/E7 -> #DIV/0! | I7: =J7/G7 -> #DIV/0!
A8: 44416 | F8: =E8/D8 -> #DIV/0! | H8: =G8/E8 -> #DIV/0! | I8: =J8/G8 -> #DIV/0!
A9: 44417 | F9: =E9/D9 -> #DIV/0! | H9: =G9/E9 -> #DIV/0! | I9: =J9/G9 -> #DIV/0!
A10: 44418 | F10: =E10/D10 -> #DIV/0! | H10: =G10/E10 -> #DIV/0! | I10: =J10/G10 -> #DIV/0!
A11: 44419 | F11: =E11/D11 -> #DIV/0! | H11: =G11/E11 -> #DIV/0! | I11: =J11/G11 -> #DIV/0!
A12: 44420 | F12: =E12/D12 -> #DIV/0! | H12: =G12/E12 -> #DIV/0! | I12: =J12/G12 -> #DIV/0!
A13: 44421 | F13: =E13/D13 -> #DIV/0! | H13: =G13/E13 -> #DIV/0! | I13: =J13/G13 -> #DIV/0!
... A36: 44444 | F36: =E36/D36 -> #DIV/0! | H36: =G36/E36 -> #DIV/0! | I36: =J36/G36 -> #DIV/0!
A37: MÉDIA | B37: =MEDIAN(B2:B36) -> #NUM! | C37: =MEDIAN(C2:C36) -> #NUM! | D37: =MEDIAN(D2:D36) -> #NUM! | E37: =MEDIAN(E2:E36) -> #NUM! | F37: =MEDIAN(F2:F36) -> #DIV/0! | G37: =MEDIAN(G2:G36) -> #NUM! | H37: =MEDIAN(H2:H36) -> #DIV/0! | J37: =MEDIAN(J2:J36) -> #NUM!
A38: TOTAL | B38: =SUM(B2:B36) -> 0 | D38: =SUM(D2:D36) -> 0 | E38: =SUM(E2:E36) -> 0 | F38: =E38/D38 -> #DIV/0! | G38: =SUM(G2:G36) -> 0 | H38: =G38/E38 -> #DIV/0! | I38: =J38/G38 -> #DIV/0! | J38: =SUM(J2:J36) -> 0

Sheet INSTA - QUENTE
A1: DIA | B1: IMPRESSÕES | C1: CTR % | D1: CLIQUE NO LINK | E1: VISUALIZAÇÃO DE PÁGINA | F1: % DE VIEW PAGES/CLIQUE | G1: NÚMERO DE LEADS | H1: CONV DA PÁGINA % | I1: CUSTO POR LEAD | J1: VALOR GASTO
A2: 44410 | F2: =E2/D2 -> #DIV/0! | H2: =G2/E2 -> #DIV/0! | I2: =J2/G2 -> #DIV/0!
A3: 44411 | F3: =E3/D3 -> #DIV/0! | H3: =G3/E3 -> #DIV/0! | I3: =J3/G3 -> #DIV/0!
A4: 44412 | F4: =E4/D4 -> #DIV/0! | H4: =G4/E4 -> #DIV/0! | I4: =J4/G4 -> #DIV/0!
A5: 44413 | F5: =E5/D5 -> #DIV/0! | H5: =G5/E5 -> #DIV/0! | I5: =J5/G5 -> #DIV/0!
A6: 44414 | F6: =E6/D6 -> #DIV/0! | H6: =G6/E6 -> #DIV/0! | I6: =J6/G6 -> #DIV/0!
A7: 44415 | F7: =E7/D7 -> #DIV/0! | H7: =G7/E7 -> #DIV/0! | I7: =J7/G7 -> #DIV/0!
A8: 44416 | F8: =E8/D8 -> #DIV/0! | H8: =G8/E8 -> #DIV/0! | I8: =J8/G8 -> #DIV/0!
A9: 44417 | F9: =E9/D9 -> #DIV/0! | H9: =G9/E9 -> #DIV/0! | I9: =J9/G9 -> #DIV/0!
A10: 44418 | F10: =E10/D10 -> #DIV/0! | H10: =G10/E10 -> #DIV/0! | I10: =J10/G10 -> #DIV/0!
A11: 44419 | F11: =E11/D11 -> #DIV/0! | H11: =G11/E11 -> #DIV/0! | I11: =J11/G11 -> #DIV/0!
A12: 44420 | F12: =E12/D12 -> #DIV/0! | H12: =G12/E12 -> #DIV/0! | I12: =J12/G12 -> #DIV/0!
A13: 44421 | F13: =E13/D13 -> #DIV/0! | H13: =G13/E13 -> #DIV/0! | I13: =J13/G13 -> #DIV/0!
... A36: 44444 | F36: =E36/D36 -> #DIV/0! | H36: =G36/E36 -> #DIV/0! | I36: =J36/G36 -> #DIV/0!
A37: MÉDIA | B37: =MEDIAN(B2:B36) -> #NUM! | C37: =MEDIAN(C2:C36) -> #NUM! | D37: =MEDIAN(D2:D36) -> #NUM! | E37: =MEDIAN(E2:E36) -> #NUM! | F37: =MEDIAN(F2:F36) -> #DIV/0! | G37: =MEDIAN(G2:G36) -> #NUM! | H37: =MEDIAN(H2:H36) -> #DIV/0! | J37: =MEDIAN(J2:J36) -> #NUM!
A38: TOTAL | B38: =SUM(B2:B36) -> 0 | D38: =SUM(D2:D36) -> 0 | E38: =SUM(E2:E36) -> 0 | F38: =E38/D38 -> #DIV/0! | G38: =SUM(G2:G36) -> 0 | H38: =G38/E38 -> #DIV/0! | I38: =J38/G38 -> #DIV/0! | J38: =SUM(J2:J36) -> 0

Sheet INSTA - FRIO
A1: DIA | B1: IMPRESSÕES | C1: CTR % | D1: CLIQUE NO LINK | E1: VISUALIZAÇÃO DE PÁGINA/PERFIL IG | F1: % DE VIEW PAGES/CLIQUE | G1: NÚMERO DE LEADS | H1: CONV DA PÁGINA % | I1: CUSTO POR LEAD | J1: VALOR GASTO
A2: 44410 | F2: =D2/E2 -> #DIV/0! | H2: =G2/E2 -> #DIV/0! | I2: =J2/G2 -> #DIV/0!
A3: 44411 | F3: =D3/E3 -> #DIV/0! | H3: =G3/E3 -> #DIV/0! | I3: =J3/G3 -> #DIV/0!
A4: 44412 | F4: =D4/E4 -> #DIV/0! | H4: =G4/E4 -> #DIV/0! | I4: =J4/G4 -> #DIV/0!
A5: 44413 | B5: 5441 | C5: 0.0099 | D5: 11 | E5: 42 | F5: =D5/E5 -> 0.26190476 | G5: 2 | H5: =G5/E5 -> 0.047619048 | I5: =J5/G5 -> 17.005 | J5: 34.01
A6: 44414 | B6: 4933 | C6: 0.0251 | D6: 11 | E6: 113 | F6: =D6/E6 -> 0.097345133 | G6: 5 | H6: =G6/E6 -> 0.044247788 | I6: =J6/G6 -> 13.076 | J6: 65.38
A7: 44415 | B7: 6078 | C7: 1.43 | D7: 29 | E7: 84 | F7: =D7/E7 -> 0.3452381 | G7: 4 | H7: =G7/E7 -> 0.047619048 | I7: =J7/G7 -> 17.1925 | J7: 68.77
A8: 44416 | B8: 3151 | C8: 1.48% | D8: 13 | E8: 53 | F8: =D8/E8 -> 0.24528302 | G8: 4 | H8: =G8/E8 -> 0.075471698 | I8: =J8/G8 -> 17.12 | J8: 68.48
A9: 44417 | B9: 566 | C9: 0.0177 | D9: 11 | E9: 11 | F9: =D9/E9 -> 1 | G9: 2 | H9: =G9/E9 -> 0.18181818 | I9: =J9/G9 -> 14.515 | J9: 29.03
A10: 44418 | F10: =D10/E10 -> #DIV/0! | H10: =G10/E10 -> #DIV/0! | I10: =J10/G10 -> #DIV/0!
A11: 44419 | F11: =D11/E11 -> #DIV/0! | H11: =G11/E11 -> #DIV/0! | I11: =J11/G11 -> #DIV/0!
A12: 44420 | F12: =D12/E12 -> #DIV/0! | H12: =G12/E12 -> #DIV/0! | I12: =J12/G12 -> #DIV/0!
A13: 44421 | F13: =D13/E13 -> #DIV/0! | H13: =G13/E13 -> #DIV/0! | I13: =J13/G13 -> #DIV/0!
A14: 44422 | F14: =D14/E14 -> #DIV/0! | H14: =G14/E14 -> #DIV/0! | I14: =J14/G14 -> #DIV/0!
A15: 44423 | F15: =D15/E15 -> #DIV/0! | H15: =G15/E15 -> #DIV/0! | I15: =J15/G15 -> #DIV/0!
A16: 44424 | F16: =D16/E16 -> #DIV/0! | H16: =G16/E16 -> #DIV/0! | I16: =J16/G16 -> #DIV/0!
A17: 44425 | F17: =D17/E17 -> #DIV/0! | H17: =G17/E17 -> #DIV/0! | I17: =J17/G17 -> #DIV/0!
A18: 44426 | F18: =D18/E18 -> #DIV/0! | H18: =G18/E18 -> #DIV/0! | I18: =J18/G18 -> #DIV/0!
A19: 44427 | F19: =D19/E19 -> #DIV/0! | H19: =G19/E19 -> #DIV/0! | I19: =J19/G19 -> #DIV/0!
A20: 44428 | F20: =D20/E20 -> #DIV/0! | H20: =G20/E20 -> #DIV/0! | I20: =J20/G20 -> #DIV/0!
A21: 44429 | F21: =D21/E21 -> #DIV/0! | H21: =G21/E21 -> #DIV/0! | I21: =J21/G21 -> #DIV/0!
... A36: 44444 | F36: =D36/E36 -> #DIV/0! | H36: =G36/E36 -> #DIV/0! | I36: =J36/G36 -> #DIV/0!
A37: MÉDIA | B37: =MEDIAN(B2:B36) -> 4933 | C37: =MEDIAN(C2:C36) -> 0.0214 | D37: =MEDIAN(D2:D36) -> 11 | E37: =MEDIAN(E2:E36) -> 53 | F37: =MEDIAN(F2:F36) -> #DIV/0! | G37: =MEDIAN(G2:G36) -> 4 | H37: =MEDIAN(H2:H36) -> #DIV/0! | J37: =MEDIAN(J2:J36) -> 65.38
A38: TOTAL | B38: =SUM(B2:B36) -> 20169 | D38: =SUM(D2:D36) -> 75 | E38: =SUM(E2:E36) -> 303 | F38: =E38/D38 -> 4.04 | G38: =SUM(G2:G36) -> 17 | H38: =G38/E38 -> 0.056105611 | I38: =J38/G38 -> 15.627647 | J38: =SUM(J2:J36) -> 265.67

Sheet GOOGLE - QUENTE
A1: DIA | B1: IMPRESSÕES | C1: CTR % | D1: CLIQUE NO LINK | E1: VISUALIZAÇÃO DE PÁGINA | F1: PORCETAGEM DE VIEW PAGES | G1: NÚMERO DE LEADS | H1: CONVERSÃO EM LEADS | I1: CUSTO POR LEAD | J1: VALOR GASTO
A2: 44410 | I2: =J2/G2 -> #DIV/0!
A3: 44411 | I3: =J3/G3 -> #DIV/0!
A4: 44412 | I4: =J4/G4 -> #DIV/0!
A5: 44413 | I5: =J5/G5 -> #DIV/0!
A6: 44414 | I6: =J6/G6 -> #DIV/0!
A7: 44415 | I7: =J7/G7 -> #DIV/0!
A8: 44416 | I8: =J8/G8 -> #DIV/0!
A9: 44417 | H9: =G9/E9 -> #DIV/0! | I9: =J9/G9 -> #DIV/0!
A10: 44418 | H10: =G10/E10 -> #DIV/0! | I10: =J10/G10 -> #DIV/0!
A11: 44419 | H11: =G11/E11 -> #DIV/0! | I11: =J11/G11 -> #DIV/0!
A12: 44420 | H12: =G12/E12 -> #DIV/0! | I12: =J12/G12 -> #DIV/0!
A13: 44421 | H13: =G13/E13 -> #DIV/0! | I13: =J13/G13 -> #DIV/0!
A14: 44422 | H14: =G14/E14 -> #DIV/0! | I14: =J14/G14 -> #DIV/0!
A15: 44423 | H15: =G15/E15 -> #DIV/0! | I15: =J15/G15 -> #DIV/0!
A16: 44424 | H16: =G16/E16 -> #DIV/0! | I16: =J16/G16 -> #DIV/0!
A17: 44425 | H17: =G17/E17 -> #DIV/0! | I17: =J17/G17 -> #DIV/0!
A18: 44426 | H18: =G18/E18 -> #DIV/0! | I18: =J18/G18 -> #DIV/0!
A19: 44427 | H19: =G19/E19 -> #DIV/0! | I19: =J19/G19 -> #DIV/0!
A20: 44428 | H20: =G20/E20 -> #DIV/0! | I20: =J20/G20 -> #DIV/0!
A21: 44429 | H21: =G21/E21 -> #DIV/0! | I21: =J21/G21 -> #DIV/0!
A22: 44430 | I22: =J22/G22 -> #DIV/0!
A23: 44431 | I23: =J23/G23 -> #DIV/0!
A24: 44432 | I24: =J24/G24 -> #DIV/0!
A25: 44433 | I25: =J25/G25 -> #DIV/0!
A26: 44434 | I26: =J26/G26 -> #DIV/0!
A27: 44435 | I27: =J27/G27 -> #DIV/0!
A28: 44436 | I28: =J28/G28 -> #DIV/0!
A29: 44437 | I29: =J29/G29 -> #DIV/0!
A30: 44438 | I30: =J30/G30 -> #DIV/0!
A31: 44439 | I31: =J31/G31 -> #DIV/0!
A32: 44440 | I32: =J32/G32 -> #DIV/0!
A33: 44441 | I33: =J33/G33 -> #DIV/0! | K33: -
A34: 44442 | I34: =J34/G34 -> #DIV/0!
A35: 44443 | I35: =J35/G35 -> #DIV/0!
A36: 44444 | I36: =J36/G36 -> #DIV/0!
A37: MÉDIA | B37: =AVERAGE(B2:B36) -> #DIV/0! | C37: =AVERAGE(C2:C36) -> #DIV/0! | D37: =AVERAGE(D2:D36) -> #DIV/0! | E37: =AVERAGE(E2:E36) -> #DIV/0! | F37: =AVERAGE(F2:F36) -> #DIV/0! | G37: =AVERAGE(G2:G36) -> #DIV/0!
A38: TOTAL | B38: =SUM(B2:B36) -> 0 | D38: =SUM(D2:D36) -> 0 | E38: =AVERAGE(E9:E27) -> #DIV/0! | F38: =AVERAGE(F9:F27) -> #DIV/0! | G38: =SUM(G2:G36) -> 0 | H38: =AVERAGE(H9:H27) -> #DIV/0! | I38: =J38/G38 -> #DIV/0! | J38: =SUM(J2:J36) -> 0

Sheet GOOGLE - FRIO
A1: DIA | B1: IMPRESSÕES | C1: CTR % | D1: CLIQUE NO LINK | E1: VISUALIZAÇÃO DE PÁGINA | F1: PORCETAGEM DE VIEW PAGES | G1: NÚMERO DE LEADS | H1: CONVERSÃO EM LEADS | I1: CUSTO POR LEAD | J1: VALOR GASTO
A2: 44410 | I2: =J2/G2 -> #DIV/0!
A3: 44411 | I3: =J3/G3 -> #DIV/0!
A4: 44412 | I4: =J4/G4 -> #DIV/0!
A5: 44413 | I5: =J5/G5 -> #DIV/0!
A6: 44414 | I6: =J6/G6 -> #DIV/0!
A7: 44415 | I7: =J7/G7 -> #DIV/0!
A8: 44416 | I8: =J8/G8 -> #DIV/0!
A9: 44417 | H9: =G9/E9 -> #DIV/0! | I9: =J9/G9 -> #DIV/0!
A10: 44418 | H10: =G10/E10 -> #DIV/0! | I10: =J10/G10 -> #DIV/0!
A11: 44419 | H11: =G11/E11 -> #DIV/0! | I11: =J11/G11 -> #DIV/0!
A12: 44420 | H12: =G12/E12 -> #DIV/0! | I12: =J12/G12 -> #DIV/0!
A13: 44421 | H13: =G13/E13 -> #DIV/0! | I13: =J13/G13 -> #DIV/0!
A14: 44422 | H14: =G14/E14 -> #DIV/0! | I14: =J14/G14 -> #DIV/0!
A15: 44423 | H15: =G15/E15 -> #DIV/0! | I15: =J15/G15 -> #DIV/0!
A16: 44424 | H16: =G16/E16 -> #DIV/0! | I16: =J16/G16 -> #DIV/0!
A17: 44425 | H17: =G17/E17 -> #DIV/0! | I17: =J17/G17 -> #DIV/0!
A18: 44426 | H18: =G18/E18 -> #DIV/0! | I18: =J18/G18 -> #DIV/0!
A19: 44427 | H19: =G19/E19 -> #DIV/0! | I19: =J19/G19 -> #DIV/0!
A20: 44428 | H20: =G20/E20 -> #DIV/0! | I20: =J20/G20 -> #DIV/0!
A21: 44429 | H21: =G21/E21 -> #DIV/0! | I21: =J21/G21 -> #DIV/0!
A22: 44430 | I22: =J22/G22 -> #DIV/0!
A23: 44431 | I23: =J23/G23 -> #DIV/0!
A24: 44432 | I24: =J24/G24 -> #DIV/0!
A25: 44433 | I25: =J25/G25 -> #DIV/0!
A26: 44434 | I26: =J26/G26 -> #DIV/0!
A27: 44435 | I27: =J27/G27 -> #DIV/0!
A28: 44436 | I28: =J28/G28 -> #DIV/0!
A29: 44437 | I29: =J29/G29 -> #DIV/0!
A30: 44438 | I30: =J30/G30 -> #DIV/0!
A31: 44439 | I31: =J31/G31 -> #DIV/0!
A32: 44440 | I32: =J32/G32 -> #DIV/0!
A33: 44441 | I33: =J33/G33 -> #DIV/0! | K33: -
A34: 44442 | I34: =J34/G34 -> #DIV/0!
A35: 44443 | I35: =J35/G35 -> #DIV/0!
A36: 44444 | I36: =J36/G36 -> #DIV/0!
A37: MÉDIA | B37: =AVERAGE(B2:B36) -> #DIV/0! | C37: =AVERAGE(C2:C36) -> #DIV/0! | D37: =AVERAGE(D2:D36) -> #DIV/0! | E37: =AVERAGE(E2:E36) -> #DIV/0! | F37: =AVERAGE(F2:F36) -> #DIV/0! | G37: =AVERAGE(G2:G36) -> #DIV/0! | H37: =AVERAGE(H2:H36) -> #DIV/0! | J37: =AVERAGE(J2:J36) -> #DIV/0!
A38: TOTAL | B38: =SUM(B2:B36) -> 0 | D38: =SUM(D2:D36) -> 0 | E38: =AVERAGE(E9:E27) -> #DIV/0! | F38: =AVERAGE(F9:F27) -> #DIV/0! | G38: =SUM(G2:G36) -> 0 | H38: =AVERAGE(H9:H27) -> #DIV/0! | I38: =J38/G38 -> #DIV/0! | J38: =SUM(J2:J36) -> 0
