Workbook

Sheet Capa
E1: Planejamento dos Produtos
B2: Menu
C3: Iniciando o planejamento do produto de Mentoria digital
C5: O processo funciona da seguinte forma:
C6: 1. Planejamento Inicial - Vamos escolher o melhor produto para começarmos à produtizar
C7: 2. Conhecendo os Clientes - Vamos entender quem são as pessoas à que se destinam esse produto e com quem vamos nos comunicar
C8: 3. Grandes Marcos do Processo (Fases) - Vamos arquitetar uma visão MACRO como as peças se encaixam em direção ao sucesso
C9: 4. Passo a Passo da Transformação (Etapas) - Indo a fundo em cada fase, com uma visão MICRO, quais são as atividades executadas passo a passo
C10: 5. Estabelecendo a os Eventos da Agenda - Dentro desse processo, quais são aqueles eventos exclusivos com o cliente que eu não posso abrir mão
C11: 6. Diagnóstico e Personalização - Quais foram as informações que eu precisarei obter de antemão para tomar as decisões ao longo do projeto
C12: 7. Como montar o Conteúdo - Definiremos como cada passo será transcrito para a plataforma, garantindo o sucesso do meu produto

Sheet Planejamento Inicial
E1: Planejamento dos Produtos
B2: Menu
C3: Escolhendo por onde começar - Escolha um dos seus produtos para começar
C5: Produtos | D5: Qtd de clientes que já atendeu | E5: Projeção de venda nos próximos 6 meses (QTD) | F5: Ticket Médio | G5: Já faturado | H5: Potencial de Faturamento (6 meses) | I5: PROVÁVEL MELHOR OPÇÃO | J5: =LARGE(H6:H13,1) -> 7500000 | K5: Dicas
C6: Implementação de CRM | D6: 25 | E6: 50 | F6: 150000 | G6: =F6*D6 -> 3750000 | H6: =E6*F6 -> 7500000 | I6: =IF(C6="","",IF(ISERROR(VLOOKUP(H6,$J$5,1,0))," ","X")) -> X
G7: =F7*D7 -> 0 | H7: =E7*F7 -> 0 | I7: =IF(C7="","",IF(ISERROR(VLOOKUP(H7,$J$5,1,0))," ","X"))
G8: =F8*D8 -> 0 | H8: =E8*F8 -> 0 | I8: =IF(C8="","",IF(ISERROR(VLOOKUP(H8,$J$5,1,0))," ","X"))
G9: =F9*D9 -> 0 | H9: =E9*F9 -> 0 | I9: =IF(C9="","",IF(ISERROR(VLOOKUP(H9,$J$5,1,0))," ","X"))
G10: =F10*D10 -> 0 | H10: =E10*F10 -> 0 | I10: =IF(C10="","",IF(ISERROR(VLOOKUP(H10,$J$5,1,0))," ","X"))
G11: =F11*D11 -> 0 | H11: =E11*F11 -> 0 | I11: =IF(C11="","",IF(ISERROR(VLOOKUP(H11,$J$5,1,0))," ","X"))
G12: =F12*D12 -> 0 | H12: =E12*F12 -> 0 | I12: =IF(C12="","",IF(ISERROR(VLOOKUP(G12,$J$5,1,0))," ","X"))
G13: =F13*D13 -> 0 | H13: =E13*F13 -> 0 | I13: =IF(C13="","",IF(ISERROR(VLOOKUP(G13,$J$5,1,0))," ","X"))

Sheet Conhecendo os Clientes
E1: Planejamento dos Produtos
B2: Menu
C3: Perfil do Cliente
C5: Qual é o seu Perfil do Cliente Ideal? | K5: Dicas
C8: Perfil médio do interlocutor?
C11: Situação média do cliente ANTES da contratação:
C14: Situação futura do cliente DEPOIS da Mentoria (enriqueça a resposta):

Sheet (Fases) Grandes Marcos
E1: Planejamento dos Produtos
B2: Menu
C3: Descrevendo as Fases - Para atingir o resultado pretendido liste os principais pontos de transformação que seu cliente passará.
C5: FASES DO PROJETO | E5: Resultado Pretendido (Valor entregue ao cliente nessa fase) | H5: O que você faz durante esse processo que garante esse resultado? | K5: Dicas
B6: Fase1 | C6: Boas Vindas Onboarding | E6: Garantir que está tudo pronto para começar o projeto com sucesso | H6: Executamos uma reunião de kickoff e estabeleço alguns acordos importantes para o processo.
B7: Fase2
B8: Fase3
B9: Fase4
B10: Fase5
B11: Fase6
B12: Fase7
B13: Fase8
B14: Fase9
B15: Fase10
B16: Fase11
B17: Fase12
B18: Fase13
... B40: Fase35

Sheet (Etapas) Passo a Passo
E1: Planejamento dos Produtos
B2: Menu
C3: Descrevendo as Etapas - Quais são os passos necessários para promover o trecho de transformação pretendido na fase
C5: ETAPA | D5: Transformação Pretendida (que mudanças ocorreram ao final da etapa?) | F5: Necessita verificar? | G5: Documentos | Ferramentas utilizadas | H5: Pulos do Gato (o que precisamos fazer para garantir que a transformação pretendida ocorra?) | K5: Dicas
B6: Fase1 | C6: ='(Fases) Grandes Marcos'!C6 -> Boas Vindas Onboarding | D6: Conhecer os novos Estrategistas, o Serviço, a Plataforma e Evitar problemas futuros ao longo do processo | F6: Não é necessário verificar nada | G6: 1- Cronograma passo a passo (PDF) | H6: Video de Dicas para melhor aproveitar que estabeleceça autoridade e reconhecimento do consultor
C13: Checklist Final de Fase | D13: Garantir que o cliente revisou o que foi feito até agora, e que o consultor analise todas as partes do processo até aqui.
C15: ='(Fases) Grandes Marcos'!$E$5 -> Resultado Pretendido (Valor entregue ao cliente nessa fase) | D15: ='(Fases) Grandes Marcos'!E6 -> Garantir que está tudo pronto para começar o projeto com sucesso | G15: ='(Fases) Grandes Marcos'!$H$5 -> O que você faz durante esse processo que garante esse resultado? | H15: ='(Fases) Grandes Marcos'!H6 -> Executamos uma reunião de kickoff e estabeleço alguns acordos importantes para o processo.
C17: ETAPA | D17: Transformação Pretendida (que mudanças ocorreram ao final da etapa?) | F17: Necessita verificar? | G17: Documentos | Ferramentas utilizadas | H17: Pulos do Gato (o que precisamos fazer para garantir que a transformação pretendida ocorra?)
B18: Fase2 | C18: ='(Fases) Grandes Marcos'!C7 | D18: Estruturação de um planejamento estratégico completo para trazer visão interna e externa de longo prazo. | F18: Entregar material obrigatório para o cliente | G18: 1- Check List da Etapa (PDF) | H18: Preenchimento junto ao cliente para implicar nas principais dores do cliente
C25: Checklist Final de Fase | D25: Garantir que o cliente revisou o que foi feito até agora, e que o consultor analise todas as partes do processo até aqui.
C27: ='(Fases) Grandes Marcos'!$E$5 -> Resultado Pretendido (Valor entregue ao cliente nessa fase) | D27: ='(Fases) Grandes Marcos'!E7 | G27: ='(Fases) Grandes Marcos'!$H$5 -> O que você faz durante esse processo que garante esse resultado? | H27: ='(Fases) Grandes Marcos'!H7
C29: ETAPA | D29: Transformação Pretendida (que mudanças ocorreram ao final da etapa?) | F29: Necessita verificar? | G29: Documentos | Ferramentas utilizadas | H29: Pulos do Gato (o que precisamos fazer para garantir que a transformação pretendida ocorra?)
B30: Fase3 | C30: ='(Fases) Grandes Marcos'!C8
C40: Checklist Final de Fase | D40: Garantir que o cliente revisou o que foi feito até agora, e que o consultor analise todas as partes do processo até aqui.
C42: ='(Fases) Grandes Marcos'!$E$5 -> Resultado Pretendido (Valor entregue ao cliente nessa fase) | D42: ='(Fases) Grandes Marcos'!E8 | G42: ='(Fases) Grandes Marcos'!$H$5 -> O que você faz durante esse processo que garante esse resultado? | H42: ='(Fases) Grandes Marcos'!H8
C44: ETAPA | D44: Transformação Pretendida (que mudanças ocorreram ao final da etapa?) | F44: Necessita verificar? | G44: Documentos | Ferramentas utilizadas | H44: Pulos do Gato (o que precisamos fazer para garantir que a transformação pretendida ocorra?)
B45: Fase4 | C45: ='(Fases) Grandes Marcos'!C9
C58: Checklist Final de Fase | D58: Garantir que o cliente revisou o que foi feito até agora, e que o consultor analise todas as partes do processo até aqui.
C60: ='(Fases) Grandes Marcos'!$E$5 -> Resultado Pretendido (Valor entregue ao cliente nessa fase) | D60: ='(Fases) Grandes Marcos'!E9 | G60: ='(Fases) Grandes Marcos'!$H$5 -> O que você faz durante esse processo que garante esse resultado? | H60: ='(Fases) Grandes Marcos'!H9
C62: ETAPA | D62: Transformação Pretendida (que mudanças ocorreram ao final da etapa?) | F62: Necessita verificar? | G62: Documentos | Ferramentas utilizadas | H62: Pulos do Gato (o que precisamos fazer para garantir que a transformação pretendida ocorra?)
B63: Fase5 | C63: ='(Fases) Grandes Marcos'!C10
C75: ='(Fases) Grandes Marcos'!$E$5 -> Resultado Pretendido (Valor entregue ao cliente nessa fase) | D75: ='(Fases) Grandes Marcos'!E10 | G75: ='(Fases) Grandes Marcos'!$H$5 -> O que você faz durante esse processo que garante esse resultado? | H75: ='(Fases) Grandes Marcos'!H10
C77: ETAPA | D77: Transformação Pretendida (que mudanças ocorreram ao final da etapa?) | F77: Necessita verificar? | G77: Documentos | Ferramentas utilizadas | H77: Pulos do Gato (o que precisamos fazer para garantir que a transformação pretendida ocorra?)
B78: Fase6 | C78: ='(Fases) Grandes Marcos'!C11
C85: Checklist Final de Fase | D85: Garantir que o cliente revisou o que foi feito até agora, e que o consultor analise todas as partes do processo até aqui.
C87: ='(Fases) Grandes Marcos'!$E$5 -> Resultado Pretendido (Valor entregue ao cliente nessa fase) | D87: ='(Fases) Grandes Marcos'!E11 | G87: ='(Fases) Grandes Marcos'!$H$5 -> O que você faz durante esse processo que garante esse resultado? | H87: ='(Fases) Grandes Marcos'!H11
C89: ETAPA | D89: Transformação Pretendida (que mudanças ocorreram ao final da etapa?) | F89: Necessita verificar? | G89: Documentos | Ferramentas utilizadas | H89: Pulos do Gato (o que precisamos fazer para garantir que a transformação pretendida ocorra?)
B90: Fase7 | C90: ='(Fases) Grandes Marcos'!C12
C97: Checklist Final de Fase | D97: Garantir que o cliente revisou o que foi feito até agora, e que o consultor analise todas as partes do processo até aqui.
C99: ='(Fases) Grandes Marcos'!$E$5 -> Resultado Pretendido (Valor entregue ao cliente nessa fase) | D99: ='(Fases) Grandes Marcos'!E12 | G99: ='(Fases) Grandes Marcos'!$H$5 -> O que você faz durante esse processo que garante esse resultado? | H99: ='(Fases) Grandes Marcos'!H12
C101: ETAPA | D101: Transformação Pretendida (que mudanças ocorreram ao final da etapa?) | F101: Necessita verificar? | G101: Documentos | Ferramentas utilizadas | H101: Pulos do Gato (o que precisamos fazer para garantir que a transformação pretendida ocorra?)
B102: Fase7 | C102: ='(Fases) Grandes Marcos'!C13
C109: Checklist Final de Fase | D109: Garantir que o cliente revisou o que foi feito até agora, e que o consultor analise todas as partes do processo até aqui.
C111: ='(Fases) Grandes Marcos'!$E$5 -> Resultado Pretendido (Valor entregue ao cliente nessa fase) | D111: ='(Fases) Grandes Marcos'!E13 | G111: ='(Fases) Grandes Marcos'!$H$5 -> O que você faz durante esse processo que garante esse resultado? | H111: ='(Fases) Grandes Marcos'!H13
C113: ETAPA | D113: Transformação Pretendida (que mudanças ocorreram ao final da etapa?) | F113: Necessita verificar? | G113: Documentos | Ferramentas utilizadas | H113: Pulos do Gato (o que precisamos fazer para garantir que a transformação pretendida ocorra?)
B114: Fase8 | C114: ='(Fases) Grandes Marcos'!C14
C121: Checklist Final de Fase | D121: Garantir que o cliente revisou o que foi feito até agora, e que o consultor analise todas as partes do processo até aqui.
C123: ='(Fases) Grandes Marcos'!$E$5 -> Resultado Pretendido (Valor entregue ao cliente nessa fase) | D123: ='(Fases) Grandes Marcos'!E14 | G123: ='(Fases) Grandes Marcos'!$H$5 -> O que você faz durante esse processo que garante esse resultado? | H123: ='(Fases) Grandes Marcos'!H14
C125: ETAPA | D125: Transformação Pretendida (que mudanças ocorreram ao final da etapa?) | F125: Necessita verificar? | G125: Documentos | Ferramentas utilizadas | H125: Pulos do Gato (o que precisamos fazer para garantir que a transformação pretendida ocorra?)
B126: Fase9 | C126: ='(Fases) Grandes Marcos'!C15
...

Sheet Eventos da Agenda
E1: Planejamento dos Produtos
B2: Menu
C3: Definindo os eventos padrão de atenção exclusiva do consultor ao projeto
C5: NOME DOS EVENTOS PADRÃO DO PROJETO | E5: Objetivo do Evento | G5: Em quantos dias úteis, a partir do início do projeto, o evento precisa acontecer? | H5: Existe uma relação com alguma fase? | K5: Dicas
C6: Exemplo: Kickoff do Projeto | E6: Iniciar o cliente sobre os principais pontos que passaremos ao longo do cronograma e gerar uma experiência imersiva na plataforma | G6: 0 | H6: Boas Vindas

Sheet Diagnóstico
E1: Planejamento dos Produtos
B2: Menu
C3: Como o diagnóstico prévio do cliente interfere na disposição das fases do seu cronograma?
C5: PERGUNTAS QUE PRECISAM SER RESPONDIDAS PARA COMPREENDER O PANORAMA DO CLIENTE. | F5: Quem precisa responder e registrar? | H5: Essa pergunta determina se alguma fase deverá ser excluída ou adicionada ao cronograma? | K5: Dicas
C6: Exemplo: Quantos colaboradores possui a sua empresa? | F6: O Cliente deve responder | H6: Exemplo: Não
C7: Exemplo2: Sua empresa possui um setor de desenvolvimento de Software? | F7: O Cliente deve responder | H7: Exemplo2: Caso ele responda não, vamos excluir a fase sobre a análise do processo de desenvolvimento de software
C8: Exemplo3: O cliente está preparado para fazer o processo avançado? | F8: O Consultor deve responder | H8: Exemplo3: Caso ele responda não, a fase sobre o processo avançado não aparece para o cliente, e ao invés disso, aparece a fase do processo básico.
C9: (Apague os exemplos e preencha com a sua realidade)

Sheet Conteúdo
E1: Planejamento dos Produtos
B2: Menu
C3: Como estruturar o conteúdo do seu serviço no processo de produtização? - Role até o final
E5: Veja o Exemplo | H5: Nossa Análise: | K5: Dicas
B6: 1 | C6: Introdução - Mini Texto | E6: O primeiro passo para as boas práticas de gestão financeira é separar as contas da empresa, das contas de seus sócios. Nessa etapa, está disponibilizada uma planilha para que o(s) dono(s) possa(m) lançar suas despesas e definir o valor adequado de seu pró-labore. | H6: Veja como esse é um texto curto e objetivo focado no que será feito nessa etapa e qual o benefício da execução dessa atividade.
B7: 2 | K7: Vamos validar as primeiras fases do se produto, e quando estiver tudo certo, vamos dar o próximo passo:
B8: 3
B9: 4
B10: 5
C12: Agora é a sua Vez, para cada etapa, crie os seguintes conteúdos:
D13: 1 | F13: 2 | G13: 3 | H13: 4 | I13: 5
C14: ETAPAS | D14: INTRODUÇÃO - Mini Texto | F14: Vídeo em destaque | G14: Atividade de transformação | H14: Texto em destaque / dicas / alertas | I14: Tópicos de Informações Complementares
B15: Fase1 | C15: ='(Etapas) Passo a Passo'!C6 -> Boas Vindas Onboarding | K15: ="Escreva uma frase que comunique ao cliente que acontecerá nessa etapa ("&L15&")" -> Escreva uma frase que comunique ao cliente que acontecerá nessa etapa (Conhecer os novos Estrategistas, o Serviço, a Plataforma e Evitar problemas futuros ao longo do processo) | L15: {='(Etapas) Passo a Passo'!D6:E6} -> Conhecer os novos Estrategistas, o Serviço, a Plataforma e Evitar problemas futuros ao longo do processo
C16: ='(Etapas) Passo a Passo'!C7
C17: ='(Etapas) Passo a Passo'!C8
C18: ='(Etapas) Passo a Passo'!C9
C19: ='(Etapas) Passo a Passo'!C10
C20: ='(Etapas) Passo a Passo'!C11
C21: ='(Etapas) Passo a Passo'!C12
C22: ='(Etapas) Passo a Passo'!C13 -> Checklist Final de Fase
D24: 1 | F24: 2 | G24: 3 | H24: 4 | I24: 5
C25: ETAPAS | D25: INTRODUÇÃO - Mini Texto | F25: Vídeo em destaque | G25: Atividade de transformação | H25: Texto em destaque / dicas / alertas | I25: Tópicos de Informações Complementares
B26: Fase2 | C26: ='(Etapas) Passo a Passo'!C18
C27: ='(Etapas) Passo a Passo'!C19
C28: ='(Etapas) Passo a Passo'!C20
C29: ='(Etapas) Passo a Passo'!C22
C30: ='(Etapas) Passo a Passo'!C23
C31: ='(Etapas) Passo a Passo'!C24
C32: ='(Etapas) Passo a Passo'!C25 -> Checklist Final de Fase
C33: ='(Etapas) Passo a Passo'!#REF! -> #ERROR!
C35: Já aprendeu a fazer? Que tal continuarmos esse processo dentro da plataforma?
C42: Não deixe de chamar o seu especialista para lhe ajudar!

Sheet controle
A1: Operações
A2: Entregar material opcional como download
A3: Entregar material obrigatório para o cliente
A4: Entregar material e solicitar devolução obrigatória
A5: Entregar material e solicitar devolução obrigatória com ok do especialista
A6: Solicitar ao cliente upload apenas
A7: Solicitar upload e ok do especialista
A8: Solicitar resposta simples do cliente
A9: Solicitar resposta simples do cliente com ok do especialista
A10: Não é necessário verificar nada

Sheet model
E1: Planejamento dos Produtos
B2: Menu
C3: Escolhendo por onde começar - Escolha um dos seus produtos para começar
B4: Assista
K5: Dicas
