Workbook
Name zsupermetrics_forceRefresh: SupermetricsQueries!$H$4
Name zsupermetrics_refreshAll: SupermetricsQueries!$H$5
Name zsupermetrics_refreshAllSilent: SupermetricsQueries!$H$6

Sheet Início
C3: Com esta planilha você conseguirá fazer uma Análise SWOT Organizacional de acordo com os seus objetivos a curto prazo. Coloque detalhadamente os fatores internos (forças e fraquezas) e fatores externos (oportunidades e ameaças) quanto a gestão de seu negócio/ projeto para extrair as melhores e maiores reflexões possíveis.
B4: IMPORTANTE: LEIA OS PASSOS E ENTENDA A PLANILHA
C6: Passo 1 | E6: FATORES INTERNOS
C7: Segundo a metodologia da análise SWOT a matriz é composta por elementos que compõem o ambiente interno e externo da empresa
C9: Forças: defina a lista com as suas forças, o que faz com que os clientes optem por seu negócio; qual disponibilidade de recursos imprescindíveis para a manutenção dos serviços ou produtos; o que diferencia seu negócio dos demais.
C10: Fraquezas: defina a lista com as suas fraquezas (altos custos com transporte; maiores gastos com a manutenção de equipamentos, colaboradores com valor/hora mais caro etc).
C11: Passo 2 | E11: FATORES EXTERNOS
C12: Após ter definido os fatores internos, defina os seus fatores externos: oportunidades e ameaças.
C14: Oportunidades: defina a lista com as oportunidades (fatores econômicos, oportunidades que estão surgindo e mudanças do mercado que podem favorecer seus clientes).
C15: Ameaças: defina a lista com as ameaças identificadas no mercado (cenário no qual se concentram todos os fatores desfavoráveis para a empresa). Assim, além da ausência de controle sobre as questões, elas se apresentam como grandes ameaças para o negócio.
C20: Passo 3 | E20: MATRIZ SWOT
C22: Nesta parte da planilha será possível visualizar a visão geral da sua pontuação para as forças, fraquezas, oportunidades e ameaças. A partir desta visão, você terá o retorno da planilha sobre o seu momento profissional atual (desenvolvimento, manutenção, crescimento e sobrevivência). Além dos indicadores, veja também a lista com todas as forças, fraquezas, ameaças e oportunidades hierarquizadas, de acordo com sua pontuação.
C25: Passo 4 | E25: CRUZAMENTOS
C26: Uma vez definido seus fatores internos e externos, chegou a hora de cruzar os dados combinando suas forças e fraquezas com ameças e oportunidades. Você pode traçar planos de ação para as combinações.
C37: Passo 5 | E37: OBJETIVOS ESTRATÉGICOS
C39: Objetivo é o resultado desejado pela organização que ao ser atingindo sustenta o seu sucesso ao longo de um período de tempo.
C42: Passo 6 | E42: DESDOBRAMENTOS
C43: Como os objetivos estratégicos se aplicam a realidade da empresa? Onde eles serão atingidos? Nessa etapa entenderemos o papel de cada aspecto da empresa para alcançar esses objetivos e atingir assim os resultados esperados.
C45: Passo 7 | E45: PLANOS DE AÇÃO
C46: Crie planos de ação de acordo com os principais itens da Análise SWOT e dos Cruzamentos feitas para obter grandes melhorias no curto e longo prazos.
C51: Passo 8 | E51: RESULTADOS SWOT
C52: Veja os resultados da SWOT como Índice de Favorabilidade, Análise Individual dos Fatores Internos e Externose gráficos da Matriz SWOT.
C55: Passo 9 | E55: RESULTADOS PLANOS DE AÇÃO
C56: Veja os resultados dos seus planos de ação graficamente.
C58: Gráficos: gráficos de desenvolvimento de planos de ação, status e conformidade dos planos em execução.
C59: Análise por Área: veja a análise geral em relação aos planos de ação com cada status e o desempenho geral delas.
C61: Passo 10 | E61: PAINEL DE CONTROLE
C62: Veja os resultados da SWOT como Índice de Favorabilidade, Análise Individual dos Fatores Internos e Externose gráficos da Matriz SWOT.
C65: Passo 11 | E65: RELATÓRIO DE IMPRESSÃO
C66: Imprima somente o que importa. Esta parte gera um relatório formatado para impressão com seu plano de ação para todas as combinações entre forças, fraquezas, oportunidades e ameaças. Além disso, tenha os gráficos, a lista hierarquizada, o ínidice de favorabilidade e as dicas.

Sheet Forças
C4: Item | D4: Importância | E4: Intensidade | F4: Tendência | G4: Pontuação | S4: 1 | T4: 1 | U4: 1 | V4: 1 | W4: 2 | X4: 2 | Y4: 2 | Z4: 2 | AA4: 2 | AB4: 2 | AC4: 2 | AD4: 2 | AE4: 2 | AF4: 2 | AG4: 2 | AH4: 2 | AI4: 3 | AJ4: 3 | AK4: 3 | AL4: 3 | AM4: 3 | AN4: 3 | AO4: 3 | AP4: 3 | AQ4: 3 | AR4: 3 | AS4: 3 | AT4: 3
C5: Ex.: A marca é reconhecida no mercado | D5: Ex.: Importante | E5: Ex.: Média | F5: Ex.: Mantém | G5: Ex.: 27 | H5: Importância
G6: =IF(ISERROR(VLOOKUP(D6,$I$6:$J$10,2,FALSE)*VLOOKUP(E6,$I$14:$J$18,2,FALSE)*VLOOKUP(F6,$I$22:$J$26,2,FALSE)),"",VLOOKUP(D6,$I$6:$J$10,2,FALSE)*VLOOKUP(E6,$I$14:$J$18,2,FALSE)*VLOOKUP(F6,$I$22:$J$26,2,FALSE)) | I6: Sem importância | J6: 1 | L6: 0.0002 | M6: =IF(G6="","",G6+L6) | N6: =IF(C6=0,"",C6) | O6: =G6
G7: =IF(ISERROR(VLOOKUP(D7,$I$6:$J$10,2,FALSE)*VLOOKUP(E7,$I$14:$J$18,2,FALSE)*VLOOKUP(F7,$I$22:$J$26,2,FALSE)),"",VLOOKUP(D7,$I$6:$J$10,2,FALSE)*VLOOKUP(E7,$I$14:$J$18,2,FALSE)*VLOOKUP(F7,$I$22:$J$26,2,FALSE)) | I7: Pouco importante | J7: 2 | L7: 0.00018 | M7: =IF(G7="","",G7+L7) | N7: =IF(C7=0,"",C7) | O7: =G7
G8: =IF(ISERROR(VLOOKUP(D8,$I$6:$J$10,2,FALSE)*VLOOKUP(E8,$I$14:$J$18,2,FALSE)*VLOOKUP(F8,$I$22:$J$26,2,FALSE)),"",VLOOKUP(D8,$I$6:$J$10,2,FALSE)*VLOOKUP(E8,$I$14:$J$18,2,FALSE)*VLOOKUP(F8,$I$22:$J$26,2,FALSE)) | I8: Importante | J8: 3 | L8: 0.00017 | M8: =IF(G8="","",G8+L8) | N8: =IF(C8=0,"",C8) | O8: =G8
G9: =IF(ISERROR(VLOOKUP(D9,$I$6:$J$10,2,FALSE)*VLOOKUP(E9,$I$14:$J$18,2,FALSE)*VLOOKUP(F9,$I$22:$J$26,2,FALSE)),"",VLOOKUP(D9,$I$6:$J$10,2,FALSE)*VLOOKUP(E9,$I$14:$J$18,2,FALSE)*VLOOKUP(F9,$I$22:$J$26,2,FALSE)) | I9: Muito importante | J9: 4 | L9: 0.00016 | M9: =IF(G9="","",G9+L9) | N9: =IF(C9=0,"",C9) | O9: =G9
G10: =IF(ISERROR(VLOOKUP(D10,$I$6:$J$10,2,FALSE)*VLOOKUP(E10,$I$14:$J$18,2,FALSE)*VLOOKUP(F10,$I$22:$J$26,2,FALSE)),"",VLOOKUP(D10,$I$6:$J$10,2,FALSE)*VLOOKUP(E10,$I$14:$J$18,2,FALSE)*VLOOKUP(F10,$I$22:$J$26,2,FALSE)) | I10: Totalmente importante | J10: 5 | L10: 0.00015 | M10: =IF(G10="","",G10+L10) | N10: =IF(C10=0,"",C10) | O10: =G10
G11: =IF(ISERROR(VLOOKUP(D11,$I$6:$J$10,2,FALSE)*VLOOKUP(E11,$I$14:$J$18,2,FALSE)*VLOOKUP(F11,$I$22:$J$26,2,FALSE)),"",VLOOKUP(D11,$I$6:$J$10,2,FALSE)*VLOOKUP(E11,$I$14:$J$18,2,FALSE)*VLOOKUP(F11,$I$22:$J$26,2,FALSE)) | L11: 0.00014 | M11: =IF(G11="","",G11+L11) | N11: =IF(C11=0,"",C11) | O11: =G11
I12: Intensidade | L12: 0.00013 | M12: =IF(G12="","",G12+L12) | N12: =IF(C12=0,"",C12) | O12: =G12
L13: 0.00012 | M13: =IF(G13="","",G13+L13) | N13: =IF(C13=0,"",C13) | O13: =G13
I14: Muito forte | J14: 5 | L14: 0.00011 | M14: =IF(G14="","",G14+L14) | N14: =IF(C14=0,"",C14) | O14: =G14
I15: Forte | J15: 4 | L15: 0.0001 | M15: =IF(G15="","",G15+L15) | N15: =IF(C15=0,"",C15) | O15: =G15
I16: Média | J16: 3 | L16: 9e-05 | M16: =IF(G16="","",G16+L16) | N16: =IF(C16=0,"",C16) | O16: =G16
I17: Fraca | J17: 2 | L17: 8e-05 | M17: =IF(G17="","",G17+L17) | N17: =IF(C17=0,"",C17) | O17: =G17
I18: Muito fraca | J18: 1 | L18: 7e-05 | M18: =IF(G18="","",G18+L18) | N18: =IF(C18=0,"",C18) | O18: =G18
L19: 6e-05 | M19: =IF(G19="","",G19+L19) | N19: =IF(C19=0,"",C19) | O19: =G19
I20: Tendência | L20: 5e-05 | M20: =IF(G20="","",G20+L20) | N20: =IF(C20=0,"",C20) | O20: =G20
G21: =IF(ISERROR(VLOOKUP(D21,$I$6:$J$10,2,FALSE)*VLOOKUP(E21,$I$14:$J$18,2,FALSE)*VLOOKUP(F21,$I$22:$J$26,2,FALSE)),"",VLOOKUP(D21,$I$6:$J$10,2,FALSE)*VLOOKUP(E21,$I$14:$J$18,2,FALSE)*VLOOKUP(F21,$I$22:$J$26,2,FALSE)) | L21: 4e-05 | M21: =IF(G21="","",G21+L21) | N21: =IF(C21=0,"",C21) | O21: =G21
G22: =IF(ISERROR(VLOOKUP(D22,$I$6:$J$10,2,FALSE)*VLOOKUP(E22,$I$14:$J$18,2,FALSE)*VLOOKUP(F22,$I$22:$J$26,2,FALSE)),"",VLOOKUP(D22,$I$6:$J$10,2,FALSE)*VLOOKUP(E22,$I$14:$J$18,2,FALSE)*VLOOKUP(F22,$I$22:$J$26,2,FALSE)) | I22: Melhora muito | J22: 5 | L22: 3e-05 | M22: =IF(G22="","",G22+L22) | N22: =IF(C22=0,"",C22) | O22: =G22
G23: =IF(ISERROR(VLOOKUP(D23,$I$6:$J$10,2,FALSE)*VLOOKUP(E23,$I$14:$J$18,2,FALSE)*VLOOKUP(F23,$I$22:$J$26,2,FALSE)),"",VLOOKUP(D23,$I$6:$J$10,2,FALSE)*VLOOKUP(E23,$I$14:$J$18,2,FALSE)*VLOOKUP(F23,$I$22:$J$26,2,FALSE)) | I23: Melhora | J23: 4 | L23: 2e-05 | M23: =IF(G23="","",G23+L23) | N23: =IF(C23=0,"",C23) | O23: =G23
G24: =IF(ISERROR(VLOOKUP(D24,$I$6:$J$10,2,FALSE)*VLOOKUP(E24,$I$14:$J$18,2,FALSE)*VLOOKUP(F24,$I$22:$J$26,2,FALSE)),"",VLOOKUP(D24,$I$6:$J$10,2,FALSE)*VLOOKUP(E24,$I$14:$J$18,2,FALSE)*VLOOKUP(F24,$I$22:$J$26,2,FALSE)) | I24: Mantém | J24: 3 | L24: 1e-05 | M24: =IF(G24="","",G24+L24) | N24: =IF(C24=0,"",C24) | O24: =G24
C25: Pontuação geral das suas Forças | F25: → | G25: =SUM(G6:G24) -> 0 | I25: Piora | J25: 2 | M25: =IF(G25="","",G25+L25) -> 0 | N25: =IF(C25=0,"",C25) -> Pontuação geral das suas Forças | O25: =G25 -> 0
I26: Piora muito | J26: 1 | M26: =IF(G26="","",G26+L26) | N26: =IF(C26=0,"",C26) | O26: =G26
M27: =IF(G27="","",G27+L27) | N27: =IF(C27=0,"",C27) | O27: =G27
M28: =IF(G28="","",G28+L28) | N28: =IF(C28=0,"",C28) | O28: =G28
M29: =IF(G29="","",G29+L29) | O29: =G29
M30: =IF(G30="","",G30+L30)

Sheet Fraquezas
C4: Item | D4: Importância | E4: Intensidade | F4: Tendência | G4: Pontuação | S4: 1 | T4: 1 | U4: 1 | V4: 1 | W4: 2 | X4: 2 | Y4: 2 | Z4: 2 | AA4: 2 | AB4: 2 | AC4: 2 | AD4: 2 | AE4: 2 | AF4: 2 | AG4: 2 | AH4: 2 | AI4: 3 | AJ4: 3 | AK4: 3 | AL4: 3 | AM4: 3 | AN4: 3 | AO4: 3 | AP4: 3 | AQ4: 3 | AR4: 3 | AS4: 3 | AT4: 3
C5: Ex.: A marca é reconhecida no mercado | D5: Ex.: Importante | E5: Ex.: Média | F5: Ex.: Mantém | G5: Ex.: 27
G6: =IF(ISERROR(VLOOKUP(D6,$I$7:$J$11,2,FALSE)*VLOOKUP(E6,$I$15:$J$19,2,FALSE)*VLOOKUP(F6,$I$23:$J$27,2,FALSE)),"",VLOOKUP(D6,$I$7:$J$11,2,FALSE)*VLOOKUP(E6,$I$15:$J$19,2,FALSE)*VLOOKUP(F6,$I$23:$J$27,2,FALSE)) | L6: 0.00019 | M6: =IF(G6="","",G6+L6) | N6: =IF(C6=0,"",C6) | O6: =G6
G7: =IF(ISERROR(VLOOKUP(D7,$I$7:$J$11,2,FALSE)*VLOOKUP(E7,$I$15:$J$19,2,FALSE)*VLOOKUP(F7,$I$23:$J$27,2,FALSE)),"",VLOOKUP(D7,$I$7:$J$11,2,FALSE)*VLOOKUP(E7,$I$15:$J$19,2,FALSE)*VLOOKUP(F7,$I$23:$J$27,2,FALSE)) | I7: Sem importância | J7: 1 | L7: 0.00018 | M7: =IF(G7="","",G7+L7) | N7: =IF(C7=0,"",C7) | O7: =G7
G8: =IF(ISERROR(VLOOKUP(D8,$I$7:$J$11,2,FALSE)*VLOOKUP(E8,$I$15:$J$19,2,FALSE)*VLOOKUP(F8,$I$23:$J$27,2,FALSE)),"",VLOOKUP(D8,$I$7:$J$11,2,FALSE)*VLOOKUP(E8,$I$15:$J$19,2,FALSE)*VLOOKUP(F8,$I$23:$J$27,2,FALSE)) | I8: Pouco importante | J8: 2 | L8: 0.00017 | M8: =IF(G8="","",G8+L8) | N8: =IF(C8=0,"",C8) | O8: =G8
G9: =IF(ISERROR(VLOOKUP(D9,$I$7:$J$11,2,FALSE)*VLOOKUP(E9,$I$15:$J$19,2,FALSE)*VLOOKUP(F9,$I$23:$J$27,2,FALSE)),"",VLOOKUP(D9,$I$7:$J$11,2,FALSE)*VLOOKUP(E9,$I$15:$J$19,2,FALSE)*VLOOKUP(F9,$I$23:$J$27,2,FALSE)) | I9: Importante | J9: 3 | L9: 0.00016 | M9: =IF(G9="","",G9+L9) | N9: =IF(C9=0,"",C9) | O9: =G9
G10: =IF(ISERROR(VLOOKUP(D10,$I$7:$J$11,2,FALSE)*VLOOKUP(E10,$I$15:$J$19,2,FALSE)*VLOOKUP(F10,$I$23:$J$27,2,FALSE)),"",VLOOKUP(D10,$I$7:$J$11,2,FALSE)*VLOOKUP(E10,$I$15:$J$19,2,FALSE)*VLOOKUP(F10,$I$23:$J$27,2,FALSE)) | I10: Muito importante | J10: 4 | L10: 0.00015 | M10: =IF(G10="","",G10+L10) | N10: =IF(C10=0,"",C10) | O10: =G10
G11: =IF(ISERROR(VLOOKUP(D11,$I$7:$J$11,2,FALSE)*VLOOKUP(E11,$I$15:$J$19,2,FALSE)*VLOOKUP(F11,$I$23:$J$27,2,FALSE)),"",VLOOKUP(D11,$I$7:$J$11,2,FALSE)*VLOOKUP(E11,$I$15:$J$19,2,FALSE)*VLOOKUP(F11,$I$23:$J$27,2,FALSE)) | I11: Totalmente importante | J11: 5 | L11: 0.00014 | M11: =IF(G11="","",G11+L11) | N11: =IF(C11=0,"",C11) | O11: =G11
G12: =IF(ISERROR(VLOOKUP(D12,$I$7:$J$11,2,FALSE)*VLOOKUP(E12,$I$15:$J$19,2,FALSE)*VLOOKUP(F12,$I$23:$J$27,2,FALSE)),"",VLOOKUP(D12,$I$7:$J$11,2,FALSE)*VLOOKUP(E12,$I$15:$J$19,2,FALSE)*VLOOKUP(F12,$I$23:$J$27,2,FALSE)) | L12: 0.00013 | M12: =IF(G12="","",G12+L12) | N12: =IF(C12=0,"",C12) | O12: =G12
G13: =IF(ISERROR(VLOOKUP(D13,$I$7:$J$11,2,FALSE)*VLOOKUP(E13,$I$15:$J$19,2,FALSE)*VLOOKUP(F13,$I$23:$J$27,2,FALSE)),"",VLOOKUP(D13,$I$7:$J$11,2,FALSE)*VLOOKUP(E13,$I$15:$J$19,2,FALSE)*VLOOKUP(F13,$I$23:$J$27,2,FALSE)) | I13: Intensidade | L13: 0.00012 | M13: =IF(G13="","",G13+L13) | N13: =IF(C13=0,"",C13) | O13: =G13
G14: =IF(ISERROR(VLOOKUP(D14,$I$7:$J$11,2,FALSE)*VLOOKUP(E14,$I$15:$J$19,2,FALSE)*VLOOKUP(F14,$I$23:$J$27,2,FALSE)),"",VLOOKUP(D14,$I$7:$J$11,2,FALSE)*VLOOKUP(E14,$I$15:$J$19,2,FALSE)*VLOOKUP(F14,$I$23:$J$27,2,FALSE)) | L14: 0.00011 | M14: =IF(G14="","",G14+L14) | N14: =IF(C14=0,"",C14) | O14: =G14
G15: =IF(ISERROR(VLOOKUP(D15,$I$7:$J$11,2,FALSE)*VLOOKUP(E15,$I$15:$J$19,2,FALSE)*VLOOKUP(F15,$I$23:$J$27,2,FALSE)),"",VLOOKUP(D15,$I$7:$J$11,2,FALSE)*VLOOKUP(E15,$I$15:$J$19,2,FALSE)*VLOOKUP(F15,$I$23:$J$27,2,FALSE)) | I15: Muito forte | J15: 1 | L15: 0.0001 | M15: =IF(G15="","",G15+L15) | N15: =IF(C15=0,"",C15) | O15: =G15
G16: =IF(ISERROR(VLOOKUP(D16,$I$7:$J$11,2,FALSE)*VLOOKUP(E16,$I$15:$J$19,2,FALSE)*VLOOKUP(F16,$I$23:$J$27,2,FALSE)),"",VLOOKUP(D16,$I$7:$J$11,2,FALSE)*VLOOKUP(E16,$I$15:$J$19,2,FALSE)*VLOOKUP(F16,$I$23:$J$27,2,FALSE)) | I16: Forte | J16: 2 | L16: 9e-05 | M16: =IF(G16="","",G16+L16) | N16: =IF(C16=0,"",C16) | O16: =G16
G17: =IF(ISERROR(VLOOKUP(D17,$I$7:$J$11,2,FALSE)*VLOOKUP(E17,$I$15:$J$19,2,FALSE)*VLOOKUP(F17,$I$23:$J$27,2,FALSE)),"",VLOOKUP(D17,$I$7:$J$11,2,FALSE)*VLOOKUP(E17,$I$15:$J$19,2,FALSE)*VLOOKUP(F17,$I$23:$J$27,2,FALSE)) | I17: Média | J17: 3 | L17: 8e-05 | M17: =IF(G17="","",G17+L17) | N17: =IF(C17=0,"",C17) | O17: =G17
G18: =IF(ISERROR(VLOOKUP(D18,$I$7:$J$11,2,FALSE)*VLOOKUP(E18,$I$15:$J$19,2,FALSE)*VLOOKUP(F18,$I$23:$J$27,2,FALSE)),"",VLOOKUP(D18,$I$7:$J$11,2,FALSE)*VLOOKUP(E18,$I$15:$J$19,2,FALSE)*VLOOKUP(F18,$I$23:$J$27,2,FALSE)) | I18: Fraca | J18: 4 | L18: 7e-05 | M18: =IF(G18="","",G18+L18) | N18: =IF(C18=0,"",C18) | O18: =G18
G19: =IF(ISERROR(VLOOKUP(D19,$I$7:$J$11,2,FALSE)*VLOOKUP(E19,$I$15:$J$19,2,FALSE)*VLOOKUP(F19,$I$23:$J$27,2,FALSE)),"",VLOOKUP(D19,$I$7:$J$11,2,FALSE)*VLOOKUP(E19,$I$15:$J$19,2,FALSE)*VLOOKUP(F19,$I$23:$J$27,2,FALSE)) | I19: Muito fraca | J19: 5 | L19: 6e-05 | M19: =IF(G19="","",G19+L19) | N19: =IF(C19=0,"",C19) | O19: =G19
G20: =IF(ISERROR(VLOOKUP(D20,$I$7:$J$11,2,FALSE)*VLOOKUP(E20,$I$15:$J$19,2,FALSE)*VLOOKUP(F20,$I$23:$J$27,2,FALSE)),"",VLOOKUP(D20,$I$7:$J$11,2,FALSE)*VLOOKUP(E20,$I$15:$J$19,2,FALSE)*VLOOKUP(F20,$I$23:$J$27,2,FALSE)) | L20: 5e-05 | M20: =IF(G20="","",G20+L20) | N20: =IF(C20=0,"",C20) | O20: =G20
G21: =IF(ISERROR(VLOOKUP(D21,$I$7:$J$11,2,FALSE)*VLOOKUP(E21,$I$15:$J$19,2,FALSE)*VLOOKUP(F21,$I$23:$J$27,2,FALSE)),"",VLOOKUP(D21,$I$7:$J$11,2,FALSE)*VLOOKUP(E21,$I$15:$J$19,2,FALSE)*VLOOKUP(F21,$I$23:$J$27,2,FALSE)) | I21: Tendência | L21: 4e-05 | M21: =IF(G21="","",G21+L21) | N21: =IF(C21=0,"",C21) | O21: =G21
G22: =IF(ISERROR(VLOOKUP(D22,$I$7:$J$11,2,FALSE)*VLOOKUP(E22,$I$15:$J$19,2,FALSE)*VLOOKUP(F22,$I$23:$J$27,2,FALSE)),"",VLOOKUP(D22,$I$7:$J$11,2,FALSE)*VLOOKUP(E22,$I$15:$J$19,2,FALSE)*VLOOKUP(F22,$I$23:$J$27,2,FALSE)) | L22: 3e-05 | M22: =IF(G22="","",G22+L22) | N22: =IF(C22=0,"",C22) | O22: =G22
G23: =IF(ISERROR(VLOOKUP(D23,$I$7:$J$11,2,FALSE)*VLOOKUP(E23,$I$15:$J$19,2,FALSE)*VLOOKUP(F23,$I$23:$J$27,2,FALSE)),"",VLOOKUP(D23,$I$7:$J$11,2,FALSE)*VLOOKUP(E23,$I$15:$J$19,2,FALSE)*VLOOKUP(F23,$I$23:$J$27,2,FALSE)) | I23: Melhora muito | J23: 1 | L23: 2e-05 | M23: =IF(G23="","",G23+L23) | N23: =IF(C23=0,"",C23) | O23: =G23
G24: =IF(ISERROR(VLOOKUP(D24,$I$7:$J$11,2,FALSE)*VLOOKUP(E24,$I$15:$J$19,2,FALSE)*VLOOKUP(F24,$I$23:$J$27,2,FALSE)),"",VLOOKUP(D24,$I$7:$J$11,2,FALSE)*VLOOKUP(E24,$I$15:$J$19,2,FALSE)*VLOOKUP(F24,$I$23:$J$27,2,FALSE)) | I24: Melhora | J24: 2 | L24: 1e-05 | M24: =IF(G24="","",G24+L24) | N24: =IF(C24=0,"",C24) | O24: =G24
C25: Pontuação geral das suas Fraquezas | F25: → | G25: =SUM(G6:G24) -> 0 | I25: Mantém | J25: 3 | N25: =IF(C25=0,"",C25) -> Pontuação geral das suas Fraquezas
I26: Piora | J26: 4 | N26: =IF(C26=0,"",C26)
I27: Piora muito | J27: 5 | N27: =IF(C27=0,"",C27)
N28: =IF(C28=0,"",C28)

Sheet Oportunidades
C4: Item | D4: Importância | E4: Urgência | F4: Tendência | G4: Pontuação | S4: 1 | T4: 1 | U4: 1 | V4: 1 | W4: 2 | X4: 2 | Y4: 2 | Z4: 2 | AA4: 2 | AB4: 2 | AC4: 2 | AD4: 2 | AE4: 2 | AF4: 2 | AG4: 2 | AH4: 2 | AI4: 3 | AJ4: 3 | AK4: 3 | AL4: 3 | AM4: 3 | AN4: 3 | AO4: 3 | AP4: 3 | AQ4: 3 | AR4: 3 | AS4: 3 | AT4: 3
C5: Ex.: Existem mercados inexplorados | D5: Ex.: Importante | E5: Ex.: Urgente | F5: Ex.: Mantém | G5: Ex.: 27
G6: =IF(ISERROR(VLOOKUP(D6,$I$8:$J$12,2,FALSE)*VLOOKUP(E6,$I$16:$J$20,2,FALSE)*VLOOKUP(F6,$I$24:$J$28,2,FALSE)),"",VLOOKUP(D6,$I$8:$J$12,2,FALSE)*VLOOKUP(E6,$I$16:$J$20,2,FALSE)*VLOOKUP(F6,$I$24:$J$28,2,FALSE)) | I6: Importância | L6: 0.0002 | M6: =IF(G6="","",G6+L7) | N6: =IF(C6=0,"",C6) | O6: =G6
G7: =IF(ISERROR(VLOOKUP(D7,$I$8:$J$12,2,FALSE)*VLOOKUP(E7,$I$16:$J$20,2,FALSE)*VLOOKUP(F7,$I$24:$J$28,2,FALSE)),"",VLOOKUP(D7,$I$8:$J$12,2,FALSE)*VLOOKUP(E7,$I$16:$J$20,2,FALSE)*VLOOKUP(F7,$I$24:$J$28,2,FALSE)) | L7: 0.00019 | M7: =IF(G7="","",G7+L8) | N7: =IF(C7=0,"",C7) | O7: =G7
G8: =IF(ISERROR(VLOOKUP(D8,$I$8:$J$12,2,FALSE)*VLOOKUP(E8,$I$16:$J$20,2,FALSE)*VLOOKUP(F8,$I$24:$J$28,2,FALSE)),"",VLOOKUP(D8,$I$8:$J$12,2,FALSE)*VLOOKUP(E8,$I$16:$J$20,2,FALSE)*VLOOKUP(F8,$I$24:$J$28,2,FALSE)) | I8: Sem importância | J8: 1 | L8: 0.00018 | M8: =IF(G8="","",G8+L9) | N8: =IF(C8=0,"",C8) | O8: =G8
G9: =IF(ISERROR(VLOOKUP(D9,$I$8:$J$12,2,FALSE)*VLOOKUP(E9,$I$16:$J$20,2,FALSE)*VLOOKUP(F9,$I$24:$J$28,2,FALSE)),"",VLOOKUP(D9,$I$8:$J$12,2,FALSE)*VLOOKUP(E9,$I$16:$J$20,2,FALSE)*VLOOKUP(F9,$I$24:$J$28,2,FALSE)) | I9: Pouco importante | J9: 2 | L9: 0.00017 | M9: =IF(G9="","",G9+L10) | N9: =IF(C9=0,"",C9) | O9: =G9
G10: =IF(ISERROR(VLOOKUP(D10,$I$8:$J$12,2,FALSE)*VLOOKUP(E10,$I$16:$J$20,2,FALSE)*VLOOKUP(F10,$I$24:$J$28,2,FALSE)),"",VLOOKUP(D10,$I$8:$J$12,2,FALSE)*VLOOKUP(E10,$I$16:$J$20,2,FALSE)*VLOOKUP(F10,$I$24:$J$28,2,FALSE)) | I10: Importante | J10: 3 | L10: 0.00016 | M10: =IF(G10="","",G10+L11) | N10: =IF(C10=0,"",C10) | O10: =G10
G11: =IF(ISERROR(VLOOKUP(D11,$I$8:$J$12,2,FALSE)*VLOOKUP(E11,$I$16:$J$20,2,FALSE)*VLOOKUP(F11,$I$24:$J$28,2,FALSE)),"",VLOOKUP(D11,$I$8:$J$12,2,FALSE)*VLOOKUP(E11,$I$16:$J$20,2,FALSE)*VLOOKUP(F11,$I$24:$J$28,2,FALSE)) | I11: Muito importante | J11: 4 | L11: 0.00015 | M11: =IF(G11="","",G11+L12) | N11: =IF(C11=0,"",C11) | O11: =G11
G12: =IF(ISERROR(VLOOKUP(D12,$I$8:$J$12,2,FALSE)*VLOOKUP(E12,$I$16:$J$20,2,FALSE)*VLOOKUP(F12,$I$24:$J$28,2,FALSE)),"",VLOOKUP(D12,$I$8:$J$12,2,FALSE)*VLOOKUP(E12,$I$16:$J$20,2,FALSE)*VLOOKUP(F12,$I$24:$J$28,2,FALSE)) | I12: Totalmente importante | J12: 5 | L12: 0.00014 | M12: =IF(G12="","",G12+L13) | N12: =IF(C12=0,"",C12) | O12: =G12
G13: =IF(ISERROR(VLOOKUP(D13,$I$8:$J$12,2,FALSE)*VLOOKUP(E13,$I$16:$J$20,2,FALSE)*VLOOKUP(F13,$I$24:$J$28,2,FALSE)),"",VLOOKUP(D13,$I$8:$J$12,2,FALSE)*VLOOKUP(E13,$I$16:$J$20,2,FALSE)*VLOOKUP(F13,$I$24:$J$28,2,FALSE)) | L13: 0.00013 | M13: =IF(G13="","",G13+L14) | N13: =IF(C13=0,"",C13) | O13: =G13
G14: =IF(ISERROR(VLOOKUP(D14,$I$8:$J$12,2,FALSE)*VLOOKUP(E14,$I$16:$J$20,2,FALSE)*VLOOKUP(F14,$I$24:$J$28,2,FALSE)),"",VLOOKUP(D14,$I$8:$J$12,2,FALSE)*VLOOKUP(E14,$I$16:$J$20,2,FALSE)*VLOOKUP(F14,$I$24:$J$28,2,FALSE)) | I14: Urgência | L14: 0.00012 | M14: =IF(G14="","",G14+L15) | N14: =IF(C14=0,"",C14) | O14: =G14
G15: =IF(ISERROR(VLOOKUP(D15,$I$8:$J$12,2,FALSE)*VLOOKUP(E15,$I$16:$J$20,2,FALSE)*VLOOKUP(F15,$I$24:$J$28,2,FALSE)),"",VLOOKUP(D15,$I$8:$J$12,2,FALSE)*VLOOKUP(E15,$I$16:$J$20,2,FALSE)*VLOOKUP(F15,$I$24:$J$28,2,FALSE)) | L15: 0.00011 | M15: =IF(G15="","",G15+L16) | N15: =IF(C15=0,"",C15) | O15: =G15
G16: =IF(ISERROR(VLOOKUP(D16,$I$8:$J$12,2,FALSE)*VLOOKUP(E16,$I$16:$J$20,2,FALSE)*VLOOKUP(F16,$I$24:$J$28,2,FALSE)),"",VLOOKUP(D16,$I$8:$J$12,2,FALSE)*VLOOKUP(E16,$I$16:$J$20,2,FALSE)*VLOOKUP(F16,$I$24:$J$28,2,FALSE)) | I16: Nada urgente | J16: 1 | L16: 0.0001 | M16: =IF(G16="","",G16+L17) | N16: =IF(C16=0,"",C16) | O16: =G16
G17: =IF(ISERROR(VLOOKUP(D17,$I$8:$J$12,2,FALSE)*VLOOKUP(E17,$I$16:$J$20,2,FALSE)*VLOOKUP(F17,$I$24:$J$28,2,FALSE)),"",VLOOKUP(D17,$I$8:$J$12,2,FALSE)*VLOOKUP(E17,$I$16:$J$20,2,FALSE)*VLOOKUP(F17,$I$24:$J$28,2,FALSE)) | I17: Pouco urgente | J17: 2 | L17: 9e-05 | M17: =IF(G17="","",G17+L18) | N17: =IF(C17=0,"",C17) | O17: =G17
G18: =IF(ISERROR(VLOOKUP(D18,$I$8:$J$12,2,FALSE)*VLOOKUP(E18,$I$16:$J$20,2,FALSE)*VLOOKUP(F18,$I$24:$J$28,2,FALSE)),"",VLOOKUP(D18,$I$8:$J$12,2,FALSE)*VLOOKUP(E18,$I$16:$J$20,2,FALSE)*VLOOKUP(F18,$I$24:$J$28,2,FALSE)) | I18: Urgente | J18: 3 | L18: 8e-05 | M18: =IF(G18="","",G18+L19) | N18: =IF(C18=0,"",C18) | O18: =G18
G19: =IF(ISERROR(VLOOKUP(D19,$I$8:$J$12,2,FALSE)*VLOOKUP(E19,$I$16:$J$20,2,FALSE)*VLOOKUP(F19,$I$24:$J$28,2,FALSE)),"",VLOOKUP(D19,$I$8:$J$12,2,FALSE)*VLOOKUP(E19,$I$16:$J$20,2,FALSE)*VLOOKUP(F19,$I$24:$J$28,2,FALSE)) | I19: Muito urgente | J19: 4 | L19: 7e-05 | M19: =IF(G19="","",G19+L20) | N19: =IF(C19=0,"",C19) | O19: =G19
G20: =IF(ISERROR(VLOOKUP(D20,$I$8:$J$12,2,FALSE)*VLOOKUP(E20,$I$16:$J$20,2,FALSE)*VLOOKUP(F20,$I$24:$J$28,2,FALSE)),"",VLOOKUP(D20,$I$8:$J$12,2,FALSE)*VLOOKUP(E20,$I$16:$J$20,2,FALSE)*VLOOKUP(F20,$I$24:$J$28,2,FALSE)) | I20: Pra ontem | J20: 5 | L20: 6e-05 | M20: =IF(G20="","",G20+L21) | N20: =IF(C20=0,"",C20) | O20: =G20
G21: =IF(ISERROR(VLOOKUP(D21,$I$8:$J$12,2,FALSE)*VLOOKUP(E21,$I$16:$J$20,2,FALSE)*VLOOKUP(F21,$I$24:$J$28,2,FALSE)),"",VLOOKUP(D21,$I$8:$J$12,2,FALSE)*VLOOKUP(E21,$I$16:$J$20,2,FALSE)*VLOOKUP(F21,$I$24:$J$28,2,FALSE)) | L21: 5e-05 | M21: =IF(G21="","",G21+L22) | N21: =IF(C21=0,"",C21) | O21: =G21
G22: =IF(ISERROR(VLOOKUP(D22,$I$8:$J$12,2,FALSE)*VLOOKUP(E22,$I$16:$J$20,2,FALSE)*VLOOKUP(F22,$I$24:$J$28,2,FALSE)),"",VLOOKUP(D22,$I$8:$J$12,2,FALSE)*VLOOKUP(E22,$I$16:$J$20,2,FALSE)*VLOOKUP(F22,$I$24:$J$28,2,FALSE)) | I22: Tendência | L22: 4e-05 | M22: =IF(G22="","",G22+L23) | N22: =IF(C22=0,"",C22) | O22: =G22
G23: =IF(ISERROR(VLOOKUP(D23,$I$8:$J$12,2,FALSE)*VLOOKUP(E23,$I$16:$J$20,2,FALSE)*VLOOKUP(F23,$I$24:$J$28,2,FALSE)),"",VLOOKUP(D23,$I$8:$J$12,2,FALSE)*VLOOKUP(E23,$I$16:$J$20,2,FALSE)*VLOOKUP(F23,$I$24:$J$28,2,FALSE)) | L23: 3e-05 | M23: =IF(G23="","",G23+L24) | N23: =IF(C23=0,"",C23) | O23: =G23
G24: =IF(ISERROR(VLOOKUP(D24,$I$8:$J$12,2,FALSE)*VLOOKUP(E24,$I$16:$J$20,2,FALSE)*VLOOKUP(F24,$I$24:$J$28,2,FALSE)),"",VLOOKUP(D24,$I$8:$J$12,2,FALSE)*VLOOKUP(E24,$I$16:$J$20,2,FALSE)*VLOOKUP(F24,$I$24:$J$28,2,FALSE)) | I24: Melhora muito | J24: 5 | L24: 2e-05 | M24: =IF(G24="","",G24+L25) | N24: =IF(C24=0,"",C24) | O24: =G24
G25: =IF(ISERROR(VLOOKUP(D25,$I$8:$J$12,2,FALSE)*VLOOKUP(E25,$I$16:$J$20,2,FALSE)*VLOOKUP(F25,$I$24:$J$28,2,FALSE)),"",VLOOKUP(D25,$I$8:$J$12,2,FALSE)*VLOOKUP(E25,$I$16:$J$20,2,FALSE)*VLOOKUP(F25,$I$24:$J$28,2,FALSE)) | I25: Melhora | J25: 4 | L25: 1e-05 | M25: =IF(G25="","",G25+L26) | N25: =IF(C25=0,"",C25) | O25: =G25
C26: Pontuação geral das suas Oportunidades | F26: → | G26: =SUM(G6:G25) -> 0 | I26: Mantém | J26: 3
I27: Piora | J27: 2
I28: Piora muito | J28: 1

Sheet Ameaças
C4: Item | D4: Importância | E4: Urgência | F4: Tendência | G4: Pontuação | S4: 1 | T4: 1 | U4: 1 | V4: 1 | W4: 2 | X4: 2 | Y4: 2 | Z4: 2 | AA4: 2 | AB4: 2 | AC4: 2 | AD4: 2 | AE4: 2 | AF4: 2 | AG4: 2 | AH4: 2 | AI4: 3 | AJ4: 3 | AK4: 3 | AL4: 3 | AM4: 3 | AN4: 3 | AO4: 3 | AP4: 3 | AQ4: 3 | AR4: 3 | AS4: 3 | AT4: 3
C5: Ex.: Existem mercados inexplorados | D5: Ex.: Importante | E5: Ex.: Urgente | F5: Ex.: Mantém | G5: Ex.: 27
G6: =IF(ISERROR(VLOOKUP(D6,$I$8:$J$12,2,FALSE)*VLOOKUP(E6,$I$16:$J$20,2,FALSE)*VLOOKUP(F6,$I$24:$J$28,2,FALSE)),"",VLOOKUP(D6,$I$8:$J$12,2,FALSE)*VLOOKUP(E6,$I$16:$J$20,2,FALSE)*VLOOKUP(F6,$I$24:$J$28,2,FALSE)) | I6: Importância | L6: 0.0002 | M6: =IF(G6="","",G6+L7) | N6: =IF(C6=0,"",C6) | O6: =G6
G7: =IF(ISERROR(VLOOKUP(D7,$I$8:$J$12,2,FALSE)*VLOOKUP(E7,$I$16:$J$20,2,FALSE)*VLOOKUP(F7,$I$24:$J$28,2,FALSE)),"",VLOOKUP(D7,$I$8:$J$12,2,FALSE)*VLOOKUP(E7,$I$16:$J$20,2,FALSE)*VLOOKUP(F7,$I$24:$J$28,2,FALSE)) | L7: 0.00019 | M7: =IF(G7="","",G7+L8) | N7: =IF(C7=0,"",C7) | O7: =G7
G8: =IF(ISERROR(VLOOKUP(D8,$I$8:$J$12,2,FALSE)*VLOOKUP(E8,$I$16:$J$20,2,FALSE)*VLOOKUP(F8,$I$24:$J$28,2,FALSE)),"",VLOOKUP(D8,$I$8:$J$12,2,FALSE)*VLOOKUP(E8,$I$16:$J$20,2,FALSE)*VLOOKUP(F8,$I$24:$J$28,2,FALSE)) | I8: Sem importância | J8: 1 | L8: 0.00018 | M8: =IF(G8="","",G8+L9) | N8: =IF(C8=0,"",C8) | O8: =G8
G9: =IF(ISERROR(VLOOKUP(D9,$I$8:$J$12,2,FALSE)*VLOOKUP(E9,$I$16:$J$20,2,FALSE)*VLOOKUP(F9,$I$24:$J$28,2,FALSE)),"",VLOOKUP(D9,$I$8:$J$12,2,FALSE)*VLOOKUP(E9,$I$16:$J$20,2,FALSE)*VLOOKUP(F9,$I$24:$J$28,2,FALSE)) | I9: Pouco importante | J9: 2 | L9: 0.00017 | M9: =IF(G9="","",G9+L10) | N9: =IF(C9=0,"",C9) | O9: =G9
G10: =IF(ISERROR(VLOOKUP(D10,$I$8:$J$12,2,FALSE)*VLOOKUP(E10,$I$16:$J$20,2,FALSE)*VLOOKUP(F10,$I$24:$J$28,2,FALSE)),"",VLOOKUP(D10,$I$8:$J$12,2,FALSE)*VLOOKUP(E10,$I$16:$J$20,2,FALSE)*VLOOKUP(F10,$I$24:$J$28,2,FALSE)) | I10: Importante | J10: 3 | L10: 0.00016 | M10: =IF(G10="","",G10+L11) | N10: =IF(C10=0,"",C10) | O10: =G10
G11: =IF(ISERROR(VLOOKUP(D11,$I$8:$J$12,2,FALSE)*VLOOKUP(E11,$I$16:$J$20,2,FALSE)*VLOOKUP(F11,$I$24:$J$28,2,FALSE)),"",VLOOKUP(D11,$I$8:$J$12,2,FALSE)*VLOOKUP(E11,$I$16:$J$20,2,FALSE)*VLOOKUP(F11,$I$24:$J$28,2,FALSE)) | I11: Muito importante | J11: 4 | L11: 0.00015 | M11: =IF(G11="","",G11+L12) | N11: =IF(C11=0,"",C11) | O11: =G11
G12: =IF(ISERROR(VLOOKUP(D12,$I$8:$J$12,2,FALSE)*VLOOKUP(E12,$I$16:$J$20,2,FALSE)*VLOOKUP(F12,$I$24:$J$28,2,FALSE)),"",VLOOKUP(D12,$I$8:$J$12,2,FALSE)*VLOOKUP(E12,$I$16:$J$20,2,FALSE)*VLOOKUP(F12,$I$24:$J$28,2,FALSE)) | I12: Totalmente importante | J12: 5 | L12: 0.00014 | M12: =IF(G12="","",G12+L13) | N12: =IF(C12=0,"",C12) | O12: =G12
G13: =IF(ISERROR(VLOOKUP(D13,$I$8:$J$12,2,FALSE)*VLOOKUP(E13,$I$16:$J$20,2,FALSE)*VLOOKUP(F13,$I$24:$J$28,2,FALSE)),"",VLOOKUP(D13,$I$8:$J$12,2,FALSE)*VLOOKUP(E13,$I$16:$J$20,2,FALSE)*VLOOKUP(F13,$I$24:$J$28,2,FALSE)) | L13: 0.00013 | M13: =IF(G13="","",G13+L14) | N13: =IF(C13=0,"",C13) | O13: =G13
G14: =IF(ISERROR(VLOOKUP(D14,$I$8:$J$12,2,FALSE)*VLOOKUP(E14,$I$16:$J$20,2,FALSE)*VLOOKUP(F14,$I$24:$J$28,2,FALSE)),"",VLOOKUP(D14,$I$8:$J$12,2,FALSE)*VLOOKUP(E14,$I$16:$J$20,2,FALSE)*VLOOKUP(F14,$I$24:$J$28,2,FALSE)) | I14: Urgência | L14: 0.00012 | M14: =IF(G14="","",G14+L15) | N14: =IF(C14=0,"",C14) | O14: =G14
G15: =IF(ISERROR(VLOOKUP(D15,$I$8:$J$12,2,FALSE)*VLOOKUP(E15,$I$16:$J$20,2,FALSE)*VLOOKUP(F15,$I$24:$J$28,2,FALSE)),"",VLOOKUP(D15,$I$8:$J$12,2,FALSE)*VLOOKUP(E15,$I$16:$J$20,2,FALSE)*VLOOKUP(F15,$I$24:$J$28,2,FALSE)) | L15: 0.00011 | M15: =IF(G15="","",G15+L16) | N15: =IF(C15=0,"",C15) | O15: =G15
G16: =IF(ISERROR(VLOOKUP(D16,$I$8:$J$12,2,FALSE)*VLOOKUP(E16,$I$16:$J$20,2,FALSE)*VLOOKUP(F16,$I$24:$J$28,2,FALSE)),"",VLOOKUP(D16,$I$8:$J$12,2,FALSE)*VLOOKUP(E16,$I$16:$J$20,2,FALSE)*VLOOKUP(F16,$I$24:$J$28,2,FALSE)) | I16: Nada urgente | J16: 1 | L16: 0.0001 | M16: =IF(G16="","",G16+L17) | N16: =IF(C16=0,"",C16) | O16: =G16
G17: =IF(ISERROR(VLOOKUP(D17,$I$8:$J$12,2,FALSE)*VLOOKUP(E17,$I$16:$J$20,2,FALSE)*VLOOKUP(F17,$I$24:$J$28,2,FALSE)),"",VLOOKUP(D17,$I$8:$J$12,2,FALSE)*VLOOKUP(E17,$I$16:$J$20,2,FALSE)*VLOOKUP(F17,$I$24:$J$28,2,FALSE)) | I17: Pouco urgente | J17: 2 | L17: 9e-05 | M17: =IF(G17="","",G17+L18) | N17: =IF(C17=0,"",C17) | O17: =G17
G18: =IF(ISERROR(VLOOKUP(D18,$I$8:$J$12,2,FALSE)*VLOOKUP(E18,$I$16:$J$20,2,FALSE)*VLOOKUP(F18,$I$24:$J$28,2,FALSE)),"",VLOOKUP(D18,$I$8:$J$12,2,FALSE)*VLOOKUP(E18,$I$16:$J$20,2,FALSE)*VLOOKUP(F18,$I$24:$J$28,2,FALSE)) | I18: Urgente | J18: 3 | L18: 8e-05 | M18: =IF(G18="","",G18+L19) | N18: =IF(C18=0,"",C18) | O18: =G18
G19: =IF(ISERROR(VLOOKUP(D19,$I$8:$J$12,2,FALSE)*VLOOKUP(E19,$I$16:$J$20,2,FALSE)*VLOOKUP(F19,$I$24:$J$28,2,FALSE)),"",VLOOKUP(D19,$I$8:$J$12,2,FALSE)*VLOOKUP(E19,$I$16:$J$20,2,FALSE)*VLOOKUP(F19,$I$24:$J$28,2,FALSE)) | I19: Muito urgente | J19: 4 | L19: 7e-05 | M19: =IF(G19="","",G19+L20) | N19: =IF(C19=0,"",C19) | O19: =G19
G20: =IF(ISERROR(VLOOKUP(D20,$I$8:$J$12,2,FALSE)*VLOOKUP(E20,$I$16:$J$20,2,FALSE)*VLOOKUP(F20,$I$24:$J$28,2,FALSE)),"",VLOOKUP(D20,$I$8:$J$12,2,FALSE)*VLOOKUP(E20,$I$16:$J$20,2,FALSE)*VLOOKUP(F20,$I$24:$J$28,2,FALSE)) | I20: Pra ontem | J20: 5 | L20: 6e-05 | M20: =IF(G20="","",G20+L21) | N20: =IF(C20=0,"",C20) | O20: =G20
G21: =IF(ISERROR(VLOOKUP(D21,$I$8:$J$12,2,FALSE)*VLOOKUP(E21,$I$16:$J$20,2,FALSE)*VLOOKUP(F21,$I$24:$J$28,2,FALSE)),"",VLOOKUP(D21,$I$8:$J$12,2,FALSE)*VLOOKUP(E21,$I$16:$J$20,2,FALSE)*VLOOKUP(F21,$I$24:$J$28,2,FALSE)) | L21: 5e-05 | M21: =IF(G21="","",G21+L22) | N21: =IF(C21=0,"",C21) | O21: =G21
G22: =IF(ISERROR(VLOOKUP(D22,$I$8:$J$12,2,FALSE)*VLOOKUP(E22,$I$16:$J$20,2,FALSE)*VLOOKUP(F22,$I$24:$J$28,2,FALSE)),"",VLOOKUP(D22,$I$8:$J$12,2,FALSE)*VLOOKUP(E22,$I$16:$J$20,2,FALSE)*VLOOKUP(F22,$I$24:$J$28,2,FALSE)) | I22: Tendência | L22: 4e-05 | M22: =IF(G22="","",G22+L23) | N22: =IF(C22=0,"",C22) | O22: =G22
G23: =IF(ISERROR(VLOOKUP(D23,$I$8:$J$12,2,FALSE)*VLOOKUP(E23,$I$16:$J$20,2,FALSE)*VLOOKUP(F23,$I$24:$J$28,2,FALSE)),"",VLOOKUP(D23,$I$8:$J$12,2,FALSE)*VLOOKUP(E23,$I$16:$J$20,2,FALSE)*VLOOKUP(F23,$I$24:$J$28,2,FALSE)) | L23: 3e-05 | M23: =IF(G23="","",G23+L24) | N23: =IF(C23=0,"",C23) | O23: =G23
G24: =IF(ISERROR(VLOOKUP(D24,$I$8:$J$12,2,FALSE)*VLOOKUP(E24,$I$16:$J$20,2,FALSE)*VLOOKUP(F24,$I$24:$J$28,2,FALSE)),"",VLOOKUP(D24,$I$8:$J$12,2,FALSE)*VLOOKUP(E24,$I$16:$J$20,2,FALSE)*VLOOKUP(F24,$I$24:$J$28,2,FALSE)) | I24: Melhora muito | J24: 1 | L24: 2e-05 | M24: =IF(G24="","",G24+L25) | N24: =IF(C24=0,"",C24) | O24: =G24
G25: =IF(ISERROR(VLOOKUP(D25,$I$8:$J$12,2,FALSE)*VLOOKUP(E25,$I$16:$J$20,2,FALSE)*VLOOKUP(F25,$I$24:$J$28,2,FALSE)),"",VLOOKUP(D25,$I$8:$J$12,2,FALSE)*VLOOKUP(E25,$I$16:$J$20,2,FALSE)*VLOOKUP(F25,$I$24:$J$28,2,FALSE)) | I25: Melhora | J25: 2 | L25: 1e-05 | M25: =IF(G25="","",G25+L26) | N25: =IF(C25=0,"",C25) | O25: =G25
C26: Pontuação geral das suas Ameaças | F26: → | G26: =SUM(G6:G25) -> 0 | I26: Mantém | J26: 3
I27: Piora | J27: 4
I28: Piora muito | J28: 5

Sheet Matriz SWOT
C4: 1. Fatores internos
C5: 1.1 Top 5 Forças | D5: =SUM(D6:D10) -> 0 | E5: 1.2 Top 5 Fraquezas | F5: =SUM(F6:F10) -> 0 | H5: 0.0002 | I5: =H5+L5 -> 0.0002 | J5: =C6 | K5: Força | L5: =D6 -> 0
B6: 1 | C6: =IF(ISERROR(VLOOKUP(LARGE('Forças'!$M$6:$M$24,$B6),'Forças'!$M$6:$N$24,2,FALSE)),"",VLOOKUP(LARGE('Forças'!$M$6:$M$24,$B6),'Forças'!$M$6:$N$24,2,FALSE)) | D6: =IF(ISERROR(VLOOKUP(LARGE('Forças'!$M$6:$M$24,$B6),'Forças'!$M$6:$O$24,3,FALSE)),0,VLOOKUP(LARGE('Forças'!$M$6:$M$24,$B6),'Forças'!$M$6:$O$24,3,FALSE)) -> 0 | E6: =IF(ISERROR(VLOOKUP(LARGE(Fraquezas!$M$6:$M$24,$B6),Fraquezas!$M$6:$N$24,2,FALSE)),"",VLOOKUP(LARGE(Fraquezas!$M$6:$M$24,$B6),Fraquezas!$M$6:$N$24,2,FALSE)) | F6: =IF(ISERROR(VLOOKUP(LARGE(Fraquezas!$M$6:$M$24,$B6),Fraquezas!$M$6:$O$24,3,FALSE)),0,VLOOKUP(LARGE(Fraquezas!$M$6:$M$24,$B6),Fraquezas!$M$6:$O$24,3,FALSE)) -> 0 | H6: 0.00019 | I6: =H6+L6 -> 0.00019 | J6: =C7 | K6: Força | L6: =D7 -> 0
B7: 2 | C7: =IF(ISERROR(VLOOKUP(LARGE('Forças'!$M$6:$M$24,$B7),'Forças'!$M$6:$N$24,2,FALSE)),"",VLOOKUP(LARGE('Forças'!$M$6:$M$24,$B7),'Forças'!$M$6:$N$24,2,FALSE)) | D7: =IF(ISERROR(VLOOKUP(LARGE('Forças'!$M$6:$M$24,$B7),'Forças'!$M$6:$O$24,3,FALSE)),0,VLOOKUP(LARGE('Forças'!$M$6:$M$24,$B7),'Forças'!$M$6:$O$24,3,FALSE)) -> 0 | E7: =IF(ISERROR(VLOOKUP(LARGE(Fraquezas!$M$6:$M$24,$B7),Fraquezas!$M$6:$N$24,2,FALSE)),"",VLOOKUP(LARGE(Fraquezas!$M$6:$M$24,$B7),Fraquezas!$M$6:$N$24,2,FALSE)) | F7: =IF(ISERROR(VLOOKUP(LARGE(Fraquezas!$M$6:$M$24,$B7),Fraquezas!$M$6:$O$24,3,FALSE)),0,VLOOKUP(LARGE(Fraquezas!$M$6:$M$24,$B7),Fraquezas!$M$6:$O$24,3,FALSE)) -> 0 | H7: 0.00018 | I7: =H7+L7 -> 0.00018 | J7: =C8 | K7: Força | L7: =D8 -> 0
B8: 3 | C8: =IF(ISERROR(VLOOKUP(LARGE('Forças'!$M$6:$M$24,$B8),'Forças'!$M$6:$N$24,2,FALSE)),"",VLOOKUP(LARGE('Forças'!$M$6:$M$24,$B8),'Forças'!$M$6:$N$24,2,FALSE)) | D8: =IF(ISERROR(VLOOKUP(LARGE('Forças'!$M$6:$M$24,$B8),'Forças'!$M$6:$O$24,3,FALSE)),0,VLOOKUP(LARGE('Forças'!$M$6:$M$24,$B8),'Forças'!$M$6:$O$24,3,FALSE)) -> 0 | E8: =IF(ISERROR(VLOOKUP(LARGE(Fraquezas!$M$6:$M$24,$B8),Fraquezas!$M$6:$N$24,2,FALSE)),"",VLOOKUP(LARGE(Fraquezas!$M$6:$M$24,$B8),Fraquezas!$M$6:$N$24,2,FALSE)) | F8: =IF(ISERROR(VLOOKUP(LARGE(Fraquezas!$M$6:$M$24,$B8),Fraquezas!$M$6:$O$24,3,FALSE)),0,VLOOKUP(LARGE(Fraquezas!$M$6:$M$24,$B8),Fraquezas!$M$6:$O$24,3,FALSE)) -> 0 | H8: 0.00017 | I8: =H8+L8 -> 0.00017 | J8: =C9 | K8: Força | L8: =D9 -> 0
B9: 4 | C9: =IF(ISERROR(VLOOKUP(LARGE('Forças'!$M$6:$M$24,$B9),'Forças'!$M$6:$N$24,2,FALSE)),"",VLOOKUP(LARGE('Forças'!$M$6:$M$24,$B9),'Forças'!$M$6:$N$24,2,FALSE)) | D9: =IF(ISERROR(VLOOKUP(LARGE('Forças'!$M$6:$M$24,$B9),'Forças'!$M$6:$O$24,3,FALSE)),0,VLOOKUP(LARGE('Forças'!$M$6:$M$24,$B9),'Forças'!$M$6:$O$24,3,FALSE)) -> 0 | E9: =IF(ISERROR(VLOOKUP(LARGE(Fraquezas!$M$6:$M$24,$B9),Fraquezas!$M$6:$N$24,2,FALSE)),"",VLOOKUP(LARGE(Fraquezas!$M$6:$M$24,$B9),Fraquezas!$M$6:$N$24,2,FALSE)) | F9: =IF(ISERROR(VLOOKUP(LARGE(Fraquezas!$M$6:$M$24,$B9),Fraquezas!$M$6:$O$24,3,FALSE)),0,VLOOKUP(LARGE(Fraquezas!$M$6:$M$24,$B9),Fraquezas!$M$6:$O$24,3,FALSE)) -> 0 | H9: 0.00016 | I9: =H9+L9 -> 0.00016 | J9: =C10 | K9: Força | L9: =D10 -> 0
B10: 5 | C10: =IF(ISERROR(VLOOKUP(LARGE('Forças'!$M$6:$M$24,$B10),'Forças'!$M$6:$N$24,2,FALSE)),"",VLOOKUP(LARGE('Forças'!$M$6:$M$24,$B10),'Forças'!$M$6:$N$24,2,FALSE)) | D10: =IF(ISERROR(VLOOKUP(LARGE('Forças'!$M$6:$M$24,$B10),'Forças'!$M$6:$O$24,3,FALSE)),0,VLOOKUP(LARGE('Forças'!$M$6:$M$24,$B10),'Forças'!$M$6:$O$24,3,FALSE)) -> 0 | E10: =IF(ISERROR(VLOOKUP(LARGE(Fraquezas!$M$6:$M$24,$B10),Fraquezas!$M$6:$N$24,2,FALSE)),"",VLOOKUP(LARGE(Fraquezas!$M$6:$M$24,$B10),Fraquezas!$M$6:$N$24,2,FALSE)) | F10: =IF(ISERROR(VLOOKUP(LARGE(Fraquezas!$M$6:$M$24,$B10),Fraquezas!$M$6:$O$24,3,FALSE)),0,VLOOKUP(LARGE(Fraquezas!$M$6:$M$24,$B10),Fraquezas!$M$6:$O$24,3,FALSE)) -> 0 | H10: 0.00015 | I10: =H10+L10 -> 0.00015 | J10: =E6 | K10: Fraqueza | L10: =F6 -> 0
H11: 0.00014 | I11: =H11+L11 -> 0.00014 | J11: =E7 | K11: Fraqueza | L11: =F7 -> 0
C12: 2. Fatores externos | H12: 0.00013 | I12: =H12+L12 -> 0.00013 | J12: =E8 | K12: Fraqueza | L12: =F8 -> 0
C13: 2.1 Top 5 Oportunidades | D13: =SUM(D14:D18) -> 0 | E13: 2.2 Top 5 Ameaças | F13: =SUM(F14:F18) -> 0 | H13: 0.00012 | I13: =H13+L13 -> 0.00012 | J13: =E9 | K13: Fraqueza | L13: =F9 -> 0
B14: 1 | C14: =IF(ISERROR(VLOOKUP(LARGE(Oportunidades!$M$6:$M$25,$B14),Oportunidades!$M$6:$N$25,2,FALSE)),"",VLOOKUP(LARGE(Oportunidades!$M$6:$M$25,$B14),Oportunidades!$M$6:$N$25,2,FALSE)) | D14: =IF(ISERROR(VLOOKUP(LARGE(Oportunidades!$M$6:$M$25,$B14),Oportunidades!$M$6:$O$25,3,FALSE)),0,VLOOKUP(LARGE(Oportunidades!$M$6:$M$25,$B14),Oportunidades!$M$6:$O$25,3,FALSE)) -> 0 | E14: =IF(ISERROR(VLOOKUP(LARGE('Ameaças'!$M$6:$M$25,$B14),'Ameaças'!$M$6:$N$25,2,FALSE)),"",VLOOKUP(LARGE('Ameaças'!$M$6:$M$25,$B14),'Ameaças'!$M$6:$N$25,2,FALSE)) | F14: =IF(ISERROR(VLOOKUP(LARGE('Ameaças'!$M$6:$M$25,$B14),'Ameaças'!$M$6:$O$25,3,FALSE)),0,VLOOKUP(LARGE('Ameaças'!$M$6:$M$25,$B14),'Ameaças'!$M$6:$O$25,3,FALSE)) -> 0 | H14: 0.00011 | I14: =H14+L14 -> 0.00011 | J14: =E10 | K14: Fraqueza | L14: =F10 -> 0
B15: 2 | C15: =IF(ISERROR(VLOOKUP(LARGE(Oportunidades!$M$6:$M$25,$B15),Oportunidades!$M$6:$N$25,2,FALSE)),"",VLOOKUP(LARGE(Oportunidades!$M$6:$M$25,$B15),Oportunidades!$M$6:$N$25,2,FALSE)) | D15: =IF(ISERROR(VLOOKUP(LARGE(Oportunidades!$M$6:$M$25,$B15),Oportunidades!$M$6:$O$25,3,FALSE)),0,VLOOKUP(LARGE(Oportunidades!$M$6:$M$25,$B15),Oportunidades!$M$6:$O$25,3,FALSE)) -> 0 | E15: =IF(ISERROR(VLOOKUP(LARGE('Ameaças'!$M$6:$M$25,$B15),'Ameaças'!$M$6:$N$25,2,FALSE)),"",VLOOKUP(LARGE('Ameaças'!$M$6:$M$25,$B15),'Ameaças'!$M$6:$N$25,2,FALSE)) | F15: =IF(ISERROR(VLOOKUP(LARGE('Ameaças'!$M$6:$M$25,$B15),'Ameaças'!$M$6:$O$25,3,FALSE)),0,VLOOKUP(LARGE('Ameaças'!$M$6:$M$25,$B15),'Ameaças'!$M$6:$O$25,3,FALSE)) -> 0 | H15: 0.0001 | I15: =H15+L15 -> 0.0001 | J15: =C14 | K15: Oportunidade | L15: =D14 -> 0
B16: 3 | C16: =IF(ISERROR(VLOOKUP(LARGE(Oportunidades!$M$6:$M$25,$B16),Oportunidades!$M$6:$N$25,2,FALSE)),"",VLOOKUP(LARGE(Oportunidades!$M$6:$M$25,$B16),Oportunidades!$M$6:$N$25,2,FALSE)) | D16: =IF(ISERROR(VLOOKUP(LARGE(Oportunidades!$M$6:$M$25,$B16),Oportunidades!$M$6:$O$25,3,FALSE)),0,VLOOKUP(LARGE(Oportunidades!$M$6:$M$25,$B16),Oportunidades!$M$6:$O$25,3,FALSE)) -> 0 | E16: =IF(ISERROR(VLOOKUP(LARGE('Ameaças'!$M$6:$M$25,$B16),'Ameaças'!$M$6:$N$25,2,FALSE)),"",VLOOKUP(LARGE('Ameaças'!$M$6:$M$25,$B16),'Ameaças'!$M$6:$N$25,2,FALSE)) | F16: =IF(ISERROR(VLOOKUP(LARGE('Ameaças'!$M$6:$M$25,$B16),'Ameaças'!$M$6:$O$25,3,FALSE)),0,VLOOKUP(LARGE('Ameaças'!$M$6:$M$25,$B16),'Ameaças'!$M$6:$O$25,3,FALSE)) -> 0 | H16: 9e-05 | I16: =H16+L16 -> 9e-05 | J16: =C15 | K16: Oportunidade | L16: =D15 -> 0
B17: 4 | C17: =IF(ISERROR(VLOOKUP(LARGE(Oportunidades!$M$6:$M$25,$B17),Oportunidades!$M$6:$N$25,2,FALSE)),"",VLOOKUP(LARGE(Oportunidades!$M$6:$M$25,$B17),Oportunidades!$M$6:$N$25,2,FALSE)) | D17: =IF(ISERROR(VLOOKUP(LARGE(Oportunidades!$M$6:$M$25,$B17),Oportunidades!$M$6:$O$25,3,FALSE)),0,VLOOKUP(LARGE(Oportunidades!$M$6:$M$25,$B17),Oportunidades!$M$6:$O$25,3,FALSE)) -> 0 | E17: =IF(ISERROR(VLOOKUP(LARGE('Ameaças'!$M$6:$M$25,$B17),'Ameaças'!$M$6:$N$25,2,FALSE)),"",VLOOKUP(LARGE('Ameaças'!$M$6:$M$25,$B17),'Ameaças'!$M$6:$N$25,2,FALSE)) | F17: =IF(ISERROR(VLOOKUP(LARGE('Ameaças'!$M$6:$M$25,$B17),'Ameaças'!$M$6:$O$25,3,FALSE)),0,VLOOKUP(LARGE('Ameaças'!$M$6:$M$25,$B17),'Ameaças'!$M$6:$O$25,3,FALSE)) -> 0 | H17: 8e-05 | I17: =H17+L17 -> 8e-05 | J17: =C16 | K17: Oportunidade | L17: =D16 -> 0
B18: 5 | C18: =IF(ISERROR(VLOOKUP(LARGE(Oportunidades!$M$6:$M$25,$B18),Oportunidades!$M$6:$N$25,2,FALSE)),"",VLOOKUP(LARGE(Oportunidades!$M$6:$M$25,$B18),Oportunidades!$M$6:$N$25,2,FALSE)) | D18: =IF(ISERROR(VLOOKUP(LARGE(Oportunidades!$M$6:$M$25,$B18),Oportunidades!$M$6:$O$25,3,FALSE)),0,VLOOKUP(LARGE(Oportunidades!$M$6:$M$25,$B18),Oportunidades!$M$6:$O$25,3,FALSE)) -> 0 | E18: =IF(ISERROR(VLOOKUP(LARGE('Ameaças'!$M$6:$M$25,$B18),'Ameaças'!$M$6:$N$25,2,FALSE)),"",VLOOKUP(LARGE('Ameaças'!$M$6:$M$25,$B18),'Ameaças'!$M$6:$N$25,2,FALSE)) | F18: =IF(ISERROR(VLOOKUP(LARGE('Ameaças'!$M$6:$M$25,$B18),'Ameaças'!$M$6:$O$25,3,FALSE)),0,VLOOKUP(LARGE('Ameaças'!$M$6:$M$25,$B18),'Ameaças'!$M$6:$O$25,3,FALSE)) -> 0 | H18: 7e-05 | I18: =H18+L18 -> 7e-05 | J18: =C17 | K18: Oportunidade | L18: =D17 -> 0
H19: 6e-05 | I19: =H19+L19 -> 6e-05 | J19: =C18 | K19: Oportunidade | L19: =D18 -> 0
H20: 5e-05 | I20: =H20+L20 -> 5e-05 | J20: =E14 | K20: Ameaça | L20: =F14 -> 0
H21: 4e-05 | I21: =H21+L21 -> 4e-05 | J21: =E15 | K21: Ameaça | L21: =F15 -> 0
H22: 3e-05 | I22: =H22+L22 -> 3e-05 | J22: =E16 | K22: Ameaça | L22: =F16 -> 0
H23: 2e-05 | I23: =H23+L23 -> 2e-05 | J23: =E17 | K23: Ameaça | L23: =F17 -> 0
H24: 1e-05 | I24: =H24+L24 -> 1e-05 | J24: =E18 | K24: Ameaça | L24: =F18 -> 0

Sheet Objetivos Estratégicos 
AN2: `
B5: PERSPECTIVA | C5: Nº | D5: OBJETIVO | E5: INDICADOR | F5: RESPONSÁVEL | G5: REALIZADO 2021 | H5: 43435 | I5: META 2021 | J5: REALIZADO 2022 | K5: META 2022 | L5: REALIZADO 2023 | M5: META 2023 | N5: 44197 | O5: 44228 | P5: 44256 | Q5: 44287 | R5: 44317 | S5: 44348 | T5: 44378 | U5: 44409 | V5: 44440 | W5: 44470 | X5: 44501 | Y5: 44531 | Z5: META 2024 | AA5: DESDOBRAMENTO 2024 | AK5: META 2025 | AN5: PERIODICIDADE
B7: FINANÇAS | C7: 1 | AA7: 210000 | AB7: 210000 | AC7: 210000 | AD7: 210000 | AE7: 210000 | AF7: 210000 | AG7: 210000 | AH7: 210000 | AI7: 210000 | AJ7: 210000 | AK7: =Z7*1.25 -> 0 | AN7: Mensal
C8: 2 | AA8: 150000 | AB8: 150000 | AC8: 150000 | AD8: 150000 | AE8: 150000 | AF8: 150000 | AG8: 150000 | AH8: 150000 | AI8: 150000 | AJ8: 150000 | AK8: =Z8*1.25 -> 0 | AN8: Mensal
C9: 3 | AA9: 360000 | AB9: 360000 | AC9: 360000 | AD9: 360000 | AE9: 360000 | AF9: 360000 | AG9: 360000 | AH9: 360000 | AI9: 360000 | AJ9: 360000 | AK9: =Z9*1.25 -> 0 | AN9: Mensal
C10: 4 | AA10: 150000 | AB10: 150000 | AC10: 150000 | AD10: 150000 | AE10: 150000 | AF10: 150000 | AG10: 150000 | AH10: 150000 | AI10: 150000 | AJ10: 150000 | AK10: =Z10*1.25 -> 0 | AN10: Mensal
C11: 5 | AK11: =Z11*1.25 -> 0 | AN11: Mensal
B13: PALESTRAS | C13: 1 | AG13: 200 | AH13: 200 | AI13: 200 | AJ13: 200 | AK13: =Z13*1.25 -> 0 | AN13: Mensal
C14: 2 | AG14: 200 | AH14: 200 | AI14: 200 | AJ14: 200 | AK14: =Z14*1.25 -> 0 | AN14: Mensal
C15: 3 | AG15: 200 | AH15: 200 | AI15: 200 | AJ15: 200 | AK15: =Z15*1.25 -> 0 | AN15: Mensal
C16: 4 | AG16: 200 | AH16: 200 | AI16: 200 | AJ16: 200 | AK16: =Z16*1.25 -> 0 | AN16: Mensal
C17: 5 | AG17: 200 | AH17: 200 | AI17: 200 | AJ17: 200 | AK17: =Z17*1.25 -> 0 | AN17: Mensal
B19: PALESTRAS | C19: 1 | AN19: Mensal
C20: 2 | AN20: Mensal
C21: 3 | AN21: Mensal
C22: 4 | AN22: Mensal
C23: 5 | AN23: Anual
B25: APRENDIZADO E CRESCIMENTO | C25: 1 | AN25: Mensal
C26: 2 | AN26: Mensal
C27: 3 | AN27: Mensal
C28: 4 | AN28: Mensal
C29: 5 | AN29: Anual

Sheet Desdobramentos
B5: PERSPECTIVA | C5: Nº | D5: OBJETIVO | E5: RESPONSÁVEL | F5: 2024 | G5: CONDIÇÃO | H5: RESULTADO | I5: 45292 | J5: 45323 | K5: 45352 | L5: 45383 | M5: 45413 | N5: 45444 | O5: 45474 | P5: 45505 | Q5: 45536 | R5: 45566 | S5: 45597 | T5: 45627
B7: FINANÇAS | C7: 1 | D7: =IF('Objetivos Estratégicos '!E7="","",'Objetivos Estratégicos '!E7) | E7: =IF('Objetivos Estratégicos '!F7="","",'Objetivos Estratégicos '!F7) | F7: META | G7: SOMA | H7: =IF(G7="SOMA",SUM(I7:T7),IF(G7="MÉDIA",AVERAGE(I7:T7),IF(G7="ÚLTIMO RESULTADO",MAX(I7:T7),""))) -> 0 | I7: ='Objetivos Estratégicos '!Z7/12 -> 0 | J7: ='Objetivos Estratégicos '!Z7/12 -> 0 | K7: ='Objetivos Estratégicos '!Z7/12 -> 0 | L7: ='Objetivos Estratégicos '!Z7/12 -> 0 | M7: ='Objetivos Estratégicos '!Z7/12 -> 0 | N7: ='Objetivos Estratégicos '!Z7/12 -> 0 | O7: ='Objetivos Estratégicos '!Z7/12 -> 0 | P7: ='Objetivos Estratégicos '!Z7/12 -> 0 | Q7: ='Objetivos Estratégicos '!Z7/12 -> 0 | R7: ='Objetivos Estratégicos '!Z7/12 -> 0 | S7: ='Objetivos Estratégicos '!Z7/12 -> 0 | T7: ='Objetivos Estratégicos '!Z7/12 -> 0
F8: REALIZADO | G8: SOMA | H8: =IF(G8="SOMA",SUM(I8:T8),IF(G8="MÉDIA",AVERAGE(I8:T8),IF(G8="ÚLTIMO RESULTADO",MAX(I8:T8),""))) -> 0
C9: 2 | D9: =IF('Objetivos Estratégicos '!E8="","",'Objetivos Estratégicos '!E8) | E9: =IF('Objetivos Estratégicos '!F8="","",'Objetivos Estratégicos '!F8) | F9: META | G9: SOMA | H9: =IF(G9="SOMA",SUM(I9:T9),IF(G9="MÉDIA",AVERAGE(I9:T9),IF(G9="ÚLTIMO RESULTADO",MAX(I9:T9),""))) -> 0 | I9: ='Objetivos Estratégicos '!Z8/12 -> 0 | J9: ='Objetivos Estratégicos '!Z8/12 -> 0 | K9: ='Objetivos Estratégicos '!Z8/12 -> 0 | L9: ='Objetivos Estratégicos '!Z8/12 -> 0 | M9: ='Objetivos Estratégicos '!Z8/12 -> 0 | N9: ='Objetivos Estratégicos '!Z8/12 -> 0 | O9: ='Objetivos Estratégicos '!Z8/12 -> 0 | P9: ='Objetivos Estratégicos '!Z8/12 -> 0 | Q9: ='Objetivos Estratégicos '!Z8/12 -> 0 | R9: ='Objetivos Estratégicos '!Z8/12 -> 0 | S9: ='Objetivos Estratégicos '!Z8/12 -> 0 | T9: ='Objetivos Estratégicos '!Z8/12 -> 0
F10: REALIZADO | G10: SOMA | H10: =IF(G10="SOMA",SUM(I10:T10),IF(G10="MÉDIA",AVERAGE(I10:T10),IF(G10="ÚLTIMO RESULTADO",MAX(I10:T10),""))) -> 0
C11: 3 | D11: =IF('Objetivos Estratégicos '!E9="","",'Objetivos Estratégicos '!E9) | E11: =IF('Objetivos Estratégicos '!F9="","",'Objetivos Estratégicos '!F9) | F11: META | G11: SOMA | H11: =IF(G11="SOMA",SUM(I11:T11),IF(G11="MÉDIA",AVERAGE(I11:T11),IF(G11="ÚLTIMO RESULTADO",MAX(I11:T11),""))) -> 0 | I11: ='Objetivos Estratégicos '!Z9/12 -> 0 | J11: ='Objetivos Estratégicos '!Z9/12 -> 0 | K11: ='Objetivos Estratégicos '!Z9/12 -> 0 | L11: ='Objetivos Estratégicos '!Z9/12 -> 0 | M11: ='Objetivos Estratégicos '!Z9/12 -> 0 | N11: ='Objetivos Estratégicos '!Z9/12 -> 0 | O11: ='Objetivos Estratégicos '!Z9/12 -> 0 | P11: ='Objetivos Estratégicos '!Z9/12 -> 0 | Q11: ='Objetivos Estratégicos '!Z9/12 -> 0 | R11: ='Objetivos Estratégicos '!Z9/12 -> 0 | S11: ='Objetivos Estratégicos '!Z9/12 -> 0 | T11: ='Objetivos Estratégicos '!Z9/12 -> 0
F12: REALIZADO | G12: SOMA | H12: =IF(G12="SOMA",SUM(I12:T12),IF(G12="MÉDIA",AVERAGE(I12:T12),IF(G12="ÚLTIMO RESULTADO",MAX(I12:T12),""))) -> 0
C13: 4 | D13: =IF('Objetivos Estratégicos '!E10="","",'Objetivos Estratégicos '!E10) | E13: =IF('Objetivos Estratégicos '!F10="","",'Objetivos Estratégicos '!F10) | F13: META | G13: SOMA | H13: =IF(G13="SOMA",SUM(I13:T13),IF(G13="MÉDIA",AVERAGE(I13:T13),IF(G13="ÚLTIMO RESULTADO",MAX(I13:T13),""))) -> 0 | I13: ='Objetivos Estratégicos '!Z10/12 -> 0 | J13: ='Objetivos Estratégicos '!Z10/12 -> 0 | K13: ='Objetivos Estratégicos '!Z10/12 -> 0 | L13: ='Objetivos Estratégicos '!Z10/12 -> 0 | M13: ='Objetivos Estratégicos '!Z10/12 -> 0 | N13: ='Objetivos Estratégicos '!Z10/12 -> 0 | O13: ='Objetivos Estratégicos '!Z10/12 -> 0 | P13: ='Objetivos Estratégicos '!Z10/12 -> 0 | Q13: ='Objetivos Estratégicos '!Z10/12 -> 0 | R13: ='Objetivos Estratégicos '!Z10/12 -> 0 | S13: ='Objetivos Estratégicos '!Z10/12 -> 0 | T13: ='Objetivos Estratégicos '!Z10/12 -> 0
F14: REALIZADO | G14: SOMA | H14: =IF(G14="SOMA",SUM(I14:T14),IF(G14="MÉDIA",AVERAGE(I14:T14),IF(G14="ÚLTIMO RESULTADO",MAX(I14:T14),""))) -> 0
C15: 5 | D15: =IF('Objetivos Estratégicos '!E11="","",'Objetivos Estratégicos '!E11) | E15: =IF('Objetivos Estratégicos '!F11="","",'Objetivos Estratégicos '!F11) | F15: META | G15: SOMA | H15: =IF(G15="SOMA",SUM(I15:T15),IF(G15="MÉDIA",AVERAGE(I15:T15),IF(G15="ÚLTIMO RESULTADO",MAX(I15:T15),""))) -> 0 | I15: ='Objetivos Estratégicos '!Z11/12 -> 0 | J15: ='Objetivos Estratégicos '!Z11/12 -> 0 | K15: ='Objetivos Estratégicos '!Z11/12 -> 0 | L15: ='Objetivos Estratégicos '!Z11/12 -> 0 | M15: ='Objetivos Estratégicos '!Z11/12 -> 0 | N15: ='Objetivos Estratégicos '!Z11/12 -> 0 | O15: ='Objetivos Estratégicos '!Z11/12 -> 0 | P15: ='Objetivos Estratégicos '!Z11/12 -> 0 | Q15: ='Objetivos Estratégicos '!Z11/12 -> 0 | R15: ='Objetivos Estratégicos '!Z11/12 -> 0 | S15: ='Objetivos Estratégicos '!Z11/12 -> 0 | T15: ='Objetivos Estratégicos '!Z11/12 -> 0
F16: REALIZADO | G16: SOMA | H16: =IF(G16="SOMA",SUM(I16:T16),IF(G16="MÉDIA",AVERAGE(I16:T16),IF(G16="ÚLTIMO RESULTADO",MAX(I16:T16),""))) -> 0
B18: CLIENTES | C18: 1 | D18: =IF('Objetivos Estratégicos '!E13="","",'Objetivos Estratégicos '!E13) | E18: =IF('Objetivos Estratégicos '!F13="","",'Objetivos Estratégicos '!F13) | F18: META | G18: SOMA | H18: =IF(G18="SOMA",SUM(I18:T18),IF(G18="MÉDIA",AVERAGE(I18:T18),IF(G18="ÚLTIMO RESULTADO",MAX(I18:T18),""))) -> 66.666667 | I18: ='Objetivos Estratégicos '!Z13/12 -> 0 | J18: ='Objetivos Estratégicos '!AA13/12 -> 0 | K18: ='Objetivos Estratégicos '!AB13/12 -> 0 | L18: ='Objetivos Estratégicos '!AC13/12 -> 0 | M18: ='Objetivos Estratégicos '!AD13/12 -> 0 | N18: ='Objetivos Estratégicos '!AE13/12 -> 0 | O18: ='Objetivos Estratégicos '!AF13/12 -> 0 | P18: ='Objetivos Estratégicos '!AG13/12 -> 16.666667 | ... T18: ='Objetivos Estratégicos '!AK13/12 -> 0
F19: REALIZADO | G19: SOMA | H19: =IF(G19="SOMA",SUM(I19:T19),IF(G19="MÉDIA",AVERAGE(I19:T19),IF(G19="ÚLTIMO RESULTADO",MAX(I19:T19),""))) -> 0
C20: 2 | D20: =IF('Objetivos Estratégicos '!E14="","",'Objetivos Estratégicos '!E14) | E20: =IF('Objetivos Estratégicos '!F14="","",'Objetivos Estratégicos '!F14) | F20: META | G20: SOMA | H20: =IF(G20="SOMA",SUM(I20:T20),IF(G20="MÉDIA",AVERAGE(I20:T20),IF(G20="ÚLTIMO RESULTADO",MAX(I20:T20),""))) -> 66.666667 | I20: ='Objetivos Estratégicos '!Z14/12 -> 0 | J20: ='Objetivos Estratégicos '!AA14/12 -> 0 | K20: ='Objetivos Estratégicos '!AB14/12 -> 0 | L20: ='Objetivos Estratégicos '!AC14/12 -> 0 | M20: ='Objetivos Estratégicos '!AD14/12 -> 0 | N20: ='Objetivos Estratégicos '!AE14/12 -> 0 | O20: ='Objetivos Estratégicos '!AF14/12 -> 0 | P20: ='Objetivos Estratégicos '!AG14/12 -> 16.666667 | ... T20: ='Objetivos Estratégicos '!AK14/12 -> 0
F21: REALIZADO | G21: SOMA | H21: =IF(G21="SOMA",SUM(I21:T21),IF(G21="MÉDIA",AVERAGE(I21:T21),IF(G21="ÚLTIMO RESULTADO",MAX(I21:T21),""))) -> 0
C22: 3 | D22: =IF('Objetivos Estratégicos '!E15="","",'Objetivos Estratégicos '!E15) | E22: =IF('Objetivos Estratégicos '!F15="","",'Objetivos Estratégicos '!F15) | F22: META | G22: SOMA | H22: =IF(G22="SOMA",SUM(I22:T22),IF(G22="MÉDIA",AVERAGE(I22:T22),IF(G22="ÚLTIMO RESULTADO",MAX(I22:T22),""))) -> 50 | I22: ='Objetivos Estratégicos '!Z15/12 -> 0 | J22: ='Objetivos Estratégicos '!AA15/12 -> 0 | K22: ='Objetivos Estratégicos '!AB15/12 -> 0 | L22: ='Objetivos Estratégicos '!AC15/12 -> 0 | M22: ='Objetivos Estratégicos '!AD15/12 -> 0 | N22: ='Objetivos Estratégicos '!AE15/12 -> 0 | O22: ='Objetivos Estratégicos '!AF15/12 -> 0 | P22: ='Objetivos Estratégicos '!AG15/12 -> 16.666667 | ... R22: ='Objetivos Estratégicos '!AI15/12 -> 16.666667 | S22: ='Objetivos Estratégicos '!AK15/12 -> 0 | T22: ='Objetivos Estratégicos '!AM15/12 -> 0
F23: REALIZADO | G23: SOMA | H23: =IF(G23="SOMA",SUM(I23:T23),IF(G23="MÉDIA",AVERAGE(I23:T23),IF(G23="ÚLTIMO RESULTADO",MAX(I23:T23),""))) -> 0
C24: 4 | D24: =IF('Objetivos Estratégicos '!E16="","",'Objetivos Estratégicos '!E16) | E24: =IF('Objetivos Estratégicos '!F16="","",'Objetivos Estratégicos '!F16) | F24: META | G24: SOMA | H24: =IF(G24="SOMA",SUM(I24:T24),IF(G24="MÉDIA",AVERAGE(I24:T24),IF(G24="ÚLTIMO RESULTADO",MAX(I24:T24),""))) -> 66.666667 | I24: ='Objetivos Estratégicos '!Z16/12 -> 0 | J24: ='Objetivos Estratégicos '!AA16/12 -> 0 | K24: ='Objetivos Estratégicos '!AB16/12 -> 0 | L24: ='Objetivos Estratégicos '!AC16/12 -> 0 | M24: ='Objetivos Estratégicos '!AD16/12 -> 0 | N24: ='Objetivos Estratégicos '!AE16/12 -> 0 | O24: ='Objetivos Estratégicos '!AF16/12 -> 0 | P24: ='Objetivos Estratégicos '!AG16/12 -> 16.666667 | ... T24: ='Objetivos Estratégicos '!AK16/12 -> 0
F25: REALIZADO | G25: SOMA | H25: =IF(G25="SOMA",SUM(I25:T25),IF(G25="MÉDIA",AVERAGE(I25:T25),IF(G25="ÚLTIMO RESULTADO",MAX(I25:T25),""))) -> 0
C26: 5 | D26: =IF('Objetivos Estratégicos '!E17="","",'Objetivos Estratégicos '!E17) | E26: =IF('Objetivos Estratégicos '!F17="","",'Objetivos Estratégicos '!F17) | F26: META | G26: SOMA | H26: =IF(G26="SOMA",SUM(I26:T26),IF(G26="MÉDIA",AVERAGE(I26:T26),IF(G26="ÚLTIMO RESULTADO",MAX(I26:T26),""))) -> 0
F27: REALIZADO | G27: SOMA | H27: =IF(G27="SOMA",SUM(I27:T27),IF(G27="MÉDIA",AVERAGE(I27:T27),IF(G27="ÚLTIMO RESULTADO",MAX(I27:T27),""))) -> 0
B29: PROCESSOS INTERNOS | C29: 1 | D29: =IF('Objetivos Estratégicos '!E19="","",'Objetivos Estratégicos '!E19) | E29: =IF('Objetivos Estratégicos '!F19="","",'Objetivos Estratégicos '!F19) | F29: META | G29: SOMA | H29: =IF(G29="SOMA",SUM(I29:T29),IF(G29="MÉDIA",AVERAGE(I29:T29),IF(G29="ÚLTIMO RESULTADO",MAX(I29:T29),""))) -> 0
F30: REALIZADO | G30: SOMA | H30: =IF(G30="SOMA",SUM(I30:T30),IF(G30="MÉDIA",AVERAGE(I30:T30),IF(G30="ÚLTIMO RESULTADO",MAX(I30:T30),""))) -> 0
C31: 2 | D31: =IF('Objetivos Estratégicos '!E20="","",'Objetivos Estratégicos '!E20) | E31: =IF('Objetivos Estratégicos '!F20="","",'Objetivos Estratégicos '!F20) | F31: META | G31: SOMA | H31: =IF(G31="SOMA",SUM(I31:T31),IF(G31="MÉDIA",AVERAGE(I31:T31),IF(G31="ÚLTIMO RESULTADO",MAX(I31:T31),""))) -> 0
F32: REALIZADO | G32: SOMA | H32: =IF(G32="SOMA",SUM(I32:T32),IF(G32="MÉDIA",AVERAGE(I32:T32),IF(G32="ÚLTIMO RESULTADO",MAX(I32:T32),""))) -> 0
C33: 3 | D33: =IF('Objetivos Estratégicos '!E21="","",'Objetivos Estratégicos '!E21) | E33: =IF('Objetivos Estratégicos '!F21="","",'Objetivos Estratégicos '!F21) | F33: META | G33: SOMA | H33: =IF(G33="SOMA",SUM(I33:T33),IF(G33="MÉDIA",AVERAGE(I33:T33),IF(G33="ÚLTIMO RESULTADO",MAX(I33:T33),""))) -> 0
F34: REALIZADO | G34: SOMA | H34: =IF(G34="SOMA",SUM(I34:T34),IF(G34="MÉDIA",AVERAGE(I34:T34),IF(G34="ÚLTIMO RESULTADO",MAX(I34:T34),""))) -> 0
C35: 4 | D35: =IF('Objetivos Estratégicos '!E22="","",'Objetivos Estratégicos '!E22) | E35: =IF('Objetivos Estratégicos '!F22="","",'Objetivos Estratégicos '!F22) | F35: META | G35: SOMA | H35: =IF(G35="SOMA",SUM(I35:T35),IF(G35="MÉDIA",AVERAGE(I35:T35),IF(G35="ÚLTIMO RESULTADO",MAX(I35:T35),""))) -> 0
F36: REALIZADO | G36: SOMA | H36: =IF(G36="SOMA",SUM(I36:T36),IF(G36="MÉDIA",AVERAGE(I36:T36),IF(G36="ÚLTIMO RESULTADO",MAX(I36:T36),""))) -> 0
C37: 5 | D37: =IF('Objetivos Estratégicos '!E23="","",'Objetivos Estratégicos '!E23) | E37: =IF('Objetivos Estratégicos '!F23="","",'Objetivos Estratégicos '!F23) | F37: META | G37: SOMA | H37: =IF(G37="SOMA",SUM(I37:T37),IF(G37="MÉDIA",AVERAGE(I37:T37),IF(G37="ÚLTIMO RESULTADO",MAX(I37:T37),""))) -> 0
F38: REALIZADO | G38: SOMA | H38: =IF(G38="SOMA",SUM(I38:T38),IF(G38="MÉDIA",AVERAGE(I38:T38),IF(G38="ÚLTIMO RESULTADO",MAX(I38:T38),""))) -> 0
G39: SOMA
B40: APRENDIZADO E CRESCIMENTO | C40: 1 | D40: =IF('Objetivos Estratégicos '!E25="","",'Objetivos Estratégicos '!E25) | E40: =IF('Objetivos Estratégicos '!F25="","",'Objetivos Estratégicos '!F25) | F40: META | G40: SOMA | H40: =IF(G40="SOMA",SUM(I40:T40),IF(G40="MÉDIA",AVERAGE(I40:T40),IF(G40="ÚLTIMO RESULTADO",MAX(I40:T40),""))) -> 0
F41: REALIZADO | G41: SOMA | H41: =IF(G41="SOMA",SUM(I41:T41),IF(G41="MÉDIA",AVERAGE(I41:T41),IF(G41="ÚLTIMO RESULTADO",MAX(I41:T41),""))) -> 0
C42: 2 | D42: =IF('Objetivos Estratégicos '!E26="","",'Objetivos Estratégicos '!E26) | E42: =IF('Objetivos Estratégicos '!F26="","",'Objetivos Estratégicos '!F26) | F42: META | G42: SOMA | H42: =IF(G42="SOMA",SUM(I42:T42),IF(G42="MÉDIA",AVERAGE(I42:T42),IF(G42="ÚLTIMO RESULTADO",MAX(I42:T42),""))) -> 0
F43: REALIZADO | G43: SOMA | H43: =IF(G43="SOMA",SUM(I43:T43),IF(G43="MÉDIA",AVERAGE(I43:T43),IF(G43="ÚLTIMO RESULTADO",MAX(I43:T43),""))) -> 0
C44: 3 | D44: =IF('Objetivos Estratégicos '!E27="","",'Objetivos Estratégicos '!E27) | E44: =IF('Objetivos Estratégicos '!F27="","",'Objetivos Estratégicos '!F27) | F44: META | G44: SOMA | H44: =IF(G44="SOMA",SUM(I44:T44),IF(G44="MÉDIA",AVERAGE(I44:T44),IF(G44="ÚLTIMO RESULTADO",MAX(I44:T44),""))) -> 0
F45: REALIZADO | G45: SOMA | H45: =IF(G45="SOMA",SUM(I45:T45),IF(G45="MÉDIA",AVERAGE(I45:T45),IF(G45="ÚLTIMO RESULTADO",MAX(I45:T45),""))) -> 0
C46: 4 | D46: =IF('Objetivos Estratégicos '!E28="","",'Objetivos Estratégicos '!E29) | E46: =IF('Objetivos Estratégicos '!F28="","",'Objetivos Estratégicos '!F29) | F46: META | G46: SOMA | H46: =IF(G46="SOMA",SUM(I46:T46),IF(G46="MÉDIA",AVERAGE(I46:T46),IF(G46="ÚLTIMO RESULTADO",MAX(I46:T46),""))) -> 0
F47: REALIZADO | G47: SOMA | H47: =IF(G47="SOMA",SUM(I47:T47),IF(G47="MÉDIA",AVERAGE(I47:T47),IF(G47="ÚLTIMO RESULTADO",MAX(I47:T47),""))) -> 0
...

Sheet Painel Estratégico 
B5: MÊS | D5: 45292 | G5: MENSAL | J5: ACUMULADO
B7: PERSPECTIVA | C7: Nº | D7: OBJETIVO | E7: UNI MEDIDA | F7: ORIENTAÇÃO | G7: META | H7: RESULTADO | I7: % | J7: META | K7: RESULTADO | L7: % | N7: PESO | O7: % TOTAL
B9: FINANÇAS | C9: 1 | D9: =IF('Objetivos Estratégicos '!E7="","",'Objetivos Estratégicos '!E7) | E9: R$ | F9: MAIS | G9: =SUMIF(Desdobramentos!$5:$5,$D$5,Desdobramentos!$7:$7) -> 0 | H9: =SUMIF(Desdobramentos!$5:$5,$D$5,Desdobramentos!$8:$8) -> 0 | I9: =IF(F9="Menos",G9/H9,IFERROR(H9/G9,"")) | J9: =SUMIF(Desdobramentos!$5:$5,"<="&$D$5,Desdobramentos!$7:$7) -> 0 | K9: =SUMIF(Desdobramentos!$5:$5,"<="&$D$5,Desdobramentos!$8:$8) -> 0 | L9: =IFERROR(K9/J9,"") | N9: 0 | O9: =IFERROR(IF(F9="Mais",(K9*100%)/J9,(100%-(K9-J9)/J9))*N9,"")
C10: 2 | D10: =IF('Objetivos Estratégicos '!E8="","",'Objetivos Estratégicos '!E8) | E10: R$ | F10: MAIS | G10: =SUMIF(Desdobramentos!$5:$5,$D$5,Desdobramentos!$9:$9) -> 0 | H10: =SUMIF(Desdobramentos!$5:$5,$D$5,Desdobramentos!$10:$10) -> 0 | I10: =IF(F10="Menos",G10/H10,IFERROR(H10/G10,"")) | J10: =SUMIF(Desdobramentos!$5:$5,"<="&$D$5,Desdobramentos!$9:$9) -> 0 | K10: =SUMIF(Desdobramentos!$5:$5,"<="&$D$5,Desdobramentos!$10:$10) -> 0 | L10: =IFERROR(K10/J10,"") | N10: 0 | O10: =IFERROR(IF(F10="Mais",(K10*100%)/J10,(100%-(K10-J10)/J10))*N10,"")
C11: 3 | D11: =IF('Objetivos Estratégicos '!E9="","",'Objetivos Estratégicos '!E9) | E11: R$ | F11: MAIS | G11: =SUMIF(Desdobramentos!$5:$5,$D$5,Desdobramentos!$11:$11) -> 0 | H11: =SUMIF(Desdobramentos!$5:$5,$D$5,Desdobramentos!$12:$12) -> 0 | I11: =IF(F11="Menos",G11/H11,IFERROR(H11/G11,"")) | J11: =SUMIF(Desdobramentos!$5:$5,"<="&$D$5,Desdobramentos!$11:$11) -> 0 | K11: =SUMIF(Desdobramentos!$5:$5,"<="&$D$5,Desdobramentos!$12:$12) -> 0 | L11: =IFERROR(K11/J11,"") | N11: 0 | O11: =IFERROR(IF(F11="Mais",(K11*100%)/J11,(100%-(K11-J11)/J11))*N11,"")
C12: 4 | D12: =IF('Objetivos Estratégicos '!E10="","",'Objetivos Estratégicos '!E10) | E12: R$ | F12: MAIS | G12: =SUMIF(Desdobramentos!$5:$5,$D$5,Desdobramentos!$13:$13) -> 0 | H12: =SUMIF(Desdobramentos!$5:$5,$D$5,Desdobramentos!$14:$14) -> 0 | I12: =IF(F12="Menos",G12/H12,IFERROR(H12/G12,"")) | J12: =SUMIF(Desdobramentos!$5:$5,"<="&$D$5,Desdobramentos!$13:$13) -> 0 | K12: =SUMIF(Desdobramentos!$5:$5,"<="&$D$5,Desdobramentos!$14:$14) -> 0 | L12: =IFERROR(K12/J12,"") | N12: 0 | O12: =IFERROR(IF(F12="Mais",(K12*100%)/J12,(100%-(K12-J12)/J12))*N12,"")
C13: 5 | D13: =IF('Objetivos Estratégicos '!E11="","",'Objetivos Estratégicos '!E11) | E13: R$ | F13: MAIS | G13: =SUMIF(Desdobramentos!$5:$5,$D$5,Desdobramentos!$15:$15) -> 0 | H13: =SUMIF(Desdobramentos!$5:$5,$D$5,Desdobramentos!$16:$16) -> 0 | I13: =IF(F13="Menos",G13/H13,IFERROR(H13/G13,"")) | J13: =SUMIF(Desdobramentos!$5:$5,"<="&$D$5,Desdobramentos!$15:$15) -> 0 | K13: =SUMIF(Desdobramentos!$5:$5,"<="&$D$5,Desdobramentos!$16:$16) -> 0 | L13: =IFERROR(K13/J13,"") | N13: 0 | O13: =IFERROR(IF(F13="Mais",(K13*100%)/J13,(100%-(K13-J13)/J13))*N13,"")
N14: =SUM(N9:N13) -> 0 | O14: =SUM(O9:O13) -> 0
B16: CLIENTES | C16: 1 | D16: =IF('Objetivos Estratégicos '!E13="","",'Objetivos Estratégicos '!E13) | F16: MAIS | G16: =SUMIF(Desdobramentos!$5:$5,$D$5,Desdobramentos!$18:$18) -> 0 | H16: =SUMIF(Desdobramentos!$5:$5,$D$5,Desdobramentos!$19:$19) -> 0 | I16: =IF(F16="Menos",G16/H16,IFERROR(H16/G16,"")) | J16: =SUMIF(Desdobramentos!$5:$5,"<="&$D$5,Desdobramentos!$18:$18) -> 0 | K16: =SUMIF(Desdobramentos!$5:$5,"<="&$D$5,Desdobramentos!$19:$19) -> 0 | L16: =IFERROR(K16/J16,"") | N16: 0 | O16: =IFERROR(IF(F16="Mais",(K16*100%)/J16,(100%-(K16-J16)/J16))*N16,"")
C17: 2 | D17: =IF('Objetivos Estratégicos '!E14="","",'Objetivos Estratégicos '!E14) | F17: MÉDIA | G17: =SUMIF(Desdobramentos!$5:$5,$D$5,Desdobramentos!$20:$20) -> 0 | H17: =SUMIF(Desdobramentos!$5:$5,$D$5,Desdobramentos!$21:$21) -> 0 | I17: =IF(F17="Menos",G17/H17,IFERROR(H17/G17,"")) | J17: =SUMIF(Desdobramentos!$5:$5,"<="&$D$5,Desdobramentos!$20:$20) -> 0 | K17: =SUMIF(Desdobramentos!$5:$5,"<="&$D$5,Desdobramentos!$21:$21) -> 0 | L17: =IFERROR(K17/J17,"") | N17: 0 | O17: =IFERROR(IF(F17="Mais",(K17*100%)/J17,(100%-(K17-J17)/J17))*N17,"")
C18: 3 | D18: =IF('Objetivos Estratégicos '!E15="","",'Objetivos Estratégicos '!E15) | G18: =SUMIF(Desdobramentos!$5:$5,$D$5,Desdobramentos!$22:$22) -> 0 | H18: =SUMIF(Desdobramentos!$5:$5,$D$5,Desdobramentos!$25:$25) -> 0 | I18: =IF(F18="Menos",G18/H18,IFERROR(H18/G18,"")) | J18: =SUMIF(Desdobramentos!$5:$5,"<="&$D$5,Desdobramentos!$22:$22) -> 0 | K18: =SUMIF(Desdobramentos!$5:$5,"<="&$D$5,Desdobramentos!$23:$23) -> 0 | L18: =IFERROR(K18/J18,"") | N18: 0 | O18: =IFERROR(IF(F18="Mais",(K18*100%)/J18,(100%-(K18-J18)/J18))*N18,"")
C19: 4 | D19: =IF('Objetivos Estratégicos '!E16="","",'Objetivos Estratégicos '!E16) | G19: =SUMIF(Desdobramentos!$5:$5,$D$5,Desdobramentos!$24:$24) -> 0 | H19: =SUMIF(Desdobramentos!$5:$5,$D$5,Desdobramentos!$25:$25) -> 0 | I19: =IF(F19="Menos",G19/H19,IFERROR(H19/G19,"")) | J19: =SUMIF(Desdobramentos!$5:$5,"<="&$D$5,Desdobramentos!$24:$24) -> 0 | K19: =SUMIF(Desdobramentos!$5:$5,"<="&$D$5,Desdobramentos!$25:$25) -> 0 | L19: =IFERROR(K19/J19,"") | N19: 0 | O19: =IFERROR(IF(F19="Mais",(K19*100%)/J19,(100%-(K19-J19)/J19))*N19,"")
C20: 5 | D20: =IF('Objetivos Estratégicos '!E17="","",'Objetivos Estratégicos '!E17) | G20: =SUMIF(Desdobramentos!$5:$5,$D$5,Desdobramentos!$26:$26) -> 0 | H20: =SUMIF(Desdobramentos!$5:$5,$D$5,Desdobramentos!$27:$27) -> 0 | I20: =IF(F20="Menos",G20/H20,IFERROR(H20/G20,"")) | J20: =SUMIF(Desdobramentos!$5:$5,"<="&$D$5,Desdobramentos!$26:$26) -> 0 | K20: =SUMIF(Desdobramentos!$5:$5,"<="&$D$5,Desdobramentos!$27:$27) -> 0 | L20: =IFERROR(K20/J20,"") | N20: 0 | O20: =IFERROR(IF(F20="Mais",(K20*100%)/J20,(100%-(K20-J20)/J20))*N20,"")
N21: =SUM(N16:N20) -> 0 | O21: =SUM(O16:O20) -> 0
