Workbook

Sheet Objetivos Estratégicos 
B5: PERSPECTIVA | C5: Nº | D5: OBJETIVO | E5: INDICADOR | F5: RESPONSÁVEL | G5: META 2022 | H5: 43101 | I5: 43132 | J5: 43160 | K5: 43191 | L5: 43221 | M5: 43252 | N5: 43282 | O5: 43313 | P5: 43344 | Q5: 43374 | R5: 43405 | S5: 43435 | T5: META 2023 | U5: 43466 | V5: 43497 | W5: 43525 | X5: 43556 | Y5: 43586 | Z5: 43617 | AA5: 43647 | AB5: 43678 | AC5: 43709 | AD5: 43739 | AE5: 43770 | AF5: 43800 | AG5: META 2024 | AH5: 43831 | AI5: 43862 | AJ5: 43891 | AK5: 43922 | AL5: 43952 | AM5: 43983 | AN5: 44013 | AO5: 44044 | AP5: 44075 | AQ5: 44105 | AR5: 44136 | AS5: 44166 | AT5: META 2025 | AU5: 44197 | AV5: 44228 | AW5: 44256 | AX5: 44287 | AY5: 44317 | AZ5: 44348 | BA5: 44378 | BB5: 44409 | BC5: 44440 | BD5: 44470 | BE5: 44501 | BF5: 44531 | BG5: META 2025 | BH5: 44562 | BI5: 44593 | BJ5: 44621 | BK5: 44652 | BL5: 44682 | BM5: 44713 | BN5: 44743 | BO5: 44774 | BP5: 44805 | BQ5: 44835 | BR5: 44866 | BS5: 44896 | BT5: PERIODICIDADE
B7: FINANÇAS | C7: 1
C8: 2
C9: 3
C10: 4
C11: 5
B13: CLIENTES | C13: 1
C14: 2
C15: 3
C16: 4
C17: 5
B19: PROCESSOS INTERNOS | C19: 1
C20: 2
C21: 3
C22: 4
C23: 5
B25: APRENDIZADO E CRESCIMENTO | C25: 1
C26: 2
C27: 3
C28: 4
C29: 5

Sheet Desdobramentos
B5: PERSPECTIVA | C5: Nº | D5: OBJETIVO | E5: RESPONSÁVEL | F5: 2022 | G5: CONDIÇÃO | H5: RESULTADO | I5: 44562 | J5: 44593 | K5: 44621 | L5: 44652 | M5: 44682 | N5: 44713 | O5: 44743 | P5: 44774 | Q5: 44805 | R5: 44835 | S5: 44866 | T5: 44896
B7: FINANÇAS | C7: 1 | D7: =IF('Objetivos Estratégicos '!E7="","",'Objetivos Estratégicos '!E7) | E7: =IF('Objetivos Estratégicos '!F7="","",'Objetivos Estratégicos '!F7) | F7: META | G7: SOMA | H7: =IF(G7="SOMA",SUM(I7:T7),IF(G7="MÉDIA",AVERAGE(I7:T7),IF(G7="ÚLTIMO RESULTADO",MAX(I7:T7),""))) -> 0 | I7: 0 | J7: 0 | K7: 0 | L7: 0 | M7: 0 | N7: 0 | O7: 0 | P7: 0 | Q7: 0 | R7: 0 | S7: 0 | T7: 0
F8: REALIZADO | G8: SOMA | H8: =IF(G8="SOMA",SUM(I8:T8),IF(G8="MÉDIA",AVERAGE(I8:T8),IF(G8="ÚLTIMO RESULTADO",MAX(I8:T8),""))) -> 0
C9: 2 | D9: =IF('Objetivos Estratégicos '!E8="","",'Objetivos Estratégicos '!E8) | E9: =IF('Objetivos Estratégicos '!F8="","",'Objetivos Estratégicos '!F8) | F9: META | G9: SOMA | H9: =IF(G9="SOMA",SUM(I9:T9),IF(G9="MÉDIA",AVERAGE(I9:T9),IF(G9="ÚLTIMO RESULTADO",MAX(I9:T9),""))) -> 0
F10: REALIZADO | G10: SOMA | H10: =IF(G10="SOMA",SUM(I10:T10),IF(G10="MÉDIA",AVERAGE(I10:T10),IF(G10="ÚLTIMO RESULTADO",MAX(I10:T10),""))) -> 0
C11: 3 | D11: =IF('Objetivos Estratégicos '!E9="","",'Objetivos Estratégicos '!E9) | E11: =IF('Objetivos Estratégicos '!F9="","",'Objetivos Estratégicos '!F9) | F11: META | G11: SOMA | H11: =IF(G11="SOMA",SUM(I11:T11),IF(G11="MÉDIA",AVERAGE(I11:T11),IF(G11="ÚLTIMO RESULTADO",MAX(I11:T11),""))) -> 0
F12: REALIZADO | G12: SOMA | H12: =IF(G12="SOMA",SUM(I12:T12),IF(G12="MÉDIA",AVERAGE(I12:T12),IF(G12="ÚLTIMO RESULTADO",MAX(I12:T12),""))) -> 0
C13: 4 | D13: =IF('Objetivos Estratégicos '!E10="","",'Objetivos Estratégicos '!E10) | E13: =IF('Objetivos Estratégicos '!F10="","",'Objetivos Estratégicos '!F10) | F13: META | G13: SOMA | H13: =IF(G13="SOMA",SUM(I13:T13),IF(G13="MÉDIA",AVERAGE(I13:T13),IF(G13="ÚLTIMO RESULTADO",MAX(I13:T13),""))) -> 0
F14: REALIZADO | G14: SOMA | H14: =IF(G14="SOMA",SUM(I14:T14),IF(G14="MÉDIA",AVERAGE(I14:T14),IF(G14="ÚLTIMO RESULTADO",MAX(I14:T14),""))) -> 0
C15: 5 | D15: =IF('Objetivos Estratégicos '!E11="","",'Objetivos Estratégicos '!E11) | E15: =IF('Objetivos Estratégicos '!F11="","",'Objetivos Estratégicos '!F11) | F15: META | G15: SOMA | H15: =IF(G15="SOMA",SUM(I15:T15),IF(G15="MÉDIA",AVERAGE(I15:T15),IF(G15="ÚLTIMO RESULTADO",MAX(I15:T15),""))) -> 0
F16: REALIZADO | G16: SOMA | H16: =IF(G16="SOMA",SUM(I16:T16),IF(G16="MÉDIA",AVERAGE(I16:T16),IF(G16="ÚLTIMO RESULTADO",MAX(I16:T16),""))) -> 0
B18: CLIENTES | C18: 1 | D18: =IF('Objetivos Estratégicos '!E13="","",'Objetivos Estratégicos '!E13) | E18: =IF('Objetivos Estratégicos '!F13="","",'Objetivos Estratégicos '!F13) | F18: META | G18: SOMA | H18: =IF(G18="SOMA",SUM(I18:T18),IF(G18="MÉDIA",AVERAGE(I18:T18),IF(G18="ÚLTIMO RESULTADO",MAX(I18:T18),""))) -> 0
F19: REALIZADO | G19: SOMA | H19: =IF(G19="SOMA",SUM(I19:T19),IF(G19="MÉDIA",AVERAGE(I19:T19),IF(G19="ÚLTIMO RESULTADO",MAX(I19:T19),""))) -> 0
C20: 2 | D20: =IF('Objetivos Estratégicos '!E14="","",'Objetivos Estratégicos '!E14) | E20: =IF('Objetivos Estratégicos '!F14="","",'Objetivos Estratégicos '!F14) | F20: META | G20: SOMA | H20: =IF(G20="SOMA",SUM(I20:T20),IF(G20="MÉDIA",AVERAGE(I20:T20),IF(G20="ÚLTIMO RESULTADO",MAX(I20:T20),""))) -> 0
F21: REALIZADO | G21: SOMA | H21: =IF(G21="SOMA",SUM(I21:T21),IF(G21="MÉDIA",AVERAGE(I21:T21),IF(G21="ÚLTIMO RESULTADO",MAX(I21:T21),""))) -> 0
C22: 3 | D22: =IF('Objetivos Estratégicos '!E15="","",'Objetivos Estratégicos '!E15) | E22: =IF('Objetivos Estratégicos '!F15="","",'Objetivos Estratégicos '!F15) | F22: META | G22: SOMA | H22: =IF(G22="SOMA",SUM(I22:T22),IF(G22="MÉDIA",AVERAGE(I22:T22),IF(G22="ÚLTIMO RESULTADO",MAX(I22:T22),""))) -> 0
F23: REALIZADO | G23: SOMA | H23: =IF(G23="SOMA",SUM(I23:T23),IF(G23="MÉDIA",AVERAGE(I23:T23),IF(G23="ÚLTIMO RESULTADO",MAX(I23:T23),""))) -> 0
C24: 4 | D24: =IF('Objetivos Estratégicos '!E16="","",'Objetivos Estratégicos '!E16) | E24: =IF('Objetivos Estratégicos '!F16="","",'Objetivos Estratégicos '!F16) | F24: META | G24: SOMA | H24: =IF(G24="SOMA",SUM(I24:T24),IF(G24="MÉDIA",AVERAGE(I24:T24),IF(G24="ÚLTIMO RESULTADO",MAX(I24:T24),""))) -> 0
F25: REALIZADO | G25: SOMA | H25: =IF(G25="SOMA",SUM(I25:T25),IF(G25="MÉDIA",AVERAGE(I25:T25),IF(G25="ÚLTIMO RESULTADO",MAX(I25:T25),""))) -> 0
C26: 5 | D26: =IF('Objetivos Estratégicos '!E17="","",'Objetivos Estratégicos '!E17) | E26: =IF('Objetivos Estratégicos '!F17="","",'Objetivos Estratégicos '!F17) | F26: META | G26: SOMA | H26: =IF(G26="SOMA",SUM(I26:T26),IF(G26="MÉDIA",AVERAGE(I26:T26),IF(G26="ÚLTIMO RESULTADO",MAX(I26:T26),""))) -> 0
F27: REALIZADO | G27: SOMA | H27: =IF(G27="SOMA",SUM(I27:T27),IF(G27="MÉDIA",AVERAGE(I27:T27),IF(G27="ÚLTIMO RESULTADO",MAX(I27:T27),""))) -> 0
B29: PROCESSOS INTERNOS | C29: 1 | D29: =IF('Objetivos Estratégicos '!E19="","",'Objetivos Estratégicos '!E19) | E29: =IF('Objetivos Estratégicos '!F19="","",'Objetivos Estratégicos '!F19) | F29: META | G29: SOMA | H29: =IF(G29="SOMA",SUM(I29:T29),IF(G29="MÉDIA",AVERAGE(I29:T29),IF(G29="ÚLTIMO RESULTADO",MAX(I29:T29),""))) -> 0
F30: REALIZADO | G30: SOMA | H30: =IF(G30="SOMA",SUM(I30:T30),IF(G30="MÉDIA",AVERAGE(I30:T30),IF(G30="ÚLTIMO RESULTADO",MAX(I30:T30),""))) -> 0
C31: 2 | D31: =IF('Objetivos Estratégicos '!E20="","",'Objetivos Estratégicos '!E20) | E31: =IF('Objetivos Estratégicos '!F20="","",'Objetivos Estratégicos '!F20) | F31: META | G31: SOMA | H31: =IF(G31="SOMA",SUM(I31:T31),IF(G31="MÉDIA",AVERAGE(I31:T31),IF(G31="ÚLTIMO RESULTADO",MAX(I31:T31),""))) -> 0
F32: REALIZADO | G32: SOMA | H32: =IF(G32="SOMA",SUM(I32:T32),IF(G32="MÉDIA",AVERAGE(I32:T32),IF(G32="ÚLTIMO RESULTADO",MAX(I32:T32),""))) -> 0
C33: 3 | D33: =IF('Objetivos Estratégicos '!E21="","",'Objetivos Estratégicos '!E21) | E33: =IF('Objetivos Estratégicos '!F21="","",'Objetivos Estratégicos '!F21) | F33: META | G33: SOMA | H33: =IF(G33="SOMA",SUM(I33:T33),IF(G33="MÉDIA",AVERAGE(I33:T33),IF(G33="ÚLTIMO RESULTADO",MAX(I33:T33),""))) -> 0
F34: REALIZADO | G34: SOMA | H34: =IF(G34="SOMA",SUM(I34:T34),IF(G34="MÉDIA",AVERAGE(I34:T34),IF(G34="ÚLTIMO RESULTADO",MAX(I34:T34),""))) -> 0
C35: 4 | D35: =IF('Objetivos Estratégicos '!E22="","",'Objetivos Estratégicos '!E22) | E35: =IF('Objetivos Estratégicos '!F22="","",'Objetivos Estratégicos '!F22) | F35: META | G35: SOMA | H35: =IF(G35="SOMA",SUM(I35:T35),IF(G35="MÉDIA",AVERAGE(I35:T35),IF(G35="ÚLTIMO RESULTADO",MAX(I35:T35),""))) -> 0
F36: REALIZADO | G36: SOMA | H36: =IF(G36="SOMA",SUM(I36:T36),IF(G36="MÉDIA",AVERAGE(I36:T36),IF(G36="ÚLTIMO RESULTADO",MAX(I36:T36),""))) -> 0
C37: 5 | D37: =IF('Objetivos Estratégicos '!E23="","",'Objetivos Estratégicos '!E23) | E37: =IF('Objetivos Estratégicos '!F23="","",'Objetivos Estratégicos '!F23) | F37: META | G37: SOMA | H37: =IF(G37="SOMA",SUM(I37:T37),IF(G37="MÉDIA",AVERAGE(I37:T37),IF(G37="ÚLTIMO RESULTADO",MAX(I37:T37),""))) -> 0
F38: REALIZADO | G38: SOMA | H38: =IF(G38="SOMA",SUM(I38:T38),IF(G38="MÉDIA",AVERAGE(I38:T38),IF(G38="ÚLTIMO RESULTADO",MAX(I38:T38),""))) -> 0
G39: SOMA
B40: APRENDIZADO E CRESCIMENTO | C40: 1 | D40: =IF('Objetivos Estratégicos '!E25="","",'Objetivos Estratégicos '!E25) | E40: =IF('Objetivos Estratégicos '!F25="","",'Objetivos Estratégicos '!F25) | F40: META | G40: SOMA | H40: =IF(G40="SOMA",SUM(I40:T40),IF(G40="MÉDIA",AVERAGE(I40:T40),IF(G40="ÚLTIMO RESULTADO",MAX(I40:T40),""))) -> 0
F41: REALIZADO | G41: SOMA | H41: =IF(G41="SOMA",SUM(I41:T41),IF(G41="MÉDIA",AVERAGE(I41:T41),IF(G41="ÚLTIMO RESULTADO",MAX(I41:T41),""))) -> 0
C42: 2 | D42: =IF('Objetivos Estratégicos '!E26="","",'Objetivos Estratégicos '!E26) | E42: =IF('Objetivos Estratégicos '!F26="","",'Objetivos Estratégicos '!F26) | F42: META | G42: SOMA | H42: =IF(G42="SOMA",SUM(I42:T42),IF(G42="MÉDIA",AVERAGE(I42:T42),IF(G42="ÚLTIMO RESULTADO",MAX(I42:T42),""))) -> 0
F43: REALIZADO | G43: SOMA | H43: =IF(G43="SOMA",SUM(I43:T43),IF(G43="MÉDIA",AVERAGE(I43:T43),IF(G43="ÚLTIMO RESULTADO",MAX(I43:T43),""))) -> 0
C44: 3 | D44: =IF('Objetivos Estratégicos '!E27="","",'Objetivos Estratégicos '!E27) | E44: =IF('Objetivos Estratégicos '!F27="","",'Objetivos Estratégicos '!F27) | F44: META | G44: SOMA | H44: =IF(G44="SOMA",SUM(I44:T44),IF(G44="MÉDIA",AVERAGE(I44:T44),IF(G44="ÚLTIMO RESULTADO",MAX(I44:T44),""))) -> 0
F45: REALIZADO | G45: SOMA | H45: =IF(G45="SOMA",SUM(I45:T45),IF(G45="MÉDIA",AVERAGE(I45:T45),IF(G45="ÚLTIMO RESULTADO",MAX(I45:T45),""))) -> 0
C46: 4 | D46: =IF('Objetivos Estratégicos '!E28="","",'Objetivos Estratégicos '!E29) | E46: =IF('Objetivos Estratégicos '!F28="","",'Objetivos Estratégicos '!F29) | F46: META | G46: SOMA | H46: =IF(G46="SOMA",SUM(I46:T46),IF(G46="MÉDIA",AVERAGE(I46:T46),IF(G46="ÚLTIMO RESULTADO",MAX(I46:T46),""))) -> 0
F47: REALIZADO | G47: SOMA | H47: =IF(G47="SOMA",SUM(I47:T47),IF(G47="MÉDIA",AVERAGE(I47:T47),IF(G47="ÚLTIMO RESULTADO",MAX(I47:T47),""))) -> 0
...

Sheet Painel Estratégico 
B5: MÊS | D5: 44562 | G5: MENSAL | J5: ACUMULADO
B7: PERSPECTIVA | C7: Nº | D7: OBJETIVO | E7: UNI MEDIDA | F7: ORIENTAÇÃO | G7: META | H7: RESULTADO | I7: % | J7: META | K7: RESULTADO | L7: % | N7: PESO | O7: % TOTAL
B9: FINANÇAS | C9: 1 | D9: =IF('Objetivos Estratégicos '!E7="","",'Objetivos Estratégicos '!E7) | E9: R$ | F9: MAIS | G9: =SUMIF(Desdobramentos!$5:$5,$D$5,Desdobramentos!$7:$7) -> 0 | H9: =SUMIF(Desdobramentos!$5:$5,$D$5,Desdobramentos!$8:$8) -> 0 | I9: =IF(F9="Menos",G9/H9,IFERROR(H9/G9,"")) | J9: =SUMIF(Desdobramentos!$5:$5,"<="&$D$5,Desdobramentos!$7:$7) -> 0 | K9: =SUMIF(Desdobramentos!$5:$5,"<="&$D$5,Desdobramentos!$8:$8) -> 0 | L9: =IFERROR(K9/J9,"") | N9: 0.4 | O9: =IFERROR(IF(F9="Mais",(K9*100%)/J9,(100%-(K9-J9)/J9))*N9,"")
C10: 2 | D10: =IF('Objetivos Estratégicos '!E8="","",'Objetivos Estratégicos '!E8) | E10: R$ | F10: MAIS | G10: =SUMIF(Desdobramentos!$5:$5,$D$5,Desdobramentos!$9:$9) -> 0 | H10: =SUMIF(Desdobramentos!$5:$5,$D$5,Desdobramentos!$10:$10) -> 0 | I10: =IF(F10="Menos",G10/H10,IFERROR(H10/G10,"")) | J10: =SUMIF(Desdobramentos!$5:$5,"<="&$D$5,Desdobramentos!$9:$9) -> 0 | K10: =SUMIF(Desdobramentos!$5:$5,"<="&$D$5,Desdobramentos!$10:$10) -> 0 | L10: =IFERROR(K10/J10,"") | N10: 0.4 | O10: =IFERROR(IF(F10="Mais",(K10*100%)/J10,(100%-(K10-J10)/J10))*N10,"")
C11: 3 | D11: =IF('Objetivos Estratégicos '!E9="","",'Objetivos Estratégicos '!E9) | E11: R$ | F11: MAIS | G11: =SUMIF(Desdobramentos!$5:$5,$D$5,Desdobramentos!$11:$11) -> 0 | H11: =SUMIF(Desdobramentos!$5:$5,$D$5,Desdobramentos!$12:$12) -> 0 | I11: =IF(F11="Menos",G11/H11,IFERROR(H11/G11,"")) | J11: =SUMIF(Desdobramentos!$5:$5,"<="&$D$5,Desdobramentos!$11:$11) -> 0 | K11: =SUMIF(Desdobramentos!$5:$5,"<="&$D$5,Desdobramentos!$12:$12) -> 0 | L11: =IFERROR(K11/J11,"") | N11: 0.2 | O11: =IFERROR(IF(F11="Mais",(K11*100%)/J11,(100%-(K11-J11)/J11))*N11,"")
C12: 4 | D12: =IF('Objetivos Estratégicos '!E10="","",'Objetivos Estratégicos '!E10) | E12: R$ | F12: MAIS | G12: =SUMIF(Desdobramentos!$5:$5,$D$5,Desdobramentos!$13:$13) -> 0 | H12: =SUMIF(Desdobramentos!$5:$5,$D$5,Desdobramentos!$14:$14) -> 0 | I12: =IF(F12="Menos",G12/H12,IFERROR(H12/G12,"")) | J12: =SUMIF(Desdobramentos!$5:$5,"<="&$D$5,Desdobramentos!$13:$13) -> 0 | K12: =SUMIF(Desdobramentos!$5:$5,"<="&$D$5,Desdobramentos!$14:$14) -> 0 | L12: =IFERROR(K12/J12,"") | N12: 0 | O12: =IFERROR(IF(F12="Mais",(K12*100%)/J12,(100%-(K12-J12)/J12))*N12,"")
C13: 5 | D13: =IF('Objetivos Estratégicos '!E11="","",'Objetivos Estratégicos '!E11) | E13: R$ | F13: MAIS | G13: =SUMIF(Desdobramentos!$5:$5,$D$5,Desdobramentos!$15:$15) -> 0 | H13: =SUMIF(Desdobramentos!$5:$5,$D$5,Desdobramentos!$16:$16) -> 0 | I13: =IF(F13="Menos",G13/H13,IFERROR(H13/G13,"")) | J13: =SUMIF(Desdobramentos!$5:$5,"<="&$D$5,Desdobramentos!$15:$15) -> 0 | K13: =SUMIF(Desdobramentos!$5:$5,"<="&$D$5,Desdobramentos!$16:$16) -> 0 | L13: =IFERROR(K13/J13,"") | N13: 0 | O13: =IFERROR(IF(F13="Mais",(K13*100%)/J13,(100%-(K13-J13)/J13))*N13,"")
N14: =SUM(N9:N13) -> 1 | O14: =SUM(O9:O13) -> 0
B16: CLIENTES | C16: 1 | D16: =IF('Objetivos Estratégicos '!E13="","",'Objetivos Estratégicos '!E13) | G16: =SUMIF(Desdobramentos!$5:$5,$D$5,Desdobramentos!$17:$17) -> 0 | H16: =SUMIF(Desdobramentos!$5:$5,$D$5,Desdobramentos!$18:$18) -> 0 | I16: =IF(F16="Menos",G16/H16,IFERROR(H16/G16,"")) | J16: =SUMIF(Desdobramentos!$5:$5,"<="&$D$5,Desdobramentos!$17:$17) -> 0 | K16: =SUMIF(Desdobramentos!$5:$5,"<="&$D$5,Desdobramentos!$18:$18) -> 0 | L16: =IFERROR(K16/J16,"") | N16: 0.2 | O16: =IFERROR(IF(F16="Mais",(K16*100%)/J16,(100%-(K16-J16)/J16))*N16,"")
C17: 2 | D17: =IF('Objetivos Estratégicos '!E14="","",'Objetivos Estratégicos '!E14) | F17: MÉDIA | G17: =SUMIF(Desdobramentos!$5:$5,$D$5,Desdobramentos!$19:$19) -> 0 | H17: =SUMIF(Desdobramentos!$5:$5,$D$5,Desdobramentos!$20:$20) -> 0 | I17: =IF(F17="Menos",G17/H17,IFERROR(H17/G17,"")) | J17: =SUMIF(Desdobramentos!$5:$5,"<="&$D$5,Desdobramentos!$19:$19) -> 0 | K17: =SUMIF(Desdobramentos!$5:$5,"<="&$D$5,Desdobramentos!$20:$20) -> 0 | L17: =IFERROR(K17/J17,"") | N17: 0.8 | O17: =IFERROR(IF(F17="Mais",(K17*100%)/J17,(100%-(K17-J17)/J17))*N17,"")
C18: 3 | D18: =IF('Objetivos Estratégicos '!E15="","",'Objetivos Estratégicos '!E15) | G18: =SUMIF(Desdobramentos!$5:$5,$D$5,Desdobramentos!$21:$21) -> 0 | H18: =SUMIF(Desdobramentos!$5:$5,$D$5,Desdobramentos!$22:$22) -> 0 | I18: =IF(F18="Menos",G18/H18,IFERROR(H18/G18,"")) | J18: =SUMIF(Desdobramentos!$5:$5,"<="&$D$5,Desdobramentos!$21:$21) -> 0 | K18: =SUMIF(Desdobramentos!$5:$5,"<="&$D$5,Desdobramentos!$22:$22) -> 0 | L18: =IFERROR(K18/J18,"") | N18: 0 | O18: =IFERROR(IF(F18="Mais",(K18*100%)/J18,(100%-(K18-J18)/J18))*N18,"")
C19: 4 | D19: =IF('Objetivos Estratégicos '!E16="","",'Objetivos Estratégicos '!E16) | G19: =SUMIF(Desdobramentos!$5:$5,$D$5,Desdobramentos!$23:$23) -> 0 | H19: =SUMIF(Desdobramentos!$5:$5,$D$5,Desdobramentos!$24:$24) -> 0 | I19: =IF(F19="Menos",G19/H19,IFERROR(H19/G19,"")) | J19: =SUMIF(Desdobramentos!$5:$5,"<="&$D$5,Desdobramentos!$23:$23) -> 0 | K19: =SUMIF(Desdobramentos!$5:$5,"<="&$D$5,Desdobramentos!$24:$24) -> 0 | L19: =IFERROR(K19/J19,"") | N19: 0 | O19: =IFERROR(IF(F19="Mais",(K19*100%)/J19,(100%-(K19-J19)/J19))*N19,"")
C20: 5 | D20: =IF('Objetivos Estratégicos '!E17="","",'Objetivos Estratégicos '!E17) | G20: =SUMIF(Desdobramentos!$5:$5,$D$5,Desdobramentos!$25:$25) -> 0 | H20: =SUMIF(Desdobramentos!$5:$5,$D$5,Desdobramentos!$26:$26) -> 0 | I20: =IF(F20="Menos",G20/H20,IFERROR(H20/G20,"")) | J20: =SUMIF(Desdobramentos!$5:$5,"<="&$D$5,Desdobramentos!$25:$25) -> 0 | K20: =SUMIF(Desdobramentos!$5:$5,"<="&$D$5,Desdobramentos!$26:$26) -> 0 | L20: =IFERROR(K20/J20,"") | N20: 0 | O20: =IFERROR(IF(F20="Mais",(K20*100%)/J20,(100%-(K20-J20)/J20))*N20,"")
N21: =SUM(N16:N20) -> 1 | O21: =SUM(O16:O20) -> 0
B23: PROCESSOS INTERNOS | C23: 1 | D23: =IF('Objetivos Estratégicos '!E19="","",'Objetivos Estratégicos '!E19) | G23: =SUMIF(Desdobramentos!$5:$5,$D$5,Desdobramentos!$28:$28) -> 0 | H23: =SUMIF(Desdobramentos!$5:$5,$D$5,Desdobramentos!$29:$29) -> 0 | I23: =IF(F23="Menos",G23/H23,IFERROR(H23/G23,"")) | J23: =SUMIF(Desdobramentos!$5:$5,"<="&$D$5,Desdobramentos!$28:$28) -> 0 | K23: =SUMIF(Desdobramentos!$5:$5,"<="&$D$5,Desdobramentos!$29:$29) -> 0 | L23: =IFERROR(K23/J23,"") | N23: 1
C24: 2 | D24: =IF('Objetivos Estratégicos '!E20="","",'Objetivos Estratégicos '!E20) | G24: =SUMIF(Desdobramentos!$5:$5,$D$5,Desdobramentos!$30:$30) -> 0 | H24: =SUMIF(Desdobramentos!$5:$5,$D$5,Desdobramentos!$31:$31) -> 0 | I24: =IF(F24="Menos",G24/H24,IFERROR(H24/G24,"")) | J24: =SUMIF(Desdobramentos!$5:$5,"<="&$D$5,Desdobramentos!$30:$30) -> 0 | K24: =SUMIF(Desdobramentos!$5:$5,"<="&$D$5,Desdobramentos!$31:$31) -> 0 | L24: =IFERROR(K24/J24,"") | N24: 0
C25: 3 | D25: =IF('Objetivos Estratégicos '!E21="","",'Objetivos Estratégicos '!E21) | G25: =SUMIF(Desdobramentos!$5:$5,$D$5,Desdobramentos!$32:$32) -> 0 | H25: =SUMIF(Desdobramentos!$5:$5,$D$5,Desdobramentos!$33:$33) -> 0 | I25: =IF(F25="Menos",G25/H25,IFERROR(H25/G25,"")) | J25: =SUMIF(Desdobramentos!$5:$5,"<="&$D$5,Desdobramentos!$32:$32) -> 0 | K25: =SUMIF(Desdobramentos!$5:$5,"<="&$D$5,Desdobramentos!$33:$33) -> 0 | L25: =IFERROR(K25/J25,"") | N25: 0
C26: 4 | D26: =IF('Objetivos Estratégicos '!E22="","",'Objetivos Estratégicos '!E22) | G26: =SUMIF(Desdobramentos!$5:$5,$D$5,Desdobramentos!$34:$34) -> 0 | H26: =SUMIF(Desdobramentos!$5:$5,$D$5,Desdobramentos!$35:$35) -> 0 | I26: =IF(F26="Menos",G26/H26,IFERROR(H26/G26,"")) | J26: =SUMIF(Desdobramentos!$5:$5,"<="&$D$5,Desdobramentos!$34:$34) -> 0 | K26: =SUMIF(Desdobramentos!$5:$5,"<="&$D$5,Desdobramentos!$35:$35) -> 0 | L26: =IFERROR(K26/J26,"") | N26: 0
C27: 5 | D27: =IF('Objetivos Estratégicos '!E23="","",'Objetivos Estratégicos '!E23) | G27: =SUMIF(Desdobramentos!$5:$5,$D$5,Desdobramentos!$36:$36) -> 0 | H27: =SUMIF(Desdobramentos!$5:$5,$D$5,Desdobramentos!$37:$37) -> 0 | I27: =IF(F27="Menos",G27/H27,IFERROR(H27/G27,"")) | J27: =SUMIF(Desdobramentos!$5:$5,"<="&$D$5,Desdobramentos!$36:$36) -> 0 | K27: =SUMIF(Desdobramentos!$5:$5,"<="&$D$5,Desdobramentos!$37:$37) -> 0 | L27: =IFERROR(K27/J27,"") | N27: 0
N28: =SUM(N23:N27) -> 1 | O28: =SUM(O23:O27) -> 0
B30: APRENDIZADO E CRESCIMENTO | C30: 1 | D30: =IF('Objetivos Estratégicos '!E25="","",'Objetivos Estratégicos '!E25) | G30: =SUMIF(Desdobramentos!$5:$5,$D$5,Desdobramentos!$38:$38) -> 0 | H30: =SUMIF(Desdobramentos!$5:$5,$D$5,Desdobramentos!$39:$39) -> 0 | I30: =IF(F30="Menos",G30/H30,IFERROR(H30/G30,"")) | J30: =SUMIF(Desdobramentos!$5:$5,"<="&$D$5,Desdobramentos!$38:$38) -> 0 | K30: =SUMIF(Desdobramentos!$5:$5,"<="&$D$5,Desdobramentos!$39:$39) -> 0 | L30: =IFERROR(K30/J30,"") | N30: 0.4
C31: 2 | D31: =IF('Objetivos Estratégicos '!E26="","",'Objetivos Estratégicos '!E26) | G31: =SUMIF(Desdobramentos!$5:$5,$D$5,Desdobramentos!$40:$40) -> 0 | H31: =SUMIF(Desdobramentos!$5:$5,$D$5,Desdobramentos!$41:$41) -> 0 | I31: =IF(F31="Menos",G31/H31,IFERROR(H31/G31,"")) | J31: =SUMIF(Desdobramentos!$5:$5,"<="&$D$5,Desdobramentos!$40:$40) -> 0 | K31: =SUMIF(Desdobramentos!$5:$5,"<="&$D$5,Desdobramentos!$41:$41) -> 0 | L31: =IFERROR(K31/J31,"") | N31: 0.4
C32: 3 | D32: =IF('Objetivos Estratégicos '!E27="","",'Objetivos Estratégicos '!E27) | G32: =SUMIF(Desdobramentos!$5:$5,$D$5,Desdobramentos!$42:$42) -> 0 | H32: =SUMIF(Desdobramentos!$5:$5,$D$5,Desdobramentos!$43:$43) -> 0 | I32: =IF(F32="Menos",G32/H32,IFERROR(H32/G32,"")) | J32: =SUMIF(Desdobramentos!$5:$5,"<="&$D$5,Desdobramentos!$42:$42) -> 0 | K32: =SUMIF(Desdobramentos!$5:$5,"<="&$D$5,Desdobramentos!$43:$43) -> 0 | L32: =IFERROR(K32/J32,"") | N32: 0
C33: 4 | D33: =IF('Objetivos Estratégicos '!E28="","",'Objetivos Estratégicos '!E28) | G33: =SUMIF(Desdobramentos!$5:$5,$D$5,Desdobramentos!$44:$44) -> 0 | H33: =SUMIF(Desdobramentos!$5:$5,$D$5,Desdobramentos!$45:$45) -> 0 | I33: =IF(F33="Menos",G33/H33,IFERROR(H33/G33,"")) | J33: =SUMIF(Desdobramentos!$5:$5,"<="&$D$5,Desdobramentos!$44:$44) -> 0 | K33: =SUMIF(Desdobramentos!$5:$5,"<="&$D$5,Desdobramentos!$45:$45) -> 0 | L33: =IFERROR(K33/J33,"") | N33: 0.1
C34: 5 | D34: =IF('Objetivos Estratégicos '!E29="","",'Objetivos Estratégicos '!E29) | G34: =SUMIF(Desdobramentos!$5:$5,$D$5,Desdobramentos!$46:$46) -> 0 | H34: =SUMIF(Desdobramentos!$5:$5,$D$5,Desdobramentos!$47:$47) -> 0 | I34: =IF(F34="Menos",G34/H34,IFERROR(H34/G34,"")) | J34: =SUMIF(Desdobramentos!$5:$5,"<="&$D$5,Desdobramentos!$46:$46) -> 0 | K34: =SUMIF(Desdobramentos!$5:$5,"<="&$D$5,Desdobramentos!$47:$47) -> 0 | L34: =IFERROR(K34/J34,"") | N34: 0.1
N35: =SUM(N30:N34) -> 1 | O35: =SUM(O30:O34) -> 0

Sheet Dúvidas e Respostas
C2: Receitas x Despesas | D2: Mês Anterior x Mês Atual | E2: Contas a Receber x Contas a Pagar | F2: Necessidade de Caixa x Acumulado
A3: =#REF! -> #REF! | B3: Positivo | C3: Parabéns! As suas receitas estão maiores do que as suas despesas. Meses com lucro são sempre interessantes para a sua empresa. Aproveite e dê uma olhada nas contas a pagar e a receber do próximo mês para saber se você vai continuar mandando bem. | D3: Boa! Suas finanças melhoraram do mês passado para esse. Que tal investigar os motivos e dedicar mais tempo para replicá-las? | E3: Legal, você tem mais recebimentos do que pagamentos para entrar em caixa. Só tome cuidado com o índice de inadimplência dos seus devedores para não transformar essa projeção em um resultado real ruim | F3: Sua necessidade de caixa para o mês que vem é menor do que você tem acumulado. Sua empresa está indo bem, mas fique de olho nos meses futuros para não ter surpresas!
A4: =#REF! -> #REF! | B4: Negativo | C4: Suas despesas estão maiores que as suas receitas, isso significa que esse mês foi de prejuízo. Você já sabe os motivos? Vale a pena olhar suas despesas no DRE para ter certeza que o resultado ruim não se repetirá. | D4: Tome cuidado, seu resultado mensal piorou do mês passado para esse. Esse mês é sempre ruim ou aconteceu alguma coisa que fez seu resultado piorar? | E4: Cuidado! Suas contas a pagar para esse mês estão superiores ao que você tem direito a receber, se você não procurar reverter essa situação, provavelmente terá prejuízo | F4: Sua necessidade de caixa para o mês que vem é maior do que você tem acumulado. É bom você ficar atento e correr atrás de mais receitas, afinal de contas, a previsão é que você entre no vermelho se tudo continuar assim
C6: Pergunta | D6: Resposta
C7: 1. O que significa SWOT? | D7: O termo SWOT é uma sigla oriunda do idioma inglês, e é um acrónimo de Forças (Strengths), Fraquezas (Weaknesses), Oportunidades (Opportunities) e Ameaças (Threats).
C8: 2. O que é análise SWOT? | D8: A Análise SWOT ou Análise FOFA ou FFOA (Forças, Fraquezas, Oportunidades e Ameaças) (em português) é uma ferramenta utilizada para fazer análise de cenário (ou análise de ambiente), sendo usada como base para gestão e planejamento estratégico de uma corporação ou empresa, mas podendo, devido a sua simplicidade, ser utilizada para qualquer tipo de análise de cenário, desde a criação de um blog à gestão de uma multinacional.
C9: 4. O que são fatores internos? | D9: Tratam-se das características específicas do seu negócio. Pontos fortes ou fracos da sua equipe, excelência ou improdutividade em processos internos, etc. Ou seja, forças e fraquezas relativas a outros players do mercado.
C10: 6. O que são forças? | D10: Forças - Vantagens internas da empresa em relação às empresas concorrentes.
C11: 7. O que são fraquezas? | D11: Fraquezas - Desvantagens internas da empresa em relação às empresas concorrentes.
C12: 5. O que são fatores externos? | D12: Tratam-se das características e mudanças que o mercado como um todo pode apresentar que poderão beneficiar ou atrapalhar seu negócio. Oportunidades são as positivas e Ameaças são as negativas.
C13: 6. O que são oportunidades? | D13: Oportunidades - Aspectos positivos do mercado com potencial de fazer crescer a vantagem competitiva da empresa.
C14: 7. O que são ameaças? | D14: Ameaças - Aspectos positivos do mercado com potencial de comprometer a vantagem competitiva da empresa.
C15: 8. O que são cruzamentos de dados? | D15: A combinação destes dois ambientes, interno e externo, e das suas variáveis, Forças e Fraquezas; Oportunidades e Ameaças, irá facilitar a análise e a procura para tomada de decisões na definição das estratégias de negócios da empresa. Forças e Oportunidades - Tirar o máximo partido dos pontos fortes para aproveitar ao máximo as oportunidades detectadas. Forças e Ameaças - Tirar o máximo partido dos pontos fortes para minimizar os efeitos das ameaças detectadas. Fraquezas e Oportunidades - Desenvolver estratégias que minimizem os efeitos negativos dos pontos fracos e que em simultâneo aproveitem as oportunidades detectadas. Fraquezas e Ameaças - As estratégias a adotar devem minimizar ou ultrapassar os pontos fracos e, tanto quanto possível, fazer face às ameaças.
C16: 9. O que é matriz SWOT | D16: É uma matriz em que se identificam as suas maiores forças, fraquezas, oportunidades e ameaças. Permite distinguir o ambiente interno - (factores e realidades internas - forças e fraquezas) e o ambiente externo (factores e aspectos futuros - oportunidades e ameaças) da organização.
C17: 8. Posso adicionar mais linhas e colunas na planilha? | D17: Nós recomendamos fortemente que você utilize a estrutura pronta apresentada, pois existem diversas fórmulas que podem ser afetadas pela adição de linhas e colunas. Além disso, para facilitar o preenchimento mantemos a planilha desbloqueada apenas nos locais para preenchimento.
... C21: 12. Como desbloquear a planilha? | D21: Basta entrar no menu superior "Revisão" e escolher o item desproteger planilha no grupo Alterações. As planilhas não possuem senhas, apenas estão bloqueadas para melhorar a usabilidade delas
