Workbook

Sheet Fixas 
F1: Despesas Recorrentes
A3: Descrição | B3: Categoria | C3: Janeiro | D3: Fevereiro | E3: Março | F3: Abril | G3: Maio | H3: Junho | I3: Julho | J3: Agosto | K3: Setembro | L3: Outubro | M3: Novembro | N3: Dezembro | P3: Total - Anual por Item
A6: Copy | B6: Serviços | P6: =SUM(C6:N6) -> 0
A7: Designer | B7: Serviços | D7: 0 | E7: 0 | F7: 0 | G7: 0 | H7: 0 | I7: 0 | J7: 0 | K7: 0 | L7: 0 | M7: 0 | P7: =SUM(C7:N7) -> 0
A8: Edição de Video | B8: Serviços | D8: 0 | E8: 0 | F8: 0 | G8: 0 | H8: 0 | I8: 0 | J8: 0 | K8: 0 | L8: 0 | M8: 0 | P8: =SUM(C8:N8) -> 0
A9: Suporte | B9: Serviços | D9: 0 | E9: 0 | F9: 0 | G9: 0 | H9: 0 | I9: 0 | J9: 0 | K9: 0 | L9: 0 | M9: 0 | P9: =SUM(C9:N9) -> 0
A10: Revisão | B10: Serviços | D10: 0 | E10: 0 | F10: 0 | G10: 0 | H10: 0 | I10: 0 | J10: 0 | K10: 0 | L10: 0 | M10: 0 | P10: =SUM(C10:N10) -> 0
A11: Active | B11: Serviços | D11: 0 | E11: 0 | F11: 0 | G11: 0 | H11: 0 | I11: 0 | J11: 0 | K11: 0 | L11: 0 | M11: 0 | P11: =SUM(C11:N11) -> 0
A12: Gestor de Tráfego | B12: Serviços | D12: 0 | E12: 0 | F12: 0 | G12: 0 | H12: 0 | I12: 0 | J12: 0 | K12: 0 | L12: 0 | M12: 0 | P12: =SUM(C12:N12) -> 0
A13: Tráfego - Investimento | B13: Insumos | D13: 0 | E13: 0 | F13: 0 | G13: 0 | H13: 0 | I13: 0 | J13: 0 | K13: 0 | L13: 0 | M13: 0 | P13: =SUM(C13:N13) -> 0
A14: TESTE | D14: 0 | E14: 0 | F14: 0 | G14: 0 | H14: 0 | I14: 0 | J14: 0 | K14: 0 | L14: 0 | M14: 0 | P14: =SUM(C14:N14) -> 0
A15: Automação | B15: Serviços | D15: 0 | E15: 0 | F15: 0 | G15: 0 | H15: 0 | I15: 0 | J15: 0 | K15: 0 | L15: 0 | M15: 0 | P15: =SUM(C15:N15) -> 0
A16: Gerente de Projetos | B16: Serviços | D16: 0 | E16: 0 | F16: 0 | G16: 0 | H16: 0 | I16: 0 | J16: 0 | K16: 0 | L16: 0 | M16: 0 | P16: =SUM(C16:N16) -> 0
A17: Domínio | B17: Ferramentas | D17: 0 | E17: 0 | F17: 0 | G17: 0 | H17: 0 | I17: 0 | J17: 0 | K17: 0 | M17: 0 | P17: =SUM(C17:N17) -> 0
A18: Hospedagem | B18: Ferramentas | D18: 0 | E18: 0 | F18: 0 | G18: 0 | H18: 0 | I18: 0 | J18: 0 | K18: 0 | M18: 0 | P18: =SUM(C18:N18) -> 0
D19: =SUM(MAIO!N24+Junho!N24+JULHO!N24+AGOSTO!N24+SETEMBRO!M21+OUTUBRO!M21+NOVEMBRO!O24+DEZEMBRO!O24+'JANEIRO/23'!O24+'Fevereiro/23'!O25+'Março/23'!O25+'Abril/23'!O27+'Maio/23'!O26) -> #REF! | P19: =SUM(C19:N19) -> #REF!
P20: =SUM(C20:N20) -> 0
P21: =SUM(C21:N21) -> 0
P22: =SUM(C22:N22) -> 0
P23: =SUM(C23:N23) -> 0
P24: =SUM(C24:N24) -> 0
P25: =SUM(C25:N25) -> 0
P26: =SUM(C26:N26) -> 0
P27: =SUM(C27:N27) -> 0
A29: Total | C29: =SUM(C6:C27) -> 0 | D29: =SUM(D6:D27) -> #REF! | E29: =SUM(E6:E27) -> 0 | F29: =SUM(F6:F27) -> 0 | G29: =SUM(G6:G27) -> 0 | H29: =SUM(H6:H27) -> 0 | I29: =SUM(I6:I27) -> 0 | J29: =SUM(J6:J27) -> 0 | ... N29: =SUM(N6:N27) -> 0
K30: Total Anual - Acumulado | M30: =SUM(C29:N29) -> #REF!
A31: Total
A32: Porcentagem Expert | B32: 0.7 | C32: =SUM(C29*B32) -> 0 | D32: =SUM(D29*B32) -> #REF! | E32: =SUM(E29*B32) -> 0 | F32: =SUM(F29*B32) -> 0 | G32: =SUM(G29*B32) -> 0 | H32: =SUM(H29*B32) -> 0 | I32: =SUM(I29*B32) -> 0 | J32: =SUM(J29*B32) -> 0 | K32: Valor Expert | M32: =SUM(M30*B32) -> #REF!
A33: Porcentagem Co - Produtor | B33: 0.3 | C33: =SUM(C29*B33) -> 0 | D33: =SUM(D29*B33) -> #REF! | E33: =SUM(E29*C33) -> 0 | F33: =SUM(F29*D33) -> #REF! | G33: =SUM(G29*E33) -> 0 | H33: =SUM(H29*F33) -> #REF! | I33: =SUM(I29*G33) -> 0 | J33: =SUM(J29*H33) -> #REF! | K33: Valor Co - Produtor | M33: =SUM(M31*B33) -> 0

Sheet Fluxo de Caixa 
G1: Fluxo de Caixa
A4: ENTRADAS | B4: Produtos | C4: Previsto - 01 | D4: Realizado - 01 | E4: Previsto - 02 | F4: Realizado - 02 | G4: Previsto - 03 | H4: Realizado - 03 | I4: Previsto - 04 | J4: Realizado - 04 | K4: Previsto - 05 | L4: Realizado - 05 | M4: Previsto - 06 | N4: Realizado - 06 | O4: Previsto - 07 | P4: Realizado - 07 | Q4: Previsto - 08 | R4: Realizado - 08 | S4: Previsto - 09 | T4: Realizado - 09 | U4: Previsto - 10 | V4: Realizado - 10 | W4: Previsto - 11 | X4: Realizado - 11 | Y4: Previsto - 12 | Z4: Previsto - 12
A7: Previsão de recebimento - Lançamentos | E7: 0 | F7: 0 | G7: 0 | H7: 0 | I7: 0 | J7: 0 | K7: 0 | L7: 0 | M7: 0 | N7: 0 | O7: 0 | P7: 0 | Q7: 0 | R7: 0 | S7: 0 | T7: 0 | U7: 0 | V7: 0 | W7: 0 | X7: 0 | Y7: 0 | Z7: 0
A8: Previsão de recebimento - Perpétuo | D8: 0 | E8: 0 | F8: 0 | G8: 0 | H8: 0 | I8: 0 | J8: 0 | K8: 0 | L8: 0 | M8: 0 | N8: 0 | O8: 0 | P8: 0 | Q8: 0 | R8: 0 | S8: 0 | T8: 0 | U8: 0 | V8: 0 | W8: 0 | X8: 0 | Y8: 0 | Z8: 0
A9: Mentoria | D9: 0 | E9: 0 | F9: 0 | G9: 0 | H9: 0 | I9: 0 | J9: 0 | K9: 0 | L9: 0 | M9: 0 | N9: 0 | O9: 0 | P9: 0 | Q9: 0 | R9: 0 | S9: 0 | T9: 0 | U9: 0 | V9: 0 | W9: 0 | X9: 0 | Y9: 0 | Z9: 0
D10: 0 | E10: 0 | F10: 0 | G10: 0 | H10: 0 | I10: 0 | J10: 0 | K10: 0 | L10: 0 | M10: 0 | N10: 0 | O10: 0 | P10: 0 | Q10: 0 | R10: 0 | S10: 0 | T10: 0 | U10: 0 | V10: 0 | W10: 0 | X10: 0 | Y10: 0 | Z10: 0
A11: TOTAL DAS ENTRADAS | C11: =SUM(C7:C9) -> 0 | D11: =SUM(D7:D9) -> 0 | E11: =SUM(E7:E9) -> 0 | F11: =SUM(F7:F9) -> 0 | G11: =SUM(G7:G9) -> 0 | H11: =SUM(H7:H9) -> 0 | I11: =SUM(I7:I9) -> 0 | J11: =SUM(J7:J9) -> 0 | ... Z11: =SUM(Z7:Z9) -> 0
A13: SAÍDAS
A15: ='Fixas '!A6 -> Copy | F15: 0 | H15: 0 | J15: 0 | L15: 0 | N15: 0 | O15: ='Fixas '!I6 | P15: 0 | Q15: ='Fixas '!J6 | R15: 0 | S15: ='Fixas '!K6 | T15: 0 | U15: ='Fixas '!L6 | V15: 0 | W15: ='Fixas '!M6 | X15: 0 | Y15: ='Fixas '!N6 | Z15: 0
A16: ='Fixas '!A7 -> Designer | D16: 0 | E16: ='Fixas '!D7 -> 0 | F16: 0 | G16: ='Fixas '!E7 -> 0 | H16: 0 | I16: ='Fixas '!F7 -> 0 | J16: 0 | K16: ='Fixas '!G7 -> 0 | L16: 0 | M16: ='Fixas '!H7 -> 0 | N16: 0 | O16: ='Fixas '!I7 -> 0 | P16: 0 | Q16: ='Fixas '!J7 -> 0 | R16: 0 | S16: ='Fixas '!K7 -> 0 | T16: 0 | U16: ='Fixas '!L7 -> 0 | V16: 0 | W16: 0 | X16: 0 | Y16: 0 | Z16: 0
A17: ='Fixas '!A8 -> Edição de Video | D17: 0 | E17: ='Fixas '!D8 -> 0 | F17: 0 | G17: ='Fixas '!E8 -> 0 | H17: 0 | I17: ='Fixas '!F8 -> 0 | J17: 0 | K17: ='Fixas '!G8 -> 0 | L17: 0 | M17: ='Fixas '!H8 -> 0 | N17: 0 | O17: ='Fixas '!I8 -> 0 | P17: 0 | Q17: ='Fixas '!J8 -> 0 | R17: 0 | S17: ='Fixas '!K8 -> 0 | T17: 0 | U17: ='Fixas '!L8 -> 0 | V17: 0 | W17: 0 | X17: 0 | Y17: 0 | Z17: 0
A18: ='Fixas '!A9 -> Suporte | D18: 0 | E18: ='Fixas '!D9 -> 0 | F18: 0 | G18: ='Fixas '!E9 -> 0 | H18: 0 | I18: ='Fixas '!F9 -> 0 | J18: 0 | K18: ='Fixas '!G9 -> 0 | L18: 0 | M18: ='Fixas '!H9 -> 0 | N18: 0 | O18: ='Fixas '!I9 -> 0 | P18: 0 | Q18: ='Fixas '!J9 -> 0 | R18: 0 | S18: ='Fixas '!K9 -> 0 | T18: 0 | U18: ='Fixas '!L9 -> 0 | V18: 0 | W18: 0 | X18: 0 | Y18: 0 | Z18: 0
A19: ='Fixas '!A10 -> Revisão | D19: 0 | E19: ='Fixas '!D10 -> 0 | F19: 0 | G19: ='Fixas '!E10 -> 0 | H19: 0 | I19: ='Fixas '!F10 -> 0 | J19: 0 | K19: ='Fixas '!G10 -> 0 | L19: 0 | M19: ='Fixas '!H10 -> 0 | N19: 0 | O19: ='Fixas '!I10 -> 0 | P19: 0 | Q19: ='Fixas '!J10 -> 0 | R19: 0 | S19: ='Fixas '!K10 -> 0 | T19: 0 | U19: ='Fixas '!L10 -> 0 | V19: 0 | W19: 0 | X19: 0 | Y19: 0 | Z19: 0
A20: ='Fixas '!A11 -> Active | C20: ='Fixas '!C11 | D20: 0 | E20: ='Fixas '!D11 -> 0 | F20: 0 | G20: ='Fixas '!E11 -> 0 | H20: 0 | I20: ='Fixas '!F11 -> 0 | J20: 0 | K20: ='Fixas '!G11 -> 0 | L20: 0 | M20: ='Fixas '!H11 -> 0 | N20: 0 | O20: ='Fixas '!I11 -> 0 | P20: 0 | Q20: ='Fixas '!J11 -> 0 | R20: 0 | S20: ='Fixas '!K11 -> 0 | T20: 0 | U20: ='Fixas '!L11 -> 0 | V20: 0 | W20: 0 | X20: 0 | Y20: 0 | Z20: 0
A21: ='Fixas '!A12 -> Gestor de Tráfego | D21: 0 | E21: ='Fixas '!D12 -> 0 | F21: 0 | G21: ='Fixas '!E12 -> 0 | H21: 0 | I21: ='Fixas '!F12 -> 0 | J21: 0 | K21: ='Fixas '!G12 -> 0 | L21: 0 | M21: ='Fixas '!H12 -> 0 | N21: 0 | O21: ='Fixas '!I12 -> 0 | P21: 0 | Q21: ='Fixas '!J12 -> 0 | R21: 0 | S21: ='Fixas '!K12 -> 0 | T21: 0 | U21: ='Fixas '!L12 -> 0 | V21: 0 | W21: 0 | X21: 0 | Y21: 0 | Z21: 0
A22: ='Fixas '!A13 -> Tráfego - Investimento | C22: ='Fixas '!C13 | D22: 0 | E22: ='Fixas '!D13 -> 0 | F22: 0 | G22: ='Fixas '!E13 -> 0 | H22: 0 | I22: ='Fixas '!F13 -> 0 | J22: 0 | K22: ='Fixas '!G13 -> 0 | L22: 0 | M22: ='Fixas '!H13 -> 0 | N22: 0 | O22: ='Fixas '!I13 -> 0 | P22: 0 | Q22: ='Fixas '!J13 -> 0 | R22: 0 | S22: ='Fixas '!K13 -> 0 | T22: 0 | U22: ='Fixas '!L13 -> 0 | V22: 0 | W22: 0 | X22: 0 | Y22: 0 | Z22: 0
A23: ='Fixas '!A14 -> TESTE | C23: ='Fixas '!C14 | D23: 0 | E23: ='Fixas '!D14 -> 0 | F23: 0 | G23: ='Fixas '!E14 -> 0 | H23: 0 | I23: ='Fixas '!F14 -> 0 | J23: 0 | K23: ='Fixas '!G14 -> 0 | L23: 0 | M23: ='Fixas '!H14 -> 0 | N23: 0 | O23: ='Fixas '!I14 -> 0 | P23: 0 | Q23: ='Fixas '!J14 -> 0 | R23: 0 | S23: ='Fixas '!K14 -> 0 | T23: 0 | U23: ='Fixas '!L14 -> 0 | V23: 0 | W23: 0 | X23: 0 | Y23: 0 | Z23: 0
A24: ='Fixas '!A15 -> Automação | D24: 0 | E24: ='Fixas '!D15 -> 0 | F24: 0 | G24: ='Fixas '!E15 -> 0 | H24: 0 | I24: ='Fixas '!F15 -> 0 | J24: 0 | K24: ='Fixas '!G15 -> 0 | L24: 0 | M24: ='Fixas '!H15 -> 0 | N24: 0 | O24: ='Fixas '!I15 -> 0 | P24: 0 | Q24: ='Fixas '!J15 -> 0 | R24: 0 | S24: ='Fixas '!K15 -> 0 | T24: 0 | U24: ='Fixas '!L15 -> 0 | V24: 0 | W24: 0 | X24: 0 | Y24: 0 | Z24: 0
A25: ='Fixas '!A16 -> Gerente de Projetos | D25: 0 | E25: ='Fixas '!D16 -> 0 | F25: 0 | G25: ='Fixas '!E16 -> 0 | H25: 0 | I25: ='Fixas '!F16 -> 0 | J25: 0 | K25: ='Fixas '!G16 -> 0 | L25: 0 | M25: ='Fixas '!H16 -> 0 | N25: 0 | O25: ='Fixas '!I16 -> 0 | P25: 0 | Q25: ='Fixas '!J16 -> 0 | R25: 0 | S25: ='Fixas '!K16 -> 0 | T25: 0 | U25: ='Fixas '!L16 -> 0 | V25: 0 | W25: 0 | X25: 0 | Y25: 0 | Z25: 0
A26: ='Fixas '!A17 -> Domínio | D26: 0 | E26: ='Fixas '!D17 -> 0 | F26: 0 | H26: 0 | J26: 0 | K26: ='Fixas '!G17 -> 0 | L26: 0 | M26: ='Fixas '!H17 -> 0 | N26: 0 | O26: ='Fixas '!I17 -> 0 | P26: 0 | Q26: ='Fixas '!J17 -> 0 | R26: 0 | S26: ='Fixas '!K17 -> 0 | T26: 0 | U26: ='Fixas '!L17 | V26: 0 | W26: 0 | X26: 0 | Y26: 0 | Z26: 0
A27: ='Fixas '!A18 -> Hospedagem | C27: ='Fixas '!C18 | D27: 0 | E27: ='Fixas '!D18 -> 0 | F27: 0 | G27: ='Fixas '!E18 -> 0 | H27: 0 | I27: ='Fixas '!F18 -> 0 | J27: 0 | K27: ='Fixas '!G18 -> 0 | L27: 0 | M27: ='Fixas '!H18 -> 0 | N27: 0 | O27: ='Fixas '!I18 -> 0 | P27: 0 | Q27: ='Fixas '!J18 -> 0 | R27: 0 | S27: ='Fixas '!K18 -> 0 | T27: 0 | U27: ='Fixas '!L18 | V27: 0 | W27: 0 | X27: 0 | Y27: 0 | Z27: 0
A28: ='Fixas '!A19 | C28: ='Fixas '!C19 | D28: 0 | E28: ='Fixas '!E19 | F28: ='Fixas '!F19 | G28: ='Fixas '!G19 | H28: ='Fixas '!H19 | I28: ='Fixas '!I19 | J28: ='Fixas '!J19 | K28: ='Fixas '!K19 | L28: ='Fixas '!L19 | ... Z28: ='Fixas '!Z19
A29: ='Fixas '!A20 | C29: ='Fixas '!C20 | D29: 0 | E29: ='Fixas '!E20 | F29: ='Fixas '!F20 | G29: ='Fixas '!G20 | H29: ='Fixas '!H20 | I29: ='Fixas '!I20 | J29: ='Fixas '!J20 | K29: ='Fixas '!K20 | L29: ='Fixas '!L20 | ... Z29: ='Fixas '!Z20
A30: Impostos | C30: ='Fixas '!C21 | D30: 0 | E30: ='Fixas '!E21 | F30: ='Fixas '!F21 | G30: ='Fixas '!G21 | H30: ='Fixas '!H21 | I30: ='Fixas '!I21 | J30: ='Fixas '!J21 | K30: ='Fixas '!K21 | L30: ='Fixas '!L21 | ... Z30: ='Fixas '!Z21
A31: Taxa hotmart | C31: ='Fixas '!C22 | D31: 0 | E31: ='Fixas '!E22 | F31: ='Fixas '!F22 | G31: ='Fixas '!G22 | H31: ='Fixas '!H22 | I31: ='Fixas '!I22 | J31: ='Fixas '!J22 | K31: ='Fixas '!K22 | L31: ='Fixas '!L22 | ... Z31: ='Fixas '!Z22
A32: Cursos e Treinamentos | C32: ='Fixas '!C23 | D32: 0 | E32: ='Fixas '!E23 | F32: ='Fixas '!F23 | G32: ='Fixas '!G23 | H32: ='Fixas '!H23 | I32: ='Fixas '!I23 | J32: ='Fixas '!J23 | K32: ='Fixas '!K23 | L32: ='Fixas '!L23 | ... Z32: ='Fixas '!Z23
C33: ='Fixas '!C24 | D33: 0 | E33: ='Fixas '!E24 | F33: ='Fixas '!F24 | G33: ='Fixas '!G24 | H33: ='Fixas '!H24 | I33: ='Fixas '!I24 | J33: ='Fixas '!J24 | K33: ='Fixas '!K24 | L33: ='Fixas '!L24 | ... Z33: ='Fixas '!Z24
C34: ='Fixas '!C19 | D34: 0 | E34: ='Fixas '!D19 -> #REF! | F34: 0 | G34: ='Fixas '!E19 | H34: 0 | I34: ='Fixas '!F19 | J34: 0 | K34: ='Fixas '!G19 | L34: 0 | M34: ='Fixas '!H19 | N34: 0 | O34: ='Fixas '!I19 | P34: 0 | Q34: ='Fixas '!J19 | R34: 0 | S34: ='Fixas '!K19 | T34: 0 | U34: ='Fixas '!L19 | V34: 0 | W34: 0 | X34: 0 | Y34: 0 | Z34: 0
A35: Total de Saídas | C35: =SUM(C15:C34) -> 0 | D35: =SUM(D15:D34) -> 0 | E35: =SUM(E15:E34) -> #REF! | F35: =SUM(F15:F34) -> 0 | G35: =SUM(G15:G34) -> 0 | H35: =SUM(H15:H34) -> 0 | I35: =SUM(I15:I34) -> 0 | J35: =SUM(J15:J34) -> 0 | ... Z35: =SUM(Z15:Z34) -> 0
A36: Entradas (menos) saídas | C36: =SUM(C11-C35) -> 0 | D36: =SUM(D11-D35) -> 0 | E36: =SUM(E11-E35) -> #REF! | F36: =SUM(F11-F35) -> 0 | G36: =SUM(G11-G35) -> 0 | H36: =SUM(H11-H35) -> 0 | I36: =SUM(I11-I35) -> 0 | J36: =SUM(J11-J35) -> 0 | ... Z36: =SUM(Z11-Z35) -> 0
A38: Total | C38: Saídas | D38: Entrada - Saída | E38: Saídas | F38: Entrada - Saída | G38: Saídas | H38: Entrada - Saída | I38: Saídas | J38: Entrada - Saída | K38: Saídas | L38: Entrada - Saída | M38: Saídas | N38: Entrada - Saída | O38: Saídas | P38: Entrada - Saída | Q38: Saídas | R38: Entrada - Saída | S38: Saídas | T38: Entrada - Saída | U38: Saídas | V38: Entrada - Saída | W38: Saídas | X38: Entrada - Saída | Y38: Saídas | Z38: Entrada - Saída | AA38: Saídas
A39: Porcentagem Expert | B39: 0.5 | C39: =SUM(C35*B39) -> 0 | D39: =SUM(D36*B39) -> 0 | E39: =SUM(E35*B39) -> #REF! | F39: =SUM(F36*B39) -> 0 | G39: =SUM(G35*B39) -> 0 | H39: =SUM(H36*B39) -> 0 | I39: =SUM(I35*B39) -> 0 | J39: =SUM(J36*B39) -> 0 | K39: =SUM(K35*B39) -> 0 | L39: =SUM(L36*B39) -> 0 | M39: =SUM(M35*B39) -> 0 | N39: =SUM(N36*B39) -> 0 | O39: =SUM(O35*B39) -> 0 | P39: =SUM(P36*B39) -> #REF! | Q39: =SUM(Q36*C39) -> 0 | R39: =SUM(R36*D39) -> 0 | S39: =SUM(S36*E39) -> #REF! | T39: =SUM(T36*F39) -> 0 | U39: =SUM(U36*G39) -> 0 | V39: =SUM(V36*B39) -> 0 | W39: =SUM(W35*B39) -> 0 | X39: =SUM(X35*B39) -> 0 | Y39: =SUM(Y35*B39) -> 0 | Z39: =SUM(Z36*B39) -> 0 | AA39: =SUM(Z35*B39) -> 0
A40: Porcentagem Co - Produtor | B40: 0.5 | C40: =SUM(C35*B40) -> 0 | D40: =SUM(D36*B40) -> 0 | E40: =SUM(E35*B40) -> #REF! | F40: =SUM(F36*B40) -> 0 | G40: =SUM(G36*B40) -> 0 | H40: =SUM(H36*B40) -> 0 | I40: =SUM(I36*B40) -> 0 | J40: =SUM(J36*B40) -> 0 | K40: =SUM(K35*B40) -> 0 | L40: =SUM(L36*B40) -> 0 | M40: =SUM(M35*B40) -> 0 | N40: =SUM(N36*B40) -> 0 | O40: =SUM(O35*B40) -> 0 | P40: =SUM(P36*B40) -> #REF! | Q40: =SUM(Q36*C40) -> 0 | R40: =SUM(R36*D40) -> 0 | S40: =SUM(S36*E40) -> #REF! | T40: =SUM(T36*F40) -> 0 | U40: =SUM(U36*G40) -> 0 | V40: =SUM(V36*B40) -> 0 | W40: =SUM(W35*B40) -> 0 | X40: =SUM(X36*B40) -> 0 | Y40: =SUM(Y35*B40) -> 0 | Z40: =SUM(Z36*B40) -> 0 | AA40: =SUM(Z36*B40) -> 0

Sheet Junho23
A4: Despesas de Serviços | G4: Taxas - Plataforma | L4: Total de Despesas
A6: Despesa | B6: Valor Mensal | C6: Dias Trabalhados | D6: Valor proporcional | E6: Tipo de Despesa | G6: Taxa - Green | I6: Total Fat | J6: Total lucro | L6: Categoria | M6: Valor | N6: Total | O6: Expert | P6: Co-produtor
A7: Infra + Suporte Operacional | C7: 30 | D7: =(B7/30)*C7 -> 0 | E7: Mensal | G7: =(J7/I7)-1 -> #DIV/0! | L7: Serviços | M7: =D24 -> 0 | N7: =M7+M8+M9+M10+M11 -> 0
A8: Social Media + Social Selling | C8: 30 | D8: =(B8/30)*C8 -> 0 | E8: Mensal | I8: Total Taxa | J8: =(I7-J7) -> 0 | L8: Impostos | M8: =I14 -> 0
A9: Editor de vídeo | C9: 30 | D9: =(B9/30)*C9 -> 0 | E9: Mensal | L9: Ferramentas | M9: =C46 -> 0
A10: Gestora de projetos | C10: 30 | D10: =(B10/30)*C10 -> 0 | E10: Mensal | L10: Tráfego + Extras | M10: =J40 -> 0
A11: copy | C11: 30 | D11: =(B11/30)*C11 -> 0 | E11: Mensal | G11: Impostos
A12: SDR | C12: 30 | D12: =(B12/30)*C12 -> 0 | E12: Mensal
A13: Gestor de trafego | C13: 30 | D13: =(B13/30)*C13 -> 0 | E13: Mensal | G13: % Imposto | H13: Valor Faturamento | I13: Total
A14: Contador | C14: 30 | D14: =(B14/30)*C14 -> 0 | E14: Mensal | G14: 0.06 | I14: =SUM(H14*G14) -> 0
A15: Closer JR | C15: 30 | D15: =(B15/30)*C15 -> 0 | E15: Mensal | L15: Total de Receitas
A16: Closer JR | C16: 30 | D16: =(B16/30)*C16 -> 0 | E16: Mensal
A17: CSCX | C17: 30 | D17: =(B17/30)*C17 -> 0 | E17: Mensal
A18: Estrategita | C18: 30 | D18: =(B18/30)*C18 -> 0 | E18: Mensal
A19: Designer | C19: 30 | D19: =(B19/30)*C19 -> 0 | E19: Mensal
A20: Webdesigner | C20: 30 | D20: =(B20/30)*C20 -> 0 | E20: Mensal
A21: Juridico | C21: 30 | D21: =(B21/30)*C21 -> 0 | E21: Mensal | L21: Vendas | M21: Quantidade | N21: Ticket | O21: Caixa Parcial | P21: Competencia
A22: Social seller | C22: 30 | D22: =(B22/30)*C22 -> 0 | E22: Mensal | L22: Green (novas vendas) | M22: 1
A23: Financeiro | C23: 30 | D23: =(B23/30)*C23 -> 0 | E23: Mensal | L23: Pix recorrencia | M23: 1
A24: Total: | B24: =SUM(B7:B23) -> 0 | D24: =SUM(D7:D23) -> 0 | L24: Pix novas vendas | M24: 1
M25: 1
G26: Custos Tráfego e Extras | M26: 1
G28: Despesa | H28: Obs | I28: Valor | J28: Tipo de Despesa | L28: Total: | O28: =SUM(O22:O27) -> 0 | P28: =SUM(P22:P27) -> 0
A29: Despesas de Ferramentas | G29: Tráfego | J29: Mensal
H30: 45203 | J30: Mensal
A31: Despesa | B31: Valor | C31: Tipo de Despesa | J31: Mensal | L31: Resultados - Liquido
A32: Active | C32: Mensal | J32: Esporádica
A33: Devzapp | C33: Mensal | J33: Esporádica | L33: Receita | M33: =O28 -> 0
A34: Panda | C34: Mensal | H34: 44959 | J34: Esporádica | L34: Despesas + taxa | M34: =N7 -> 0
A35: Typeform | C35: Mensal | H35: 44959 | J35: Esporádica | L35: Saldo | M35: =SUM(M33-M34) -> 0
A36: Loom | C36: Mensal | H36: 44927 | J36: Esporádica
A37: Cademi | C37: Mensal | H37: 44958 | J37: Esporádica
A38: Manychat | C38: Mensal | J38: Esporádica | L38: Divisão | M38: Descrição | N38: Porcentagem | O38: R - D | P38: Saldo
A39: Stape.io+geoloc | C39: Mensal | J39: Esporádica
A40: Zoom | C40: Mensal | G40: Total: | J40: =SUM(I29:I39) -> 0 | L40: Expert | M40: Receita | N40: 1 | O40: =O28 -> 0 | P40: =O40-O41 -> 0
A41: TurboCloud | C41: Mensal | M41: Despesa | O41: =M34 -> 0
A42: Enotas | C42: Esporádica | L42: Co-produtor | M42: Receita | N42: 1 | O42: =SUM(O22:O27) -> 0 | P42: =O42-O43 -> 0
A43: Conta azul | C43: Esporádica | M43: Despesa | O43: =O41 -> 0
A44: Calendly | C44: Esporádica
A45: Clicksign | C45: Esporádica
...

Sheet Anual
B3: Projeto | C3: Faturamento | D3: Despesas | E3: Saldo Final | G3: Custos - Divisão | K3: Lucros - Divisão
G5: Porcentagem Expert | H5: Porcentagem - Co Produtor | K5: Porcentagem Expert | L5: Porcentagem - Co Produtor
B6: Lançamento 01 | G6: 0.5 | H6: 0.5 | K6: 0.5 | L6: 0.5
G7: =SUM(D6*G6) -> 0 | H7: =SUM(D6*H6) -> 0 | K7: =SUM(E6*K6) -> 0 | L7: =SUM(E6*L6) -> 0
B8: Lançamento 2 | G8: =SUM(D8*G6) -> 0 | H8: =SUM(D8*H6) -> 0 | K8: =SUM(E8*K6) -> 0 | L8: =SUM(E8*L6) -> 0
B10: Lançamento 03 | C10: =#REF! -> #REF! | D10: =#REF! -> #REF! | G10: =SUM(D10*G6) -> #REF! | H10: =SUM(D10*H6) -> #REF! | K10: =SUM(E10*K6) -> 0 | L10: =SUM(E10*L6) -> 0
B12: Lançamento 04 | C12: =#REF! -> #REF! | D12: =#REF! -> #REF! | G12: =SUM(D12*G6) -> #REF! | H12: =SUM(D12*H6) -> #REF! | K12: =SUM(E12*K6) -> 0 | L12: =SUM(E12*L6) -> 0
B14: Lançamento 05 | C14: =#REF! -> #REF! | D14: =#REF! -> #REF! | G14: =SUM(D14*G6) -> #REF! | H14: =SUM(D14*H6) -> #REF! | K14: =SUM(D14*K6) -> #REF! | L14: =SUM(E14*L6) -> 0
B16: Lançamento 06 | C16: =#REF! -> #REF! | D16: =#REF! -> #REF! | G16: =SUM(D16*G6) -> #REF! | H16: =SUM(D16*H6) -> #REF! | K16: =SUM(E16*K6) -> 0 | L16: =SUM(E16*L7) -> 0
B20: Anual | G20: Custos - Anual | K20: Tráfego pago
L22: Faturamento | M22: Investimento | N22: ROI
B23: Faturamento | D23: =SUM(C6:C17) -> #REF! | G23: Ferramentas | I23: =SUM(#REF!) -> #REF! | K23: Lançamento 01 | M23: ='FRAN CALDAS'!H23 -> #REF! | N23: =SUM(L23-M23/M23) -> #REF!
G24: Serviços | K24: Lançamento 02 | M24: ='CATARINA LEAL '!H23 -> #REF! | N24: =SUM(L24-M24/M24) -> #REF!
B25: Despesas | D25: =SUM(D6:D17) -> #REF! | G25: Insumos e Extras | I25: =SUM('FRAN CALDAS:CATARINA LEAL '!I33) -> #REF! | K25: Lançamento 03 | L25: =C10 -> #REF! | M25: =#REF! -> #REF! | N25: =SUM(L25-M25/M25) -> #REF!
G26: Taxas | K26: Lançamento 04 | L26: =C12 -> #REF! | M26: =#REF! -> #REF! | N26: =SUM(L26-M26/M26) -> #REF!
B27: Saldo Final | D27: =SUM(D23-D25) -> #REF! | G27: Impostos | K27: Lançamento 05 | L27: =C14 -> #REF! | M27: =#REF! -> #REF! | N27: =SUM(L27-M27/M27) -> #REF!
G28: Outros | I28: 0 | K28: Lançamento 06 | L28: =C16 -> #REF! | M28: =#REF! -> #REF! | N28: =SUM(L28-M28/M28) -> #REF!
B31: Divisão
C33: Porcentagem | D33: Faturamento | E33: Despesas
B34: Expert | C34: 0.5 | D34: =SUM(D23*C34) -> #REF! | E34: =SUM(D25*C34) -> #REF!
B35: Coprodutor | C35: 0.5 | D35: =SUM(D23*C35) -> #REF! | E35: =SUM(D25*C35) -> #REF!
B37: Saldo Final
B39: Expert | D39: CO produtor
B40: =SUM(D34-E34) -> #REF! | D40: =SUM(D35-E35) -> #REF!
