Workbook

Sheet Instruções
C2: INSTRUÇÕES DE PREENCHIMENTO
C3: DA ANÁLISE DE MATURIDADE
C6: Uso pelo Planilhas Google
B8: 1° | C8: Clique em Arquivo na barra do menu inicial, selecionar Fazer uma cópia.
B10: 2° | C10: Na aba Análise de Maturidade, preencha apenas os quadrados com um "X"
C11: Selecione apenas uma opção em cada questão.
B13: 3° | C13: Ao final do preenchimento das 12 questões o resultado estará no gráfico ao final da página.
C16: Uso pela Planilha Excel
B18: 1° | C18: Faça o Download do arquivo em excel (.xlsx)
C19: Para fazer o download do arquivo, basta clicar em Arquivo na barra do menu inicial, selecionar Fazer o download e escolher o formato Microsoft Excel (.xlsx).
B21: 2° | C21: Na aba Análise de Maturidade, preencha apenas os quadrados com um "X"
C22: Selecione apenas uma opção em cada questão.
B24: 3° | C24: Ao final do preenchimento das 12 questões o resultado estará no gráfico ao final da página.

Sheet Análise de Maturidade
D3: ANÁLISE DO NÍVEL DE MATURIDADE
D4: DO(A) COLABORADOR(A)
B7: Para responder as próximas perguntas tenha em mente uma pessoa em expecífico, lembrando de como esse(a) colaborador(a) corresponde à cada questão colocada.
B8: Para cada questão abaixo, marque com X apenas uma opção.
B10: 1.Ao passar uma tarefa simples para um(a) colaborador(a):
B12: x | C12: A | D12: É necessário o acompanhamento de uma pessoa mais experiente e que conhece as melhores formas de executar a tarefa.
C15: B | D15: Esse(a) colaborador(a) desempenha a tarefa facilmente, sem necessidade de acompanhamento.
C18: C | D18: O(a) colaborador(a) em questão sabe desempenhar a tarefa, mas é necessário incentivá-lo(a) e conferir o resultado.
C21: D | D21: O(a) colaborador(a) apresenta muita vontade de realizar, mas ainda é pouco habilidoso(a) e tem muitas dúvidas.
B25: 2.Sobre o domínio das atividades e atribuições que o(a) colaborador(a) possui:
C27: A | D27: 90% das atribuições do(a) colaborador(a), são realizadas com qualidade e prazo esperados, sem necessidade de acompanhamento.
C30: B | D30: 70% das atribuições do(a) colaborador(a), são realizadas com qualidade e prazo esperados com algum acompanhamento.
C33: C | D33: Somente 20% ou menos das atividades realizadas pelo(a) colaborador(a), são entregues com qualidade e prazo esperados, sendo necessário acompanhamento constante.
C36: D | D36: O(a) colaborador(a) tem domínio sobre 50% das suas atribuições entregando com qualidade e prazo esperados, sendo necessária alguma orientação para sua conclusão.
B40: 3.Ao receber uma nova atribuição, o(a) colaborador(a):
C42: A | D42: Fica inseguro(a), necessita de muitas orientações, direcionamento e acompanhamento.
C45: B | D45: Recebe com grande energia e já quer iniciar imediatamente, mas precisa ser orientado(a) e direcionado(a).
C48: C | D48: Recebe de forma natural, mas precisa ser incentivado e apoiado em diversos momentos.
B51: x | C51: D | D51: Recebe de forma natural, entende o que é necessário para sua realização e entrega o que foi solicitado.
B55: 4.Para uma atividade em questão, o(a) colaborador(a):
B57: x | C57: A | D57: Necessita de treinamento iniciando pelo básico, e seu tempo para conclusão é mais longo que o desejado.
C60: B | D60: Tem os conhecimentos e habilidades e falta energia para realizar de forma autônoma.
C63: C | D63: Já tem alguma habilidade, mas ainda precisa de ajustes.
B66: x | C66: D | D66: É capaz de treinar outras pessoas pelo alto nível de experiência, conhecimento e comprometimento.
B70: 5.Na ausência de uma pessoa mais experiente que coordene e acompanhe o trabalho:
C72: A | D72: O(a) colaborador(a) fica perdido e deixa de fazer suas atividades ou deixa atrasá-las.
C75: B | D75: O(a) colaborador(a) toma a frente e assume as responsabilidades, gerindo as suas tarefas e de outros de forma mais natural, por uma liderança informal.
C78: C | D78: As tarefas são realizadas por esse(a) colaborador(a), no entanto não há sugestões de melhorias e acontecimentos atípicos ficam sem tratativa.
C81: D | D81: Metade das atribuições do(a) colaborador(a) são realizadas de forma habitual, mas pode perder em qualidade e prazo.
B85: 6.Relacionado à novas idéias e melhorias para a empresa:
C87: A | D87: É necessário incentivar constantemente, fornecendo feedbacks de forma contínua, sendo que a decisão sempre deve ser tomada pelo(a) líder.
C90: B | D90: O(a) colaborador(a) assume a responsabilidade na maior parte do que é feito, exigindo pouco ou nenhuma supervisão.
B93: x | C93: C | D93: Raramente consegue trazer uma nova idéia ou uma melhoria, entende pouco sobre os processos e caminhos para realizar as suas tarefas dentro da empresa.
C96: D | D96: É capaz de elaborar novas idéias e algumas melhorias, e expõe quando solicitado, com alguma insegurança.
B100: 7.Refletindo sobre o posicionamento do(a) colaborador(a):
B102: x | C102: A | D102: Tem uma boa noção das suas responsabilidades, se posiciona quando necessário, mas tem dificuldade em assumir novas ou maiores responsabilidades.
C105: B | D105: Conhece seus papéis na empresa com algumas incertezas, não mostra total comprometimento, e percebe as consequências de suas ações depois de tê-las realizado.
C108: C | D108: Ainda não conhece os seus papéis, se vê constantemente fazendo atividades que não são de sua alçada e busca constantemente orientação de alguém mais experiente.
C111: D | D111: Sabe seu papel na empresa, conhece e se comporta de acordo com suas responsabilidades mostrando-se um(a) profissional madura e as consequências de suas ações.
B115: 8.Acerca da complexidade e quantidade de tarefas diferentes desse(a) colaborador(a):
...

Sheet Gabarito
A1: Pergunta | B1: Resposta | C1: Resposta | D1: Peso | E1: Pontos | H1: Pontos | I1: Peso
A2: 1 | B2: A | C2: =IF('Análise de Maturidade'!B12="x","X","") -> X | D2: 1 | E2: 1 | G2: Fase 1 - Bebê | H2: =SUMIFS($E$2:$E$49,$C$2:$C$49,"X",$D$2:$D$49,I2) -> 2 | I2: 1
A3: 1 | B3: B | C3: =IF('Análise de Maturidade'!B15="x","X","") | D3: 4 | E3: 1 | G3: Fase 2 - Criança | H3: =SUMIFS($E$2:$E$49,$C$2:$C$49,"X",$D$2:$D$49,I3) -> 3 | I3: 2
A4: 1 | B4: C | C4: =IF('Análise de Maturidade'!B18="x","X","") | D4: 3 | E4: 1 | G4: Fase 3 - Adolescente | H4: =SUMIFS($E$2:$E$49,$C$2:$C$49,"X",$D$2:$D$49,I4) -> 1 | I4: 3
A5: 1 | B5: D | C5: =IF('Análise de Maturidade'!B21="x","X","") | D5: 2 | E5: 1 | G5: Fase 4 - Adulto | H5: =SUMIFS($E$2:$E$49,$C$2:$C$49,"X",$D$2:$D$49,I5) -> 1 | I5: 4
A6: 2 | B6: A | C6: =IF('Análise de Maturidade'!B27="x","X","") | D6: 4 | E6: 1
A7: 2 | B7: B | C7: =IF('Análise de Maturidade'!B30="x","X","") | D7: 3 | E7: 1
A8: 2 | B8: C | C8: =IF('Análise de Maturidade'!B33="x","X","") | D8: 1 | E8: 1
A9: 2 | B9: D | C9: =IF('Análise de Maturidade'!B36="x","X","") | D9: 2 | E9: 1
A10: 3 | B10: A | C10: =IF('Análise de Maturidade'!B42="x","X","") | D10: 1 | E10: 1
A11: 3 | B11: B | C11: =IF('Análise de Maturidade'!B45="x","X","") | D11: 2 | E11: 1
A12: 3 | B12: C | C12: =IF('Análise de Maturidade'!B48="x","X","") | D12: 3 | E12: 1
A13: 3 | B13: D | C13: =IF('Análise de Maturidade'!B51="x","X","") -> X | D13: 4 | E13: 1
A14: 4 | B14: A | C14: =IF('Análise de Maturidade'!B57="x","X","") -> X | D14: 1 | E14: 1
A15: 4 | B15: B | C15: =IF('Análise de Maturidade'!B60="x","X","") | D15: 3 | E15: 1
A16: 4 | B16: C | C16: =IF('Análise de Maturidade'!B63="x","X","") | D16: 2 | E16: 1
A17: 4 | B17: D | C17: =IF('Análise de Maturidade'!B67="x","X","") | D17: 4 | E17: 1
A18: 5 | B18: A | C18: =IF('Análise de Maturidade'!B72="x","X","") | D18: 1 | E18: 1
A19: 5 | B19: B | C19: =IF('Análise de Maturidade'!B75="x","X","") | D19: 4 | E19: 1
A20: 5 | B20: C | C20: =IF('Análise de Maturidade'!B78="x","X","") | D20: 3 | E20: 1
A21: 5 | B21: D | C21: =IF('Análise de Maturidade'!B81="x","X","") | D21: 2 | E21: 1
A22: 6 | B22: A | C22: =IF('Análise de Maturidade'!B87="x","X","") | D22: 1 | E22: 1
A23: 6 | B23: B | C23: =IF('Análise de Maturidade'!B90="x","X","") | D23: 4 | E23: 1
A24: 6 | B24: C | C24: =IF('Análise de Maturidade'!B93="x","X","") -> X | D24: 2 | E24: 1
A25: 6 | B25: D | C25: =IF('Análise de Maturidade'!B96="x","X","") | D25: 3 | E25: 1
A26: 7 | B26: A | C26: =IF('Análise de Maturidade'!B102="x","X","") -> X | D26: 3 | E26: 1
A27: 7 | B27: B | C27: =IF('Análise de Maturidade'!B105="x","X","") | D27: 2 | E27: 1
A28: 7 | B28: C | C28: =IF('Análise de Maturidade'!B108="x","X","") | D28: 1 | E28: 1
A29: 7 | B29: D | C29: =IF('Análise de Maturidade'!B111="x","X","") | D29: 4 | E29: 1
A30: 8 | B30: A | C30: =IF('Análise de Maturidade'!B117="x","X","") | D30: 4 | E30: 1
A31: 8 | B31: B | C31: =IF('Análise de Maturidade'!B120="x","X","") | D31: 3 | E31: 1
A32: 8 | B32: C | C32: =IF('Análise de Maturidade'!B123="x","X","") | D32: 1 | E32: 1
A33: 8 | B33: D | C33: =IF('Análise de Maturidade'!B127="x","X","") | D33: 2 | E33: 1
A34: 9 | B34: A | C34: =IF('Análise de Maturidade'!B132="x","X","") | D34: 3 | E34: 1
A35: 9 | B35: B | C35: =IF('Análise de Maturidade'!B135="x","X","") | D35: 1 | E35: 1
A36: 9 | B36: C | C36: =IF('Análise de Maturidade'!B138="x","X","") | D36: 4 | E36: 1
A37: 9 | B37: D | C37: =IF('Análise de Maturidade'!B141="x","X","") -> X | D37: 2 | E37: 1
A38: 10 | B38: A | C38: =IF('Análise de Maturidade'!B147="x","X","") | D38: 4 | E38: 1
A39: 10 | B39: B | C39: =IF('Análise de Maturidade'!B150="x","X","") | D39: 3 | E39: 1
A40: 10 | B40: C | C40: =IF('Análise de Maturidade'!B153="x","X","") | D40: 1 | E40: 1
...
