Workbook

Sheet GERALZÃO
A1: DISTRIBUIÇÃO DE CONTEÚDO NO YOUTUBE | J1: DISTRIBUIÇÃO DE CONTEÚDO NO YOUTUBE
A2: PLANILHAMENTO GERAL TODOS ADS POR SEMANA | J2: PLANILHAMENTO ADS GERAL
A3: INICIO | B3: FIM | C3: LIKES | D3: PLAYLIST | E3: INSCRITOS | F3: CUSTO INSC | G3: VIEWS REC | H3: GASTO | J3: ANÚNCIO | K3: LIKES | L3: PLAYLIST | M3: INSCRITOS | N3: CUSTO INSC | O3: VIEWS REC | P3: GASTO
A4: 44197 | B4: 44203 | C4: ='GERAL YOUTUBE'!C19 -> 0 | D4: ='GERAL YOUTUBE'!D19 -> 0 | E4: ='GERAL YOUTUBE'!E19 -> 0 | F4: =H4/E4 -> #DIV/0! | G4: ='GERAL YOUTUBE'!G19 -> 0 | H4: ='GERAL YOUTUBE'!H19 -> 0 | J4: AD 01 | K4: ='GERAL YOUTUBE'!C4+'GERAL YOUTUBE'!C23+'GERAL YOUTUBE'!C42+'GERAL YOUTUBE'!C61+'GERAL YOUTUBE'!C80+'GERAL YOUTUBE'!C99+'GERAL YOUTUBE'!C118+'GERAL YOUTUBE'!C137+'GERAL YOUTUBE'!C156+'GERAL YOUTUBE'!C175+'GERAL YOUTUBE'!C194+'GERAL YOUTUBE'!C213+'GERAL YOUTUBE'!C232+'GERAL YOUTUBE'!C251+'GERAL YOUTUBE'!C277 -> 0 | L4: ='GERAL YOUTUBE'!D4+'GERAL YOUTUBE'!D23+'GERAL YOUTUBE'!D42+'GERAL YOUTUBE'!D61+'GERAL YOUTUBE'!D80+'GERAL YOUTUBE'!D99+'GERAL YOUTUBE'!D118+'GERAL YOUTUBE'!D137+'GERAL YOUTUBE'!D156+'GERAL YOUTUBE'!D175+'GERAL YOUTUBE'!D194+'GERAL YOUTUBE'!D213+'GERAL YOUTUBE'!D232+'GERAL YOUTUBE'!D251+'GERAL YOUTUBE'!D277 -> 0 | M4: ='GERAL YOUTUBE'!E4+'GERAL YOUTUBE'!E23+'GERAL YOUTUBE'!E42+'GERAL YOUTUBE'!E61+'GERAL YOUTUBE'!E80+'GERAL YOUTUBE'!E99+'GERAL YOUTUBE'!E118+'GERAL YOUTUBE'!E137+'GERAL YOUTUBE'!E156+'GERAL YOUTUBE'!E175+'GERAL YOUTUBE'!E194+'GERAL YOUTUBE'!E213+'GERAL YOUTUBE'!E232+'GERAL YOUTUBE'!E251+'GERAL YOUTUBE'!E277 -> 0 | N4: =P4/M4 -> #DIV/0! | O4: ='GERAL YOUTUBE'!G4+'GERAL YOUTUBE'!G23+'GERAL YOUTUBE'!G42+'GERAL YOUTUBE'!G61+'GERAL YOUTUBE'!G80+'GERAL YOUTUBE'!G99+'GERAL YOUTUBE'!G118+'GERAL YOUTUBE'!G137+'GERAL YOUTUBE'!G156+'GERAL YOUTUBE'!G175+'GERAL YOUTUBE'!G194+'GERAL YOUTUBE'!G213+'GERAL YOUTUBE'!G232+'GERAL YOUTUBE'!G251+'GERAL YOUTUBE'!G277 -> 0 | P4: ='GERAL YOUTUBE'!H4+'GERAL YOUTUBE'!H23+'GERAL YOUTUBE'!H42+'GERAL YOUTUBE'!H61+'GERAL YOUTUBE'!H80+'GERAL YOUTUBE'!H99+'GERAL YOUTUBE'!H118+'GERAL YOUTUBE'!H137+'GERAL YOUTUBE'!H156+'GERAL YOUTUBE'!H175+'GERAL YOUTUBE'!H194+'GERAL YOUTUBE'!H213+'GERAL YOUTUBE'!H232+'GERAL YOUTUBE'!H251+'GERAL YOUTUBE'!H277 -> 0
A5: 44204 | B5: 44210 | C5: ='GERAL YOUTUBE'!C38 -> 0 | D5: ='GERAL YOUTUBE'!D38 -> 0 | E5: ='GERAL YOUTUBE'!E38 -> 0 | F5: =H5/E5 -> #DIV/0! | G5: ='GERAL YOUTUBE'!G38 -> 0 | H5: ='GERAL YOUTUBE'!H38 -> 0 | J5: AD 02 | K5: ='GERAL YOUTUBE'!C5+'GERAL YOUTUBE'!C24+'GERAL YOUTUBE'!C43+'GERAL YOUTUBE'!C62+'GERAL YOUTUBE'!C81+'GERAL YOUTUBE'!C100+'GERAL YOUTUBE'!C119+'GERAL YOUTUBE'!C138+'GERAL YOUTUBE'!C157+'GERAL YOUTUBE'!C176+'GERAL YOUTUBE'!C195+'GERAL YOUTUBE'!C214+'GERAL YOUTUBE'!C233+'GERAL YOUTUBE'!C252+'GERAL YOUTUBE'!C278 -> 0 | L5: ='GERAL YOUTUBE'!D5+'GERAL YOUTUBE'!D24+'GERAL YOUTUBE'!D43+'GERAL YOUTUBE'!D62+'GERAL YOUTUBE'!D81+'GERAL YOUTUBE'!D100+'GERAL YOUTUBE'!D119+'GERAL YOUTUBE'!D138+'GERAL YOUTUBE'!D157+'GERAL YOUTUBE'!D176+'GERAL YOUTUBE'!D195+'GERAL YOUTUBE'!D214+'GERAL YOUTUBE'!D233+'GERAL YOUTUBE'!D252+'GERAL YOUTUBE'!D278 -> 0 | M5: ='GERAL YOUTUBE'!E5+'GERAL YOUTUBE'!E24+'GERAL YOUTUBE'!E43+'GERAL YOUTUBE'!E62+'GERAL YOUTUBE'!E81+'GERAL YOUTUBE'!E100+'GERAL YOUTUBE'!E119+'GERAL YOUTUBE'!E138+'GERAL YOUTUBE'!E157+'GERAL YOUTUBE'!E176+'GERAL YOUTUBE'!E195+'GERAL YOUTUBE'!E214+'GERAL YOUTUBE'!E233+'GERAL YOUTUBE'!E252+'GERAL YOUTUBE'!E278 -> 0 | N5: =P5/M5 -> #DIV/0! | O5: ='GERAL YOUTUBE'!G5+'GERAL YOUTUBE'!G24+'GERAL YOUTUBE'!G43+'GERAL YOUTUBE'!G62+'GERAL YOUTUBE'!G81+'GERAL YOUTUBE'!G100+'GERAL YOUTUBE'!G119+'GERAL YOUTUBE'!G138+'GERAL YOUTUBE'!G157+'GERAL YOUTUBE'!G176+'GERAL YOUTUBE'!G195+'GERAL YOUTUBE'!G214+'GERAL YOUTUBE'!G233+'GERAL YOUTUBE'!G252+'GERAL YOUTUBE'!G278 -> 0 | P5: ='GERAL YOUTUBE'!H5+'GERAL YOUTUBE'!H24+'GERAL YOUTUBE'!H43+'GERAL YOUTUBE'!H62+'GERAL YOUTUBE'!H81+'GERAL YOUTUBE'!H100+'GERAL YOUTUBE'!H119+'GERAL YOUTUBE'!H138+'GERAL YOUTUBE'!H157+'GERAL YOUTUBE'!H176+'GERAL YOUTUBE'!H195+'GERAL YOUTUBE'!H214+'GERAL YOUTUBE'!H233+'GERAL YOUTUBE'!H252+'GERAL YOUTUBE'!H278 -> 0
A6: 44211 | B6: 44217 | C6: ='GERAL YOUTUBE'!C57 -> 0 | D6: ='GERAL YOUTUBE'!D57 -> 0 | E6: ='GERAL YOUTUBE'!E57 -> 0 | F6: =H6/E6 -> #DIV/0! | G6: ='GERAL YOUTUBE'!G57 -> 0 | H6: ='GERAL YOUTUBE'!H57 -> 0 | J6: AD 03 | K6: ='GERAL YOUTUBE'!C6+'GERAL YOUTUBE'!C25+'GERAL YOUTUBE'!C44+'GERAL YOUTUBE'!C63+'GERAL YOUTUBE'!C82+'GERAL YOUTUBE'!C101+'GERAL YOUTUBE'!C120+'GERAL YOUTUBE'!C139+'GERAL YOUTUBE'!C158+'GERAL YOUTUBE'!C177+'GERAL YOUTUBE'!C196+'GERAL YOUTUBE'!C215+'GERAL YOUTUBE'!C234+'GERAL YOUTUBE'!C253+'GERAL YOUTUBE'!C279 -> 0 | L6: ='GERAL YOUTUBE'!D6+'GERAL YOUTUBE'!D25+'GERAL YOUTUBE'!D44+'GERAL YOUTUBE'!D63+'GERAL YOUTUBE'!D82+'GERAL YOUTUBE'!D101+'GERAL YOUTUBE'!D120+'GERAL YOUTUBE'!D139+'GERAL YOUTUBE'!D158+'GERAL YOUTUBE'!D177+'GERAL YOUTUBE'!D196+'GERAL YOUTUBE'!D215+'GERAL YOUTUBE'!D234+'GERAL YOUTUBE'!D253+'GERAL YOUTUBE'!D279 -> 0 | M6: ='GERAL YOUTUBE'!E6+'GERAL YOUTUBE'!E25+'GERAL YOUTUBE'!E44+'GERAL YOUTUBE'!E63+'GERAL YOUTUBE'!E82+'GERAL YOUTUBE'!E101+'GERAL YOUTUBE'!E120+'GERAL YOUTUBE'!E139+'GERAL YOUTUBE'!E158+'GERAL YOUTUBE'!E177+'GERAL YOUTUBE'!E196+'GERAL YOUTUBE'!E215+'GERAL YOUTUBE'!E234+'GERAL YOUTUBE'!E253+'GERAL YOUTUBE'!E279 -> 0 | N6: =P6/M6 -> #DIV/0! | O6: ='GERAL YOUTUBE'!G6+'GERAL YOUTUBE'!G25+'GERAL YOUTUBE'!G44+'GERAL YOUTUBE'!G63+'GERAL YOUTUBE'!G82+'GERAL YOUTUBE'!G101+'GERAL YOUTUBE'!G120+'GERAL YOUTUBE'!G139+'GERAL YOUTUBE'!G158+'GERAL YOUTUBE'!G177+'GERAL YOUTUBE'!G196+'GERAL YOUTUBE'!G215+'GERAL YOUTUBE'!G234+'GERAL YOUTUBE'!G253+'GERAL YOUTUBE'!G279 -> 0 | P6: ='GERAL YOUTUBE'!H6+'GERAL YOUTUBE'!H25+'GERAL YOUTUBE'!H44+'GERAL YOUTUBE'!H63+'GERAL YOUTUBE'!H82+'GERAL YOUTUBE'!H101+'GERAL YOUTUBE'!H120+'GERAL YOUTUBE'!H139+'GERAL YOUTUBE'!H158+'GERAL YOUTUBE'!H177+'GERAL YOUTUBE'!H196+'GERAL YOUTUBE'!H215+'GERAL YOUTUBE'!H234+'GERAL YOUTUBE'!H253+'GERAL YOUTUBE'!H279 -> 0
A7: 44218 | B7: 44224 | C7: ='GERAL YOUTUBE'!C76 -> 0 | D7: ='GERAL YOUTUBE'!D76 -> 0 | E7: ='GERAL YOUTUBE'!E76 -> 0 | F7: =H7/E7 -> #DIV/0! | G7: ='GERAL YOUTUBE'!G76 -> 0 | H7: ='GERAL YOUTUBE'!H76 -> 0 | J7: AD 04 | K7: ='GERAL YOUTUBE'!C7+'GERAL YOUTUBE'!C26+'GERAL YOUTUBE'!C45+'GERAL YOUTUBE'!C64+'GERAL YOUTUBE'!C83+'GERAL YOUTUBE'!C102+'GERAL YOUTUBE'!C121+'GERAL YOUTUBE'!C140+'GERAL YOUTUBE'!C159+'GERAL YOUTUBE'!C178+'GERAL YOUTUBE'!C197+'GERAL YOUTUBE'!C216+'GERAL YOUTUBE'!C235+'GERAL YOUTUBE'!C254+'GERAL YOUTUBE'!C280 -> 0 | L7: ='GERAL YOUTUBE'!D7+'GERAL YOUTUBE'!D26+'GERAL YOUTUBE'!D45+'GERAL YOUTUBE'!D64+'GERAL YOUTUBE'!D83+'GERAL YOUTUBE'!D102+'GERAL YOUTUBE'!D121+'GERAL YOUTUBE'!D140+'GERAL YOUTUBE'!D159+'GERAL YOUTUBE'!D178+'GERAL YOUTUBE'!D197+'GERAL YOUTUBE'!D216+'GERAL YOUTUBE'!D235+'GERAL YOUTUBE'!D254+'GERAL YOUTUBE'!D280 -> 0 | M7: ='GERAL YOUTUBE'!E7+'GERAL YOUTUBE'!E26+'GERAL YOUTUBE'!E45+'GERAL YOUTUBE'!E64+'GERAL YOUTUBE'!E83+'GERAL YOUTUBE'!E102+'GERAL YOUTUBE'!E121+'GERAL YOUTUBE'!E140+'GERAL YOUTUBE'!E159+'GERAL YOUTUBE'!E178+'GERAL YOUTUBE'!E197+'GERAL YOUTUBE'!E216+'GERAL YOUTUBE'!E235+'GERAL YOUTUBE'!E254+'GERAL YOUTUBE'!E280 -> 0 | N7: =P7/M7 -> #DIV/0! | O7: ='GERAL YOUTUBE'!G7+'GERAL YOUTUBE'!G26+'GERAL YOUTUBE'!G45+'GERAL YOUTUBE'!G64+'GERAL YOUTUBE'!G83+'GERAL YOUTUBE'!G102+'GERAL YOUTUBE'!G121+'GERAL YOUTUBE'!G140+'GERAL YOUTUBE'!G159+'GERAL YOUTUBE'!G178+'GERAL YOUTUBE'!G197+'GERAL YOUTUBE'!G216+'GERAL YOUTUBE'!G235+'GERAL YOUTUBE'!G254+'GERAL YOUTUBE'!G280 -> 0 | P7: ='GERAL YOUTUBE'!H7+'GERAL YOUTUBE'!H26+'GERAL YOUTUBE'!H45+'GERAL YOUTUBE'!H64+'GERAL YOUTUBE'!H83+'GERAL YOUTUBE'!H102+'GERAL YOUTUBE'!H121+'GERAL YOUTUBE'!H140+'GERAL YOUTUBE'!H159+'GERAL YOUTUBE'!H178+'GERAL YOUTUBE'!H197+'GERAL YOUTUBE'!H216+'GERAL YOUTUBE'!H235+'GERAL YOUTUBE'!H254+'GERAL YOUTUBE'!H280 -> 0
A8: 44225 | B8: 44231 | C8: ='GERAL YOUTUBE'!C95 | D8: ='GERAL YOUTUBE'!D95 | E8: ='GERAL YOUTUBE'!E95 | F8: =H8/E8 -> #DIV/0! | G8: ='GERAL YOUTUBE'!G95 | H8: ='GERAL YOUTUBE'!H95 | J8: AD 05 | K8: ='GERAL YOUTUBE'!C8+'GERAL YOUTUBE'!C27+'GERAL YOUTUBE'!C46+'GERAL YOUTUBE'!C65+'GERAL YOUTUBE'!C84+'GERAL YOUTUBE'!C103+'GERAL YOUTUBE'!C122+'GERAL YOUTUBE'!C141+'GERAL YOUTUBE'!C160+'GERAL YOUTUBE'!C179+'GERAL YOUTUBE'!C198+'GERAL YOUTUBE'!C217+'GERAL YOUTUBE'!C236+'GERAL YOUTUBE'!C255+'GERAL YOUTUBE'!C281 -> 0 | L8: ='GERAL YOUTUBE'!D8+'GERAL YOUTUBE'!D27+'GERAL YOUTUBE'!D46+'GERAL YOUTUBE'!D65+'GERAL YOUTUBE'!D84+'GERAL YOUTUBE'!D103+'GERAL YOUTUBE'!D122+'GERAL YOUTUBE'!D141+'GERAL YOUTUBE'!D160+'GERAL YOUTUBE'!D179+'GERAL YOUTUBE'!D198+'GERAL YOUTUBE'!D217+'GERAL YOUTUBE'!D236+'GERAL YOUTUBE'!D255+'GERAL YOUTUBE'!D281 -> 0 | M8: ='GERAL YOUTUBE'!E8+'GERAL YOUTUBE'!E27+'GERAL YOUTUBE'!E46+'GERAL YOUTUBE'!E65+'GERAL YOUTUBE'!E84+'GERAL YOUTUBE'!E103+'GERAL YOUTUBE'!E122+'GERAL YOUTUBE'!E141+'GERAL YOUTUBE'!E160+'GERAL YOUTUBE'!E179+'GERAL YOUTUBE'!E198+'GERAL YOUTUBE'!E217+'GERAL YOUTUBE'!E236+'GERAL YOUTUBE'!E255+'GERAL YOUTUBE'!E281 -> 0 | N8: =P8/M8 -> #DIV/0! | O8: ='GERAL YOUTUBE'!G8+'GERAL YOUTUBE'!G27+'GERAL YOUTUBE'!G46+'GERAL YOUTUBE'!G65+'GERAL YOUTUBE'!G84+'GERAL YOUTUBE'!G103+'GERAL YOUTUBE'!G122+'GERAL YOUTUBE'!G141+'GERAL YOUTUBE'!G160+'GERAL YOUTUBE'!G179+'GERAL YOUTUBE'!G198+'GERAL YOUTUBE'!G217+'GERAL YOUTUBE'!G236+'GERAL YOUTUBE'!G255+'GERAL YOUTUBE'!G281 -> 0 | P8: ='GERAL YOUTUBE'!H8+'GERAL YOUTUBE'!H27+'GERAL YOUTUBE'!H46+'GERAL YOUTUBE'!H65+'GERAL YOUTUBE'!H84+'GERAL YOUTUBE'!H103+'GERAL YOUTUBE'!H122+'GERAL YOUTUBE'!H141+'GERAL YOUTUBE'!H160+'GERAL YOUTUBE'!H179+'GERAL YOUTUBE'!H198+'GERAL YOUTUBE'!H217+'GERAL YOUTUBE'!H236+'GERAL YOUTUBE'!H255+'GERAL YOUTUBE'!H281 -> 0
A9: 44232 | B9: 44238 | C9: ='GERAL YOUTUBE'!C114 | D9: ='GERAL YOUTUBE'!D114 | E9: ='GERAL YOUTUBE'!E114 | F9: =H9/E9 -> #DIV/0! | G9: ='GERAL YOUTUBE'!G114 | H9: ='GERAL YOUTUBE'!H114 | J9: AD 06 | K9: ='GERAL YOUTUBE'!C9+'GERAL YOUTUBE'!C28+'GERAL YOUTUBE'!C47+'GERAL YOUTUBE'!C66+'GERAL YOUTUBE'!C85+'GERAL YOUTUBE'!C104+'GERAL YOUTUBE'!C123+'GERAL YOUTUBE'!C142+'GERAL YOUTUBE'!C161+'GERAL YOUTUBE'!C180+'GERAL YOUTUBE'!C199+'GERAL YOUTUBE'!C218+'GERAL YOUTUBE'!C237+'GERAL YOUTUBE'!C256+'GERAL YOUTUBE'!C282 -> 0 | L9: ='GERAL YOUTUBE'!D9+'GERAL YOUTUBE'!D28+'GERAL YOUTUBE'!D47+'GERAL YOUTUBE'!D66+'GERAL YOUTUBE'!D85+'GERAL YOUTUBE'!D104+'GERAL YOUTUBE'!D123+'GERAL YOUTUBE'!D142+'GERAL YOUTUBE'!D161+'GERAL YOUTUBE'!D180+'GERAL YOUTUBE'!D199+'GERAL YOUTUBE'!D218+'GERAL YOUTUBE'!D237+'GERAL YOUTUBE'!D256+'GERAL YOUTUBE'!D282 -> 0 | M9: ='GERAL YOUTUBE'!E9+'GERAL YOUTUBE'!E28+'GERAL YOUTUBE'!E47+'GERAL YOUTUBE'!E66+'GERAL YOUTUBE'!E85+'GERAL YOUTUBE'!E104+'GERAL YOUTUBE'!E123+'GERAL YOUTUBE'!E142+'GERAL YOUTUBE'!E161+'GERAL YOUTUBE'!E180+'GERAL YOUTUBE'!E199+'GERAL YOUTUBE'!E218+'GERAL YOUTUBE'!E237+'GERAL YOUTUBE'!E256+'GERAL YOUTUBE'!E282 -> 0 | N9: =P9/M9 -> #DIV/0! | O9: ='GERAL YOUTUBE'!G9+'GERAL YOUTUBE'!G28+'GERAL YOUTUBE'!G47+'GERAL YOUTUBE'!G66+'GERAL YOUTUBE'!G85+'GERAL YOUTUBE'!G104+'GERAL YOUTUBE'!G123+'GERAL YOUTUBE'!G142+'GERAL YOUTUBE'!G161+'GERAL YOUTUBE'!G180+'GERAL YOUTUBE'!G199+'GERAL YOUTUBE'!G218+'GERAL YOUTUBE'!G237+'GERAL YOUTUBE'!G256+'GERAL YOUTUBE'!G282 -> 0 | P9: ='GERAL YOUTUBE'!H9+'GERAL YOUTUBE'!H28+'GERAL YOUTUBE'!H47+'GERAL YOUTUBE'!H66+'GERAL YOUTUBE'!H85+'GERAL YOUTUBE'!H104+'GERAL YOUTUBE'!H123+'GERAL YOUTUBE'!H142+'GERAL YOUTUBE'!H161+'GERAL YOUTUBE'!H180+'GERAL YOUTUBE'!H199+'GERAL YOUTUBE'!H218+'GERAL YOUTUBE'!H237+'GERAL YOUTUBE'!H256+'GERAL YOUTUBE'!H282 -> 0
A10: 44239 | B10: 44245 | C10: ='GERAL YOUTUBE'!C133 | D10: ='GERAL YOUTUBE'!D133 | E10: ='GERAL YOUTUBE'!E133 | F10: =H10/E10 -> #DIV/0! | G10: ='GERAL YOUTUBE'!G133 | H10: ='GERAL YOUTUBE'!H133 | J10: AD 07 | K10: ='GERAL YOUTUBE'!C10+'GERAL YOUTUBE'!C29+'GERAL YOUTUBE'!C48+'GERAL YOUTUBE'!C67+'GERAL YOUTUBE'!C86+'GERAL YOUTUBE'!C105+'GERAL YOUTUBE'!C124+'GERAL YOUTUBE'!C143+'GERAL YOUTUBE'!C162+'GERAL YOUTUBE'!C181+'GERAL YOUTUBE'!C200+'GERAL YOUTUBE'!C219+'GERAL YOUTUBE'!C238+'GERAL YOUTUBE'!C257+'GERAL YOUTUBE'!C283 -> 0 | L10: ='GERAL YOUTUBE'!D10+'GERAL YOUTUBE'!D29+'GERAL YOUTUBE'!D48+'GERAL YOUTUBE'!D67+'GERAL YOUTUBE'!D86+'GERAL YOUTUBE'!D105+'GERAL YOUTUBE'!D124+'GERAL YOUTUBE'!D143+'GERAL YOUTUBE'!D162+'GERAL YOUTUBE'!D181+'GERAL YOUTUBE'!D200+'GERAL YOUTUBE'!D219+'GERAL YOUTUBE'!D238+'GERAL YOUTUBE'!D257+'GERAL YOUTUBE'!D283 -> 0 | M10: ='GERAL YOUTUBE'!E10+'GERAL YOUTUBE'!E29+'GERAL YOUTUBE'!E48+'GERAL YOUTUBE'!E67+'GERAL YOUTUBE'!E86+'GERAL YOUTUBE'!E105+'GERAL YOUTUBE'!E124+'GERAL YOUTUBE'!E143+'GERAL YOUTUBE'!E162+'GERAL YOUTUBE'!E181+'GERAL YOUTUBE'!E200+'GERAL YOUTUBE'!E219+'GERAL YOUTUBE'!E238+'GERAL YOUTUBE'!E257+'GERAL YOUTUBE'!E283 -> 0 | N10: =P10/M10 -> #DIV/0! | O10: ='GERAL YOUTUBE'!G10+'GERAL YOUTUBE'!G29+'GERAL YOUTUBE'!G48+'GERAL YOUTUBE'!G67+'GERAL YOUTUBE'!G86+'GERAL YOUTUBE'!G105+'GERAL YOUTUBE'!G124+'GERAL YOUTUBE'!G143+'GERAL YOUTUBE'!G162+'GERAL YOUTUBE'!G181+'GERAL YOUTUBE'!G200+'GERAL YOUTUBE'!G219+'GERAL YOUTUBE'!G238+'GERAL YOUTUBE'!G257+'GERAL YOUTUBE'!G283 -> 0 | P10: ='GERAL YOUTUBE'!H10+'GERAL YOUTUBE'!H29+'GERAL YOUTUBE'!H48+'GERAL YOUTUBE'!H67+'GERAL YOUTUBE'!H86+'GERAL YOUTUBE'!H105+'GERAL YOUTUBE'!H124+'GERAL YOUTUBE'!H143+'GERAL YOUTUBE'!H162+'GERAL YOUTUBE'!H181+'GERAL YOUTUBE'!H200+'GERAL YOUTUBE'!H219+'GERAL YOUTUBE'!H238+'GERAL YOUTUBE'!H257+'GERAL YOUTUBE'!H283 -> 0
A11: 44246 | B11: 44252 | C11: ='GERAL YOUTUBE'!C152 -> 0 | D11: ='GERAL YOUTUBE'!D152 -> 0 | E11: ='GERAL YOUTUBE'!E152 -> 0 | F11: =H11/E11 -> #DIV/0! | G11: ='GERAL YOUTUBE'!G152 -> 0 | H11: ='GERAL YOUTUBE'!H152 -> 0 | J11: AD 08 | K11: ='GERAL YOUTUBE'!C11+'GERAL YOUTUBE'!C30+'GERAL YOUTUBE'!C49+'GERAL YOUTUBE'!C68+'GERAL YOUTUBE'!C87+'GERAL YOUTUBE'!C106+'GERAL YOUTUBE'!C125+'GERAL YOUTUBE'!C144+'GERAL YOUTUBE'!C163+'GERAL YOUTUBE'!C182+'GERAL YOUTUBE'!C201+'GERAL YOUTUBE'!C220+'GERAL YOUTUBE'!C239+'GERAL YOUTUBE'!C258+'GERAL YOUTUBE'!C284 -> 0 | L11: ='GERAL YOUTUBE'!D11+'GERAL YOUTUBE'!D30+'GERAL YOUTUBE'!D49+'GERAL YOUTUBE'!D68+'GERAL YOUTUBE'!D87+'GERAL YOUTUBE'!D106+'GERAL YOUTUBE'!D125+'GERAL YOUTUBE'!D144+'GERAL YOUTUBE'!D163+'GERAL YOUTUBE'!D182+'GERAL YOUTUBE'!D201+'GERAL YOUTUBE'!D220+'GERAL YOUTUBE'!D239+'GERAL YOUTUBE'!D258+'GERAL YOUTUBE'!D284 -> 0 | M11: ='GERAL YOUTUBE'!E11+'GERAL YOUTUBE'!E30+'GERAL YOUTUBE'!E49+'GERAL YOUTUBE'!E68+'GERAL YOUTUBE'!E87+'GERAL YOUTUBE'!E106+'GERAL YOUTUBE'!E125+'GERAL YOUTUBE'!E144+'GERAL YOUTUBE'!E163+'GERAL YOUTUBE'!E182+'GERAL YOUTUBE'!E201+'GERAL YOUTUBE'!E220+'GERAL YOUTUBE'!E239+'GERAL YOUTUBE'!E258+'GERAL YOUTUBE'!E284 -> 0 | N11: =P11/M11 -> #DIV/0! | O11: ='GERAL YOUTUBE'!G11+'GERAL YOUTUBE'!G30+'GERAL YOUTUBE'!G49+'GERAL YOUTUBE'!G68+'GERAL YOUTUBE'!G87+'GERAL YOUTUBE'!G106+'GERAL YOUTUBE'!G125+'GERAL YOUTUBE'!G144+'GERAL YOUTUBE'!G163+'GERAL YOUTUBE'!G182+'GERAL YOUTUBE'!G201+'GERAL YOUTUBE'!G220+'GERAL YOUTUBE'!G239+'GERAL YOUTUBE'!G258+'GERAL YOUTUBE'!G284 -> 0 | P11: ='GERAL YOUTUBE'!H11+'GERAL YOUTUBE'!H30+'GERAL YOUTUBE'!H49+'GERAL YOUTUBE'!H68+'GERAL YOUTUBE'!H87+'GERAL YOUTUBE'!H106+'GERAL YOUTUBE'!H125+'GERAL YOUTUBE'!H144+'GERAL YOUTUBE'!H163+'GERAL YOUTUBE'!H182+'GERAL YOUTUBE'!H201+'GERAL YOUTUBE'!H220+'GERAL YOUTUBE'!H239+'GERAL YOUTUBE'!H258+'GERAL YOUTUBE'!H284 -> 0
A12: 44253 | B12: 44259 | C12: ='GERAL YOUTUBE'!C171 -> 0 | D12: ='GERAL YOUTUBE'!D171 -> 0 | E12: ='GERAL YOUTUBE'!E171 -> 0 | F12: =H12/E12 -> #DIV/0! | G12: ='GERAL YOUTUBE'!G171 -> 0 | H12: ='GERAL YOUTUBE'!H171 -> 0 | J12: AD 09 | K12: ='GERAL YOUTUBE'!C12+'GERAL YOUTUBE'!C31+'GERAL YOUTUBE'!C50+'GERAL YOUTUBE'!C69+'GERAL YOUTUBE'!C88+'GERAL YOUTUBE'!C107+'GERAL YOUTUBE'!C126+'GERAL YOUTUBE'!C145+'GERAL YOUTUBE'!C164+'GERAL YOUTUBE'!C183+'GERAL YOUTUBE'!C202+'GERAL YOUTUBE'!C221+'GERAL YOUTUBE'!C240+'GERAL YOUTUBE'!C259+'GERAL YOUTUBE'!C285 -> 0 | L12: ='GERAL YOUTUBE'!D12+'GERAL YOUTUBE'!D31+'GERAL YOUTUBE'!D50+'GERAL YOUTUBE'!D69+'GERAL YOUTUBE'!D88+'GERAL YOUTUBE'!D107+'GERAL YOUTUBE'!D126+'GERAL YOUTUBE'!D145+'GERAL YOUTUBE'!D164+'GERAL YOUTUBE'!D183+'GERAL YOUTUBE'!D202+'GERAL YOUTUBE'!D221+'GERAL YOUTUBE'!D240+'GERAL YOUTUBE'!D259+'GERAL YOUTUBE'!D285 -> 0 | M12: ='GERAL YOUTUBE'!E12+'GERAL YOUTUBE'!E31+'GERAL YOUTUBE'!E50+'GERAL YOUTUBE'!E69+'GERAL YOUTUBE'!E88+'GERAL YOUTUBE'!E107+'GERAL YOUTUBE'!E126+'GERAL YOUTUBE'!E145+'GERAL YOUTUBE'!E164+'GERAL YOUTUBE'!E183+'GERAL YOUTUBE'!E202+'GERAL YOUTUBE'!E221+'GERAL YOUTUBE'!E240+'GERAL YOUTUBE'!E259+'GERAL YOUTUBE'!E285 -> 0 | N12: =P12/M12 -> #DIV/0! | O12: ='GERAL YOUTUBE'!G12+'GERAL YOUTUBE'!G31+'GERAL YOUTUBE'!G50+'GERAL YOUTUBE'!G69+'GERAL YOUTUBE'!G88+'GERAL YOUTUBE'!G107+'GERAL YOUTUBE'!G126+'GERAL YOUTUBE'!G145+'GERAL YOUTUBE'!G164+'GERAL YOUTUBE'!G183+'GERAL YOUTUBE'!G202+'GERAL YOUTUBE'!G221+'GERAL YOUTUBE'!G240+'GERAL YOUTUBE'!G259+'GERAL YOUTUBE'!G285 -> 0 | P12: ='GERAL YOUTUBE'!H12+'GERAL YOUTUBE'!H31+'GERAL YOUTUBE'!H50+'GERAL YOUTUBE'!H69+'GERAL YOUTUBE'!H88+'GERAL YOUTUBE'!H107+'GERAL YOUTUBE'!H126+'GERAL YOUTUBE'!H145+'GERAL YOUTUBE'!H164+'GERAL YOUTUBE'!H183+'GERAL YOUTUBE'!H202+'GERAL YOUTUBE'!H221+'GERAL YOUTUBE'!H240+'GERAL YOUTUBE'!H259+'GERAL YOUTUBE'!H285 -> 0
A13: 44260 | B13: 44266 | C13: ='GERAL YOUTUBE'!C190 -> 0 | D13: ='GERAL YOUTUBE'!D190 -> 0 | E13: ='GERAL YOUTUBE'!E190 -> 0 | F13: =H13/E13 -> #DIV/0! | G13: ='GERAL YOUTUBE'!G190 -> 0 | H13: ='GERAL YOUTUBE'!H190 -> 0 | J13: AD 10 | K13: ='GERAL YOUTUBE'!C13+'GERAL YOUTUBE'!C32+'GERAL YOUTUBE'!C51+'GERAL YOUTUBE'!C70+'GERAL YOUTUBE'!C89+'GERAL YOUTUBE'!C108+'GERAL YOUTUBE'!C127+'GERAL YOUTUBE'!C146+'GERAL YOUTUBE'!C165+'GERAL YOUTUBE'!C184+'GERAL YOUTUBE'!C203+'GERAL YOUTUBE'!C222+'GERAL YOUTUBE'!C241+'GERAL YOUTUBE'!C260+'GERAL YOUTUBE'!C286 -> 0 | L13: ='GERAL YOUTUBE'!D13+'GERAL YOUTUBE'!D32+'GERAL YOUTUBE'!D51+'GERAL YOUTUBE'!D70+'GERAL YOUTUBE'!D89+'GERAL YOUTUBE'!D108+'GERAL YOUTUBE'!D127+'GERAL YOUTUBE'!D146+'GERAL YOUTUBE'!D165+'GERAL YOUTUBE'!D184+'GERAL YOUTUBE'!D203+'GERAL YOUTUBE'!D222+'GERAL YOUTUBE'!D241+'GERAL YOUTUBE'!D260+'GERAL YOUTUBE'!D286 -> 0 | M13: ='GERAL YOUTUBE'!E13+'GERAL YOUTUBE'!E32+'GERAL YOUTUBE'!E51+'GERAL YOUTUBE'!E70+'GERAL YOUTUBE'!E89+'GERAL YOUTUBE'!E108+'GERAL YOUTUBE'!E127+'GERAL YOUTUBE'!E146+'GERAL YOUTUBE'!E165+'GERAL YOUTUBE'!E184+'GERAL YOUTUBE'!E203+'GERAL YOUTUBE'!E222+'GERAL YOUTUBE'!E241+'GERAL YOUTUBE'!E260+'GERAL YOUTUBE'!E286 -> 0 | N13: =P13/M13 -> #DIV/0! | O13: ='GERAL YOUTUBE'!G13+'GERAL YOUTUBE'!G32+'GERAL YOUTUBE'!G51+'GERAL YOUTUBE'!G70+'GERAL YOUTUBE'!G89+'GERAL YOUTUBE'!G108+'GERAL YOUTUBE'!G127+'GERAL YOUTUBE'!G146+'GERAL YOUTUBE'!G165+'GERAL YOUTUBE'!G184+'GERAL YOUTUBE'!G203+'GERAL YOUTUBE'!G222+'GERAL YOUTUBE'!G241+'GERAL YOUTUBE'!G260+'GERAL YOUTUBE'!G286 -> 0 | P13: ='GERAL YOUTUBE'!H13+'GERAL YOUTUBE'!H32+'GERAL YOUTUBE'!H51+'GERAL YOUTUBE'!H70+'GERAL YOUTUBE'!H89+'GERAL YOUTUBE'!H108+'GERAL YOUTUBE'!H127+'GERAL YOUTUBE'!H146+'GERAL YOUTUBE'!H165+'GERAL YOUTUBE'!H184+'GERAL YOUTUBE'!H203+'GERAL YOUTUBE'!H222+'GERAL YOUTUBE'!H241+'GERAL YOUTUBE'!H260+'GERAL YOUTUBE'!H286 -> 0
A14: 44267 | B14: 44273 | C14: ='GERAL YOUTUBE'!C209 -> 0 | D14: ='GERAL YOUTUBE'!D209 -> 0 | E14: ='GERAL YOUTUBE'!E209 -> 0 | F14: =H14/E14 -> #DIV/0! | G14: ='GERAL YOUTUBE'!G209 -> 0 | H14: ='GERAL YOUTUBE'!H209 -> 0 | J14: AD 11 | K14: ='GERAL YOUTUBE'!C14+'GERAL YOUTUBE'!C33+'GERAL YOUTUBE'!C52+'GERAL YOUTUBE'!C71+'GERAL YOUTUBE'!C90+'GERAL YOUTUBE'!C109+'GERAL YOUTUBE'!C128+'GERAL YOUTUBE'!C147+'GERAL YOUTUBE'!C166+'GERAL YOUTUBE'!C185+'GERAL YOUTUBE'!C204+'GERAL YOUTUBE'!C223+'GERAL YOUTUBE'!C242+'GERAL YOUTUBE'!C261+'GERAL YOUTUBE'!C287 -> 0 | L14: ='GERAL YOUTUBE'!D14+'GERAL YOUTUBE'!D33+'GERAL YOUTUBE'!D52+'GERAL YOUTUBE'!D71+'GERAL YOUTUBE'!D90+'GERAL YOUTUBE'!D109+'GERAL YOUTUBE'!D128+'GERAL YOUTUBE'!D147+'GERAL YOUTUBE'!D166+'GERAL YOUTUBE'!D185+'GERAL YOUTUBE'!D204+'GERAL YOUTUBE'!D223+'GERAL YOUTUBE'!D242+'GERAL YOUTUBE'!D261+'GERAL YOUTUBE'!D287 -> 0 | M14: ='GERAL YOUTUBE'!E14+'GERAL YOUTUBE'!E33+'GERAL YOUTUBE'!E52+'GERAL YOUTUBE'!E71+'GERAL YOUTUBE'!E90+'GERAL YOUTUBE'!E109+'GERAL YOUTUBE'!E128+'GERAL YOUTUBE'!E147+'GERAL YOUTUBE'!E166+'GERAL YOUTUBE'!E185+'GERAL YOUTUBE'!E204+'GERAL YOUTUBE'!E223+'GERAL YOUTUBE'!E242+'GERAL YOUTUBE'!E261+'GERAL YOUTUBE'!E287 -> 0 | N14: =P14/M14 -> #DIV/0! | O14: ='GERAL YOUTUBE'!G14+'GERAL YOUTUBE'!G33+'GERAL YOUTUBE'!G52+'GERAL YOUTUBE'!G71+'GERAL YOUTUBE'!G90+'GERAL YOUTUBE'!G109+'GERAL YOUTUBE'!G128+'GERAL YOUTUBE'!G147+'GERAL YOUTUBE'!G166+'GERAL YOUTUBE'!G185+'GERAL YOUTUBE'!G204+'GERAL YOUTUBE'!G223+'GERAL YOUTUBE'!G242+'GERAL YOUTUBE'!G261+'GERAL YOUTUBE'!G287 -> 0 | P14: ='GERAL YOUTUBE'!H14+'GERAL YOUTUBE'!H33+'GERAL YOUTUBE'!H52+'GERAL YOUTUBE'!H71+'GERAL YOUTUBE'!H90+'GERAL YOUTUBE'!H109+'GERAL YOUTUBE'!H128+'GERAL YOUTUBE'!H147+'GERAL YOUTUBE'!H166+'GERAL YOUTUBE'!H185+'GERAL YOUTUBE'!H204+'GERAL YOUTUBE'!H223+'GERAL YOUTUBE'!H242+'GERAL YOUTUBE'!H261+'GERAL YOUTUBE'!H287 -> 0
A15: 44274 | B15: 44280 | C15: ='GERAL YOUTUBE'!C228 -> 0 | D15: ='GERAL YOUTUBE'!D228 -> 0 | E15: ='GERAL YOUTUBE'!E228 -> 0 | F15: =H15/E15 -> #DIV/0! | G15: ='GERAL YOUTUBE'!G228 -> 0 | H15: ='GERAL YOUTUBE'!H228 -> 0 | J15: AD 12 | K15: ='GERAL YOUTUBE'!C15+'GERAL YOUTUBE'!C34+'GERAL YOUTUBE'!C53+'GERAL YOUTUBE'!C72+'GERAL YOUTUBE'!C91+'GERAL YOUTUBE'!C110+'GERAL YOUTUBE'!C129+'GERAL YOUTUBE'!C148+'GERAL YOUTUBE'!C167+'GERAL YOUTUBE'!C186+'GERAL YOUTUBE'!C205+'GERAL YOUTUBE'!C224+'GERAL YOUTUBE'!C243+'GERAL YOUTUBE'!C262+'GERAL YOUTUBE'!C288 -> 0 | L15: ='GERAL YOUTUBE'!D15+'GERAL YOUTUBE'!D34+'GERAL YOUTUBE'!D53+'GERAL YOUTUBE'!D72+'GERAL YOUTUBE'!D91+'GERAL YOUTUBE'!D110+'GERAL YOUTUBE'!D129+'GERAL YOUTUBE'!D148+'GERAL YOUTUBE'!D167+'GERAL YOUTUBE'!D186+'GERAL YOUTUBE'!D205+'GERAL YOUTUBE'!D224+'GERAL YOUTUBE'!D243+'GERAL YOUTUBE'!D262+'GERAL YOUTUBE'!D288 -> 0 | M15: ='GERAL YOUTUBE'!E15+'GERAL YOUTUBE'!E34+'GERAL YOUTUBE'!E53+'GERAL YOUTUBE'!E72+'GERAL YOUTUBE'!E91+'GERAL YOUTUBE'!E110+'GERAL YOUTUBE'!E129+'GERAL YOUTUBE'!E148+'GERAL YOUTUBE'!E167+'GERAL YOUTUBE'!E186+'GERAL YOUTUBE'!E205+'GERAL YOUTUBE'!E224+'GERAL YOUTUBE'!E243+'GERAL YOUTUBE'!E262+'GERAL YOUTUBE'!E288 -> 0 | N15: =P15/M15 -> #DIV/0! | O15: ='GERAL YOUTUBE'!G15+'GERAL YOUTUBE'!G34+'GERAL YOUTUBE'!G53+'GERAL YOUTUBE'!G72+'GERAL YOUTUBE'!G91+'GERAL YOUTUBE'!G110+'GERAL YOUTUBE'!G129+'GERAL YOUTUBE'!G148+'GERAL YOUTUBE'!G167+'GERAL YOUTUBE'!G186+'GERAL YOUTUBE'!G205+'GERAL YOUTUBE'!G224+'GERAL YOUTUBE'!G243+'GERAL YOUTUBE'!G262+'GERAL YOUTUBE'!G288 -> 0 | P15: ='GERAL YOUTUBE'!H15+'GERAL YOUTUBE'!H34+'GERAL YOUTUBE'!H53+'GERAL YOUTUBE'!H72+'GERAL YOUTUBE'!H91+'GERAL YOUTUBE'!H110+'GERAL YOUTUBE'!H129+'GERAL YOUTUBE'!H148+'GERAL YOUTUBE'!H167+'GERAL YOUTUBE'!H186+'GERAL YOUTUBE'!H205+'GERAL YOUTUBE'!H224+'GERAL YOUTUBE'!H243+'GERAL YOUTUBE'!H262+'GERAL YOUTUBE'!H288 -> 0
A16: 44281 | B16: 44287 | C16: ='GERAL YOUTUBE'!C247 -> 0 | D16: ='GERAL YOUTUBE'!D247 -> 0 | E16: ='GERAL YOUTUBE'!E247 -> 0 | F16: =H16/E16 -> #DIV/0! | G16: ='GERAL YOUTUBE'!G247 -> 0 | H16: ='GERAL YOUTUBE'!H247 -> 0 | J16: AD 13 | K16: ='GERAL YOUTUBE'!C16+'GERAL YOUTUBE'!C35+'GERAL YOUTUBE'!C54+'GERAL YOUTUBE'!C73+'GERAL YOUTUBE'!C92+'GERAL YOUTUBE'!C111+'GERAL YOUTUBE'!C130+'GERAL YOUTUBE'!C149+'GERAL YOUTUBE'!C168+'GERAL YOUTUBE'!C187+'GERAL YOUTUBE'!C206+'GERAL YOUTUBE'!C225+'GERAL YOUTUBE'!C244+'GERAL YOUTUBE'!C263+'GERAL YOUTUBE'!C289 -> 0 | L16: ='GERAL YOUTUBE'!D16+'GERAL YOUTUBE'!D35+'GERAL YOUTUBE'!D54+'GERAL YOUTUBE'!D73+'GERAL YOUTUBE'!D92+'GERAL YOUTUBE'!D111+'GERAL YOUTUBE'!D130+'GERAL YOUTUBE'!D149+'GERAL YOUTUBE'!D168+'GERAL YOUTUBE'!D187+'GERAL YOUTUBE'!D206+'GERAL YOUTUBE'!D225+'GERAL YOUTUBE'!D244+'GERAL YOUTUBE'!D263+'GERAL YOUTUBE'!D289 -> 0 | M16: ='GERAL YOUTUBE'!E16+'GERAL YOUTUBE'!E35+'GERAL YOUTUBE'!E54+'GERAL YOUTUBE'!E73+'GERAL YOUTUBE'!E92+'GERAL YOUTUBE'!E111+'GERAL YOUTUBE'!E130+'GERAL YOUTUBE'!E149+'GERAL YOUTUBE'!E168+'GERAL YOUTUBE'!E187+'GERAL YOUTUBE'!E206+'GERAL YOUTUBE'!E225+'GERAL YOUTUBE'!E244+'GERAL YOUTUBE'!E263+'GERAL YOUTUBE'!E289 -> 0 | N16: =P16/M16 -> #DIV/0! | O16: ='GERAL YOUTUBE'!G16+'GERAL YOUTUBE'!G35+'GERAL YOUTUBE'!G54+'GERAL YOUTUBE'!G73+'GERAL YOUTUBE'!G92+'GERAL YOUTUBE'!G111+'GERAL YOUTUBE'!G130+'GERAL YOUTUBE'!G149+'GERAL YOUTUBE'!G168+'GERAL YOUTUBE'!G187+'GERAL YOUTUBE'!G206+'GERAL YOUTUBE'!G225+'GERAL YOUTUBE'!G244+'GERAL YOUTUBE'!G263+'GERAL YOUTUBE'!G289 -> 0 | P16: ='GERAL YOUTUBE'!H16+'GERAL YOUTUBE'!H35+'GERAL YOUTUBE'!H54+'GERAL YOUTUBE'!H73+'GERAL YOUTUBE'!H92+'GERAL YOUTUBE'!H111+'GERAL YOUTUBE'!H130+'GERAL YOUTUBE'!H149+'GERAL YOUTUBE'!H168+'GERAL YOUTUBE'!H187+'GERAL YOUTUBE'!H206+'GERAL YOUTUBE'!H225+'GERAL YOUTUBE'!H244+'GERAL YOUTUBE'!H263+'GERAL YOUTUBE'!H289 -> 0
A17: 44288 | B17: 44294 | C17: ='GERAL YOUTUBE'!C266 | D17: ='GERAL YOUTUBE'!D266 | E17: ='GERAL YOUTUBE'!E266 | F17: =H17/E17 -> #DIV/0! | G17: ='GERAL YOUTUBE'!G266 | H17: ='GERAL YOUTUBE'!H266 | J17: AD 14 | K17: ='GERAL YOUTUBE'!C17+'GERAL YOUTUBE'!C36+'GERAL YOUTUBE'!C55+'GERAL YOUTUBE'!C74+'GERAL YOUTUBE'!C93+'GERAL YOUTUBE'!C112+'GERAL YOUTUBE'!C131+'GERAL YOUTUBE'!C150+'GERAL YOUTUBE'!C169+'GERAL YOUTUBE'!C188+'GERAL YOUTUBE'!C207+'GERAL YOUTUBE'!C226+'GERAL YOUTUBE'!C245+'GERAL YOUTUBE'!C264+'GERAL YOUTUBE'!C290 -> 0 | L17: ='GERAL YOUTUBE'!D17+'GERAL YOUTUBE'!D36+'GERAL YOUTUBE'!D55+'GERAL YOUTUBE'!D74+'GERAL YOUTUBE'!D93+'GERAL YOUTUBE'!D112+'GERAL YOUTUBE'!D131+'GERAL YOUTUBE'!D150+'GERAL YOUTUBE'!D169+'GERAL YOUTUBE'!D188+'GERAL YOUTUBE'!D207+'GERAL YOUTUBE'!D226+'GERAL YOUTUBE'!D245+'GERAL YOUTUBE'!D264+'GERAL YOUTUBE'!D290 -> 0 | M17: ='GERAL YOUTUBE'!E17+'GERAL YOUTUBE'!E36+'GERAL YOUTUBE'!E55+'GERAL YOUTUBE'!E74+'GERAL YOUTUBE'!E93+'GERAL YOUTUBE'!E112+'GERAL YOUTUBE'!E131+'GERAL YOUTUBE'!E150+'GERAL YOUTUBE'!E169+'GERAL YOUTUBE'!E188+'GERAL YOUTUBE'!E207+'GERAL YOUTUBE'!E226+'GERAL YOUTUBE'!E245+'GERAL YOUTUBE'!E264+'GERAL YOUTUBE'!E290 -> 0 | N17: =P17/M17 -> #DIV/0! | O17: ='GERAL YOUTUBE'!G17+'GERAL YOUTUBE'!G36+'GERAL YOUTUBE'!G55+'GERAL YOUTUBE'!G74+'GERAL YOUTUBE'!G93+'GERAL YOUTUBE'!G112+'GERAL YOUTUBE'!G131+'GERAL YOUTUBE'!G150+'GERAL YOUTUBE'!G169+'GERAL YOUTUBE'!G188+'GERAL YOUTUBE'!G207+'GERAL YOUTUBE'!G226+'GERAL YOUTUBE'!G245+'GERAL YOUTUBE'!G264+'GERAL YOUTUBE'!G290 -> 0 | P17: ='GERAL YOUTUBE'!H17+'GERAL YOUTUBE'!H36+'GERAL YOUTUBE'!H55+'GERAL YOUTUBE'!H74+'GERAL YOUTUBE'!H93+'GERAL YOUTUBE'!H112+'GERAL YOUTUBE'!H131+'GERAL YOUTUBE'!H150+'GERAL YOUTUBE'!H169+'GERAL YOUTUBE'!H188+'GERAL YOUTUBE'!H207+'GERAL YOUTUBE'!H226+'GERAL YOUTUBE'!H245+'GERAL YOUTUBE'!H264+'GERAL YOUTUBE'!H290 -> 0 | Q17: =SUM(P4:P15) -> 0
A18: 44295 | B18: 44301 | F18: =H18/E18 -> #DIV/0! | J18: AD 15 | K18: ='GERAL YOUTUBE'!C18+'GERAL YOUTUBE'!C37+'GERAL YOUTUBE'!C56+'GERAL YOUTUBE'!C75+'GERAL YOUTUBE'!C94+'GERAL YOUTUBE'!C113+'GERAL YOUTUBE'!C132+'GERAL YOUTUBE'!C151+'GERAL YOUTUBE'!C170+'GERAL YOUTUBE'!C189+'GERAL YOUTUBE'!C208+'GERAL YOUTUBE'!C227+'GERAL YOUTUBE'!C246+'GERAL YOUTUBE'!C265+'GERAL YOUTUBE'!C291 -> 0 | L18: ='GERAL YOUTUBE'!D18+'GERAL YOUTUBE'!D37+'GERAL YOUTUBE'!D56+'GERAL YOUTUBE'!D75+'GERAL YOUTUBE'!D94+'GERAL YOUTUBE'!D113+'GERAL YOUTUBE'!D132+'GERAL YOUTUBE'!D151+'GERAL YOUTUBE'!D170+'GERAL YOUTUBE'!D189+'GERAL YOUTUBE'!D208+'GERAL YOUTUBE'!D227+'GERAL YOUTUBE'!D246+'GERAL YOUTUBE'!D265+'GERAL YOUTUBE'!D291 -> 0 | M18: ='GERAL YOUTUBE'!E18+'GERAL YOUTUBE'!E37+'GERAL YOUTUBE'!E56+'GERAL YOUTUBE'!E75+'GERAL YOUTUBE'!E94+'GERAL YOUTUBE'!E113+'GERAL YOUTUBE'!E132+'GERAL YOUTUBE'!E151+'GERAL YOUTUBE'!E170+'GERAL YOUTUBE'!E189+'GERAL YOUTUBE'!E208+'GERAL YOUTUBE'!E227+'GERAL YOUTUBE'!E246+'GERAL YOUTUBE'!E265+'GERAL YOUTUBE'!E291 -> 0 | N18: =P18/M18 -> #DIV/0! | O18: ='GERAL YOUTUBE'!G18+'GERAL YOUTUBE'!G37+'GERAL YOUTUBE'!G56+'GERAL YOUTUBE'!G75+'GERAL YOUTUBE'!G94+'GERAL YOUTUBE'!G113+'GERAL YOUTUBE'!G132+'GERAL YOUTUBE'!G151+'GERAL YOUTUBE'!G170+'GERAL YOUTUBE'!G189+'GERAL YOUTUBE'!G208+'GERAL YOUTUBE'!G227+'GERAL YOUTUBE'!G246+'GERAL YOUTUBE'!G265+'GERAL YOUTUBE'!G291 -> 0 | P18: ='GERAL YOUTUBE'!H18+'GERAL YOUTUBE'!H37+'GERAL YOUTUBE'!H56+'GERAL YOUTUBE'!H75+'GERAL YOUTUBE'!H94+'GERAL YOUTUBE'!H113+'GERAL YOUTUBE'!H132+'GERAL YOUTUBE'!H151+'GERAL YOUTUBE'!H170+'GERAL YOUTUBE'!H189+'GERAL YOUTUBE'!H208+'GERAL YOUTUBE'!H227+'GERAL YOUTUBE'!H246+'GERAL YOUTUBE'!H265+'GERAL YOUTUBE'!H291 -> 0
A19: 44302 | B19: 44308 | F19: =H19/E19 -> #DIV/0! | J19: AD 16
A20: 44309 | B20: 44315 | F20: =H20/E20 -> #DIV/0! | J20: AD 17
A21: 44316 | B21: 44322 | F21: =H21/E21 -> #DIV/0! | J21: AD 18
A22: 44323 | B22: 44329 | F22: =H22/E22 -> #DIV/0! | J22: AD 19
A23: 44330 | B23: 44336 | F23: =H23/E23 -> #DIV/0! | J23: AD 20
A24: 44337 | B24: 44343 | F24: =H24/E24 -> #DIV/0! | J24: AD 21
A25: 44344 | B25: 44350 | F25: =H25/E25 -> #DIV/0! | J25: AD 22
A26: 44351 | B26: 44357 | F26: =H26/E26 -> #DIV/0! | J26: AD 23
A27: 44358 | B27: 44364 | F27: =H27/E27 -> #DIV/0! | J27: AD 24
A28: 44365 | B28: 44371 | F28: =H28/E28 -> #DIV/0! | J28: AD 25
A29: 44372 | B29: 44378 | F29: =H29/E29 -> #DIV/0! | J29: AD 26
A30: 44379 | B30: 44385 | F30: =H30/E30 -> #DIV/0! | J30: AD 27
... A54: 44547 | B54: 44553 | F54: =H54/E54 -> #DIV/0! | J54: AD 51
A55: 44554 | B55: 44560 | J55: AD 52
C56: LIKES | D56: PLAYLIST | E56: INSCRITOS | F56: INSCRITOS | G56: VIEWS REC | H56: GASTO
C57: =SUM(C4:C55) -> 0 | D57: =SUM(D4:D55) -> 0 | E57: =SUM(E4:E55) -> 0 | F57: =SUM(F4:F55) -> #DIV/0! | G57: =SUM(G4:G55) -> 0 | H57: =SUM(H4:H55) -> 0

Sheet GERAL YOUTUBE
A1: YOUTUBE
A2: PLANILHA GERAL - 01/01 - 07/01
A3: VÍDEOS | B3: LINK | C3: LIKES | D3: PLAYLIST | E3: INSCRITOS | F3: CUSTO INSC | G3: VIEWS | H3: GASTO
A4: AD 01 | F4: =H4/E4 -> #DIV/0!
A5: AD 02 | F5: =H5/E5 -> #DIV/0!
A6: AD 03 | F6: =H6/E6 -> #DIV/0!
A7: AD 04 | F7: =H7/E7 -> #DIV/0!
A8: AD 05 | F8: =H8/E8 -> #DIV/0!
A9: AD 06 | F9: =H9/E9 -> #DIV/0!
A10: AD 07 | F10: =H10/E10 -> #DIV/0!
A11: AD 08 | F11: =H11/E11 -> #DIV/0!
A12: AD 09 | F12: =H12/E12 -> #DIV/0!
A13: AD 10 | F13: =H13/E13 -> #DIV/0!
A14: AD 11 | F14: =H14/E14 -> #DIV/0!
A15: AD 12 | F15: =H15/E15 -> #DIV/0!
... A18: AD 15 | F18: =H18/E18 -> #DIV/0!
A19: TOTAL | C19: =SUM(C4:C18) -> 0 | D19: =SUM(D4:D18) -> 0 | E19: =SUM(E4:E18) -> 0 | F19: =AVERAGE(F4:F18) -> #DIV/0! | G19: =SUM(G4:G18) -> 0 | H19: =SUM(H4:H18) -> 0
A21: PLANILHA GERAL - 08/01 - 14/01
A22: VÍDEOS | C22: LIKES | D22: PLAYLIST | E22: INSCRITOS | F22: CUSTO INSC | G22: VIEWS | H22: GASTO
A23: AD 01
A24: AD 02
A25: AD 03
A26: AD 04
A27: AD 05
A28: AD 06
A29: AD 07
A30: AD 08
A31: AD 09
A32: AD 10
A33: AD 11
A34: AD 12
... A37: AD 15
A38: TOTAL | C38: =SUM(C23:C37) -> 0 | D38: =SUM(D23:D37) -> 0 | E38: =SUM(E23:E37) -> 0 | F38: =AVERAGE(F23:F37) -> #DIV/0! | G38: =SUM(G23:G37) -> 0 | H38: =SUM(H23:H37) -> 0
A40: PLANILHA GERAL - 15/01 - 21/01
A41: VÍDEOS | C41: LIKES | D41: PLAYLIST | E41: INSCRITOS | F41: CUSTO INSC | G41: VIEWS | H41: GASTO
A42: AD 01
A43: AD 02
A44: AD 03
A45: AD 04
A46: AD 05
...
