Workbook

Sheet 2022
B2: 2022
B4: Balanço | H4: Saldo | J4: Custo Fixo | L4: Ticket Médio | N4: Reservas - OPCIONAL
A6: ATACADO | B6: Faturamento | C6: Entradas | D6: à Receber | E6: Saídas | F6: Balanço Final | G6: % | H6: Meta Mensal | I6: % da Meta | J6: Valor | K6: % | L6: Vendas | M6: Ticket Médio | N6: Lucro | O6: Investimento | P6: Marketing | Q6: Colaboradores | R6: Prosperidade | S6: Oportunidade | T6: Total | U6: Saldo
A7: Janeiro | B7: 1 | C7: 1 | D7: 1 | E7: 0.5 | F7: =C7-E7 -> 0.5 | G7: =F7/C7 -> 0.5 | H7: =$K$23*'Histórico '!V5 -> #DIV/0! | I7: =(B7/H7)-100% -> #DIV/0! | J7: 0.5 | K7: =J7/B7 -> 0.5 | L7: 100 | M7: =B7/L7 -> 0.01 | N7: =B7*0.05 -> 0.05 | O7: =B7*0.05 -> 0.05 | P7: =B7*0.02 -> 0.02 | Q7: =B7*0.05 -> 0.05 | R7: =B7*0.1 -> 0.1 | S7: 0 | T7: =SUM(N7:R7) -> 0.27 | U7: 0
A8: Fevereiro | B8: 0 | C8: 0 | D8: 0 | E8: 0 | F8: =C8-E8 -> 0 | G8: =F8/C8 -> #DIV/0! | H8: =$K$23*'Histórico '!V6 -> #DIV/0! | I8: =(B8/H8)-100% -> #DIV/0! | J8: 0 | K8: =J8/B8 -> #DIV/0! | L8: 0 | M8: =B8/L8 -> #DIV/0! | N8: =B8*0.05 -> 0 | O8: =B8*0.05 -> 0 | P8: =B8*0.02 -> 0 | Q8: =B8*0.05 -> 0 | R8: =B8*0.1 -> 0 | S8: 0 | T8: =N8+O8+Q8+R8+P8 -> 0 | U8: =#REF!-T8 -> #REF!
A9: Março | B9: 0 | C9: 0 | D9: 0 | E9: 0 | F9: =C9-E9 -> 0 | G9: =F9/C9 -> #DIV/0! | H9: =$K$23*'Histórico '!V7 -> #DIV/0! | I9: =(B9/H9)-100% -> #DIV/0! | J9: 0 | K9: =J9/B9 -> #DIV/0! | L9: 0 | M9: =B9/L9 -> #DIV/0! | N9: =B9*0.05 -> 0 | O9: =B9*0.05 -> 0 | P9: =B9*0.02 -> 0 | Q9: =B9*0.05 -> 0 | R9: =B9*0.1 -> 0 | S9: 0 | T9: =SUM(N9:R9) -> 0
A10: Abril | B10: 0 | C10: 0 | D10: 0 | E10: 0 | F10: =C10-E10 -> 0 | G10: =F10/C10 -> #DIV/0! | H10: =$K$23*'Histórico '!V8 -> #DIV/0! | I10: =(B10/H10)-100% -> #DIV/0! | J10: 0 | K10: =J10/B10 -> #DIV/0! | L10: 0 | M10: =B10/L10 -> #DIV/0! | N10: =B10*0.05 -> 0 | O10: =B10*0.05 -> 0 | P10: =B10*0.02 -> 0 | Q10: =B10*0.05 -> 0 | R10: =B10*0.1 -> 0 | S10: 0 | T10: =SUM(N10:R10) -> 0
A11: Maio | B11: 0 | C11: 0 | D11: 0 | E11: 0 | F11: =C11-E11 -> 0 | G11: =F11/C11 -> #DIV/0! | H11: =$K$23*'Histórico '!V9 -> #DIV/0! | I11: =(B11/H11)-100% -> #DIV/0! | J11: 0 | K11: =J11/B11 -> #DIV/0! | L11: 0 | M11: =B11/L11 -> #DIV/0! | N11: =B11*0.05 -> 0 | O11: =B11*0.05 -> 0 | P11: =B11*0.02 -> 0 | Q11: =B11*0.05 -> 0 | R11: =B11*0.1 -> 0 | S11: 0 | T11: =SUM(N11:R11) -> 0
A12: Junho | B12: 0 | C12: 0 | D12: 0 | E12: 0 | F12: =C12-E12 -> 0 | G12: =F12/C12 -> #DIV/0! | H12: =$K$23*'Histórico '!V10 -> #DIV/0! | I12: =(B12/H12)-100% -> #DIV/0! | J12: 0 | K12: =J12/B12 -> #DIV/0! | L12: 0 | M12: =B12/L12 -> #DIV/0! | N12: =B12*0.05 -> 0 | O12: =B12*0.05 -> 0 | P12: =B12*0.02 -> 0 | Q12: =B12*0.05 -> 0 | R12: =B12*0.1 -> 0 | S12: 0 | T12: =SUM(N12:R12) -> 0
A13: Julho | B13: 0 | C13: 0 | D13: 0 | E13: 0 | F13: =C13-E13 -> 0 | G13: =F13/C13 -> #DIV/0! | H13: =$K$23*'Histórico '!V11 -> #DIV/0! | I13: =(B13/H13)-100% -> #DIV/0! | J13: 0 | K13: =J13/B13 -> #DIV/0! | L13: 0 | M13: =B13/L13 -> #DIV/0! | N13: =B13*0.05 -> 0 | O13: =B13*0.05 -> 0 | P13: =B13*0.02 -> 0 | Q13: =B13*0.05 -> 0 | R13: =B13*0.1 -> 0 | S13: 0 | T13: =SUM(N13:R13) -> 0
A14: Agosto | B14: 0 | C14: 0 | D14: 0 | E14: 0 | F14: =C14-E14 -> 0 | G14: =F14/C14 -> #DIV/0! | H14: =$K$23*'Histórico '!V12 -> #DIV/0! | I14: =(B14/H14)-100% -> #DIV/0! | J14: 0 | K14: =J14/B14 -> #DIV/0! | L14: 0 | M14: =B14/L14 -> #DIV/0! | N14: =B14*0.05 -> 0 | O14: =B14*0.05 -> 0 | P14: =B14*0.02 -> 0 | Q14: =B14*0.05 -> 0 | R14: =B14*0.1 -> 0 | S14: 0 | T14: =SUM(N14:R14) -> 0
A15: Setembro | B15: 0 | C15: 0 | D15: 0 | E15: 0 | F15: =C15-E15 -> 0 | G15: =F15/C15 -> #DIV/0! | H15: =$K$23*'Histórico '!V13 -> #DIV/0! | I15: =(B15/H15)-100% -> #DIV/0! | J15: 0 | K15: =J15/B15 -> #DIV/0! | L15: 0 | M15: =B15/L15 -> #DIV/0! | N15: =B15*0.05 -> 0 | O15: =B15*0.05 -> 0 | P15: =B15*0.02 -> 0 | Q15: =B15*0.05 -> 0 | R15: =B15*0.1 -> 0 | S15: 0 | T15: =SUM(N15:R15) -> 0
A16: Outubro | B16: 0 | C16: 0 | D16: 0 | E16: 0 | F16: =C16-E16 -> 0 | G16: =F16/C16 -> #DIV/0! | H16: =$K$23*'Histórico '!V14 -> #DIV/0! | I16: =(B16/H16)-100% -> #DIV/0! | J16: 0 | K16: =J16/B16 -> #DIV/0! | L16: 0 | M16: =B16/L16 -> #DIV/0! | N16: =B16*0.05 -> 0 | O16: =B16*0.05 -> 0 | P16: 0 | Q16: =B16*0.05 -> 0 | R16: =B16*0.1 -> 0 | S16: 0 | T16: =SUM(N16:R16) -> 0
A17: Novembro | B17: 0 | C17: 0 | D17: 0 | E17: 0 | F17: =C17-E17 -> 0 | G17: =F17/C17 -> #DIV/0! | H17: =$K$23*'Histórico '!V15 -> #DIV/0! | I17: =(B17/H17)-100% -> #DIV/0! | J17: 0 | K17: =J17/B17 -> #DIV/0! | L17: 0 | M17: =B17/L17 -> #DIV/0! | N17: =B17*0.05 -> 0 | O17: =B17*0.05 -> 0 | P17: 0 | Q17: =B17*0.05 -> 0 | R17: =B17*0.1 -> 0 | S17: 0 | T17: =SUM(N17:R17) -> 0
A18: Dezembro | B18: 0 | C18: 0 | D18: 0 | E18: 0 | F18: =C18-E18 -> 0 | G18: =F18/C18 -> #DIV/0! | H18: =$K$23*'Histórico '!V16 -> #DIV/0! | I18: =(B18/H18)-100% -> #DIV/0! | J18: 0 | K18: =J18/B18 -> #DIV/0! | L18: 0 | M18: =B18/L18 -> #DIV/0! | N18: =B18*0.05 -> 0 | O18: =B18*0.05 -> 0 | P18: 0 | Q18: =B18*0.05 -> 0 | R18: =B18*0.1 -> 0 | S18: 0 | T18: =SUM(N18:R18) -> 0
A20: TOTAL | B20: =SUM(B7:B18) -> 1 | C20: =SUM(C7:C18) -> 1 | D20: =SUM(D7:D18) -> 1 | E20: =SUM(E7:E18) -> 0.5 | F20: =SUM(F7:F18) -> 0.5 | G20: =G7 -> 0.5 | J20: =SUM(H7:H18) -> #DIV/0! | M20: =SUM(K7:K18)/12 -> #DIV/0! | N20: =SUM(N7:N18) -> 0.05 | O20: =SUM(O7:O18) -> 0.05 | P20: =SUM(P7:P18) -> 0.02 | Q20: =SUM(Q7:Q18) -> 0.05 | R20: =SUM(R7:R18) -> 0.1 | S20: =SUM(S7:S18) -> 0
A22: VAREJO | B22: Faturamento | C22: Entradas | D22: Saídas | E22: Balanço Final | F22: % | G22: Vendas | H22: Ticket Médio | J22: META | K22: Meta | L22: Acumulado | M22: %
A23: Janeiro | B23: 1 | C23: 1 | D23: 1 | E23: =C23-D23 -> 0 | F23: =E23/C23 -> 0 | G23: 0 | H23: =B23/G23 -> #DIV/0! | J23: Anual | L23: =$B$20 -> 1
A24: Fevereiro | B24: 0 | C24: 0 | D24: 0 | E24: =C24-D24 -> 0 | F24: =E24/C24 -> #DIV/0! | G24: 0 | H24: =B24/G24 -> #DIV/0! | J24: 1 Trimestre | K24: =$K$23/4 -> 0 | L24: =$B$7+$B$8+$B$9 -> 1 | M24: =L24/K24 -> #DIV/0!
A25: Março | B25: 0 | C25: 0 | D25: 0 | E25: =C25-D25 -> 0 | F25: =E25/C25 -> #DIV/0! | G25: 0 | H25: =B25/G25 -> #DIV/0! | J25: 2 Trimestre | K25: =$K$23/4 -> 0 | L25: =$B$10+$B$11+$B$12 -> 0 | M25: =L25/K25 -> #DIV/0!
A26: Abril | B26: 0 | C26: 0 | D26: 0 | E26: =C26-D26 -> 0 | F26: =E26/C26 -> #DIV/0! | G26: 0 | H26: =B26/G26 -> #DIV/0! | J26: 3 Trimestre | K26: =$K$23/4 -> 0 | L26: =$B$13+$B$14+$B$15 -> 0 | M26: =L26/K26 -> #DIV/0!
A27: Maio | B27: 0 | C27: 0 | D27: 0 | E27: =C27-D27 -> 0 | F27: =E27/C27 -> #DIV/0! | G27: 0 | H27: =B27/G27 -> #DIV/0! | J27: 4 Trimestre | K27: =$K$23/4 -> 0 | L27: =$B$16+$B$17+$B$18 -> 0 | M27: =L27/K27 -> #DIV/0!
A28: Junho | B28: 0 | C28: 0 | D28: 0 | E28: =C28-D28 -> 0 | F28: =E28/C28 -> #DIV/0! | G28: 0 | H28: =B28/G28 -> #DIV/0!
A29: Julho | B29: 0 | C29: 0 | D29: 0 | E29: =C29-D29 -> 0 | F29: =E29/C29 -> #DIV/0! | G29: 0 | H29: =B29/G29 -> #DIV/0!
A30: Agosto | B30: 0 | C30: 0 | D30: 0 | E30: =C30-D30 -> 0 | F30: =E30/C30 -> #DIV/0! | G30: 0 | H30: =B30/G30 -> #DIV/0!
A31: Setembro | B31: 0 | C31: 0 | D31: 0 | E31: =C31-D31 -> 0 | F31: =E31/C31 -> #DIV/0! | G31: 0 | H31: =B31/G31 -> #DIV/0!
A32: Outubro | B32: 0 | C32: 0 | D32: 0 | E32: =C32-D32 -> 0 | F32: =E32/C32 -> #DIV/0! | G32: 0 | H32: =B32/G32 -> #DIV/0!
A33: Novembro | B33: 0 | C33: 0 | D33: 0 | E33: =C33-D33 -> 0 | F33: =E33/C33 -> #DIV/0! | G33: 0 | H33: =B33/G33 -> #DIV/0!
A34: Dezembro | B34: 0 | C34: 0 | D34: 0 | E34: =C34-D34 -> 0 | F34: =E34/C34 -> #DIV/0! | G34: 0 | H34: =B34/G34 -> #DIV/0!
A36: TOTAL | B36: =SUM(B23:B26)/4 -> 0.25 | C36: =SUM(C23:C34) -> 1 | D36: =SUM(D23:D34) -> 1 | E36: =SUM(E23:E34) -> 0 | F36: =F23 -> 0 | G36: =SUM(G23:G34) -> 0 | H36: =SUM(H23:H34) -> #DIV/0!
A38: GERENCIAMENTO DE CONTAS | B38: Santander | C38: Itaú | D38: Nubank | E38: Sicredi
B39: Entrada ( nomes opcionais, escolha os seus) | C39: Entrada Distribuidora | D39: Em loja | E39: Oportunidade/ Marketing
A40: Janeiro | B40: 0 | C40: 0 | D40: 0 | E40: 0
A41: Fevereiro | B41: 0 | C41: 0 | D41: 0 | E41: 0
A42: Março | B42: 0 | C42: 0 | D42: 0 | E42: 0
A43: Abril | B43: 0 | C43: 0 | D43: 0 | E43: 0
A44: Maio | B44: 0 | C44: 0 | D44: 0 | E44: 0
A45: Junho | B45: 0 | C45: 0 | D45: 0 | E45: 0
A46: Julho | B46: 0 | C46: 0 | D46: 0 | E46: 0
A47: Agosto | B47: 0 | C47: 0 | D47: 0 | E47: 0
...

Sheet Histórico 
B2: Histórico | V2: Média de Faturamento
C3: 2019 | F3: 2020 | I3: 2021 | L3: 2022 | O3: 2023 | R3: 2024
C4: Faturamento | D4: Vendas | E4: Ticket Médio | F4: Faturamento | G4: Vendas | H4: Ticket Médio | I4: Faturamento | J4: Vendas | K4: Ticket Médio | L4: Faturamento | M4: Vendas | N4: Ticket Médio | O4: Faturamento | P4: Vendas | Q4: Ticket Médio | R4: Faturamento | S4: Vendas | T4: Ticket Médio | U4: Média Fat. 2022 | W4: META | X4: +10% | Y4: +25%
B5: Janeiro | C5: 0 | E5: =C5/D5 -> #DIV/0! | F5: 0 | H5: =F5/G5 -> #DIV/0! | I5: 0 | K5: =I5/J5 -> #DIV/0! | L5: 0 | N5: =L5/M5 -> #DIV/0! | O5: 0 | Q5: =O5/P5 -> #DIV/0! | R5: 0 | T5: =R5/S5 -> #DIV/0! | U5: =R5/$R$17 -> #DIV/0! | V5: =(C5+F5+I5+L5+O5+R5)/$V$17 -> #DIV/0! | W5: =600000*V5 -> #DIV/0! | X5: =W5+10%*W5 -> #DIV/0! | Y5: =X5+20%*X5 -> #DIV/0!
B6: Fevereiro | C6: 0 | E6: =C6/D6 -> #DIV/0! | F6: 0 | H6: =F6/G6 -> #DIV/0! | I6: 0 | K6: =I6/J6 -> #DIV/0! | L6: 0 | N6: =L6/M6 -> #DIV/0! | O6: 0 | Q6: =O6/P6 -> #DIV/0! | R6: 0 | T6: =R6/S6 -> #DIV/0! | U6: =R6/$R$17 -> #DIV/0! | V6: =(C6+F6+I6+L6+O6+R6)/$V$17 -> #DIV/0! | W6: =600000*V6 -> #DIV/0! | X6: =W6+10%*W6 -> #DIV/0! | Y6: =X6+20%*X6 -> #DIV/0!
B7: Março | C7: 0 | E7: =C7/D7 -> #DIV/0! | F7: 0 | H7: =F7/G7 -> #DIV/0! | I7: 0 | K7: =I7/J7 -> #DIV/0! | L7: 0 | N7: =L7/M7 -> #DIV/0! | O7: 0 | Q7: =O7/P7 -> #DIV/0! | R7: 0 | T7: =R7/S7 -> #DIV/0! | U7: =R7/$R$17 -> #DIV/0! | V7: =(C7+F7+I7+L7+O7+R7)/$V$17 -> #DIV/0! | W7: =600000*V7 -> #DIV/0! | X7: =W7+10%*W7 -> #DIV/0! | Y7: =X7+20%*X7 -> #DIV/0!
B8: Abril | C8: 0 | E8: =C8/D8 -> #DIV/0! | F8: 0 | H8: =F8/G8 -> #DIV/0! | I8: 0 | K8: =I8/J8 -> #DIV/0! | L8: 0 | N8: =L8/M8 -> #DIV/0! | O8: 0 | Q8: =O8/P8 -> #DIV/0! | R8: 0 | T8: =R8/S8 -> #DIV/0! | U8: =R8/$R$17 -> #DIV/0! | V8: =(C8+F8+I8+L8+O8+R8)/$V$17 -> #DIV/0! | W8: =600000*V8 -> #DIV/0! | X8: =W8+10%*W8 -> #DIV/0! | Y8: =X8+20%*X8 -> #DIV/0!
B9: Maio | C9: 0 | E9: =C9/D9 -> #DIV/0! | F9: 0 | H9: =F9/G9 -> #DIV/0! | I9: 0 | K9: =I9/J9 -> #DIV/0! | L9: 0 | N9: =L9/M9 -> #DIV/0! | O9: 0 | Q9: =O9/P9 -> #DIV/0! | R9: 0 | T9: =R9/S9 -> #DIV/0! | U9: =R9/$R$17 -> #DIV/0! | V9: =(C9+F9+I9+L9+O9+R9)/$V$17 -> #DIV/0! | W9: =600000*V9 -> #DIV/0! | X9: =W9+5%*W9 -> #DIV/0! | Y9: =X9+20%*X9 -> #DIV/0!
B10: Junho | C10: 0 | E10: =C10/D10 -> #DIV/0! | F10: 0 | H10: =F10/G10 -> #DIV/0! | I10: 0 | K10: =I10/J10 -> #DIV/0! | L10: 0 | N10: =L10/M10 -> #DIV/0! | O10: 0 | Q10: =O10/P10 -> #DIV/0! | R10: 0 | T10: =R10/S10 -> #DIV/0! | U10: =R10/$R$17 -> #DIV/0! | V10: =(C10+F10+I10+L10+O10+R10)/$V$17 -> #DIV/0! | W10: =600000*V10 -> #DIV/0! | X10: =W10+10%*W10 -> #DIV/0! | Y10: =X10+20%*X10 -> #DIV/0!
B11: Julho | C11: 0 | E11: =C11/D11 -> #DIV/0! | F11: 0 | H11: =F11/G11 -> #DIV/0! | I11: 0 | K11: =I11/J11 -> #DIV/0! | L11: 0 | N11: =L11/M11 -> #DIV/0! | O11: 0 | Q11: =O11/P11 -> #DIV/0! | R11: 0 | T11: =R11/S11 -> #DIV/0! | U11: =R11/$R$17 -> #DIV/0! | V11: =(C11+F11+I11+L11+O11+R11)/$V$17 -> #DIV/0! | W11: =600000*V11 -> #DIV/0! | X11: =W11+10%*W11 -> #DIV/0! | Y11: =X11+20%*X11 -> #DIV/0!
B12: Agosto | C12: 0 | E12: =C12/D12 -> #DIV/0! | F12: 0 | H12: =F12/G12 -> #DIV/0! | I12: 0 | K12: =I12/J12 -> #DIV/0! | L12: 0 | N12: =L12/M12 -> #DIV/0! | O12: 0 | Q12: =O12/P12 -> #DIV/0! | R12: 0 | T12: =R12/S12 -> #DIV/0! | U12: =R12/$R$17 -> #DIV/0! | V12: =(C12+F12+I12+L12+O12+R12)/$V$17 -> #DIV/0! | W12: =600000*V12 -> #DIV/0! | X12: =W12+10%*W12 -> #DIV/0! | Y12: =X12+20%*X12 -> #DIV/0!
B13: Setembro | C13: 0 | E13: =C13/D13 -> #DIV/0! | F13: 0 | H13: =F13/G13 -> #DIV/0! | I13: 0 | K13: =I13/J13 -> #DIV/0! | L13: 0 | N13: =L13/M13 -> #DIV/0! | O13: 0 | Q13: =O13/P13 -> #DIV/0! | R13: 0 | T13: =R13/S13 -> #DIV/0! | U13: =R13/$R$17 -> #DIV/0! | V13: =(C13+F13+I13+L13+O13+R13)/$V$17 -> #DIV/0! | W13: =600000*V13 -> #DIV/0! | X13: =W13+10%*W13 -> #DIV/0! | Y13: =X13+20%*X13 -> #DIV/0!
B14: Outubro | C14: 0 | E14: =C14/D14 -> #DIV/0! | F14: 0 | H14: =F14/G14 -> #DIV/0! | I14: 0 | K14: =I14/J14 -> #DIV/0! | L14: 0 | N14: =L14/M14 -> #DIV/0! | O14: 0 | Q14: =O14/P14 -> #DIV/0! | R14: 0 | T14: =R14/S14 -> #DIV/0! | U14: =R14/$R$17 -> #DIV/0! | V14: =(C14+F14+I14+L14+O14+R14)/$V$17 -> #DIV/0! | W14: =600000*V14 -> #DIV/0! | X14: =W14+10%*W14 -> #DIV/0! | Y14: =X14+20%*X14 -> #DIV/0!
B15: Novembro | C15: 0 | E15: =C15/D15 -> #DIV/0! | F15: 0 | H15: =F15/G15 -> #DIV/0! | I15: 0 | K15: =I15/J15 -> #DIV/0! | L15: 0 | N15: =L15/M15 -> #DIV/0! | O15: 0 | Q15: =O15/P15 -> #DIV/0! | R15: 0 | T15: =R15/S15 -> #DIV/0! | U15: =R15/$R$17 -> #DIV/0! | V15: =(C15+F15+I15+L15+O15+R15)/$V$17 -> #DIV/0! | W15: =600000*V15 -> #DIV/0! | X15: =W15+10%*W15 -> #DIV/0! | Y15: =X15+20%*X15 -> #DIV/0!
B16: Dezembro | C16: 0 | E16: =C16/D16 -> #DIV/0! | F16: 0 | H16: =F16/G16 -> #DIV/0! | I16: 0 | K16: =I16/J16 -> #DIV/0! | L16: 0 | N16: =L16/M16 -> #DIV/0! | O16: 0 | Q16: =O16/P16 -> #DIV/0! | R16: 0 | T16: =R16/S16 -> #DIV/0! | U16: =R16/$R$17 -> #DIV/0! | V16: =(C16+F16+I16+L16+O16+R16)/$V$17 -> #DIV/0! | W16: =600000*V16 -> #DIV/0! | X16: =W16+10%*W16 -> #DIV/0! | Y16: =X16+20%*X16 -> #DIV/0!
B17: Total | C17: =SUM(C5:C16) -> 0 | D17: =SUM(D5:D16) -> 0 | E17: - | F17: =SUM(F5:F16) -> 0 | G17: =SUM(G5:G16) -> 0 | H17: =SUM(H5:H16) -> #DIV/0! | I17: =SUM(I5:I16) -> 0 | J17: =SUM(J5:J16) -> 0 | K17: - | L17: =SUM(L5:L16) -> 0 | M17: =SUM(M5:M16) -> 0 | N17: - | O17: =SUM(O5:O16) -> 0 | P17: =SUM(P5:P16) -> 0 | Q17: - | R17: =SUM(R5:R16) -> 0 | S17: =SUM(S5:S16) -> 0 | T17: - | V17: =C17+F17+I17+L17+O17 -> 0 | W17: =SUM(W5:W16) -> #DIV/0! | X17: =W17+10%*W17 -> #DIV/0! | Y17: =X17+20%*X17 -> #DIV/0!
B18: Média | C18: =C17/12 -> 0 | D18: =D17/2 -> 0 | E18: =(E15+E16)/2 -> #DIV/0! | F18: =F17/12 -> 0 | G18: =G17/12 -> 0 | H18: =SUM(H5:H16)/12 -> #DIV/0! | I18: =I17/12 -> 0 | J18: =J17/12 -> 0 | K18: =SUM(K5:K16)/12 -> #DIV/0! | L18: =L17/12 -> 0 | M18: =M17/12 -> 0 | N18: =SUM(N5:N16)/12 -> #DIV/0! | O18: =O17/12 -> 0 | P18: =P17/12 -> 0 | Q18: =SUM(Q5:Q16)/12 -> #DIV/0! | R18: =R17/12 -> 0 | S18: =S17/12 -> 0 | T18: =SUM(T5:T16)/12 -> #DIV/0! | V18: =V17/4 -> 0
R19: =W17-R17 -> #DIV/0!
O20: CRESCIMENTO | P20: %
O21: 2020 | P21: =($F$17/$C$17)-100% -> #DIV/0!
O22: 2021 | P22: =($I$17/$F$17)-100% -> #DIV/0!
O23: 2022 | P23: =($L$17/$I$17)-100% -> #DIV/0!
P24: =($O$17/$L$17)-100% -> #DIV/0!
P25: =($R$17/$O$17)-100% -> #DIV/0!

Sheet 2021
B2: 2021
B4: Balanço | J4: Custo Fixo | L4: Ticket Médio
A6: ATACADO | B6: Faturamento | C6: Entradas | D6: à Receber | E6: Saídas | F6: Balanço Final | G6: % | H6: Meta Mensal | I6: % da Meta | J6: Valor | K6: % | L6: Vendas | M6: Ticket Médio | N6: Custo Ticket | O6: Lucro Ticket
A7: Janeiro | B7: 1 | C7: 1 | D7: 1 | E7: 0.5 | F7: =C7-E7 -> 0.5 | G7: =F7/C7 -> 0.5 | H7: 0 | I7: =(B7/H7)-100% -> #DIV/0! | J7: 0 | K7: =J7/B7 -> 0 | L7: 0 | M7: =B7/L7 -> #DIV/0! | N7: =E7/L7 -> #DIV/0! | O7: =C7/L7 -> #DIV/0!
A8: Fevereiro | B8: 0 | C8: 0 | D8: 0 | E8: 0 | F8: =C8-E8 -> 0 | G8: =F8/C8 -> #DIV/0! | H8: 0 | I8: =(B8/H8)-100% -> #DIV/0! | J8: 0 | K8: =J8/B8 -> #DIV/0! | L8: 0 | M8: =B8/L8 -> #DIV/0! | N8: =E8/L8 -> #DIV/0! | O8: =C8/L8 -> #DIV/0!
A9: Março | B9: 0 | C9: 0 | D9: 0 | E9: 0 | F9: =C9-E9 -> 0 | G9: =F9/C9 -> #DIV/0! | H9: 0 | I9: =(B9/H9)-100% -> #DIV/0! | J9: 0 | K9: =J9/B9 -> #DIV/0! | L9: 0 | M9: =B9/L9 -> #DIV/0! | N9: =E9/L9 -> #DIV/0! | O9: =C9/L9 -> #DIV/0!
A10: Abril | B10: 0 | C10: 0 | D10: 0 | E10: 0 | F10: =C10-E10 -> 0 | G10: =F10/C10 -> #DIV/0! | H10: 0 | I10: =(B10/H10)-100% -> #DIV/0! | J10: 0 | K10: =J10/B10 -> #DIV/0! | L10: 0 | M10: =B10/L10 -> #DIV/0! | N10: =E10/L10 -> #DIV/0! | O10: =C10/L10 -> #DIV/0!
A11: Maio | B11: 0 | C11: 0 | D11: 0 | E11: 0 | F11: =C11-E11 -> 0 | G11: =F11/C11 -> #DIV/0! | H11: 0 | I11: =(B11/H11)-100% -> #DIV/0! | J11: 0 | K11: =J11/B11 -> #DIV/0! | L11: 0 | M11: =B11/L11 -> #DIV/0! | N11: =E11/L11 -> #DIV/0! | O11: =C11/L11 -> #DIV/0!
A12: Junho | B12: 0 | C12: 0 | D12: 0 | E12: 0 | F12: =C12-E12 -> 0 | G12: =F12/C12 -> #DIV/0! | H12: 0 | I12: =(B12/H12)-100% -> #DIV/0! | J12: 0 | K12: =J12/B12 -> #DIV/0! | L12: 0 | M12: =B12/L12 -> #DIV/0! | N12: =E12/L12 -> #DIV/0! | O12: =C12/L12 -> #DIV/0!
A13: Julho | B13: 0 | C13: 0 | D13: 0 | E13: 0 | F13: =C13-E13 -> 0 | G13: =F13/C13 -> #DIV/0! | H13: 0 | I13: =(B13/H13)-100% -> #DIV/0! | J13: 0 | K13: =J13/B13 -> #DIV/0! | L13: 0 | M13: =B13/L13 -> #DIV/0! | N13: =E13/L13 -> #DIV/0! | O13: =C13/L13 -> #DIV/0!
A14: Agosto | B14: 0 | C14: 0 | D14: 0 | E14: 0 | F14: =C14-E14 -> 0 | G14: =F14/C14 -> #DIV/0! | H14: 0 | I14: =(B14/H14)-100% -> #DIV/0! | J14: 0 | K14: =J14/B14 -> #DIV/0! | L14: 0 | M14: =B14/L14 -> #DIV/0! | N14: =E14/L14 -> #DIV/0! | O14: =C14/L14 -> #DIV/0!
A15: Setembro | B15: 0 | C15: 0 | D15: 0 | E15: 0 | F15: =C15-E15 -> 0 | G15: =F15/C15 -> #DIV/0! | H15: 0 | I15: =(B15/H15)-100% -> #DIV/0! | J15: 0 | K15: =J15/B15 -> #DIV/0! | L15: 0 | M15: =B15/L15 -> #DIV/0! | N15: =E15/L15 -> #DIV/0! | O15: =C15/L15 -> #DIV/0!
A16: Outubro | B16: 0 | C16: 0 | D16: 0 | E16: 0 | F16: =C16-E16 -> 0 | G16: =F16/C16 -> #DIV/0! | H16: 0 | I16: =(B16/H16)-100% -> #DIV/0! | J16: 0 | K16: =J16/B16 -> #DIV/0! | L16: 0 | M16: =B16/L16 -> #DIV/0! | N16: =E16/L16 -> #DIV/0! | O16: =C16/L16 -> #DIV/0!
A17: Novembro | B17: 0 | C17: 0 | D17: 0 | E17: 0 | F17: =C17-E17 -> 0 | G17: =F17/C17 -> #DIV/0! | H17: 0 | I17: =(B17/H17)-100% -> #DIV/0! | J17: 0 | K17: =J17/B17 -> #DIV/0! | L17: 0 | M17: =B17/L17 -> #DIV/0! | N17: =E17/L17 -> #DIV/0! | O17: =C17/L17 -> #DIV/0!
A18: Dezembro | B18: 0 | C18: 0 | D18: 0 | E18: 0 | F18: =C18-E18 -> 0 | G18: =F18/C18 -> #DIV/0! | H18: 0 | I18: =(B18/H18)-100% -> #DIV/0! | J18: 0 | K18: =J18/B18 -> #DIV/0! | L18: 0 | M18: =B18/L18 -> #DIV/0! | N18: =E18/L18 -> #DIV/0! | O18: =C18/L18 -> #DIV/0!
A20: TOTAL | B20: =SUM(B7:B18) -> 1 | C20: =SUM(C7:C18) -> 1 | D20: =SUM(D7:D18) -> 1 | E20: =SUM(E7:E18) -> 0.5 | F20: =SUM(F7:F18) -> 0.5 | G20: =SUM(G7:G18)/12 -> #DIV/0! | H20: =SUM(H7:H18) -> 0 | K20: =SUM(K7:K18)/12 -> #DIV/0! | L20: =SUM(L7:L18) -> 0 | M20: =SUM(M7:M18)/12 -> #DIV/0!
A22: VAREJO | B22: Faturamento | C22: Entradas | D22: Saídas | E22: Balanço Final | F22: % | G22: Vendas | H22: Ticket Médio | J22: META | K22: Meta | L22: Acumulado | M22: %
A23: Janeiro | B23: 1 | C23: 1 | D23: 1 | E23: =C23-D23 -> 0 | F23: =E23/C23 -> 0 | G23: 0 | H23: =B23/G23 -> #DIV/0! | J23: Anual | L23: =$B$20 -> 1 | M23: =(L23/K23)-100% -> #DIV/0!
A24: Fevereiro | B24: 0 | C24: 0 | D24: 0 | E24: =C24-D24 -> 0 | F24: =E24/C24 -> #DIV/0! | G24: 0 | H24: =B24/G24 -> #DIV/0! | J24: 1 Trimestre | K24: =$K$23/4 -> 0 | L24: =$B$7+$B$8+$B$9 -> 1 | M24: =(L24/K24)-100% -> #DIV/0!
A25: Março | B25: 0 | C25: 0 | D25: 0 | E25: =C25-D25 -> 0 | F25: =E25/C25 -> #DIV/0! | G25: 0 | H25: =B25/G25 -> #DIV/0! | J25: 2 Trimestre | K25: =$K$23/4 -> 0 | L25: =$B$10+$B$11+$B$12 -> 0 | M25: =(L25/K25)-100% -> #DIV/0!
A26: Abril | B26: 0 | C26: 0 | D26: 0 | E26: =C26-D26 -> 0 | F26: =E26/C26 -> #DIV/0! | G26: 0 | H26: =B26/G26 -> #DIV/0! | J26: 3 Trimestre | K26: =$K$23/4 -> 0 | L26: =$B$13+$B$14+$B$15 -> 0 | M26: =(L26/K26)-100% -> #DIV/0!
A27: Maio | B27: 0 | C27: 0 | D27: 0 | E27: =C27-D27 -> 0 | F27: =E27/C27 -> #DIV/0! | G27: 0 | H27: =B27/G27 -> #DIV/0! | J27: 4 Trimestre | K27: =$K$23/4 -> 0 | L27: =$B$16+$B$17+$B$18 -> 0 | M27: =(L27/K27)-100% -> #DIV/0!
A28: Junho | B28: 0 | C28: 0 | D28: 0 | E28: =C28-D28 -> 0 | F28: =E28/C28 -> #DIV/0! | G28: 0 | H28: =B28/G28 -> #DIV/0!
A29: Julho | B29: 0 | C29: 0 | D29: 0 | E29: =C29-D29 -> 0 | F29: =E29/C29 -> #DIV/0! | G29: 0 | H29: =B29/G29 -> #DIV/0!
A30: Agosto | B30: 0 | C30: 0 | D30: 0 | E30: =C30-D30 -> 0 | F30: =E30/C30 -> #DIV/0! | G30: 0 | H30: =B30/G30 -> #DIV/0!
A31: Setembro | B31: 0 | C31: 0 | D31: 0 | E31: =C31-D31 -> 0 | F31: =E31/C31 -> #DIV/0! | G31: 0 | H31: =B31/G31 -> #DIV/0!
A32: Outubro | B32: 0 | C32: 0 | D32: 0 | E32: =C32-D32 -> 0 | F32: =E32/C32 -> #DIV/0! | G32: 0 | H32: =B32/G32 -> #DIV/0!
A33: Novembro | B33: 0 | C33: 0 | D33: 0 | E33: =C33-D33 -> 0 | F33: =E33/C33 -> #DIV/0! | G33: 0 | H33: =B33/G33 -> #DIV/0!
A34: Dezembro | B34: 0 | C34: 0 | D34: 0 | E34: 0 | F34: 0 | G34: 0 | H34: =B34/G34 -> #DIV/0!
A36: TOTAL | B36: =SUM(B23:B34) -> 1 | C36: =SUM(C23:C34) -> 1 | D36: =SUM(D23:D34) -> 1 | E36: =SUM(E23:E34) -> 0 | F36: =SUM(F28:F34)/7 -> #DIV/0! | G36: =SUM(G28:G34) -> 0 | H36: =SUM(H23:H34)/7 -> #DIV/0!

Sheet Parcelados
A2: Descrição | B2: Forma de pagamento | C2: Valor | D2: 44592 | E2: 44593 | F2: 44621 | G2: 44652 | H2: 44682 | I2: 44713 | J2: 44743 | K2: 44774 | L2: 44805 | M2: 44835 | N2: 44866 | O2: 44896 | P2: 44927 | Q2: 44958 | R2: 44987 | S2: 44960 | T2: 44961 | U2: 44962 | V2: 44963 | W2: 44964 | X2: 44965 | Y2: 44966 | Z2: 44967 | AA2: 44968 | AB2: 44969 | AC2: 44970 | AD2: 44971 | AE2: 44972 | AF2: 44973 | AG2: 44974 | AH2: 44975
D3: 0 | E3: 0 | F3: 0 | G3: 0 | H3: 0 | I3: 0 | J3: 0 | K3: 0 | L3: 0 | M3: 0 | N3: 0 | O3: 0 | P3: 0 | Q3: 0 | R3: 0 | S3: 0 | T3: 0 | U3: 0 | V3: 0 | W3: 0 | X3: 0 | Y3: 0 | Z3: 0 | AA3: 0 | AB3: 0 | AC3: 0 | AD3: 0 | AE3: 0 | AF3: 0 | AG3: 0 | AH3: 0
D4: 0 | E4: 0 | F4: 0 | G4: 0 | H4: 0 | I4: 0 | J4: 0 | K4: 0 | L4: 0 | M4: 0 | N4: 0 | O4: 0 | P4: 0 | Q4: 0 | R4: 0 | S4: 0 | T4: 0 | U4: 0 | V4: 0 | W4: 0 | X4: 0 | Y4: 0 | Z4: 0 | AA4: 0 | AB4: 0 | AC4: 0 | AD4: 0 | AE4: 0 | AF4: 0 | AG4: 0 | AH4: 0
D5: 0 | E5: 0 | F5: 0 | G5: 0 | H5: 0 | I5: 0 | J5: 0 | K5: 0 | L5: 0 | M5: 0 | N5: 0 | O5: 0 | P5: 0 | Q5: 0 | R5: 0 | S5: 0 | T5: 0 | U5: 0 | V5: 0 | W5: 0 | X5: 0 | Y5: 0 | Z5: 0 | AA5: 0 | AB5: 0 | AC5: 0 | AD5: 0 | AE5: 0 | AF5: 0 | AG5: 0 | AH5: 0
D6: 0 | E6: 0 | F6: 0 | G6: 0 | H6: 0 | I6: 0 | J6: 0 | K6: 0 | L6: 0 | M6: 0 | N6: 0 | O6: 0 | P6: 0 | Q6: 0 | R6: 0 | S6: 0 | T6: 0 | U6: 0 | V6: 0 | W6: 0 | X6: 0 | Y6: 0 | Z6: 0 | AA6: 0 | AB6: 0 | AC6: 0 | AD6: 0 | AE6: 0 | AF6: 0 | AG6: 0 | AH6: 0
D7: 0 | E7: 0 | F7: 0 | G7: 0 | H7: 0 | I7: 0 | J7: 0 | K7: 0 | L7: 0 | M7: 0 | N7: 0 | O7: 0 | P7: 0 | Q7: 0 | R7: 0 | S7: 0 | T7: 0 | U7: 0 | V7: 0 | W7: 0 | X7: 0 | Y7: 0 | Z7: 0 | AA7: 0 | AB7: 0 | AC7: 0 | AD7: 0 | AE7: 0 | AF7: 0 | AG7: 0 | AH7: 0
D8: 0 | E8: 0 | F8: 0 | G8: 0 | H8: 0 | I8: 0 | J8: 0 | K8: 0 | L8: 0 | M8: 0 | N8: 0 | O8: 0 | P8: 0 | Q8: 0 | R8: 0 | S8: 0 | T8: 0 | U8: 0 | V8: 0 | W8: 0 | X8: 0 | Y8: 0 | Z8: 0 | AA8: 0 | AB8: 0 | AC8: 0 | AD8: 0 | AE8: 0 | AF8: 0 | AG8: 0 | AH8: 0
D9: 0 | E9: 0 | F9: 0 | G9: 0 | H9: 0 | I9: 0 | J9: 0 | K9: 0 | L9: 0 | M9: 0 | N9: 0 | O9: 0 | P9: 0 | Q9: 0 | R9: 0 | S9: 0 | T9: 0 | U9: 0 | V9: 0 | W9: 0 | X9: 0 | Y9: 0 | Z9: 0 | AA9: 0 | AB9: 0 | AC9: 0 | AD9: 0 | AE9: 0 | AF9: 0 | AG9: 0 | AH9: 0
D10: 0 | E10: 0 | F10: 0 | G10: 0 | H10: 0 | I10: 0 | J10: 0 | K10: 0 | L10: 0 | M10: 0 | N10: 0 | O10: 0 | P10: 0 | Q10: 0 | R10: 0 | S10: 0 | T10: 0 | U10: 0 | V10: 0 | W10: 0 | X10: 0 | Y10: 0 | Z10: 0 | AA10: 0 | AB10: 0 | AC10: 0 | AD10: 0 | AE10: 0 | AF10: 0 | AG10: 0 | AH10: 0
D11: 0 | E11: 0 | F11: 0 | G11: 0 | H11: 0 | I11: 0 | J11: 0 | K11: 0 | L11: 0 | M11: 0 | N11: 0 | O11: 0 | P11: 0 | Q11: 0 | R11: 0 | S11: 0 | T11: 0 | U11: 0 | V11: 0 | W11: 0 | X11: 0 | Y11: 0 | Z11: 0 | AA11: 0 | AB11: 0 | AC11: 0 | AD11: 0 | AE11: 0 | AF11: 0 | AG11: 0 | AH11: 0
D12: 0 | E12: 0 | F12: 0 | G12: 0 | H12: 0 | I12: 0 | J12: 0 | K12: 0 | L12: 0 | M12: 0 | N12: 0 | O12: 0 | P12: 0 | Q12: 0 | R12: 0 | S12: 0 | T12: 0 | U12: 0 | V12: 0 | W12: 0 | X12: 0 | Y12: 0 | Z12: 0 | AA12: 0 | AB12: 0 | AC12: 0 | AD12: 0 | AE12: 0 | AF12: 0 | AG12: 0 | AH12: 0
D13: 0 | E13: 0 | F13: 0 | G13: 0 | H13: 0 | I13: 0 | J13: 0 | K13: 0 | L13: 0 | M13: 0 | N13: 0 | O13: 0 | P13: 0 | Q13: 0 | R13: 0 | S13: 0 | T13: 0 | U13: 0 | V13: 0 | W13: 0 | X13: 0 | Y13: 0 | Z13: 0 | AA13: 0 | AB13: 0 | AC13: 0 | AD13: 0 | AE13: 0 | AF13: 0 | AG13: 0 | AH13: 0
D14: 0 | E14: 0 | F14: 0 | G14: 0 | H14: 0 | I14: 0 | J14: 0 | K14: 0 | L14: 0 | M14: 0 | N14: 0 | O14: 0 | P14: 0 | Q14: 0 | R14: 0 | S14: 0 | T14: 0 | U14: 0 | V14: 0 | W14: 0 | X14: 0 | Y14: 0 | Z14: 0 | AA14: 0 | AB14: 0 | AC14: 0 | AD14: 0 | AE14: 0 | AF14: 0 | AG14: 0 | AH14: 0
... D37: 0 | E37: 0 | F37: 0 | G37: 0 | H37: 0 | I37: 0 | J37: 0 | K37: 0 | L37: 0 | M37: 0 | N37: 0 | O37: 0 | P37: 0 | Q37: 0 | R37: 0 | S37: 0 | T37: 0 | U37: 0 | V37: 0 | W37: 0 | X37: 0 | Y37: 0 | Z37: 0 | AA37: 0 | AB37: 0 | AC37: 0 | AD37: 0 | AE37: 0 | AF37: 0 | AG37: 0 | AH37: 0
C38: 0 | D38: 0 | E38: 0 | F38: 0 | G38: 0 | H38: 0 | I38: 0 | J38: 0 | K38: 0 | L38: 0 | M38: 0 | N38: 0 | O38: 0 | P38: 0 | Q38: 0 | R38: 0 | S38: 0 | T38: 0 | U38: 0 | V38: 0 | W38: 0 | X38: 0 | Y38: 0 | Z38: 0 | AA38: 0 | AB38: 0 | AC38: 0 | AD38: 0 | AE38: 0 | AF38: 0 | AG38: 0 | AH38: 0
C39: 0 | D39: 0 | E39: 0 | F39: 0 | G39: 0 | H39: 0 | I39: 0 | J39: 0 | K39: 0 | L39: 0 | M39: 0 | N39: 0 | O39: 0 | P39: 0 | Q39: 0 | R39: 0 | S39: 0 | T39: 0 | U39: 0 | V39: 0 | W39: 0 | X39: 0 | Y39: 0 | Z39: 0 | AA39: 0 | AB39: 0 | AC39: 0 | AD39: 0 | AE39: 0 | AF39: 0 | AG39: 0 | AH39: 0
B40: TOTAL | C40: =SUM(C2:C39) -> 0 | D40: =SUM(D3:D39) -> 0 | E40: =SUM(E3:E39) -> 0 | F40: =SUM(F3:F39) -> 0 | G40: =SUM(G3:G39) -> 0 | H40: =SUM(H3:H39) -> 0 | I40: =SUM(I3:I39) -> 0 | J40: =SUM(J3:J39) -> 0 | K40: =SUM(K3:K39) -> 0 | ... AH40: =SUM(AH3:AH39) -> 0
B41: TRANSFERENCIA BANCARIA
D50: Cheque 03 | F50: 25000
D51: Cheque 05 | F51: 53924
D52: Cheque 07 | F52: 61400
D53: Cheque 08 | F53: 69587 | G53: Dia 10 | H53: 356.5
D54: Cheque 10 | F54: 10000
D55: Cheque 11 | F55: 14648 | G55: dia 25 | H55: 356.5
D56: Cheque 15 | F56: 61739
D57: Cheque 17 | F57: 50000
D58: Cheque 19 | F58: 5200
D59: Cheque 20 | F59: 57400
D60: Cheque 22 | F60: 71832
D61: Cheque 25 | F61: 60000
D62: Cheque 26 | F62: 20200
D63: Cheque 27 | F63: 22665
D64: Cheque 29 | F64: 14500
D65: Cheque 31 | F65: 115527
