Workbook

Sheet Início
C3: Com esta planilha você conseguirá fazer uma Análise SWOT Organizacional de acordo com os seus objetivos a curto prazo. Coloque detalhadamente os fatores internos (forças e fraquezas) e fatores externos (oportunidades e ameaças) quanto a gestão de seu negócio/ projeto para extrair as melhores e maiores reflexões possíveis.
B4: IMPORTANTE: LEIA OS PASSOS E ENTENDA A PLANILHA
C6: Passo 1 | E6: FATORES INTERNOS
C7: Segundo a metodologia da análise SWOT a matriz é composta por elementos que compõem o ambiente interno e externo da empresa
C9: Forças: defina a lista com as suas forças, o que faz com que os clientes optem por seu negócio; qual disponibilidade de recursos imprescindíveis para a manutenção dos serviços ou produtos; o que diferencia seu negócio dos demais.
C10: Fraquezas: defina a lista com as suas fraquezas (altos custos com transporte; maiores gastos com a manutenção de equipamentos, colaboradores com valor/hora mais caro etc).
C11: Passo 2 | E11: FATORES EXTERNOS
C12: Após ter definido os fatores internos, defina os seus fatores externos: oportunidades e ameaças.
C14: Oportunidades: defina a lista com as oportunidades (fatores econômicos, oportunidades que estão surgindo e mudanças do mercado que podem favorecer seus clientes).
C15: Ameaças: defina a lista com as ameaças identificadas no mercado (cenário no qual se concentram todos os fatores desfavoráveis para a empresa). Assim, além da ausência de controle sobre as questões, elas se apresentam como grandes ameaças para o negócio.
C20: Passo 3 | E20: MATRIZ SWOT
C22: Nesta parte da planilha será possível visualizar a visão geral da sua pontuação para as forças, fraquezas, oportunidades e ameaças. A partir desta visão, você terá o retorno da planilha sobre o seu momento profissional atual (desenvolvimento, manutenção, crescimento e sobrevivência). Além dos indicadores, veja também a lista com todas as forças, fraquezas, ameaças e oportunidades hierarquizadas, de acordo com sua pontuação.
C25: Passo 4 | E25: CRUZAMENTOS
C26: Uma vez definido seus fatores internos e externos, chegou a hora de cruzar os dados combinando suas forças e fraquezas com ameças e oportunidades. Você pode traçar planos de ação para as combinações.
C37: Passo 5 | E37: OBJETIVOS ESTRATÉGICOS
C39: Objetivo é o resultado desejado pela organização que ao ser atingindo sustenta o seu sucesso ao longo de um período de tempo.
C42: Passo 6 | E42: DESDOBRAMENTOS
C43: Como os objetivos estratégicos se aplicam a realidade da empresa? Onde eles serão atingidos? Nessa etapa entenderemos o papel de cada aspecto da empresa para alcançar esses objetivos e atingir assim os resultados esperados.
C45: Passo 7 | E45: PLANOS DE AÇÃO
C46: Crie planos de ação de acordo com os principais itens da Análise SWOT e dos Cruzamentos feitas para obter grandes melhorias no curto e longo prazos.
C51: Passo 8 | E51: RESULTADOS SWOT
C52: Veja os resultados da SWOT como Índice de Favorabilidade, Análise Individual dos Fatores Internos e Externose gráficos da Matriz SWOT.
C55: Passo 9 | E55: RESULTADOS PLANOS DE AÇÃO
C56: Veja os resultados dos seus planos de ação graficamente.
C58: Gráficos: gráficos de desenvolvimento de planos de ação, status e conformidade dos planos em execução.
C59: Análise por Área: veja a análise geral em relação aos planos de ação com cada status e o desempenho geral delas.
C61: Passo 10 | E61: PAINEL DE CONTROLE
C62: Veja os resultados da SWOT como Índice de Favorabilidade, Análise Individual dos Fatores Internos e Externose gráficos da Matriz SWOT.
C65: Passo 11 | E65: RELATÓRIO DE IMPRESSÃO
C66: Imprima somente o que importa. Esta parte gera um relatório formatado para impressão com seu plano de ação para todas as combinações entre forças, fraquezas, oportunidades e ameaças. Além disso, tenha os gráficos, a lista hierarquizada, o ínidice de favorabilidade e as dicas.

Sheet Forças
C4: Item | D4: Importância | E4: Intensidade | F4: Tendência | G4: Pontuação | S4: 1 | T4: 1 | U4: 1 | V4: 1 | W4: 2 | X4: 2 | Y4: 2 | Z4: 2 | AA4: 2 | AB4: 2 | AC4: 2 | AD4: 2 | AE4: 2 | AF4: 2 | AG4: 2 | AH4: 2 | AI4: 3 | AJ4: 3 | AK4: 3 | AL4: 3 | AM4: 3 | AN4: 3 | AO4: 3 | AP4: 3 | AQ4: 3 | AR4: 3 | AS4: 3 | AT4: 3
C5: Ex.: A marca é reconhecida no mercado | D5: Ex.: Importante | E5: Ex.: Média | F5: Ex.: Mantém | G5: Ex.: 27
C6: dasd | D6: Pouco importante | E6: Média | F6: Melhora muito | G6: =IF(ISERROR(VLOOKUP(D6,$I$7:$J$11,2,FALSE)*VLOOKUP(E6,$I$15:$J$19,2,FALSE)*VLOOKUP(F6,$I$23:$J$27,2,FALSE)),"",VLOOKUP(D6,$I$7:$J$11,2,FALSE)*VLOOKUP(E6,$I$15:$J$19,2,FALSE)*VLOOKUP(F6,$I$23:$J$27,2,FALSE)) -> 30 | H6: Importância | K6: 0.0002 | L6: =IF(G6="","",G6+K6) -> 30.0002 | M6: =IF(C6=0,"",C6) -> dasd | N6: =G6 -> 30
G7: =IF(ISERROR(VLOOKUP(D7,$I$7:$J$11,2,FALSE)*VLOOKUP(E7,$I$15:$J$19,2,FALSE)*VLOOKUP(F7,$I$23:$J$27,2,FALSE)),"",VLOOKUP(D7,$I$7:$J$11,2,FALSE)*VLOOKUP(E7,$I$15:$J$19,2,FALSE)*VLOOKUP(F7,$I$23:$J$27,2,FALSE)) | I7: Sem importância | J7: 1 | L7: 0.00018 | M7: =IF(G7="","",G7+L7) | N7: =IF(C7=0,"",C7) | O7: =G7
G8: =IF(ISERROR(VLOOKUP(D8,$I$7:$J$11,2,FALSE)*VLOOKUP(E8,$I$15:$J$19,2,FALSE)*VLOOKUP(F8,$I$23:$J$27,2,FALSE)),"",VLOOKUP(D8,$I$7:$J$11,2,FALSE)*VLOOKUP(E8,$I$15:$J$19,2,FALSE)*VLOOKUP(F8,$I$23:$J$27,2,FALSE)) | I8: Pouco importante | J8: 2 | L8: 0.00017 | M8: =IF(G8="","",G8+L8) | N8: =IF(C8=0,"",C8) | O8: =G8
G9: =IF(ISERROR(VLOOKUP(D9,$I$7:$J$11,2,FALSE)*VLOOKUP(E9,$I$15:$J$19,2,FALSE)*VLOOKUP(F9,$I$23:$J$27,2,FALSE)),"",VLOOKUP(D9,$I$7:$J$11,2,FALSE)*VLOOKUP(E9,$I$15:$J$19,2,FALSE)*VLOOKUP(F9,$I$23:$J$27,2,FALSE)) | I9: Importante | J9: 3 | L9: 0.00016 | M9: =IF(G9="","",G9+L9) | N9: =IF(C9=0,"",C9) | O9: =G9
G10: =IF(ISERROR(VLOOKUP(D10,$I$7:$J$11,2,FALSE)*VLOOKUP(E10,$I$15:$J$19,2,FALSE)*VLOOKUP(F10,$I$23:$J$27,2,FALSE)),"",VLOOKUP(D10,$I$7:$J$11,2,FALSE)*VLOOKUP(E10,$I$15:$J$19,2,FALSE)*VLOOKUP(F10,$I$23:$J$27,2,FALSE)) | I10: Muito importante | J10: 4 | L10: 0.00015 | M10: =IF(G10="","",G10+L10) | N10: =IF(C10=0,"",C10) | O10: =G10
G11: =IF(ISERROR(VLOOKUP(D11,$I$7:$J$11,2,FALSE)*VLOOKUP(E11,$I$15:$J$19,2,FALSE)*VLOOKUP(F11,$I$23:$J$27,2,FALSE)),"",VLOOKUP(D11,$I$7:$J$11,2,FALSE)*VLOOKUP(E11,$I$15:$J$19,2,FALSE)*VLOOKUP(F11,$I$23:$J$27,2,FALSE)) | I11: Totalmente importante | J11: 5 | L11: 0.00014 | M11: =IF(G11="","",G11+L11) | N11: =IF(C11=0,"",C11) | O11: =G11
G12: =IF(ISERROR(VLOOKUP(D12,$I$7:$J$11,2,FALSE)*VLOOKUP(E12,$I$15:$J$19,2,FALSE)*VLOOKUP(F12,$I$23:$J$27,2,FALSE)),"",VLOOKUP(D12,$I$7:$J$11,2,FALSE)*VLOOKUP(E12,$I$15:$J$19,2,FALSE)*VLOOKUP(F12,$I$23:$J$27,2,FALSE)) | L12: 0.00013 | M12: =IF(G12="","",G12+L12) | N12: =IF(C12=0,"",C12) | O12: =G12
G13: =IF(ISERROR(VLOOKUP(D13,$I$7:$J$11,2,FALSE)*VLOOKUP(E13,$I$15:$J$19,2,FALSE)*VLOOKUP(F13,$I$23:$J$27,2,FALSE)),"",VLOOKUP(D13,$I$7:$J$11,2,FALSE)*VLOOKUP(E13,$I$15:$J$19,2,FALSE)*VLOOKUP(F13,$I$23:$J$27,2,FALSE)) | I13: Intensidade | L13: 0.00012 | M13: =IF(G13="","",G13+L13) | N13: =IF(C13=0,"",C13) | O13: =G13
G14: =IF(ISERROR(VLOOKUP(D14,$I$7:$J$11,2,FALSE)*VLOOKUP(E14,$I$15:$J$19,2,FALSE)*VLOOKUP(F14,$I$23:$J$27,2,FALSE)),"",VLOOKUP(D14,$I$7:$J$11,2,FALSE)*VLOOKUP(E14,$I$15:$J$19,2,FALSE)*VLOOKUP(F14,$I$23:$J$27,2,FALSE)) | L14: 0.00011 | M14: =IF(G14="","",G14+L14) | N14: =IF(C14=0,"",C14) | O14: =G14
G15: =IF(ISERROR(VLOOKUP(D15,$I$7:$J$11,2,FALSE)*VLOOKUP(E15,$I$15:$J$19,2,FALSE)*VLOOKUP(F15,$I$23:$J$27,2,FALSE)),"",VLOOKUP(D15,$I$7:$J$11,2,FALSE)*VLOOKUP(E15,$I$15:$J$19,2,FALSE)*VLOOKUP(F15,$I$23:$J$27,2,FALSE)) | I15: Muito forte | J15: 5 | L15: 0.0001 | M15: =IF(G15="","",G15+L15) | N15: =IF(C15=0,"",C15) | O15: =G15
G16: =IF(ISERROR(VLOOKUP(D16,$I$7:$J$11,2,FALSE)*VLOOKUP(E16,$I$15:$J$19,2,FALSE)*VLOOKUP(F16,$I$23:$J$27,2,FALSE)),"",VLOOKUP(D16,$I$7:$J$11,2,FALSE)*VLOOKUP(E16,$I$15:$J$19,2,FALSE)*VLOOKUP(F16,$I$23:$J$27,2,FALSE)) | I16: Forte | J16: 4 | L16: 9e-05 | M16: =IF(G16="","",G16+L16) | N16: =IF(C16=0,"",C16) | O16: =G16
G17: =IF(ISERROR(VLOOKUP(D17,$I$7:$J$11,2,FALSE)*VLOOKUP(E17,$I$15:$J$19,2,FALSE)*VLOOKUP(F17,$I$23:$J$27,2,FALSE)),"",VLOOKUP(D17,$I$7:$J$11,2,FALSE)*VLOOKUP(E17,$I$15:$J$19,2,FALSE)*VLOOKUP(F17,$I$23:$J$27,2,FALSE)) | I17: Média | J17: 3 | L17: 8e-05 | M17: =IF(G17="","",G17+L17) | N17: =IF(C17=0,"",C17) | O17: =G17
G18: =IF(ISERROR(VLOOKUP(D18,$I$7:$J$11,2,FALSE)*VLOOKUP(E18,$I$15:$J$19,2,FALSE)*VLOOKUP(F18,$I$23:$J$27,2,FALSE)),"",VLOOKUP(D18,$I$7:$J$11,2,FALSE)*VLOOKUP(E18,$I$15:$J$19,2,FALSE)*VLOOKUP(F18,$I$23:$J$27,2,FALSE)) | I18: Fraca | J18: 2 | L18: 7e-05 | M18: =IF(G18="","",G18+L18) | N18: =IF(C18=0,"",C18) | O18: =G18
G19: =IF(ISERROR(VLOOKUP(D19,$I$7:$J$11,2,FALSE)*VLOOKUP(E19,$I$15:$J$19,2,FALSE)*VLOOKUP(F19,$I$23:$J$27,2,FALSE)),"",VLOOKUP(D19,$I$7:$J$11,2,FALSE)*VLOOKUP(E19,$I$15:$J$19,2,FALSE)*VLOOKUP(F19,$I$23:$J$27,2,FALSE)) | I19: Muito fraca | J19: 1 | L19: 6e-05 | M19: =IF(G19="","",G19+L19) | N19: =IF(C19=0,"",C19) | O19: =G19
G20: =IF(ISERROR(VLOOKUP(D20,$I$7:$J$11,2,FALSE)*VLOOKUP(E20,$I$15:$J$19,2,FALSE)*VLOOKUP(F20,$I$23:$J$27,2,FALSE)),"",VLOOKUP(D20,$I$7:$J$11,2,FALSE)*VLOOKUP(E20,$I$15:$J$19,2,FALSE)*VLOOKUP(F20,$I$23:$J$27,2,FALSE)) | L20: 5e-05 | M20: =IF(G20="","",G20+L20) | N20: =IF(C20=0,"",C20) | O20: =G20
G21: =IF(ISERROR(VLOOKUP(D21,$I$7:$J$11,2,FALSE)*VLOOKUP(E21,$I$15:$J$19,2,FALSE)*VLOOKUP(F21,$I$23:$J$27,2,FALSE)),"",VLOOKUP(D21,$I$7:$J$11,2,FALSE)*VLOOKUP(E21,$I$15:$J$19,2,FALSE)*VLOOKUP(F21,$I$23:$J$27,2,FALSE)) | I21: Tendência | L21: 4e-05 | M21: =IF(G21="","",G21+L21) | N21: =IF(C21=0,"",C21) | O21: =G21
G22: =IF(ISERROR(VLOOKUP(D22,$I$7:$J$11,2,FALSE)*VLOOKUP(E22,$I$15:$J$19,2,FALSE)*VLOOKUP(F22,$I$23:$J$27,2,FALSE)),"",VLOOKUP(D22,$I$7:$J$11,2,FALSE)*VLOOKUP(E22,$I$15:$J$19,2,FALSE)*VLOOKUP(F22,$I$23:$J$27,2,FALSE)) | L22: 3e-05 | M22: =IF(G22="","",G22+L22) | N22: =IF(C22=0,"",C22) | O22: =G22
G23: =IF(ISERROR(VLOOKUP(D23,$I$7:$J$11,2,FALSE)*VLOOKUP(E23,$I$15:$J$19,2,FALSE)*VLOOKUP(F23,$I$23:$J$27,2,FALSE)),"",VLOOKUP(D23,$I$7:$J$11,2,FALSE)*VLOOKUP(E23,$I$15:$J$19,2,FALSE)*VLOOKUP(F23,$I$23:$J$27,2,FALSE)) | I23: Melhora muito | J23: 5 | L23: 2e-05 | M23: =IF(G23="","",G23+L23) | N23: =IF(C23=0,"",C23) | O23: =G23
G24: =IF(ISERROR(VLOOKUP(D24,$I$7:$J$11,2,FALSE)*VLOOKUP(E24,$I$15:$J$19,2,FALSE)*VLOOKUP(F24,$I$23:$J$27,2,FALSE)),"",VLOOKUP(D24,$I$7:$J$11,2,FALSE)*VLOOKUP(E24,$I$15:$J$19,2,FALSE)*VLOOKUP(F24,$I$23:$J$27,2,FALSE)) | I24: Melhora | J24: 4 | L24: 1e-05 | M24: =IF(G24="","",G24+L24) | N24: =IF(C24=0,"",C24) | O24: =G24
C25: Pontuação geral das suas Forças | F25: → | G25: =SUM(G6:G24) -> 30 | I25: Mantém | J25: 3
I26: Piora | J26: 2
I27: Piora muito | J27: 1

Sheet Fraquezas
C4: Item | D4: Importância | E4: Intensidade | F4: Tendência | G4: Pontuação | S4: 1 | T4: 1 | U4: 1 | V4: 1 | W4: 2 | X4: 2 | Y4: 2 | Z4: 2 | AA4: 2 | AB4: 2 | AC4: 2 | AD4: 2 | AE4: 2 | AF4: 2 | AG4: 2 | AH4: 2 | AI4: 3 | AJ4: 3 | AK4: 3 | AL4: 3 | AM4: 3 | AN4: 3 | AO4: 3 | AP4: 3 | AQ4: 3 | AR4: 3 | AS4: 3 | AT4: 3
C5: Ex.: A marca é reconhecida no mercado | D5: Ex.: Importante | E5: Ex.: Média | F5: Ex.: Mantém | G5: Ex.: 27
G6: =IF(ISERROR(VLOOKUP(D6,$I$7:$J$11,2,FALSE)*VLOOKUP(E6,$I$15:$J$19,2,FALSE)*VLOOKUP(F6,$I$23:$J$27,2,FALSE)),"",VLOOKUP(D6,$I$7:$J$11,2,FALSE)*VLOOKUP(E6,$I$15:$J$19,2,FALSE)*VLOOKUP(F6,$I$23:$J$27,2,FALSE)) | L6: 0.00019 | M6: =IF(G6="","",G6+L6) | N6: =IF(C6=0,"",C6) | O6: =G6
G7: =IF(ISERROR(VLOOKUP(D7,$I$7:$J$11,2,FALSE)*VLOOKUP(E7,$I$15:$J$19,2,FALSE)*VLOOKUP(F7,$I$23:$J$27,2,FALSE)),"",VLOOKUP(D7,$I$7:$J$11,2,FALSE)*VLOOKUP(E7,$I$15:$J$19,2,FALSE)*VLOOKUP(F7,$I$23:$J$27,2,FALSE)) | I7: Sem importância | J7: 1 | L7: 0.00018 | M7: =IF(G7="","",G7+L7) | N7: =IF(C10=0,"",C10) | O7: =G7
G8: =IF(ISERROR(VLOOKUP(D8,$I$7:$J$11,2,FALSE)*VLOOKUP(E8,$I$15:$J$19,2,FALSE)*VLOOKUP(F8,$I$23:$J$27,2,FALSE)),"",VLOOKUP(D8,$I$7:$J$11,2,FALSE)*VLOOKUP(E8,$I$15:$J$19,2,FALSE)*VLOOKUP(F8,$I$23:$J$27,2,FALSE)) | I8: Pouco importante | J8: 2 | L8: 0.00017 | M8: =IF(G8="","",G8+L8) | N8: =IF(C11=0,"",C11) | O8: =G8
G9: =IF(ISERROR(VLOOKUP(D9,$I$7:$J$11,2,FALSE)*VLOOKUP(E9,$I$15:$J$19,2,FALSE)*VLOOKUP(F9,$I$23:$J$27,2,FALSE)),"",VLOOKUP(D9,$I$7:$J$11,2,FALSE)*VLOOKUP(E9,$I$15:$J$19,2,FALSE)*VLOOKUP(F9,$I$23:$J$27,2,FALSE)) | I9: Importante | J9: 3 | L9: 0.00016 | M9: =IF(G9="","",G9+L9) | N9: =IF(C12=0,"",C12) | O9: =G9
G10: =IF(ISERROR(VLOOKUP(D10,$I$7:$J$11,2,FALSE)*VLOOKUP(E10,$I$15:$J$19,2,FALSE)*VLOOKUP(F10,$I$23:$J$27,2,FALSE)),"",VLOOKUP(D10,$I$7:$J$11,2,FALSE)*VLOOKUP(E10,$I$15:$J$19,2,FALSE)*VLOOKUP(F10,$I$23:$J$27,2,FALSE)) | I10: Muito importante | J10: 4 | L10: 0.00015 | M10: =IF(G10="","",G10+L10) | N10: =IF(C13=0,"",C13) | O10: =G10
G11: =IF(ISERROR(VLOOKUP(D11,$I$7:$J$11,2,FALSE)*VLOOKUP(E11,$I$15:$J$19,2,FALSE)*VLOOKUP(F11,$I$23:$J$27,2,FALSE)),"",VLOOKUP(D11,$I$7:$J$11,2,FALSE)*VLOOKUP(E11,$I$15:$J$19,2,FALSE)*VLOOKUP(F11,$I$23:$J$27,2,FALSE)) | I11: Totalmente importante | J11: 5 | L11: 0.00014 | M11: =IF(G11="","",G11+L11) | N11: =IF(C14=0,"",C14) | O11: =G11
G12: =IF(ISERROR(VLOOKUP(D12,$I$7:$J$11,2,FALSE)*VLOOKUP(E12,$I$15:$J$19,2,FALSE)*VLOOKUP(F12,$I$23:$J$27,2,FALSE)),"",VLOOKUP(D12,$I$7:$J$11,2,FALSE)*VLOOKUP(E12,$I$15:$J$19,2,FALSE)*VLOOKUP(F12,$I$23:$J$27,2,FALSE)) | L12: 0.00013 | M12: =IF(G12="","",G12+L12) | N12: =IF(C15=0,"",C15) | O12: =G12
G13: =IF(ISERROR(VLOOKUP(D13,$I$7:$J$11,2,FALSE)*VLOOKUP(E13,$I$15:$J$19,2,FALSE)*VLOOKUP(F13,$I$23:$J$27,2,FALSE)),"",VLOOKUP(D13,$I$7:$J$11,2,FALSE)*VLOOKUP(E13,$I$15:$J$19,2,FALSE)*VLOOKUP(F13,$I$23:$J$27,2,FALSE)) | I13: Intensidade | L13: 0.00012 | M13: =IF(G13="","",G13+L13) | N13: =IF(C16=0,"",C16) | O13: =G13
G14: =IF(ISERROR(VLOOKUP(D14,$I$7:$J$11,2,FALSE)*VLOOKUP(E14,$I$15:$J$19,2,FALSE)*VLOOKUP(F14,$I$23:$J$27,2,FALSE)),"",VLOOKUP(D14,$I$7:$J$11,2,FALSE)*VLOOKUP(E14,$I$15:$J$19,2,FALSE)*VLOOKUP(F14,$I$23:$J$27,2,FALSE)) | L14: 0.00011 | M14: =IF(G14="","",G14+L14) | N14: =IF(C17=0,"",C17) | O14: =G14
G15: =IF(ISERROR(VLOOKUP(D15,$I$7:$J$11,2,FALSE)*VLOOKUP(E15,$I$15:$J$19,2,FALSE)*VLOOKUP(F15,$I$23:$J$27,2,FALSE)),"",VLOOKUP(D15,$I$7:$J$11,2,FALSE)*VLOOKUP(E15,$I$15:$J$19,2,FALSE)*VLOOKUP(F15,$I$23:$J$27,2,FALSE)) | I15: Muito forte | J15: 1 | L15: 0.0001 | M15: =IF(G15="","",G15+L15) | N15: =IF(C18=0,"",C18) | O15: =G15
G16: =IF(ISERROR(VLOOKUP(D16,$I$7:$J$11,2,FALSE)*VLOOKUP(E16,$I$15:$J$19,2,FALSE)*VLOOKUP(F16,$I$23:$J$27,2,FALSE)),"",VLOOKUP(D16,$I$7:$J$11,2,FALSE)*VLOOKUP(E16,$I$15:$J$19,2,FALSE)*VLOOKUP(F16,$I$23:$J$27,2,FALSE)) | I16: Forte | J16: 2 | L16: 9e-05 | M16: =IF(G16="","",G16+L16) | N16: =IF(C19=0,"",C19) | O16: =G16
G17: =IF(ISERROR(VLOOKUP(D17,$I$7:$J$11,2,FALSE)*VLOOKUP(E17,$I$15:$J$19,2,FALSE)*VLOOKUP(F17,$I$23:$J$27,2,FALSE)),"",VLOOKUP(D17,$I$7:$J$11,2,FALSE)*VLOOKUP(E17,$I$15:$J$19,2,FALSE)*VLOOKUP(F17,$I$23:$J$27,2,FALSE)) | I17: Média | J17: 3 | L17: 8e-05 | M17: =IF(G17="","",G17+L17) | N17: =IF(C20=0,"",C20) | O17: =G17
G18: =IF(ISERROR(VLOOKUP(D18,$I$7:$J$11,2,FALSE)*VLOOKUP(E18,$I$15:$J$19,2,FALSE)*VLOOKUP(F18,$I$23:$J$27,2,FALSE)),"",VLOOKUP(D18,$I$7:$J$11,2,FALSE)*VLOOKUP(E18,$I$15:$J$19,2,FALSE)*VLOOKUP(F18,$I$23:$J$27,2,FALSE)) | I18: Fraca | J18: 4 | L18: 7e-05 | M18: =IF(G18="","",G18+L18) | N18: =IF(C21=0,"",C21) | O18: =G18
G19: =IF(ISERROR(VLOOKUP(D19,$I$7:$J$11,2,FALSE)*VLOOKUP(E19,$I$15:$J$19,2,FALSE)*VLOOKUP(F19,$I$23:$J$27,2,FALSE)),"",VLOOKUP(D19,$I$7:$J$11,2,FALSE)*VLOOKUP(E19,$I$15:$J$19,2,FALSE)*VLOOKUP(F19,$I$23:$J$27,2,FALSE)) | I19: Muito fraca | J19: 5 | L19: 6e-05 | M19: =IF(G19="","",G19+L19) | N19: =IF(C22=0,"",C22) | O19: =G19
G20: =IF(ISERROR(VLOOKUP(D20,$I$7:$J$11,2,FALSE)*VLOOKUP(E20,$I$15:$J$19,2,FALSE)*VLOOKUP(F20,$I$23:$J$27,2,FALSE)),"",VLOOKUP(D20,$I$7:$J$11,2,FALSE)*VLOOKUP(E20,$I$15:$J$19,2,FALSE)*VLOOKUP(F20,$I$23:$J$27,2,FALSE)) | L20: 5e-05 | M20: =IF(G20="","",G20+L20) | N20: =IF(#REF!=0,"",#REF!) -> #REF! | O20: =G20
G21: =IF(ISERROR(VLOOKUP(D21,$I$7:$J$11,2,FALSE)*VLOOKUP(E21,$I$15:$J$19,2,FALSE)*VLOOKUP(F21,$I$23:$J$27,2,FALSE)),"",VLOOKUP(D21,$I$7:$J$11,2,FALSE)*VLOOKUP(E21,$I$15:$J$19,2,FALSE)*VLOOKUP(F21,$I$23:$J$27,2,FALSE)) | I21: Tendência | L21: 4e-05 | M21: =IF(G21="","",G21+L21) | N21: =IF(#REF!=0,"",#REF!) -> #REF! | O21: =G21
G22: =IF(ISERROR(VLOOKUP(D22,$I$7:$J$11,2,FALSE)*VLOOKUP(E22,$I$15:$J$19,2,FALSE)*VLOOKUP(F22,$I$23:$J$27,2,FALSE)),"",VLOOKUP(D22,$I$7:$J$11,2,FALSE)*VLOOKUP(E22,$I$15:$J$19,2,FALSE)*VLOOKUP(F22,$I$23:$J$27,2,FALSE)) | L22: 3e-05 | M22: =IF(G22="","",G22+L22) | N22: =IF(#REF!=0,"",#REF!) -> #REF! | O22: =G22
G23: =IF(ISERROR(VLOOKUP(D23,$I$7:$J$11,2,FALSE)*VLOOKUP(E23,$I$15:$J$19,2,FALSE)*VLOOKUP(F23,$I$23:$J$27,2,FALSE)),"",VLOOKUP(D23,$I$7:$J$11,2,FALSE)*VLOOKUP(E23,$I$15:$J$19,2,FALSE)*VLOOKUP(F23,$I$23:$J$27,2,FALSE)) | I23: Melhora muito | J23: 1 | L23: 2e-05 | M23: =IF(G23="","",G23+L23) | N23: =IF(C23=0,"",C23) | O23: =G23
G24: =IF(ISERROR(VLOOKUP(D24,$I$7:$J$11,2,FALSE)*VLOOKUP(E24,$I$15:$J$19,2,FALSE)*VLOOKUP(F24,$I$23:$J$27,2,FALSE)),"",VLOOKUP(D24,$I$7:$J$11,2,FALSE)*VLOOKUP(E24,$I$15:$J$19,2,FALSE)*VLOOKUP(F24,$I$23:$J$27,2,FALSE)) | I24: Melhora | J24: 2 | L24: 1e-05 | M24: =IF(G24="","",G24+L24) | N24: =IF(C24=0,"",C24) | O24: =G24
C25: Pontuação geral das suas Fraquezas | F25: → | G25: =SUM(G6:G24) -> 0 | I25: Mantém | J25: 3
I26: Piora | J26: 4
I27: Piora muito | J27: 5

Sheet Oportunidades
C4: Item | D4: Importância | E4: Urgência | F4: Tendência | G4: Pontuação | S4: 1 | T4: 1 | U4: 1 | V4: 1 | W4: 2 | X4: 2 | Y4: 2 | Z4: 2 | AA4: 2 | AB4: 2 | AC4: 2 | AD4: 2 | AE4: 2 | AF4: 2 | AG4: 2 | AH4: 2 | AI4: 3 | AJ4: 3 | AK4: 3 | AL4: 3 | AM4: 3 | AN4: 3 | AO4: 3 | AP4: 3 | AQ4: 3 | AR4: 3 | AS4: 3 | AT4: 3
C5: Ex.: Existem mercados inexplorados | D5: Ex.: Importante | E5: Ex.: Urgente | F5: Ex.: Mantém | G5: Ex.: 27
G6: =IF(ISERROR(VLOOKUP(D6,$I$8:$J$12,2,FALSE)*VLOOKUP(E6,$I$16:$J$20,2,FALSE)*VLOOKUP(F6,$I$24:$J$28,2,FALSE)),"",VLOOKUP(D6,$I$8:$J$12,2,FALSE)*VLOOKUP(E6,$I$16:$J$20,2,FALSE)*VLOOKUP(F6,$I$24:$J$28,2,FALSE)) | I6: Importância | L6: 0.0002 | M6: =IF(G6="","",G6+L7) | N6: =IF(C6=0,"",C6) | O6: =G6
G7: =IF(ISERROR(VLOOKUP(D7,$I$8:$J$12,2,FALSE)*VLOOKUP(E7,$I$16:$J$20,2,FALSE)*VLOOKUP(F7,$I$24:$J$28,2,FALSE)),"",VLOOKUP(D7,$I$8:$J$12,2,FALSE)*VLOOKUP(E7,$I$16:$J$20,2,FALSE)*VLOOKUP(F7,$I$24:$J$28,2,FALSE)) | L7: 0.00019 | M7: =IF(G7="","",G7+L8) | N7: =IF(C7=0,"",C7) | O7: =G7
G8: =IF(ISERROR(VLOOKUP(D8,$I$8:$J$12,2,FALSE)*VLOOKUP(E8,$I$16:$J$20,2,FALSE)*VLOOKUP(F8,$I$24:$J$28,2,FALSE)),"",VLOOKUP(D8,$I$8:$J$12,2,FALSE)*VLOOKUP(E8,$I$16:$J$20,2,FALSE)*VLOOKUP(F8,$I$24:$J$28,2,FALSE)) | I8: Sem importância | J8: 1 | L8: 0.00018 | M8: =IF(G8="","",G8+L9) | N8: =IF(C8=0,"",C8) | O8: =G8
G9: =IF(ISERROR(VLOOKUP(D9,$I$8:$J$12,2,FALSE)*VLOOKUP(E9,$I$16:$J$20,2,FALSE)*VLOOKUP(F9,$I$24:$J$28,2,FALSE)),"",VLOOKUP(D9,$I$8:$J$12,2,FALSE)*VLOOKUP(E9,$I$16:$J$20,2,FALSE)*VLOOKUP(F9,$I$24:$J$28,2,FALSE)) | I9: Pouco importante | J9: 2 | L9: 0.00017 | M9: =IF(G9="","",G9+L10) | N9: =IF(C9=0,"",C9) | O9: =G9
G10: =IF(ISERROR(VLOOKUP(D10,$I$8:$J$12,2,FALSE)*VLOOKUP(E10,$I$16:$J$20,2,FALSE)*VLOOKUP(F10,$I$24:$J$28,2,FALSE)),"",VLOOKUP(D10,$I$8:$J$12,2,FALSE)*VLOOKUP(E10,$I$16:$J$20,2,FALSE)*VLOOKUP(F10,$I$24:$J$28,2,FALSE)) | I10: Importante | J10: 3 | L10: 0.00016 | M10: =IF(G10="","",G10+L11) | N10: =IF(C10=0,"",C10) | O10: =G10
G11: =IF(ISERROR(VLOOKUP(D11,$I$8:$J$12,2,FALSE)*VLOOKUP(E11,$I$16:$J$20,2,FALSE)*VLOOKUP(F11,$I$24:$J$28,2,FALSE)),"",VLOOKUP(D11,$I$8:$J$12,2,FALSE)*VLOOKUP(E11,$I$16:$J$20,2,FALSE)*VLOOKUP(F11,$I$24:$J$28,2,FALSE)) | I11: Muito importante | J11: 4 | L11: 0.00015 | M11: =IF(G11="","",G11+L12) | N11: =IF(C11=0,"",C11) | O11: =G11
G12: =IF(ISERROR(VLOOKUP(D12,$I$8:$J$12,2,FALSE)*VLOOKUP(E12,$I$16:$J$20,2,FALSE)*VLOOKUP(F12,$I$24:$J$28,2,FALSE)),"",VLOOKUP(D12,$I$8:$J$12,2,FALSE)*VLOOKUP(E12,$I$16:$J$20,2,FALSE)*VLOOKUP(F12,$I$24:$J$28,2,FALSE)) | I12: Totalmente importante | J12: 5 | L12: 0.00014 | M12: =IF(G12="","",G12+L13) | N12: =IF(C12=0,"",C12) | O12: =G12
G13: =IF(ISERROR(VLOOKUP(D13,$I$8:$J$12,2,FALSE)*VLOOKUP(E13,$I$16:$J$20,2,FALSE)*VLOOKUP(F13,$I$24:$J$28,2,FALSE)),"",VLOOKUP(D13,$I$8:$J$12,2,FALSE)*VLOOKUP(E13,$I$16:$J$20,2,FALSE)*VLOOKUP(F13,$I$24:$J$28,2,FALSE)) | L13: 0.00013 | M13: =IF(G13="","",G13+L14) | N13: =IF(C13=0,"",C13) | O13: =G13
G14: =IF(ISERROR(VLOOKUP(D14,$I$8:$J$12,2,FALSE)*VLOOKUP(E14,$I$16:$J$20,2,FALSE)*VLOOKUP(F14,$I$24:$J$28,2,FALSE)),"",VLOOKUP(D14,$I$8:$J$12,2,FALSE)*VLOOKUP(E14,$I$16:$J$20,2,FALSE)*VLOOKUP(F14,$I$24:$J$28,2,FALSE)) | I14: Urgência | L14: 0.00012 | M14: =IF(G14="","",G14+L15) | N14: =IF(C14=0,"",C14) | O14: =G14
G15: =IF(ISERROR(VLOOKUP(D15,$I$8:$J$12,2,FALSE)*VLOOKUP(E15,$I$16:$J$20,2,FALSE)*VLOOKUP(F15,$I$24:$J$28,2,FALSE)),"",VLOOKUP(D15,$I$8:$J$12,2,FALSE)*VLOOKUP(E15,$I$16:$J$20,2,FALSE)*VLOOKUP(F15,$I$24:$J$28,2,FALSE)) | L15: 0.00011 | M15: =IF(G15="","",G15+L16) | N15: =IF(C15=0,"",C15) | O15: =G15
G16: =IF(ISERROR(VLOOKUP(D16,$I$8:$J$12,2,FALSE)*VLOOKUP(E16,$I$16:$J$20,2,FALSE)*VLOOKUP(F16,$I$24:$J$28,2,FALSE)),"",VLOOKUP(D16,$I$8:$J$12,2,FALSE)*VLOOKUP(E16,$I$16:$J$20,2,FALSE)*VLOOKUP(F16,$I$24:$J$28,2,FALSE)) | I16: Nada urgente | J16: 1 | L16: 0.0001 | M16: =IF(G16="","",G16+L17) | N16: =IF(C16=0,"",C16) | O16: =G16
G17: =IF(ISERROR(VLOOKUP(D17,$I$8:$J$12,2,FALSE)*VLOOKUP(E17,$I$16:$J$20,2,FALSE)*VLOOKUP(F17,$I$24:$J$28,2,FALSE)),"",VLOOKUP(D17,$I$8:$J$12,2,FALSE)*VLOOKUP(E17,$I$16:$J$20,2,FALSE)*VLOOKUP(F17,$I$24:$J$28,2,FALSE)) | I17: Pouco urgente | J17: 2 | L17: 9e-05 | M17: =IF(G17="","",G17+L18) | N17: =IF(C17=0,"",C17) | O17: =G17
G18: =IF(ISERROR(VLOOKUP(D18,$I$8:$J$12,2,FALSE)*VLOOKUP(E18,$I$16:$J$20,2,FALSE)*VLOOKUP(F18,$I$24:$J$28,2,FALSE)),"",VLOOKUP(D18,$I$8:$J$12,2,FALSE)*VLOOKUP(E18,$I$16:$J$20,2,FALSE)*VLOOKUP(F18,$I$24:$J$28,2,FALSE)) | I18: Urgente | J18: 3 | L18: 8e-05 | M18: =IF(G18="","",G18+L19) | N18: =IF(C18=0,"",C18) | O18: =G18
G19: =IF(ISERROR(VLOOKUP(D19,$I$8:$J$12,2,FALSE)*VLOOKUP(E19,$I$16:$J$20,2,FALSE)*VLOOKUP(F19,$I$24:$J$28,2,FALSE)),"",VLOOKUP(D19,$I$8:$J$12,2,FALSE)*VLOOKUP(E19,$I$16:$J$20,2,FALSE)*VLOOKUP(F19,$I$24:$J$28,2,FALSE)) | I19: Muito urgente | J19: 4 | L19: 7e-05 | M19: =IF(G19="","",G19+L20) | N19: =IF(C19=0,"",C19) | O19: =G19
G20: =IF(ISERROR(VLOOKUP(D20,$I$8:$J$12,2,FALSE)*VLOOKUP(E20,$I$16:$J$20,2,FALSE)*VLOOKUP(F20,$I$24:$J$28,2,FALSE)),"",VLOOKUP(D20,$I$8:$J$12,2,FALSE)*VLOOKUP(E20,$I$16:$J$20,2,FALSE)*VLOOKUP(F20,$I$24:$J$28,2,FALSE)) | I20: Pra ontem | J20: 5 | L20: 6e-05 | M20: =IF(G20="","",G20+L21) | N20: =IF(C20=0,"",C20) | O20: =G20
G21: =IF(ISERROR(VLOOKUP(D21,$I$8:$J$12,2,FALSE)*VLOOKUP(E21,$I$16:$J$20,2,FALSE)*VLOOKUP(F21,$I$24:$J$28,2,FALSE)),"",VLOOKUP(D21,$I$8:$J$12,2,FALSE)*VLOOKUP(E21,$I$16:$J$20,2,FALSE)*VLOOKUP(F21,$I$24:$J$28,2,FALSE)) | L21: 5e-05 | M21: =IF(G21="","",G21+L22) | N21: =IF(C21=0,"",C21) | O21: =G21
G22: =IF(ISERROR(VLOOKUP(D22,$I$8:$J$12,2,FALSE)*VLOOKUP(E22,$I$16:$J$20,2,FALSE)*VLOOKUP(F22,$I$24:$J$28,2,FALSE)),"",VLOOKUP(D22,$I$8:$J$12,2,FALSE)*VLOOKUP(E22,$I$16:$J$20,2,FALSE)*VLOOKUP(F22,$I$24:$J$28,2,FALSE)) | I22: Tendência | L22: 4e-05 | M22: =IF(G22="","",G22+L23) | N22: =IF(C22=0,"",C22) | O22: =G22
G23: =IF(ISERROR(VLOOKUP(D23,$I$8:$J$12,2,FALSE)*VLOOKUP(E23,$I$16:$J$20,2,FALSE)*VLOOKUP(F23,$I$24:$J$28,2,FALSE)),"",VLOOKUP(D23,$I$8:$J$12,2,FALSE)*VLOOKUP(E23,$I$16:$J$20,2,FALSE)*VLOOKUP(F23,$I$24:$J$28,2,FALSE)) | L23: 3e-05 | M23: =IF(G23="","",G23+L24) | N23: =IF(C23=0,"",C23) | O23: =G23
G24: =IF(ISERROR(VLOOKUP(D24,$I$8:$J$12,2,FALSE)*VLOOKUP(E24,$I$16:$J$20,2,FALSE)*VLOOKUP(F24,$I$24:$J$28,2,FALSE)),"",VLOOKUP(D24,$I$8:$J$12,2,FALSE)*VLOOKUP(E24,$I$16:$J$20,2,FALSE)*VLOOKUP(F24,$I$24:$J$28,2,FALSE)) | I24: Melhora muito | J24: 5 | L24: 2e-05 | M24: =IF(G24="","",G24+L25) | N24: =IF(C24=0,"",C24) | O24: =G24
G25: =IF(ISERROR(VLOOKUP(D25,$I$8:$J$12,2,FALSE)*VLOOKUP(E25,$I$16:$J$20,2,FALSE)*VLOOKUP(F25,$I$24:$J$28,2,FALSE)),"",VLOOKUP(D25,$I$8:$J$12,2,FALSE)*VLOOKUP(E25,$I$16:$J$20,2,FALSE)*VLOOKUP(F25,$I$24:$J$28,2,FALSE)) | I25: Melhora | J25: 4 | L25: 1e-05 | M25: =IF(G25="","",G25+L26) | N25: =IF(C25=0,"",C25) | O25: =G25
C26: Pontuação geral das suas Oportunidades | F26: → | G26: =SUM(G6:G25) -> 0 | I26: Mantém | J26: 3
I27: Piora | J27: 2
I28: Piora muito | J28: 1

Sheet Ameaças
C4: Item | D4: Importância | E4: Urgência | F4: Tendência | G4: Pontuação | S4: 1 | T4: 1 | U4: 1 | V4: 1 | W4: 2 | X4: 2 | Y4: 2 | Z4: 2 | AA4: 2 | AB4: 2 | AC4: 2 | AD4: 2 | AE4: 2 | AF4: 2 | AG4: 2 | AH4: 2 | AI4: 3 | AJ4: 3 | AK4: 3 | AL4: 3 | AM4: 3 | AN4: 3 | AO4: 3 | AP4: 3 | AQ4: 3 | AR4: 3 | AS4: 3 | AT4: 3
C5: Ex.: Existem mercados inexplorados | D5: Ex.: Importante | E5: Ex.: Urgente | F5: Ex.: Mantém | G5: Ex.: 27
G6: =IF(ISERROR(VLOOKUP(D6,$I$8:$J$12,2,FALSE)*VLOOKUP(E6,$I$16:$J$20,2,FALSE)*VLOOKUP(F6,$I$24:$J$28,2,FALSE)),"",VLOOKUP(D6,$I$8:$J$12,2,FALSE)*VLOOKUP(E6,$I$16:$J$20,2,FALSE)*VLOOKUP(F6,$I$24:$J$28,2,FALSE)) | I6: Importância | L6: 0.0002 | M6: =IF(G6="","",G6+L7) | N6: =IF(C6=0,"",C6) | O6: =G6
G7: =IF(ISERROR(VLOOKUP(D7,$I$8:$J$12,2,FALSE)*VLOOKUP(E7,$I$16:$J$20,2,FALSE)*VLOOKUP(F7,$I$24:$J$28,2,FALSE)),"",VLOOKUP(D7,$I$8:$J$12,2,FALSE)*VLOOKUP(E7,$I$16:$J$20,2,FALSE)*VLOOKUP(F7,$I$24:$J$28,2,FALSE)) | L7: 0.00019 | M7: =IF(G7="","",G7+L8) | N7: =IF(C7=0,"",C7) | O7: =G7
G8: =IF(ISERROR(VLOOKUP(D8,$I$8:$J$12,2,FALSE)*VLOOKUP(E8,$I$16:$J$20,2,FALSE)*VLOOKUP(F8,$I$24:$J$28,2,FALSE)),"",VLOOKUP(D8,$I$8:$J$12,2,FALSE)*VLOOKUP(E8,$I$16:$J$20,2,FALSE)*VLOOKUP(F8,$I$24:$J$28,2,FALSE)) | I8: Sem importância | J8: 1 | L8: 0.00018 | M8: =IF(G8="","",G8+L9) | N8: =IF(C8=0,"",C8) | O8: =G8
G9: =IF(ISERROR(VLOOKUP(D9,$I$8:$J$12,2,FALSE)*VLOOKUP(E9,$I$16:$J$20,2,FALSE)*VLOOKUP(F9,$I$24:$J$28,2,FALSE)),"",VLOOKUP(D9,$I$8:$J$12,2,FALSE)*VLOOKUP(E9,$I$16:$J$20,2,FALSE)*VLOOKUP(F9,$I$24:$J$28,2,FALSE)) | I9: Pouco importante | J9: 2 | L9: 0.00017 | M9: =IF(G9="","",G9+L10) | N9: =IF(C9=0,"",C9) | O9: =G9
G10: =IF(ISERROR(VLOOKUP(D10,$I$8:$J$12,2,FALSE)*VLOOKUP(E10,$I$16:$J$20,2,FALSE)*VLOOKUP(F10,$I$24:$J$28,2,FALSE)),"",VLOOKUP(D10,$I$8:$J$12,2,FALSE)*VLOOKUP(E10,$I$16:$J$20,2,FALSE)*VLOOKUP(F10,$I$24:$J$28,2,FALSE)) | I10: Importante | J10: 3 | L10: 0.00016 | M10: =IF(G10="","",G10+L11) | N10: =IF(C10=0,"",C10) | O10: =G10
G11: =IF(ISERROR(VLOOKUP(D11,$I$8:$J$12,2,FALSE)*VLOOKUP(E11,$I$16:$J$20,2,FALSE)*VLOOKUP(F11,$I$24:$J$28,2,FALSE)),"",VLOOKUP(D11,$I$8:$J$12,2,FALSE)*VLOOKUP(E11,$I$16:$J$20,2,FALSE)*VLOOKUP(F11,$I$24:$J$28,2,FALSE)) | I11: Muito importante | J11: 4 | L11: 0.00015 | M11: =IF(G11="","",G11+L12) | N11: =IF(C11=0,"",C11) | O11: =G11
G12: =IF(ISERROR(VLOOKUP(D12,$I$8:$J$12,2,FALSE)*VLOOKUP(E12,$I$16:$J$20,2,FALSE)*VLOOKUP(F12,$I$24:$J$28,2,FALSE)),"",VLOOKUP(D12,$I$8:$J$12,2,FALSE)*VLOOKUP(E12,$I$16:$J$20,2,FALSE)*VLOOKUP(F12,$I$24:$J$28,2,FALSE)) | I12: Totalmente importante | J12: 5 | L12: 0.00014 | M12: =IF(G12="","",G12+L13) | N12: =IF(C12=0,"",C12) | O12: =G12
G13: =IF(ISERROR(VLOOKUP(D13,$I$8:$J$12,2,FALSE)*VLOOKUP(E13,$I$16:$J$20,2,FALSE)*VLOOKUP(F13,$I$24:$J$28,2,FALSE)),"",VLOOKUP(D13,$I$8:$J$12,2,FALSE)*VLOOKUP(E13,$I$16:$J$20,2,FALSE)*VLOOKUP(F13,$I$24:$J$28,2,FALSE)) | L13: 0.00013 | M13: =IF(G13="","",G13+L14) | N13: =IF(C13=0,"",C13) | O13: =G13
G14: =IF(ISERROR(VLOOKUP(D14,$I$8:$J$12,2,FALSE)*VLOOKUP(E14,$I$16:$J$20,2,FALSE)*VLOOKUP(F14,$I$24:$J$28,2,FALSE)),"",VLOOKUP(D14,$I$8:$J$12,2,FALSE)*VLOOKUP(E14,$I$16:$J$20,2,FALSE)*VLOOKUP(F14,$I$24:$J$28,2,FALSE)) | I14: Urgência | L14: 0.00012 | M14: =IF(G14="","",G14+L15) | N14: =IF(C14=0,"",C14) | O14: =G14
G15: =IF(ISERROR(VLOOKUP(D15,$I$8:$J$12,2,FALSE)*VLOOKUP(E15,$I$16:$J$20,2,FALSE)*VLOOKUP(F15,$I$24:$J$28,2,FALSE)),"",VLOOKUP(D15,$I$8:$J$12,2,FALSE)*VLOOKUP(E15,$I$16:$J$20,2,FALSE)*VLOOKUP(F15,$I$24:$J$28,2,FALSE)) | L15: 0.00011 | M15: =IF(G15="","",G15+L16) | N15: =IF(C15=0,"",C15) | O15: =G15
G16: =IF(ISERROR(VLOOKUP(D16,$I$8:$J$12,2,FALSE)*VLOOKUP(E16,$I$16:$J$20,2,FALSE)*VLOOKUP(F16,$I$24:$J$28,2,FALSE)),"",VLOOKUP(D16,$I$8:$J$12,2,FALSE)*VLOOKUP(E16,$I$16:$J$20,2,FALSE)*VLOOKUP(F16,$I$24:$J$28,2,FALSE)) | I16: Nada urgente | J16: 1 | L16: 0.0001 | M16: =IF(G16="","",G16+L17) | N16: =IF(C16=0,"",C16) | O16: =G16
G17: =IF(ISERROR(VLOOKUP(D17,$I$8:$J$12,2,FALSE)*VLOOKUP(E17,$I$16:$J$20,2,FALSE)*VLOOKUP(F17,$I$24:$J$28,2,FALSE)),"",VLOOKUP(D17,$I$8:$J$12,2,FALSE)*VLOOKUP(E17,$I$16:$J$20,2,FALSE)*VLOOKUP(F17,$I$24:$J$28,2,FALSE)) | I17: Pouco urgente | J17: 2 | L17: 9e-05 | M17: =IF(G17="","",G17+L18) | N17: =IF(C17=0,"",C17) | O17: =G17
G18: =IF(ISERROR(VLOOKUP(D18,$I$8:$J$12,2,FALSE)*VLOOKUP(E18,$I$16:$J$20,2,FALSE)*VLOOKUP(F18,$I$24:$J$28,2,FALSE)),"",VLOOKUP(D18,$I$8:$J$12,2,FALSE)*VLOOKUP(E18,$I$16:$J$20,2,FALSE)*VLOOKUP(F18,$I$24:$J$28,2,FALSE)) | I18: Urgente | J18: 3 | L18: 8e-05 | M18: =IF(G18="","",G18+L19) | N18: =IF(C18=0,"",C18) | O18: =G18
G19: =IF(ISERROR(VLOOKUP(D19,$I$8:$J$12,2,FALSE)*VLOOKUP(E19,$I$16:$J$20,2,FALSE)*VLOOKUP(F19,$I$24:$J$28,2,FALSE)),"",VLOOKUP(D19,$I$8:$J$12,2,FALSE)*VLOOKUP(E19,$I$16:$J$20,2,FALSE)*VLOOKUP(F19,$I$24:$J$28,2,FALSE)) | I19: Muito urgente | J19: 4 | L19: 7e-05 | M19: =IF(G19="","",G19+L20) | N19: =IF(C19=0,"",C19) | O19: =G19
G20: =IF(ISERROR(VLOOKUP(D20,$I$8:$J$12,2,FALSE)*VLOOKUP(E20,$I$16:$J$20,2,FALSE)*VLOOKUP(F20,$I$24:$J$28,2,FALSE)),"",VLOOKUP(D20,$I$8:$J$12,2,FALSE)*VLOOKUP(E20,$I$16:$J$20,2,FALSE)*VLOOKUP(F20,$I$24:$J$28,2,FALSE)) | I20: Pra ontem | J20: 5 | L20: 6e-05 | M20: =IF(G20="","",G20+L21) | N20: =IF(C20=0,"",C20) | O20: =G20
G21: =IF(ISERROR(VLOOKUP(D21,$I$8:$J$12,2,FALSE)*VLOOKUP(E21,$I$16:$J$20,2,FALSE)*VLOOKUP(F21,$I$24:$J$28,2,FALSE)),"",VLOOKUP(D21,$I$8:$J$12,2,FALSE)*VLOOKUP(E21,$I$16:$J$20,2,FALSE)*VLOOKUP(F21,$I$24:$J$28,2,FALSE)) | L21: 5e-05 | M21: =IF(G21="","",G21+L22) | N21: =IF(C21=0,"",C21) | O21: =G21
G22: =IF(ISERROR(VLOOKUP(D22,$I$8:$J$12,2,FALSE)*VLOOKUP(E22,$I$16:$J$20,2,FALSE)*VLOOKUP(F22,$I$24:$J$28,2,FALSE)),"",VLOOKUP(D22,$I$8:$J$12,2,FALSE)*VLOOKUP(E22,$I$16:$J$20,2,FALSE)*VLOOKUP(F22,$I$24:$J$28,2,FALSE)) | I22: Tendência | L22: 4e-05 | M22: =IF(G22="","",G22+L23) | N22: =IF(C22=0,"",C22) | O22: =G22
G23: =IF(ISERROR(VLOOKUP(D23,$I$8:$J$12,2,FALSE)*VLOOKUP(E23,$I$16:$J$20,2,FALSE)*VLOOKUP(F23,$I$24:$J$28,2,FALSE)),"",VLOOKUP(D23,$I$8:$J$12,2,FALSE)*VLOOKUP(E23,$I$16:$J$20,2,FALSE)*VLOOKUP(F23,$I$24:$J$28,2,FALSE)) | L23: 3e-05 | M23: =IF(G23="","",G23+L24) | N23: =IF(C23=0,"",C23) | O23: =G23
G24: =IF(ISERROR(VLOOKUP(D24,$I$8:$J$12,2,FALSE)*VLOOKUP(E24,$I$16:$J$20,2,FALSE)*VLOOKUP(F24,$I$24:$J$28,2,FALSE)),"",VLOOKUP(D24,$I$8:$J$12,2,FALSE)*VLOOKUP(E24,$I$16:$J$20,2,FALSE)*VLOOKUP(F24,$I$24:$J$28,2,FALSE)) | I24: Melhora muito | J24: 1 | L24: 2e-05 | M24: =IF(G24="","",G24+L25) | N24: =IF(C24=0,"",C24) | O24: =G24
G25: =IF(ISERROR(VLOOKUP(D25,$I$8:$J$12,2,FALSE)*VLOOKUP(E25,$I$16:$J$20,2,FALSE)*VLOOKUP(F25,$I$24:$J$28,2,FALSE)),"",VLOOKUP(D25,$I$8:$J$12,2,FALSE)*VLOOKUP(E25,$I$16:$J$20,2,FALSE)*VLOOKUP(F25,$I$24:$J$28,2,FALSE)) | I25: Melhora | J25: 2 | L25: 1e-05 | M25: =IF(G25="","",G25+L26) | N25: =IF(C25=0,"",C25) | O25: =G25
C26: Pontuação geral das suas Ameaças | F26: → | G26: =SUM(G6:G25) -> 0 | I26: Mantém | J26: 3
I27: Piora | J27: 4
I28: Piora muito | J28: 5

Sheet Matriz SWOT
C4: 1. Fatores internos
C5: 1.1 Top 5 Forças | D5: =SUM(D6:D10) -> 0 | E5: 1.2 Top 5 Fraquezas | F5: =SUM(F6:F10) -> 0 | H5: 0.0002 | I5: =H5+L5 -> 0.0002 | J5: =C6 | K5: Força | L5: =D6 -> 0
B6: 1 | C6: =IF(ISERROR(VLOOKUP(LARGE('Forças'!$M$6:$M$24,$B6),'Forças'!$M$6:$N$24,2,FALSE)),"",VLOOKUP(LARGE('Forças'!$M$6:$M$24,$B6),'Forças'!$M$6:$N$24,2,FALSE)) | D6: =IF(ISERROR(VLOOKUP(LARGE('Forças'!$M$6:$M$24,$B6),'Forças'!$M$6:$O$24,3,FALSE)),0,VLOOKUP(LARGE('Forças'!$M$6:$M$24,$B6),'Forças'!$M$6:$O$24,3,FALSE)) -> 0 | E6: =IF(ISERROR(VLOOKUP(LARGE(Fraquezas!$M$6:$M$24,$B6),Fraquezas!$M$6:$N$24,2,FALSE)),"",VLOOKUP(LARGE(Fraquezas!$M$6:$M$24,$B6),Fraquezas!$M$6:$N$24,2,FALSE)) | F6: =IF(ISERROR(VLOOKUP(LARGE(Fraquezas!$M$6:$M$24,$B6),Fraquezas!$M$6:$O$24,3,FALSE)),0,VLOOKUP(LARGE(Fraquezas!$M$6:$M$24,$B6),Fraquezas!$M$6:$O$24,3,FALSE)) -> 0 | H6: 0.00019 | I6: =H6+L6 -> 0.00019 | J6: =C7 | K6: Força | L6: =D7 -> 0
B7: 2 | C7: =IF(ISERROR(VLOOKUP(LARGE('Forças'!$M$6:$M$24,$B7),'Forças'!$M$6:$N$24,2,FALSE)),"",VLOOKUP(LARGE('Forças'!$M$6:$M$24,$B7),'Forças'!$M$6:$N$24,2,FALSE)) | D7: =IF(ISERROR(VLOOKUP(LARGE('Forças'!$M$6:$M$24,$B7),'Forças'!$M$6:$O$24,3,FALSE)),0,VLOOKUP(LARGE('Forças'!$M$6:$M$24,$B7),'Forças'!$M$6:$O$24,3,FALSE)) -> 0 | E7: =IF(ISERROR(VLOOKUP(LARGE(Fraquezas!$M$6:$M$24,$B7),Fraquezas!$M$6:$N$24,2,FALSE)),"",VLOOKUP(LARGE(Fraquezas!$M$6:$M$24,$B7),Fraquezas!$M$6:$N$24,2,FALSE)) | F7: =IF(ISERROR(VLOOKUP(LARGE(Fraquezas!$M$6:$M$24,$B7),Fraquezas!$M$6:$O$24,3,FALSE)),0,VLOOKUP(LARGE(Fraquezas!$M$6:$M$24,$B7),Fraquezas!$M$6:$O$24,3,FALSE)) -> 0 | H7: 0.00018 | I7: =H7+L7 -> 0.00018 | J7: =C8 | K7: Força | L7: =D8 -> 0
B8: 3 | C8: =IF(ISERROR(VLOOKUP(LARGE('Forças'!$M$6:$M$24,$B8),'Forças'!$M$6:$N$24,2,FALSE)),"",VLOOKUP(LARGE('Forças'!$M$6:$M$24,$B8),'Forças'!$M$6:$N$24,2,FALSE)) | D8: =IF(ISERROR(VLOOKUP(LARGE('Forças'!$M$6:$M$24,$B8),'Forças'!$M$6:$O$24,3,FALSE)),0,VLOOKUP(LARGE('Forças'!$M$6:$M$24,$B8),'Forças'!$M$6:$O$24,3,FALSE)) -> 0 | E8: =IF(ISERROR(VLOOKUP(LARGE(Fraquezas!$M$6:$M$24,$B8),Fraquezas!$M$6:$N$24,2,FALSE)),"",VLOOKUP(LARGE(Fraquezas!$M$6:$M$24,$B8),Fraquezas!$M$6:$N$24,2,FALSE)) | F8: =IF(ISERROR(VLOOKUP(LARGE(Fraquezas!$M$6:$M$24,$B8),Fraquezas!$M$6:$O$24,3,FALSE)),0,VLOOKUP(LARGE(Fraquezas!$M$6:$M$24,$B8),Fraquezas!$M$6:$O$24,3,FALSE)) -> 0 | H8: 0.00017 | I8: =H8+L8 -> 0.00017 | J8: =C9 | K8: Força | L8: =D9 -> 0
B9: 4 | C9: =IF(ISERROR(VLOOKUP(LARGE('Forças'!$M$6:$M$24,$B9),'Forças'!$M$6:$N$24,2,FALSE)),"",VLOOKUP(LARGE('Forças'!$M$6:$M$24,$B9),'Forças'!$M$6:$N$24,2,FALSE)) | D9: =IF(ISERROR(VLOOKUP(LARGE('Forças'!$M$6:$M$24,$B9),'Forças'!$M$6:$O$24,3,FALSE)),0,VLOOKUP(LARGE('Forças'!$M$6:$M$24,$B9),'Forças'!$M$6:$O$24,3,FALSE)) -> 0 | E9: =IF(ISERROR(VLOOKUP(LARGE(Fraquezas!$M$6:$M$24,$B9),Fraquezas!$M$6:$N$24,2,FALSE)),"",VLOOKUP(LARGE(Fraquezas!$M$6:$M$24,$B9),Fraquezas!$M$6:$N$24,2,FALSE)) | F9: =IF(ISERROR(VLOOKUP(LARGE(Fraquezas!$M$6:$M$24,$B9),Fraquezas!$M$6:$O$24,3,FALSE)),0,VLOOKUP(LARGE(Fraquezas!$M$6:$M$24,$B9),Fraquezas!$M$6:$O$24,3,FALSE)) -> 0 | H9: 0.00016 | I9: =H9+L9 -> 0.00016 | J9: =C10 | K9: Força | L9: =D10 -> 0
B10: 5 | C10: =IF(ISERROR(VLOOKUP(LARGE('Forças'!$M$6:$M$24,$B10),'Forças'!$M$6:$N$24,2,FALSE)),"",VLOOKUP(LARGE('Forças'!$M$6:$M$24,$B10),'Forças'!$M$6:$N$24,2,FALSE)) | D10: =IF(ISERROR(VLOOKUP(LARGE('Forças'!$M$6:$M$24,$B10),'Forças'!$M$6:$O$24,3,FALSE)),0,VLOOKUP(LARGE('Forças'!$M$6:$M$24,$B10),'Forças'!$M$6:$O$24,3,FALSE)) -> 0 | E10: =IF(ISERROR(VLOOKUP(LARGE(Fraquezas!$M$6:$M$24,$B10),Fraquezas!$M$6:$N$24,2,FALSE)),"",VLOOKUP(LARGE(Fraquezas!$M$6:$M$24,$B10),Fraquezas!$M$6:$N$24,2,FALSE)) | F10: =IF(ISERROR(VLOOKUP(LARGE(Fraquezas!$M$6:$M$24,$B10),Fraquezas!$M$6:$O$24,3,FALSE)),0,VLOOKUP(LARGE(Fraquezas!$M$6:$M$24,$B10),Fraquezas!$M$6:$O$24,3,FALSE)) -> 0 | H10: 0.00015 | I10: =H10+L10 -> 0.00015 | J10: =E6 | K10: Fraqueza | L10: =F6 -> 0
H11: 0.00014 | I11: =H11+L11 -> 0.00014 | J11: =E7 | K11: Fraqueza | L11: =F7 -> 0
C12: 2. Fatores externos | H12: 0.00013 | I12: =H12+L12 -> 0.00013 | J12: =E8 | K12: Fraqueza | L12: =F8 -> 0
C13: 2.1 Top 5 Oportunidades | D13: =SUM(D14:D18) -> 0 | E13: 2.2 Top 5 Ameaças | F13: =SUM(F14:F18) -> 0 | H13: 0.00012 | I13: =H13+L13 -> 0.00012 | J13: =E9 | K13: Fraqueza | L13: =F9 -> 0
B14: 1 | C14: =IF(ISERROR(VLOOKUP(LARGE(Oportunidades!$M$6:$M$25,$B14),Oportunidades!$M$6:$N$25,2,FALSE)),"",VLOOKUP(LARGE(Oportunidades!$M$6:$M$25,$B14),Oportunidades!$M$6:$N$25,2,FALSE)) | D14: =IF(ISERROR(VLOOKUP(LARGE(Oportunidades!$M$6:$M$25,$B14),Oportunidades!$M$6:$O$25,3,FALSE)),0,VLOOKUP(LARGE(Oportunidades!$M$6:$M$25,$B14),Oportunidades!$M$6:$O$25,3,FALSE)) -> 0 | E14: =IF(ISERROR(VLOOKUP(LARGE('Ameaças'!$M$6:$M$25,$B14),'Ameaças'!$M$6:$N$25,2,FALSE)),"",VLOOKUP(LARGE('Ameaças'!$M$6:$M$25,$B14),'Ameaças'!$M$6:$N$25,2,FALSE)) | F14: =IF(ISERROR(VLOOKUP(LARGE('Ameaças'!$M$6:$M$25,$B14),'Ameaças'!$M$6:$O$25,3,FALSE)),0,VLOOKUP(LARGE('Ameaças'!$M$6:$M$25,$B14),'Ameaças'!$M$6:$O$25,3,FALSE)) -> 0 | H14: 0.00011 | I14: =H14+L14 -> 0.00011 | J14: =E10 | K14: Fraqueza | L14: =F10 -> 0
B15: 2 | C15: =IF(ISERROR(VLOOKUP(LARGE(Oportunidades!$M$6:$M$25,$B15),Oportunidades!$M$6:$N$25,2,FALSE)),"",VLOOKUP(LARGE(Oportunidades!$M$6:$M$25,$B15),Oportunidades!$M$6:$N$25,2,FALSE)) | D15: =IF(ISERROR(VLOOKUP(LARGE(Oportunidades!$M$6:$M$25,$B15),Oportunidades!$M$6:$O$25,3,FALSE)),0,VLOOKUP(LARGE(Oportunidades!$M$6:$M$25,$B15),Oportunidades!$M$6:$O$25,3,FALSE)) -> 0 | E15: =IF(ISERROR(VLOOKUP(LARGE('Ameaças'!$M$6:$M$25,$B15),'Ameaças'!$M$6:$N$25,2,FALSE)),"",VLOOKUP(LARGE('Ameaças'!$M$6:$M$25,$B15),'Ameaças'!$M$6:$N$25,2,FALSE)) | F15: =IF(ISERROR(VLOOKUP(LARGE('Ameaças'!$M$6:$M$25,$B15),'Ameaças'!$M$6:$O$25,3,FALSE)),0,VLOOKUP(LARGE('Ameaças'!$M$6:$M$25,$B15),'Ameaças'!$M$6:$O$25,3,FALSE)) -> 0 | H15: 0.0001 | I15: =H15+L15 -> 0.0001 | J15: =C14 | K15: Oportunidade | L15: =D14 -> 0
B16: 3 | C16: =IF(ISERROR(VLOOKUP(LARGE(Oportunidades!$M$6:$M$25,$B16),Oportunidades!$M$6:$N$25,2,FALSE)),"",VLOOKUP(LARGE(Oportunidades!$M$6:$M$25,$B16),Oportunidades!$M$6:$N$25,2,FALSE)) | D16: =IF(ISERROR(VLOOKUP(LARGE(Oportunidades!$M$6:$M$25,$B16),Oportunidades!$M$6:$O$25,3,FALSE)),0,VLOOKUP(LARGE(Oportunidades!$M$6:$M$25,$B16),Oportunidades!$M$6:$O$25,3,FALSE)) -> 0 | E16: =IF(ISERROR(VLOOKUP(LARGE('Ameaças'!$M$6:$M$25,$B16),'Ameaças'!$M$6:$N$25,2,FALSE)),"",VLOOKUP(LARGE('Ameaças'!$M$6:$M$25,$B16),'Ameaças'!$M$6:$N$25,2,FALSE)) | F16: =IF(ISERROR(VLOOKUP(LARGE('Ameaças'!$M$6:$M$25,$B16),'Ameaças'!$M$6:$O$25,3,FALSE)),0,VLOOKUP(LARGE('Ameaças'!$M$6:$M$25,$B16),'Ameaças'!$M$6:$O$25,3,FALSE)) -> 0 | H16: 9e-05 | I16: =H16+L16 -> 9e-05 | J16: =C15 | K16: Oportunidade | L16: =D15 -> 0
B17: 4 | C17: =IF(ISERROR(VLOOKUP(LARGE(Oportunidades!$M$6:$M$25,$B17),Oportunidades!$M$6:$N$25,2,FALSE)),"",VLOOKUP(LARGE(Oportunidades!$M$6:$M$25,$B17),Oportunidades!$M$6:$N$25,2,FALSE)) | D17: =IF(ISERROR(VLOOKUP(LARGE(Oportunidades!$M$6:$M$25,$B17),Oportunidades!$M$6:$O$25,3,FALSE)),0,VLOOKUP(LARGE(Oportunidades!$M$6:$M$25,$B17),Oportunidades!$M$6:$O$25,3,FALSE)) -> 0 | E17: =IF(ISERROR(VLOOKUP(LARGE('Ameaças'!$M$6:$M$25,$B17),'Ameaças'!$M$6:$N$25,2,FALSE)),"",VLOOKUP(LARGE('Ameaças'!$M$6:$M$25,$B17),'Ameaças'!$M$6:$N$25,2,FALSE)) | F17: =IF(ISERROR(VLOOKUP(LARGE('Ameaças'!$M$6:$M$25,$B17),'Ameaças'!$M$6:$O$25,3,FALSE)),0,VLOOKUP(LARGE('Ameaças'!$M$6:$M$25,$B17),'Ameaças'!$M$6:$O$25,3,FALSE)) -> 0 | H17: 8e-05 | I17: =H17+L17 -> 8e-05 | J17: =C16 | K17: Oportunidade | L17: =D16 -> 0
B18: 5 | C18: =IF(ISERROR(VLOOKUP(LARGE(Oportunidades!$M$6:$M$25,$B18),Oportunidades!$M$6:$N$25,2,FALSE)),"",VLOOKUP(LARGE(Oportunidades!$M$6:$M$25,$B18),Oportunidades!$M$6:$N$25,2,FALSE)) | D18: =IF(ISERROR(VLOOKUP(LARGE(Oportunidades!$M$6:$M$25,$B18),Oportunidades!$M$6:$O$25,3,FALSE)),0,VLOOKUP(LARGE(Oportunidades!$M$6:$M$25,$B18),Oportunidades!$M$6:$O$25,3,FALSE)) -> 0 | E18: =IF(ISERROR(VLOOKUP(LARGE('Ameaças'!$M$6:$M$25,$B18),'Ameaças'!$M$6:$N$25,2,FALSE)),"",VLOOKUP(LARGE('Ameaças'!$M$6:$M$25,$B18),'Ameaças'!$M$6:$N$25,2,FALSE)) | F18: =IF(ISERROR(VLOOKUP(LARGE('Ameaças'!$M$6:$M$25,$B18),'Ameaças'!$M$6:$O$25,3,FALSE)),0,VLOOKUP(LARGE('Ameaças'!$M$6:$M$25,$B18),'Ameaças'!$M$6:$O$25,3,FALSE)) -> 0 | H18: 7e-05 | I18: =H18+L18 -> 7e-05 | J18: =C17 | K18: Oportunidade | L18: =D17 -> 0
H19: 6e-05 | I19: =H19+L19 -> 6e-05 | J19: =C18 | K19: Oportunidade | L19: =D18 -> 0
H20: 5e-05 | I20: =H20+L20 -> 5e-05 | J20: =E14 | K20: Ameaça | L20: =F14 -> 0
H21: 4e-05 | I21: =H21+L21 -> 4e-05 | J21: =E15 | K21: Ameaça | L21: =F15 -> 0
H22: 3e-05 | I22: =H22+L22 -> 3e-05 | J22: =E16 | K22: Ameaça | L22: =F16 -> 0
H23: 2e-05 | I23: =H23+L23 -> 2e-05 | J23: =E17 | K23: Ameaça | L23: =F17 -> 0
H24: 1e-05 | I24: =H24+L24 -> 1e-05 | J24: =E18 | K24: Ameaça | L24: =F18 -> 0

Sheet Cruzamento
C4: Importante: Veja o potencial ofensivo e desenvolva a melhor estratégia para impulsionar suas forças e resuzir as fraquezas relacionando-as com oportunidades e ameaças. Apenas as 5 principais forças, fraquezas, oportunidades e ameaças (as mais bem pontuadas em "Fatores internos" e "Fatores externos") estão sendo exibidas para que você tenha foco e objetividade nas ações.
R6: Setembro | S6: Outubro | T6: Novembro | U6: Dezembro | V6: Janeiro | W6: Fevereiro | X6: Março | Y6: Abril | Z6: Maio
C7: Forças e Fraquezas | D7: No seu negócio | E7: Oportunidades e Ameaças | F7: No seu negócio | G7: Tipo de estratégia | H7: Recomendação | R7: 1 | S7: 1 | T7: 1 | U7: 1 | V7: 2 | W7: 2 | X7: 2 | Y7: 2 | Z7: 2
C8: Ex.: O portfólio de produtos/serviços é variado | D8: Ex.: Força | E8: Ex.: Aproveita avanço tecnológico | F8: Ex.: Ameaça | G8: Ex.: Estratégia ofensiva | H8: Ex.: Procure criar planos de ação para desenvolver as vantagens competitivas.
D9: =IF(ISERROR(VLOOKUP(C9,'Matriz SWOT'!$J$5:$K$14,2,FALSE)),"",VLOOKUP(C9,'Matriz SWOT'!$J$5:$K$14,2,FALSE)) | F9: =IF(ISERROR(VLOOKUP(E9,'Matriz SWOT'!$J$5:$K$24,2,FALSE)),"",VLOOKUP(E9,'Matriz SWOT'!$J$5:$K$24,2,FALSE)) | G9: =IF(F9="","",VLOOKUP(D9&F9,$M$9:$O$12,2,FALSE)) | H9: =IF(G9="","",VLOOKUP(G9,$N$9:$O$12,2,FALSE)) | I9: 1 | J9: =VLOOKUP(LARGE('Matriz SWOT'!$I$5:$I$14,Cruzamento!I9),'Matriz SWOT'!$I$5:$J$14,2,FALSE) | K9: =VLOOKUP(LARGE('Matriz SWOT'!$I$15:$I$24,Cruzamento!I9),'Matriz SWOT'!$I$15:$J$24,2,FALSE) | M9: ForçaOportunidade | N9: Estratégia ofensiva | O9: Procure criar planos de ação para desenvolver as vantagens competitivas.
D10: =IF(ISERROR(VLOOKUP(C10,'Matriz SWOT'!$J$5:$K$14,2,FALSE)),"",VLOOKUP(C10,'Matriz SWOT'!$J$5:$K$14,2,FALSE)) | F10: =IF(ISERROR(VLOOKUP(E10,'Matriz SWOT'!$J$5:$K$24,2,FALSE)),"",VLOOKUP(E10,'Matriz SWOT'!$J$5:$K$24,2,FALSE)) | G10: =IF(F10="","",VLOOKUP(D10&F10,$M$9:$O$12,2,FALSE)) | H10: =IF(G10="","",VLOOKUP(G10,$N$9:$O$12,2,FALSE)) | I10: 2 | J10: =VLOOKUP(LARGE('Matriz SWOT'!$I$5:$I$14,Cruzamento!I10),'Matriz SWOT'!$I$5:$J$14,2,FALSE) | K10: =VLOOKUP(LARGE('Matriz SWOT'!$I$15:$I$24,Cruzamento!I10),'Matriz SWOT'!$I$15:$J$24,2,FALSE) | M10: ForçaAmeaça | N10: Estratégia de confronto | O10: Procure elaborar planos de ação para modificar o ambiente a favor do seu negócio.
D11: =IF(ISERROR(VLOOKUP(C11,'Matriz SWOT'!$J$5:$K$14,2,FALSE)),"",VLOOKUP(C11,'Matriz SWOT'!$J$5:$K$14,2,FALSE)) | F11: =IF(ISERROR(VLOOKUP(E11,'Matriz SWOT'!$J$5:$K$24,2,FALSE)),"",VLOOKUP(E11,'Matriz SWOT'!$J$5:$K$24,2,FALSE)) | G11: =IF(F11="","",VLOOKUP(D11&F11,$M$9:$O$12,2,FALSE)) | H11: =IF(G11="","",VLOOKUP(G11,$N$9:$O$12,2,FALSE)) | I11: 3 | J11: =VLOOKUP(LARGE('Matriz SWOT'!$I$5:$I$14,Cruzamento!I11),'Matriz SWOT'!$I$5:$J$14,2,FALSE) | K11: =VLOOKUP(LARGE('Matriz SWOT'!$I$15:$I$24,Cruzamento!I11),'Matriz SWOT'!$I$15:$J$24,2,FALSE) | M11: FraquezaOportunidade | N11: Estratégia de reforço | O11: Procure criar planos de ação para aproveitar melhor as oportunidades que o ambiente proporciona.
D12: =IF(ISERROR(VLOOKUP(C12,'Matriz SWOT'!$J$5:$K$14,2,FALSE)),"",VLOOKUP(C12,'Matriz SWOT'!$J$5:$K$14,2,FALSE)) | F12: =IF(ISERROR(VLOOKUP(E12,'Matriz SWOT'!$J$5:$K$24,2,FALSE)),"",VLOOKUP(E12,'Matriz SWOT'!$J$5:$K$24,2,FALSE)) | G12: =IF(F12="","",VLOOKUP(D12&F12,$M$9:$O$12,2,FALSE)) | H12: =IF(G12="","",VLOOKUP(G12,$N$9:$O$12,2,FALSE)) | I12: 4 | J12: =VLOOKUP(LARGE('Matriz SWOT'!$I$5:$I$14,Cruzamento!I12),'Matriz SWOT'!$I$5:$J$14,2,FALSE) | K12: =VLOOKUP(LARGE('Matriz SWOT'!$I$15:$I$24,Cruzamento!I12),'Matriz SWOT'!$I$15:$J$24,2,FALSE) | M12: FraquezaAmeaça | N12: Estratégia defensiva | O12: Isto pode ser um sinal de que você precisará fazer profundas mudanças para proteger a empresa.
D13: =IF(ISERROR(VLOOKUP(C13,'Matriz SWOT'!$J$5:$K$14,2,FALSE)),"",VLOOKUP(C13,'Matriz SWOT'!$J$5:$K$14,2,FALSE)) | F13: =IF(ISERROR(VLOOKUP(E13,'Matriz SWOT'!$J$5:$K$24,2,FALSE)),"",VLOOKUP(E13,'Matriz SWOT'!$J$5:$K$24,2,FALSE)) | G13: =IF(F13="","",VLOOKUP(D13&F13,$M$9:$O$12,2,FALSE)) | H13: =IF(G13="","",VLOOKUP(G13,$N$9:$O$12,2,FALSE)) | I13: 5 | J13: =VLOOKUP(LARGE('Matriz SWOT'!$I$5:$I$14,Cruzamento!I13),'Matriz SWOT'!$I$5:$J$14,2,FALSE) | K13: =VLOOKUP(LARGE('Matriz SWOT'!$I$15:$I$24,Cruzamento!I13),'Matriz SWOT'!$I$15:$J$24,2,FALSE)
D14: =IF(ISERROR(VLOOKUP(C14,'Matriz SWOT'!$J$5:$K$14,2,FALSE)),"",VLOOKUP(C14,'Matriz SWOT'!$J$5:$K$14,2,FALSE)) | F14: =IF(ISERROR(VLOOKUP(E14,'Matriz SWOT'!$J$5:$K$24,2,FALSE)),"",VLOOKUP(E14,'Matriz SWOT'!$J$5:$K$24,2,FALSE)) | G14: =IF(F14="","",VLOOKUP(D14&F14,$M$9:$O$12,2,FALSE)) | H14: =IF(G14="","",VLOOKUP(G14,$N$9:$O$12,2,FALSE)) | I14: 6 | J14: =VLOOKUP(LARGE('Matriz SWOT'!$I$5:$I$14,Cruzamento!I14),'Matriz SWOT'!$I$5:$J$14,2,FALSE) | K14: =VLOOKUP(LARGE('Matriz SWOT'!$I$15:$I$24,Cruzamento!I14),'Matriz SWOT'!$I$15:$J$24,2,FALSE)
D15: =IF(ISERROR(VLOOKUP(C15,'Matriz SWOT'!$J$5:$K$14,2,FALSE)),"",VLOOKUP(C15,'Matriz SWOT'!$J$5:$K$14,2,FALSE)) | F15: =IF(ISERROR(VLOOKUP(E15,'Matriz SWOT'!$J$5:$K$24,2,FALSE)),"",VLOOKUP(E15,'Matriz SWOT'!$J$5:$K$24,2,FALSE)) | G15: =IF(F15="","",VLOOKUP(D15&F15,$M$9:$O$12,2,FALSE)) | H15: =IF(G15="","",VLOOKUP(G15,$N$9:$O$12,2,FALSE)) | I15: 7 | J15: =VLOOKUP(LARGE('Matriz SWOT'!$I$5:$I$14,Cruzamento!I15),'Matriz SWOT'!$I$5:$J$14,2,FALSE) | K15: =VLOOKUP(LARGE('Matriz SWOT'!$I$15:$I$24,Cruzamento!I15),'Matriz SWOT'!$I$15:$J$24,2,FALSE)
D16: =IF(ISERROR(VLOOKUP(C16,'Matriz SWOT'!$J$5:$K$14,2,FALSE)),"",VLOOKUP(C16,'Matriz SWOT'!$J$5:$K$14,2,FALSE)) | F16: =IF(ISERROR(VLOOKUP(E16,'Matriz SWOT'!$J$5:$K$24,2,FALSE)),"",VLOOKUP(E16,'Matriz SWOT'!$J$5:$K$24,2,FALSE)) | G16: =IF(F16="","",VLOOKUP(D16&F16,$M$9:$O$12,2,FALSE)) | H16: =IF(G16="","",VLOOKUP(G16,$N$9:$O$12,2,FALSE)) | I16: 8 | J16: =VLOOKUP(LARGE('Matriz SWOT'!$I$5:$I$14,Cruzamento!I16),'Matriz SWOT'!$I$5:$J$14,2,FALSE) | K16: =VLOOKUP(LARGE('Matriz SWOT'!$I$15:$I$24,Cruzamento!I16),'Matriz SWOT'!$I$15:$J$24,2,FALSE)
D17: =IF(ISERROR(VLOOKUP(C17,'Matriz SWOT'!$J$5:$K$14,2,FALSE)),"",VLOOKUP(C17,'Matriz SWOT'!$J$5:$K$14,2,FALSE)) | F17: =IF(ISERROR(VLOOKUP(E17,'Matriz SWOT'!$J$5:$K$24,2,FALSE)),"",VLOOKUP(E17,'Matriz SWOT'!$J$5:$K$24,2,FALSE)) | G17: =IF(F17="","",VLOOKUP(D17&F17,$M$9:$O$12,2,FALSE)) | H17: =IF(G17="","",VLOOKUP(G17,$N$9:$O$12,2,FALSE)) | I17: 9 | J17: =VLOOKUP(LARGE('Matriz SWOT'!$I$5:$I$14,Cruzamento!I17),'Matriz SWOT'!$I$5:$J$14,2,FALSE) | K17: =VLOOKUP(LARGE('Matriz SWOT'!$I$15:$I$24,Cruzamento!I17),'Matriz SWOT'!$I$15:$J$24,2,FALSE)
D18: =IF(ISERROR(VLOOKUP(C18,'Matriz SWOT'!$J$5:$K$14,2,FALSE)),"",VLOOKUP(C18,'Matriz SWOT'!$J$5:$K$14,2,FALSE)) | F18: =IF(ISERROR(VLOOKUP(E18,'Matriz SWOT'!$J$5:$K$24,2,FALSE)),"",VLOOKUP(E18,'Matriz SWOT'!$J$5:$K$24,2,FALSE)) | G18: =IF(F18="","",VLOOKUP(D18&F18,$M$9:$O$12,2,FALSE)) | H18: =IF(G18="","",VLOOKUP(G18,$N$9:$O$12,2,FALSE)) | I18: 10 | J18: =VLOOKUP(LARGE('Matriz SWOT'!$I$5:$I$14,Cruzamento!I18),'Matriz SWOT'!$I$5:$J$14,2,FALSE) | K18: =VLOOKUP(LARGE('Matriz SWOT'!$I$15:$I$24,Cruzamento!I18),'Matriz SWOT'!$I$15:$J$24,2,FALSE)
D19: =IF(ISERROR(VLOOKUP(C19,'Matriz SWOT'!$J$5:$K$14,2,FALSE)),"",VLOOKUP(C19,'Matriz SWOT'!$J$5:$K$14,2,FALSE)) | F19: =IF(ISERROR(VLOOKUP(E19,'Matriz SWOT'!$J$5:$K$24,2,FALSE)),"",VLOOKUP(E19,'Matriz SWOT'!$J$5:$K$24,2,FALSE)) | G19: =IF(F19="","",VLOOKUP(D19&F19,$M$9:$O$12,2,FALSE)) | H19: =IF(G19="","",VLOOKUP(G19,$N$9:$O$12,2,FALSE))
D20: =IF(ISERROR(VLOOKUP(C20,'Matriz SWOT'!$J$5:$K$14,2,FALSE)),"",VLOOKUP(C20,'Matriz SWOT'!$J$5:$K$14,2,FALSE)) | F20: =IF(ISERROR(VLOOKUP(E20,'Matriz SWOT'!$J$5:$K$24,2,FALSE)),"",VLOOKUP(E20,'Matriz SWOT'!$J$5:$K$24,2,FALSE)) | G20: =IF(F20="","",VLOOKUP(D20&F20,$M$9:$O$12,2,FALSE)) | H20: =IF(G20="","",VLOOKUP(G20,$N$9:$O$12,2,FALSE))
D21: =IF(ISERROR(VLOOKUP(C21,'Matriz SWOT'!$J$5:$K$14,2,FALSE)),"",VLOOKUP(C21,'Matriz SWOT'!$J$5:$K$14,2,FALSE)) | F21: =IF(ISERROR(VLOOKUP(E21,'Matriz SWOT'!$J$5:$K$24,2,FALSE)),"",VLOOKUP(E21,'Matriz SWOT'!$J$5:$K$24,2,FALSE)) | G21: =IF(F21="","",VLOOKUP(D21&F21,$M$9:$O$12,2,FALSE)) | H21: =IF(G21="","",VLOOKUP(G21,$N$9:$O$12,2,FALSE))
D22: =IF(ISERROR(VLOOKUP(C22,'Matriz SWOT'!$J$5:$K$14,2,FALSE)),"",VLOOKUP(C22,'Matriz SWOT'!$J$5:$K$14,2,FALSE)) | F22: =IF(ISERROR(VLOOKUP(E22,'Matriz SWOT'!$J$5:$K$24,2,FALSE)),"",VLOOKUP(E22,'Matriz SWOT'!$J$5:$K$24,2,FALSE)) | G22: =IF(F22="","",VLOOKUP(D22&F22,$M$9:$O$12,2,FALSE)) | H22: =IF(G22="","",VLOOKUP(G22,$N$9:$O$12,2,FALSE))
D23: =IF(ISERROR(VLOOKUP(C23,'Matriz SWOT'!$J$5:$K$14,2,FALSE)),"",VLOOKUP(C23,'Matriz SWOT'!$J$5:$K$14,2,FALSE)) | F23: =IF(ISERROR(VLOOKUP(E23,'Matriz SWOT'!$J$5:$K$24,2,FALSE)),"",VLOOKUP(E23,'Matriz SWOT'!$J$5:$K$24,2,FALSE)) | G23: =IF(F23="","",VLOOKUP(D23&F23,$M$9:$O$12,2,FALSE)) | H23: =IF(G23="","",VLOOKUP(G23,$N$9:$O$12,2,FALSE))
D24: =IF(ISERROR(VLOOKUP(C24,'Matriz SWOT'!$J$5:$K$14,2,FALSE)),"",VLOOKUP(C24,'Matriz SWOT'!$J$5:$K$14,2,FALSE)) | F24: =IF(ISERROR(VLOOKUP(E24,'Matriz SWOT'!$J$5:$K$24,2,FALSE)),"",VLOOKUP(E24,'Matriz SWOT'!$J$5:$K$24,2,FALSE)) | G24: =IF(F24="","",VLOOKUP(D24&F24,$M$9:$O$12,2,FALSE)) | H24: =IF(G24="","",VLOOKUP(G24,$N$9:$O$12,2,FALSE))
D25: =IF(ISERROR(VLOOKUP(C25,'Matriz SWOT'!$J$5:$K$14,2,FALSE)),"",VLOOKUP(C25,'Matriz SWOT'!$J$5:$K$14,2,FALSE)) | F25: =IF(ISERROR(VLOOKUP(E25,'Matriz SWOT'!$J$5:$K$24,2,FALSE)),"",VLOOKUP(E25,'Matriz SWOT'!$J$5:$K$24,2,FALSE)) | G25: =IF(F25="","",VLOOKUP(D25&F25,$M$9:$O$12,2,FALSE)) | H25: =IF(G25="","",VLOOKUP(G25,$N$9:$O$12,2,FALSE))
D26: =IF(ISERROR(VLOOKUP(C26,'Matriz SWOT'!$J$5:$K$14,2,FALSE)),"",VLOOKUP(C26,'Matriz SWOT'!$J$5:$K$14,2,FALSE)) | F26: =IF(ISERROR(VLOOKUP(E26,'Matriz SWOT'!$J$5:$K$24,2,FALSE)),"",VLOOKUP(E26,'Matriz SWOT'!$J$5:$K$24,2,FALSE)) | G26: =IF(F26="","",VLOOKUP(D26&F26,$M$9:$O$12,2,FALSE)) | H26: =IF(G26="","",VLOOKUP(G26,$N$9:$O$12,2,FALSE))
D27: =IF(ISERROR(VLOOKUP(C27,'Matriz SWOT'!$J$5:$K$14,2,FALSE)),"",VLOOKUP(C27,'Matriz SWOT'!$J$5:$K$14,2,FALSE)) | F27: =IF(ISERROR(VLOOKUP(E27,'Matriz SWOT'!$J$5:$K$24,2,FALSE)),"",VLOOKUP(E27,'Matriz SWOT'!$J$5:$K$24,2,FALSE)) | G27: =IF(F27="","",VLOOKUP(D27&F27,$M$9:$O$12,2,FALSE)) | H27: =IF(G27="","",VLOOKUP(G27,$N$9:$O$12,2,FALSE))
D28: =IF(ISERROR(VLOOKUP(C28,'Matriz SWOT'!$J$5:$K$14,2,FALSE)),"",VLOOKUP(C28,'Matriz SWOT'!$J$5:$K$14,2,FALSE)) | F28: =IF(ISERROR(VLOOKUP(E28,'Matriz SWOT'!$J$5:$K$24,2,FALSE)),"",VLOOKUP(E28,'Matriz SWOT'!$J$5:$K$24,2,FALSE)) | G28: =IF(F28="","",VLOOKUP(D28&F28,$M$9:$O$12,2,FALSE)) | H28: =IF(G28="","",VLOOKUP(G28,$N$9:$O$12,2,FALSE))
D29: =IF(ISERROR(VLOOKUP(C29,'Matriz SWOT'!$J$5:$K$14,2,FALSE)),"",VLOOKUP(C29,'Matriz SWOT'!$J$5:$K$14,2,FALSE)) | F29: =IF(ISERROR(VLOOKUP(E29,'Matriz SWOT'!$J$5:$K$24,2,FALSE)),"",VLOOKUP(E29,'Matriz SWOT'!$J$5:$K$24,2,FALSE)) | G29: =IF(F29="","",VLOOKUP(D29&F29,$M$9:$O$12,2,FALSE)) | H29: =IF(G29="","",VLOOKUP(G29,$N$9:$O$12,2,FALSE))
D30: =IF(ISERROR(VLOOKUP(C30,'Matriz SWOT'!$J$5:$K$14,2,FALSE)),"",VLOOKUP(C30,'Matriz SWOT'!$J$5:$K$14,2,FALSE)) | F30: =IF(ISERROR(VLOOKUP(E30,'Matriz SWOT'!$J$5:$K$24,2,FALSE)),"",VLOOKUP(E30,'Matriz SWOT'!$J$5:$K$24,2,FALSE)) | G30: =IF(F30="","",VLOOKUP(D30&F30,$M$9:$O$12,2,FALSE)) | H30: =IF(G30="","",VLOOKUP(G30,$N$9:$O$12,2,FALSE))
... D108: =IF(ISERROR(VLOOKUP(C108,'Matriz SWOT'!$J$5:$K$14,2,FALSE)),"",VLOOKUP(C108,'Matriz SWOT'!$J$5:$K$14,2,FALSE)) | F108: =IF(ISERROR(VLOOKUP(E108,'Matriz SWOT'!$J$5:$K$24,2,FALSE)),"",VLOOKUP(E108,'Matriz SWOT'!$J$5:$K$24,2,FALSE)) | G108: =IF(F108="","",VLOOKUP(D108&F108,$M$9:$O$12,2,FALSE)) | H108: =IF(G108="","",VLOOKUP(G108,$N$9:$O$12,2,FALSE))

Sheet Objetivos Estratégicos 
B5: PERSPECTIVA | C5: Nº | D5: OBJETIVO | E5: INDICADOR | F5: RESPONSÁVEL | G5: META 2022 | H5: 43101 | I5: 43132 | J5: 43160 | K5: 43191 | L5: 43221 | M5: 43252 | N5: 43282 | O5: 43313 | P5: 43344 | Q5: 43374 | R5: 43405 | S5: 43435 | T5: META 2023 | U5: 43466 | V5: 43497 | W5: 43525 | X5: 43556 | Y5: 43586 | Z5: 43617 | AA5: 43647 | AB5: 43678 | AC5: 43709 | AD5: 43739 | AE5: 43770 | AF5: 43800 | AG5: META 2024 | AH5: 43831 | AI5: 43862 | AJ5: 43891 | AK5: 43922 | AL5: 43952 | AM5: 43983 | AN5: 44013 | AO5: 44044 | AP5: 44075 | AQ5: 44105 | AR5: 44136 | AS5: 44166 | AT5: META 2025 | AU5: 44197 | AV5: 44228 | AW5: 44256 | AX5: 44287 | AY5: 44317 | AZ5: 44348 | BA5: 44378 | BB5: 44409 | BC5: 44440 | BD5: 44470 | BE5: 44501 | BF5: 44531 | BG5: META 2025 | BH5: 44562 | BI5: 44593 | BJ5: 44621 | BK5: 44652 | BL5: 44682 | BM5: 44713 | BN5: 44743 | BO5: 44774 | BP5: 44805 | BQ5: 44835 | BR5: 44866 | BS5: 44896 | BT5: PERIODICIDADE
B7: FINANÇAS | C7: 1
C8: 2
C9: 3
C10: 4
C11: 5
B13: CLIENTES | C13: 1
C14: 2
C15: 3
C16: 4
C17: 5
B19: PROCESSOS INTERNOS | C19: 1
C20: 2
C21: 3
C22: 4
C23: 5
B25: APRENDIZADO E CRESCIMENTO | C25: 1
C26: 2
C27: 3
C28: 4
C29: 5

Sheet Desdobramentos
B5: PERSPECTIVA | C5: Nº | D5: OBJETIVO | E5: RESPONSÁVEL | F5: 2022 | G5: CONDIÇÃO | H5: RESULTADO | I5: 44562 | J5: 44593 | K5: 44621 | L5: 44652 | M5: 44682 | N5: 44713 | O5: 44743 | P5: 44774 | Q5: 44805 | R5: 44835 | S5: 44866 | T5: 44896
B7: FINANÇAS | C7: 1 | D7: =IF('Objetivos Estratégicos '!E7="","",'Objetivos Estratégicos '!E7) | E7: =IF('Objetivos Estratégicos '!F7="","",'Objetivos Estratégicos '!F7) | F7: META | G7: SOMA | H7: =IF(G7="SOMA",SUM(I7:T7),IF(G7="MÉDIA",AVERAGE(I7:T7),IF(G7="ÚLTIMO RESULTADO",MAX(I7:T7),""))) -> 15526452 | I7: 1293871 | J7: 1293871 | K7: 1293871 | L7: 1293871 | M7: 1293871 | N7: 1293871 | O7: 1293871 | P7: 1293871 | Q7: 1293871 | R7: 1293871 | S7: 1293871 | T7: 1293871
F8: REALIZADO | G8: SOMA | H8: =IF(G8="SOMA",SUM(I8:T8),IF(G8="MÉDIA",AVERAGE(I8:T8),IF(G8="ÚLTIMO RESULTADO",MAX(I8:T8),""))) -> 387756 | I8: 32313 | J8: 32313 | K8: 32313 | L8: 32313 | M8: 32313 | N8: 32313 | O8: 32313 | P8: 32313 | Q8: 32313 | R8: 32313 | S8: 32313 | T8: 32313
C9: 2 | D9: =IF('Objetivos Estratégicos '!E8="","",'Objetivos Estratégicos '!E8) | E9: =IF('Objetivos Estratégicos '!F8="","",'Objetivos Estratégicos '!F8) | F9: META | G9: SOMA | H9: =IF(G9="SOMA",SUM(I9:T9),IF(G9="MÉDIA",AVERAGE(I9:T9),IF(G9="ÚLTIMO RESULTADO",MAX(I9:T9),""))) -> 0
F10: REALIZADO | G10: SOMA | H10: =IF(G10="SOMA",SUM(I10:T10),IF(G10="MÉDIA",AVERAGE(I10:T10),IF(G10="ÚLTIMO RESULTADO",MAX(I10:T10),""))) -> 0
C11: 3 | D11: =IF('Objetivos Estratégicos '!E9="","",'Objetivos Estratégicos '!E9) | E11: =IF('Objetivos Estratégicos '!F9="","",'Objetivos Estratégicos '!F9) | F11: META | G11: SOMA | H11: =IF(G11="SOMA",SUM(I11:T11),IF(G11="MÉDIA",AVERAGE(I11:T11),IF(G11="ÚLTIMO RESULTADO",MAX(I11:T11),""))) -> 0
F12: REALIZADO | G12: SOMA | H12: =IF(G12="SOMA",SUM(I12:T12),IF(G12="MÉDIA",AVERAGE(I12:T12),IF(G12="ÚLTIMO RESULTADO",MAX(I12:T12),""))) -> 0
C13: 4 | D13: =IF('Objetivos Estratégicos '!E10="","",'Objetivos Estratégicos '!E10) | E13: =IF('Objetivos Estratégicos '!F10="","",'Objetivos Estratégicos '!F10) | F13: META | G13: SOMA | H13: =IF(G13="SOMA",SUM(I13:T13),IF(G13="MÉDIA",AVERAGE(I13:T13),IF(G13="ÚLTIMO RESULTADO",MAX(I13:T13),""))) -> 0
F14: REALIZADO | G14: SOMA | H14: =IF(G14="SOMA",SUM(I14:T14),IF(G14="MÉDIA",AVERAGE(I14:T14),IF(G14="ÚLTIMO RESULTADO",MAX(I14:T14),""))) -> 0
C15: 5 | D15: =IF('Objetivos Estratégicos '!E11="","",'Objetivos Estratégicos '!E11) | E15: =IF('Objetivos Estratégicos '!F11="","",'Objetivos Estratégicos '!F11) | F15: META | G15: SOMA | H15: =IF(G15="SOMA",SUM(I15:T15),IF(G15="MÉDIA",AVERAGE(I15:T15),IF(G15="ÚLTIMO RESULTADO",MAX(I15:T15),""))) -> 0
F16: REALIZADO | G16: SOMA | H16: =IF(G16="SOMA",SUM(I16:T16),IF(G16="MÉDIA",AVERAGE(I16:T16),IF(G16="ÚLTIMO RESULTADO",MAX(I16:T16),""))) -> 0
B18: CLIENTES | C18: 1 | D18: =IF('Objetivos Estratégicos '!E13="","",'Objetivos Estratégicos '!E13) | E18: =IF('Objetivos Estratégicos '!F13="","",'Objetivos Estratégicos '!F13) | F18: META | G18: SOMA | H18: =IF(G18="SOMA",SUM(I18:T18),IF(G18="MÉDIA",AVERAGE(I18:T18),IF(G18="ÚLTIMO RESULTADO",MAX(I18:T18),""))) -> 0
F19: REALIZADO | G19: SOMA | H19: =IF(G19="SOMA",SUM(I19:T19),IF(G19="MÉDIA",AVERAGE(I19:T19),IF(G19="ÚLTIMO RESULTADO",MAX(I19:T19),""))) -> 0
C20: 2 | D20: =IF('Objetivos Estratégicos '!E14="","",'Objetivos Estratégicos '!E14) | E20: =IF('Objetivos Estratégicos '!F14="","",'Objetivos Estratégicos '!F14) | F20: META | G20: SOMA | H20: =IF(G20="SOMA",SUM(I20:T20),IF(G20="MÉDIA",AVERAGE(I20:T20),IF(G20="ÚLTIMO RESULTADO",MAX(I20:T20),""))) -> 0
F21: REALIZADO | G21: SOMA | H21: =IF(G21="SOMA",SUM(I21:T21),IF(G21="MÉDIA",AVERAGE(I21:T21),IF(G21="ÚLTIMO RESULTADO",MAX(I21:T21),""))) -> 0
C22: 3 | D22: =IF('Objetivos Estratégicos '!E15="","",'Objetivos Estratégicos '!E15) | E22: =IF('Objetivos Estratégicos '!F15="","",'Objetivos Estratégicos '!F15) | F22: META | G22: SOMA | H22: =IF(G22="SOMA",SUM(I22:T22),IF(G22="MÉDIA",AVERAGE(I22:T22),IF(G22="ÚLTIMO RESULTADO",MAX(I22:T22),""))) -> 0
F23: REALIZADO | G23: SOMA | H23: =IF(G23="SOMA",SUM(I23:T23),IF(G23="MÉDIA",AVERAGE(I23:T23),IF(G23="ÚLTIMO RESULTADO",MAX(I23:T23),""))) -> 0
C24: 4 | D24: =IF('Objetivos Estratégicos '!E16="","",'Objetivos Estratégicos '!E16) | E24: =IF('Objetivos Estratégicos '!F16="","",'Objetivos Estratégicos '!F16) | F24: META | G24: SOMA | H24: =IF(G24="SOMA",SUM(I24:T24),IF(G24="MÉDIA",AVERAGE(I24:T24),IF(G24="ÚLTIMO RESULTADO",MAX(I24:T24),""))) -> 0
F25: REALIZADO | G25: SOMA | H25: =IF(G25="SOMA",SUM(I25:T25),IF(G25="MÉDIA",AVERAGE(I25:T25),IF(G25="ÚLTIMO RESULTADO",MAX(I25:T25),""))) -> 0
C26: 5 | D26: =IF('Objetivos Estratégicos '!E17="","",'Objetivos Estratégicos '!E17) | E26: =IF('Objetivos Estratégicos '!F17="","",'Objetivos Estratégicos '!F17) | F26: META | G26: SOMA | H26: =IF(G26="SOMA",SUM(I26:T26),IF(G26="MÉDIA",AVERAGE(I26:T26),IF(G26="ÚLTIMO RESULTADO",MAX(I26:T26),""))) -> 0
F27: REALIZADO | G27: SOMA | H27: =IF(G27="SOMA",SUM(I27:T27),IF(G27="MÉDIA",AVERAGE(I27:T27),IF(G27="ÚLTIMO RESULTADO",MAX(I27:T27),""))) -> 0
B29: PROCESSOS INTERNOS | C29: 1 | D29: =IF('Objetivos Estratégicos '!E19="","",'Objetivos Estratégicos '!E19) | E29: =IF('Objetivos Estratégicos '!F19="","",'Objetivos Estratégicos '!F19) | F29: META | G29: SOMA | H29: =IF(G29="SOMA",SUM(I29:T29),IF(G29="MÉDIA",AVERAGE(I29:T29),IF(G29="ÚLTIMO RESULTADO",MAX(I29:T29),""))) -> 0
F30: REALIZADO | G30: SOMA | H30: =IF(G30="SOMA",SUM(I30:T30),IF(G30="MÉDIA",AVERAGE(I30:T30),IF(G30="ÚLTIMO RESULTADO",MAX(I30:T30),""))) -> 0
C31: 2 | D31: =IF('Objetivos Estratégicos '!E20="","",'Objetivos Estratégicos '!E20) | E31: =IF('Objetivos Estratégicos '!F20="","",'Objetivos Estratégicos '!F20) | F31: META | G31: SOMA | H31: =IF(G31="SOMA",SUM(I31:T31),IF(G31="MÉDIA",AVERAGE(I31:T31),IF(G31="ÚLTIMO RESULTADO",MAX(I31:T31),""))) -> 0
F32: REALIZADO | G32: SOMA | H32: =IF(G32="SOMA",SUM(I32:T32),IF(G32="MÉDIA",AVERAGE(I32:T32),IF(G32="ÚLTIMO RESULTADO",MAX(I32:T32),""))) -> 0
C33: 3 | D33: =IF('Objetivos Estratégicos '!E21="","",'Objetivos Estratégicos '!E21) | E33: =IF('Objetivos Estratégicos '!F21="","",'Objetivos Estratégicos '!F21) | F33: META | G33: SOMA | H33: =IF(G33="SOMA",SUM(I33:T33),IF(G33="MÉDIA",AVERAGE(I33:T33),IF(G33="ÚLTIMO RESULTADO",MAX(I33:T33),""))) -> 0
F34: REALIZADO | G34: SOMA | H34: =IF(G34="SOMA",SUM(I34:T34),IF(G34="MÉDIA",AVERAGE(I34:T34),IF(G34="ÚLTIMO RESULTADO",MAX(I34:T34),""))) -> 0
C35: 4 | D35: =IF('Objetivos Estratégicos '!E22="","",'Objetivos Estratégicos '!E22) | E35: =IF('Objetivos Estratégicos '!F22="","",'Objetivos Estratégicos '!F22) | F35: META | G35: SOMA | H35: =IF(G35="SOMA",SUM(I35:T35),IF(G35="MÉDIA",AVERAGE(I35:T35),IF(G35="ÚLTIMO RESULTADO",MAX(I35:T35),""))) -> 0
F36: REALIZADO | G36: SOMA | H36: =IF(G36="SOMA",SUM(I36:T36),IF(G36="MÉDIA",AVERAGE(I36:T36),IF(G36="ÚLTIMO RESULTADO",MAX(I36:T36),""))) -> 0
C37: 5 | D37: =IF('Objetivos Estratégicos '!E23="","",'Objetivos Estratégicos '!E23) | E37: =IF('Objetivos Estratégicos '!F23="","",'Objetivos Estratégicos '!F23) | F37: META | G37: SOMA | H37: =IF(G37="SOMA",SUM(I37:T37),IF(G37="MÉDIA",AVERAGE(I37:T37),IF(G37="ÚLTIMO RESULTADO",MAX(I37:T37),""))) -> 0
F38: REALIZADO | G38: SOMA | H38: =IF(G38="SOMA",SUM(I38:T38),IF(G38="MÉDIA",AVERAGE(I38:T38),IF(G38="ÚLTIMO RESULTADO",MAX(I38:T38),""))) -> 0
G39: SOMA
