Workbook
Name zsupermetrics_refreshAll: SupermetricsQueries!$H$5
Name zsupermetrics_forceRefresh: SupermetricsQueries!$H$4
Name zsupermetrics_refreshAllSilent: SupermetricsQueries!$H$6

Sheet WEBINAR SEMANAL
A1: WEBINAR SEMANAL (MKT) | B1: VOLUME | J1: CUSTOS | R1: NUM FINAIS | AC1: VOLUME SEMANAL | AK1: NÚMEROS FINAIS SEMANAL
B2: Leads | C2: Leads +MQL | D2: AGENDAMENTOS | E2: CALLS | F2: PESSOAS NO PITCH | G2: VENDAS | H2: V. MKT | I2: V. COM | J2: CPL | K2: CPL MQL | L2: CP AG | M2: CP. C.R | N2: C P/ PESSOA PITCH | O2: CAC GERAL | P2: CAC MKT | Q2: CAC COM | R2: INVESTIMENTO | S2: FATURAMENTO | T2: FAT MKT | U2: FAT COM | V2: Ticket médio | W2: T.M MKT | X2: T.M COM | Y2: ROAS | Z2: ROAS MKT | AA2: ROAS COM | AC2: Leads | AD2: Leads +MQL | AE2: AGENDAMENTOS | AF2: CALLS | AG2: PESSOAS NO PITCH | AH2: VENDAS | AI2: V. MKT | AJ2: V. COM | AK2: INVESTIMENTO | AL2: FATURAMENTO | AM2: FAT MKT | AN2: FAT COM | AO2: Ticket médio | AP2: T.M MKT | AQ2: T.M COM | AR2: ROAS | AS2: ROAS MKT | AT2: ROAS COM
A3: Janeiro | B3: =R3/J3 -> 500 | C3: =B3*0.25 -> 125 | D3: =B3*0.1 -> 50 | E3: =D3*0.7 -> 35 | F3: =B3*0.25 -> 125 | G3: =H3+I3 -> 17 | H3: =F3*0.08 -> 10 | I3: =E3*0.2 -> 7 | J3: =20 -> 20 | K3: =R3/C3 -> 80 | L3: =R3/D3 -> 200 | M3: =R3/E3 -> 285.71429 | N3: =R3/F3 -> 80 | O3: =R3/G3 -> 588.23529 | P3: =R3/H3 -> 1000 | Q3: =R3/I3 -> 1428.5714 | R3: =10000 -> 10000 | S3: =T3+U3 -> 165000 | T3: =W3*H3 -> 25000 | U3: =X3*I3 -> 140000 | V3: =S3/G3 -> 9705.8824 | W3: 2500 | X3: =20000 -> 20000 | Y3: =S3/R3 -> 16.5 | Z3: =T3/R3 -> 2.5 | AA3: =U3/R3 -> 14 | AC3: =B3/4 -> 125 | AD3: =C3/4 -> 31.25 | AE3: =D3/4 -> 12.5 | AF3: =E3/4 -> 8.75 | AG3: =F3/4 -> 31.25 | AH3: =G3/4 -> 4.25 | AI3: =H3/4 -> 2.5 | AJ3: =I3/4 -> 1.75 | AK3: =R3/4 -> 2500 | AL3: =S3/4 -> 41250 | AM3: =T3/4 -> 6250 | AN3: =U3/4 -> 35000 | AO3: =AL3/AH3 -> 9705.8824 | AP3: 2500 | AQ3: =20000 -> 20000 | AR3: =AL3/AK3 -> 16.5 | AS3: =AM3/AK3 -> 2.5 | AT3: =AN3/AK3 -> 14
A4: fevereiro | B4: =R4/J4 -> 1000 | C4: =B4*0.25 -> 250 | D4: =B4*0.1 -> 100 | E4: =D4*0.7 -> 70 | F4: =B4*0.25 -> 250 | G4: =H4+I4 -> 34 | H4: =F4*0.08 -> 20 | I4: =E4*0.2 -> 14 | J4: =20 -> 20 | K4: =R4/C4 -> 80 | L4: =R4/D4 -> 200 | M4: =R4/E4 -> 285.71429 | N4: =R4/F4 -> 80 | O4: =R4/G4 -> 588.23529 | P4: =R4/H4 -> 1000 | Q4: =R4/I4 -> 1428.5714 | R4: =20000 -> 20000 | S4: =T4+U4 -> 330000 | T4: =W4*H4 -> 50000 | U4: =X4*I4 -> 280000 | V4: =S4/G4 -> 9705.8824 | W4: 2500 | X4: =20000 -> 20000 | Y4: =S4/R4 -> 16.5 | Z4: =T4/R4 -> 2.5 | AA4: =U4/R4 -> 14 | AC4: =B4/4 -> 250 | AD4: =C4/4 -> 62.5 | AE4: =D4/4 -> 25 | AF4: =E4/4 -> 17.5 | AG4: =F4/4 -> 62.5 | AH4: =G4/4 -> 8.5 | AI4: =H4/4 -> 5 | AJ4: =I4/4 -> 3.5 | AK4: =R4/4 -> 5000 | AL4: =S4/4 -> 82500 | AM4: =T4/4 -> 12500 | AN4: =U4/4 -> 70000 | AO4: =AL4/AH4 -> 9705.8824 | AP4: 2500 | AQ4: =20000 -> 20000 | AR4: =AL4/AK4 -> 16.5 | AS4: =AM4/AK4 -> 2.5 | AT4: =AN4/AK4 -> 14
A5: março | B5: =R5/J5 -> 1500 | C5: =B5*0.25 -> 375 | D5: =B5*0.1 -> 150 | E5: =D5*0.7 -> 105 | F5: =B5*0.25 -> 375 | G5: =H5+I5 -> 51 | H5: =F5*0.08 -> 30 | I5: =E5*0.2 -> 21 | J5: =20 -> 20 | K5: =R5/C5 -> 80 | L5: =R5/D5 -> 200 | M5: =R5/E5 -> 285.71429 | N5: =R5/F5 -> 80 | O5: =R5/G5 -> 588.23529 | P5: =R5/H5 -> 1000 | Q5: =R5/I5 -> 1428.5714 | R5: =30000 -> 30000 | S5: =T5+U5 -> 495000 | T5: =W5*H5 -> 75000 | U5: =X5*I5 -> 420000 | V5: =S5/G5 -> 9705.8824 | W5: 2500 | X5: =20000 -> 20000 | Y5: =S5/R5 -> 16.5 | Z5: =T5/R5 -> 2.5 | AA5: =U5/R5 -> 14 | AC5: =B5/4 -> 375 | AD5: =C5/4 -> 93.75 | AE5: =D5/4 -> 37.5 | AF5: =E5/4 -> 26.25 | AG5: =F5/4 -> 93.75 | AH5: =G5/4 -> 12.75 | AI5: =H5/4 -> 7.5 | AJ5: =I5/4 -> 5.25 | AK5: =R5/4 -> 7500 | AL5: =S5/4 -> 123750 | AM5: =T5/4 -> 18750 | AN5: =U5/4 -> 105000 | AO5: =AL5/AH5 -> 9705.8824 | AP5: 2500 | AQ5: =20000 -> 20000 | AR5: =AL5/AK5 -> 16.5 | AS5: =AM5/AK5 -> 2.5 | AT5: =AN5/AK5 -> 14
A6: abril | B6: =R6/J6 -> 2500 | C6: =B6*0.25 -> 625 | D6: =B6*0.1 -> 250 | E6: =D6*0.7 -> 175 | F6: =B6*0.25 -> 625 | G6: =H6+I6 -> 85 | H6: =F6*0.08 -> 50 | I6: =E6*0.2 -> 35 | J6: =20 -> 20 | K6: =R6/C6 -> 80 | L6: =R6/D6 -> 200 | M6: =R6/E6 -> 285.71429 | N6: =R6/F6 -> 80 | O6: =R6/G6 -> 588.23529 | P6: =R6/H6 -> 1000 | Q6: =R6/I6 -> 1428.5714 | R6: =50000 -> 50000 | S6: =T6+U6 -> 825000 | T6: =W6*H6 -> 125000 | U6: =X6*I6 -> 700000 | V6: =S6/G6 -> 9705.8824 | W6: 2500 | X6: =20000 -> 20000 | Y6: =S6/R6 -> 16.5 | Z6: =T6/R6 -> 2.5 | AA6: =U6/R6 -> 14 | AC6: =B6/4 -> 625 | AD6: =C6/4 -> 156.25 | AE6: =D6/4 -> 62.5 | AF6: =E6/4 -> 43.75 | AG6: =F6/4 -> 156.25 | AH6: =G6/4 -> 21.25 | AI6: =H6/4 -> 12.5 | AJ6: =I6/4 -> 8.75 | AK6: =R6/4 -> 12500 | AL6: =S6/4 -> 206250 | AM6: =T6/4 -> 31250 | AN6: =U6/4 -> 175000 | AO6: =AL6/AH6 -> 9705.8824 | AP6: 2500 | AQ6: =20000 -> 20000 | AR6: =AL6/AK6 -> 16.5 | AS6: =AM6/AK6 -> 2.5 | AT6: =AN6/AK6 -> 14
A7: maio | B7: =R7/J7 -> 2500 | C7: =B7*0.25 -> 625 | D7: =B7*0.1 -> 250 | E7: =D7*0.7 -> 175 | F7: =B7*0.25 -> 625 | G7: =H7+I7 -> 85 | H7: =F7*0.08 -> 50 | I7: =E7*0.2 -> 35 | J7: =20 -> 20 | K7: =R7/C7 -> 80 | L7: =R7/D7 -> 200 | M7: =R7/E7 -> 285.71429 | N7: =R7/F7 -> 80 | O7: =R7/G7 -> 588.23529 | P7: =R7/H7 -> 1000 | Q7: =R7/I7 -> 1428.5714 | R7: =50000 -> 50000 | S7: =T7+U7 -> 825000 | T7: =W7*H7 -> 125000 | U7: =X7*I7 -> 700000 | V7: =S7/G7 -> 9705.8824 | W7: 2500 | X7: =20000 -> 20000 | Y7: =S7/R7 -> 16.5 | Z7: =T7/R7 -> 2.5 | AA7: =U7/R7 -> 14 | AC7: =B7/4 -> 625 | AD7: =C7/4 -> 156.25 | AE7: =D7/4 -> 62.5 | AF7: =E7/4 -> 43.75 | AG7: =F7/4 -> 156.25 | AH7: =G7/4 -> 21.25 | AI7: =H7/4 -> 12.5 | AJ7: =I7/4 -> 8.75 | AK7: =R7/4 -> 12500 | AL7: =S7/4 -> 206250 | AM7: =T7/4 -> 31250 | AN7: =U7/4 -> 175000 | AO7: =AL7/AH7 -> 9705.8824 | AP7: 2500 | AQ7: =20000 -> 20000 | AR7: =AL7/AK7 -> 16.5 | AS7: =AM7/AK7 -> 2.5 | AT7: =AN7/AK7 -> 14
A8: junho | B8: =R8/J8 -> 500 | C8: =B8*0.25 -> 125 | D8: =B8*0.1 -> 50 | E8: =D8*0.7 -> 35 | F8: =B8*0.25 -> 125 | G8: =H8+I8 -> 17 | H8: =F8*0.08 -> 10 | I8: =E8*0.2 -> 7 | J8: =20 -> 20 | K8: =R8/C8 -> 80 | L8: =R8/D8 -> 200 | M8: =R8/E8 -> 285.71429 | N8: =R8/F8 -> 80 | O8: =R8/G8 -> 588.23529 | P8: =R8/H8 -> 1000 | Q8: =R8/I8 -> 1428.5714 | R8: =10000 -> 10000 | S8: =T8+U8 -> 165000 | T8: =W8*H8 -> 25000 | U8: =X8*I8 -> 140000 | V8: =S8/G8 -> 9705.8824 | W8: 2500 | X8: =20000 -> 20000 | Y8: =S8/R8 -> 16.5 | Z8: =T8/R8 -> 2.5 | AA8: =U8/R8 -> 14 | AC8: =B8/4 -> 125 | AD8: =C8/4 -> 31.25 | AE8: =D8/4 -> 12.5 | AF8: =E8/4 -> 8.75 | AG8: =F8/4 -> 31.25 | AH8: =G8/4 -> 4.25 | AI8: =H8/4 -> 2.5 | AJ8: =I8/4 -> 1.75 | AK8: =R8/4 -> 2500 | AL8: =S8/4 -> 41250 | AM8: =T8/4 -> 6250 | AN8: =U8/4 -> 35000 | AO8: =AL8/AH8 -> 9705.8824 | AP8: 2500 | AQ8: =20000 -> 20000 | AR8: =AL8/AK8 -> 16.5 | AS8: =AM8/AK8 -> 2.5 | AT8: =AN8/AK8 -> 14
A9: julho | B9: =R9/J9 -> 1500 | C9: =B9*0.25 -> 375 | D9: =B9*0.1 -> 150 | E9: =D9*0.7 -> 105 | F9: =B9*0.25 -> 375 | G9: =H9+I9 -> 51 | H9: =F9*0.08 -> 30 | I9: =E9*0.2 -> 21 | J9: =20 -> 20 | K9: =R9/C9 -> 80 | L9: =R9/D9 -> 200 | M9: =R9/E9 -> 285.71429 | N9: =R9/F9 -> 80 | O9: =R9/G9 -> 588.23529 | P9: =R9/H9 -> 1000 | Q9: =R9/I9 -> 1428.5714 | R9: 30000 | S9: =T9+U9 -> 495000 | T9: =W9*H9 -> 75000 | U9: =X9*I9 -> 420000 | V9: =S9/G9 -> 9705.8824 | W9: 2500 | X9: =20000 -> 20000 | Y9: =S9/R9 -> 16.5 | Z9: =T9/R9 -> 2.5 | AA9: =U9/R9 -> 14 | AC9: =B9/4 -> 375 | AD9: =C9/4 -> 93.75 | AE9: =D9/4 -> 37.5 | AF9: =E9/4 -> 26.25 | AG9: =F9/4 -> 93.75 | AH9: =G9/4 -> 12.75 | AI9: =H9/4 -> 7.5 | AJ9: =I9/4 -> 5.25 | AK9: =R9/4 -> 7500 | AL9: =S9/4 -> 123750 | AM9: =T9/4 -> 18750 | AN9: =U9/4 -> 105000 | AO9: =AL9/AH9 -> 9705.8824 | AP9: 2500 | AQ9: =20000 -> 20000 | AR9: =AL9/AK9 -> 16.5 | AS9: =AM9/AK9 -> 2.5 | AT9: =AN9/AK9 -> 14
A10: agosto | B10: =R10/J10 -> 1500 | C10: =B10*0.25 -> 375 | D10: =B10*0.1 -> 150 | E10: =D10*0.7 -> 105 | F10: =B10*0.25 -> 375 | G10: =H10+I10 -> 51 | H10: =F10*0.08 -> 30 | I10: =E10*0.2 -> 21 | J10: =20 -> 20 | K10: =R10/C10 -> 80 | L10: =R10/D10 -> 200 | M10: =R10/E10 -> 285.71429 | N10: =R10/F10 -> 80 | O10: =R10/G10 -> 588.23529 | P10: =R10/H10 -> 1000 | Q10: =R10/I10 -> 1428.5714 | R10: =30000 -> 30000 | S10: =T10+U10 -> 495000 | T10: =W10*H10 -> 75000 | U10: =X10*I10 -> 420000 | V10: =S10/G10 -> 9705.8824 | W10: 2500 | X10: =20000 -> 20000 | Y10: =S10/R10 -> 16.5 | Z10: =T10/R10 -> 2.5 | AA10: =U10/R10 -> 14 | AC10: =B10/4 -> 375 | AD10: =C10/4 -> 93.75 | AE10: =D10/4 -> 37.5 | AF10: =E10/4 -> 26.25 | AG10: =F10/4 -> 93.75 | AH10: =G10/4 -> 12.75 | AI10: =H10/4 -> 7.5 | AJ10: =I10/4 -> 5.25 | AK10: =R10/4 -> 7500 | AL10: =S10/4 -> 123750 | AM10: =T10/4 -> 18750 | AN10: =U10/4 -> 105000 | AO10: =AL10/AH10 -> 9705.8824 | AP10: 2500 | AQ10: =20000 -> 20000 | AR10: =AL10/AK10 -> 16.5 | AS10: =AM10/AK10 -> 2.5 | AT10: =AN10/AK10 -> 14
A11: setembro | B11: =R11/J11 -> 1500 | C11: =B11*0.25 -> 375 | D11: =B11*0.1 -> 150 | E11: =D11*0.7 -> 105 | F11: =B11*0.25 -> 375 | G11: =H11+I11 -> 51 | H11: =F11*0.08 -> 30 | I11: =E11*0.2 -> 21 | J11: =20 -> 20 | K11: =R11/C11 -> 80 | L11: =R11/D11 -> 200 | M11: =R11/E11 -> 285.71429 | N11: =R11/F11 -> 80 | O11: =R11/G11 -> 588.23529 | P11: =R11/H11 -> 1000 | Q11: =R11/I11 -> 1428.5714 | R11: =30000 -> 30000 | S11: =T11+U11 -> 495000 | T11: =W11*H11 -> 75000 | U11: =X11*I11 -> 420000 | V11: =S11/G11 -> 9705.8824 | W11: 2500 | X11: =20000 -> 20000 | Y11: =S11/R11 -> 16.5 | Z11: =T11/R11 -> 2.5 | AA11: =U11/R11 -> 14 | AC11: =B11/4 -> 375 | AD11: =C11/4 -> 93.75 | AE11: =D11/4 -> 37.5 | AF11: =E11/4 -> 26.25 | AG11: =F11/4 -> 93.75 | AH11: =G11/4 -> 12.75 | AI11: =H11/4 -> 7.5 | AJ11: =I11/4 -> 5.25 | AK11: =R11/4 -> 7500 | AL11: =S11/4 -> 123750 | AM11: =T11/4 -> 18750 | AN11: =U11/4 -> 105000 | AO11: =AL11/AH11 -> 9705.8824 | AP11: 2500 | AQ11: =20000 -> 20000 | AR11: =AL11/AK11 -> 16.5 | AS11: =AM11/AK11 -> 2.5 | AT11: =AN11/AK11 -> 14
A12: outubro | B12: =R12/J12 -> 2500 | C12: =B12*0.25 -> 625 | D12: =B12*0.1 -> 250 | E12: =D12*0.7 -> 175 | F12: =B12*0.25 -> 625 | G12: =H12+I12 -> 85 | H12: =F12*0.08 -> 50 | I12: =E12*0.2 -> 35 | J12: =20 -> 20 | K12: =R12/C12 -> 80 | L12: =R12/D12 -> 200 | M12: =R12/E12 -> 285.71429 | N12: =R12/F12 -> 80 | O12: =R12/G12 -> 588.23529 | P12: =R12/H12 -> 1000 | Q12: =R12/I12 -> 1428.5714 | R12: =50000 -> 50000 | S12: =T12+U12 -> 825000 | T12: =W12*H12 -> 125000 | U12: =X12*I12 -> 700000 | V12: =S12/G12 -> 9705.8824 | W12: 2500 | X12: =20000 -> 20000 | Y12: =S12/R12 -> 16.5 | Z12: =T12/R12 -> 2.5 | AA12: =U12/R12 -> 14 | AC12: =B12/4 -> 625 | AD12: =C12/4 -> 156.25 | AE12: =D12/4 -> 62.5 | AF12: =E12/4 -> 43.75 | AG12: =F12/4 -> 156.25 | AH12: =G12/4 -> 21.25 | AI12: =H12/4 -> 12.5 | AJ12: =I12/4 -> 8.75 | AK12: =R12/4 -> 12500 | AL12: =S12/4 -> 206250 | AM12: =T12/4 -> 31250 | AN12: =U12/4 -> 175000 | AO12: =AL12/AH12 -> 9705.8824 | AP12: 2500 | AQ12: =20000 -> 20000 | AR12: =AL12/AK12 -> 16.5 | AS12: =AM12/AK12 -> 2.5 | AT12: =AN12/AK12 -> 14
A13: novembro | B13: =R13/J13 -> 2500 | C13: =B13*0.25 -> 625 | D13: =B13*0.1 -> 250 | E13: =D13*0.7 -> 175 | F13: =B13*0.25 -> 625 | G13: =H13+I13 -> 85 | H13: =F13*0.08 -> 50 | I13: =E13*0.2 -> 35 | J13: =20 -> 20 | K13: =R13/C13 -> 80 | L13: =R13/D13 -> 200 | M13: =R13/E13 -> 285.71429 | N13: =R13/F13 -> 80 | O13: =R13/G13 -> 588.23529 | P13: =R13/H13 -> 1000 | Q13: =R13/I13 -> 1428.5714 | R13: =50000 -> 50000 | S13: =T13+U13 -> 825000 | T13: =W13*H13 -> 125000 | U13: =X13*I13 -> 700000 | V13: =S13/G13 -> 9705.8824 | W13: 2500 | X13: =20000 -> 20000 | Y13: =S13/R13 -> 16.5 | Z13: =T13/R13 -> 2.5 | AA13: =U13/R13 -> 14 | AC13: =B13/4 -> 625 | AD13: =C13/4 -> 156.25 | AE13: =D13/4 -> 62.5 | AF13: =E13/4 -> 43.75 | AG13: =F13/4 -> 156.25 | AH13: =G13/4 -> 21.25 | AI13: =H13/4 -> 12.5 | AJ13: =I13/4 -> 8.75 | AK13: =R13/4 -> 12500 | AL13: =S13/4 -> 206250 | AM13: =T13/4 -> 31250 | AN13: =U13/4 -> 175000 | AO13: =AL13/AH13 -> 9705.8824 | AP13: 2500 | AQ13: =20000 -> 20000 | AR13: =AL13/AK13 -> 16.5 | AS13: =AM13/AK13 -> 2.5 | AT13: =AN13/AK13 -> 14
A14: dezembro | B14: =R14/J14 -> 500 | C14: =B14*0.25 -> 125 | D14: =B14*0.1 -> 50 | E14: =D14*0.7 -> 35 | F14: =B14*0.25 -> 125 | G14: =H14+I14 -> 17 | H14: =F14*0.08 -> 10 | I14: =E14*0.2 -> 7 | J14: =20 -> 20 | K14: =R14/C14 -> 80 | L14: =R14/D14 -> 200 | M14: =R14/E14 -> 285.71429 | N14: =R14/F14 -> 80 | O14: =R14/G14 -> 588.23529 | P14: =R14/H14 -> 1000 | Q14: =R14/I14 -> 1428.5714 | R14: =10000 -> 10000 | S14: =T14+U14 -> 165000 | T14: =W14*H14 -> 25000 | U14: =X14*I14 -> 140000 | V14: =S14/G14 -> 9705.8824 | W14: 2500 | X14: =20000 -> 20000 | Y14: =S14/R14 -> 16.5 | Z14: =T14/R14 -> 2.5 | AA14: =U14/R14 -> 14 | AC14: =B14/4 -> 125 | AD14: =C14/4 -> 31.25 | AE14: =D14/4 -> 12.5 | AF14: =E14/4 -> 8.75 | AG14: =F14/4 -> 31.25 | AH14: =G14/4 -> 4.25 | AI14: =H14/4 -> 2.5 | AJ14: =I14/4 -> 1.75 | AK14: =R14/4 -> 2500 | AL14: =S14/4 -> 41250 | AM14: =T14/4 -> 6250 | AN14: =U14/4 -> 35000 | AO14: =AL14/AH14 -> 9705.8824 | AP14: 2500 | AQ14: =20000 -> 20000 | AR14: =AL14/AK14 -> 16.5 | AS14: =AM14/AK14 -> 2.5 | AT14: =AN14/AK14 -> 14
A16: TOTAL | B16: =SUM(B3:B14) -> 18500 | C16: =SUM(C3:C14) -> 4625 | D16: =SUM(D3:D14) -> 1850 | E16: =SUM(E3:E14) -> 1295 | F16: =SUM(F3:F14) -> 4625 | G16: =SUM(G3:G14) -> 629 | H16: =SUM(H3:H14) -> 370 | I16: =SUM(I3:I14) -> 259 | R16: =SUM(R3:R14) -> 370000 | S16: =SUM(S3:S14) -> 6105000 | T16: =SUM(T3:T14) -> 925000 | U16: =SUM(U3:U14) -> 5180000

Sheet TRAINING DAY (FORA DE SP)
A1: TRAINING DAY (FORA DE SP) | B1: VOLUME | J1: CUSTOS | R1: NUM FINAIS | AC1: VOLUME SEMANAL | AK1: NÚMEROS FINAIS SEMANAL
B2: Compras Pres | C2: Compras +MQL | F2: PESSOAS NO PITCH | G2: VENDAS | H2: V. MKT | I2: V. COM | J2: CAC | K2: CAC MQL | N2: C P/ PESSOA PITCH | O2: CAC GERAL | P2: CAC MKT | Q2: CAC COM | R2: INVESTIMENTO | S2: FATURAMENTO | T2: FAT MKT | U2: FAT COM | V2: Ticket médio | W2: T.M MKT | X2: T.M COM | Y2: ROAS | Z2: ROAS MKT | AA2: ROAS COM | AC2: COMPRAS | AD2: Compras +MQL | AG2: PESSOAS NO PITCH | AH2: VENDAS | AI2: V. MKT | AJ2: V. COM | AK2: INVESTIMENTO | AL2: FATURAMENTO | AM2: FAT MKT | AN2: FAT COM | AO2: Ticket médio | AP2: T.M MKT | AQ2: T.M COM | AR2: ROAS | AS2: ROAS MKT | AT2: ROAS COM
A3: Janeiro | B3: =R3/J3 -> 50 | C3: =B3*0.5 -> 25 | F3: =B3+B3*0.25 -> 62.5 | G3: =H3+I3 -> 59.375 | H3: =B3 -> 50 | I3: =F3*0.15 -> 9.375 | J3: =400 -> 400 | K3: =R3/C3 -> 800 | N3: =R3/F3 -> 320 | O3: =R3/G3 -> 336.84211 | P3: =R3/H3 -> 400 | Q3: =R3/I3 -> 2133.3333 | R3: =20000 -> 20000 | S3: =T3+U3 -> 202500 | T3: =W3*H3 -> 15000 | U3: =X3*I3 -> 187500 | V3: =S3/G3 -> 3410.5263 | W3: 300 | X3: =20000 -> 20000 | Y3: =S3/R3 -> 10.125 | Z3: =T3/R3 -> 0.75 | AA3: =U3/R3 -> 9.375 | AC3: =B3/4 -> 12.5 | AD3: =C3/4 -> 6.25 | AG3: =F3/4 -> 15.625 | AH3: =G3/4 -> 14.84375 | AI3: =H3/4 -> 12.5 | AJ3: =I3/4 -> 2.34375 | AK3: =R3/4 -> 5000 | AL3: =S3/4 -> 50625 | AM3: =T3/4 -> 3750 | AN3: =U3/4 -> 46875 | AO3: =AL3/AH3 -> 3410.5263 | AP3: 2500 | AQ3: =20000 -> 20000 | AR3: =AL3/AK3 -> 10.125 | AS3: =AM3/AK3 -> 0.75 | AT3: =AN3/AK3 -> 9.375
A4: fevereiro | B4: =R4/J4 -> 150 | C4: =B4*0.5 -> 75 | F4: =B4+B4*0.25 -> 187.5 | G4: =H4+I4 -> 178.125 | H4: =B4 -> 150 | I4: =F4*0.15 -> 28.125 | J4: =400 -> 400 | K4: =R4/C4 -> 800 | N4: =R4/F4 -> 320 | O4: =R4/G4 -> 336.84211 | P4: =R4/H4 -> 400 | Q4: =R4/I4 -> 2133.3333 | R4: =60000 -> 60000 | S4: =T4+U4 -> 607500 | T4: =W4*H4 -> 45000 | U4: =X4*I4 -> 562500 | V4: =S4/G4 -> 3410.5263 | W4: 300 | X4: =20000 -> 20000 | Y4: =S4/R4 -> 10.125 | Z4: =T4/R4 -> 0.75 | AA4: =U4/R4 -> 9.375 | AC4: =B4/4 -> 37.5 | AD4: =C4/4 -> 18.75 | AG4: =F4/4 -> 46.875 | AH4: =G4/4 -> 44.53125 | AI4: =H4/4 -> 37.5 | AJ4: =I4/4 -> 7.03125 | AK4: =R4/4 -> 15000 | AL4: =S4/4 -> 151875 | AM4: =T4/4 -> 11250 | AN4: =U4/4 -> 140625 | AO4: =AL4/AH4 -> 3410.5263 | AP4: 2500 | AQ4: =20000 -> 20000 | AR4: =AL4/AK4 -> 10.125 | AS4: =AM4/AK4 -> 0.75 | AT4: =AN4/AK4 -> 9.375
A5: março | B5: =R5/J5 -> 50 | C5: =B5*0.5 -> 25 | F5: =B5+B5*0.25 -> 62.5 | G5: =H5+I5 -> 59.375 | H5: =B5 -> 50 | I5: =F5*0.15 -> 9.375 | J5: =400 -> 400 | K5: =R5/C5 -> 800 | N5: =R5/F5 -> 320 | O5: =R5/G5 -> 336.84211 | P5: =R5/H5 -> 400 | Q5: =R5/I5 -> 2133.3333 | R5: =20000 -> 20000 | S5: =T5+U5 -> 202500 | T5: =W5*H5 -> 15000 | U5: =X5*I5 -> 187500 | V5: =S5/G5 -> 3410.5263 | W5: 300 | X5: =20000 -> 20000 | Y5: =S5/R5 -> 10.125 | Z5: =T5/R5 -> 0.75 | AA5: =U5/R5 -> 9.375 | AC5: =B5/4 -> 12.5 | AD5: =C5/4 -> 6.25 | AG5: =F5/4 -> 15.625 | AH5: =G5/4 -> 14.84375 | AI5: =H5/4 -> 12.5 | AJ5: =I5/4 -> 2.34375 | AK5: =R5/4 -> 5000 | AL5: =S5/4 -> 50625 | AM5: =T5/4 -> 3750 | AN5: =U5/4 -> 46875 | AO5: =AL5/AH5 -> 3410.5263 | AP5: 2500 | AQ5: =20000 -> 20000 | AR5: =AL5/AK5 -> 10.125 | AS5: =AM5/AK5 -> 0.75 | AT5: =AN5/AK5 -> 9.375
A6: abril | B6: =R6/J6 -> 125 | C6: =B6*0.5 -> 62.5 | F6: =B6+B6*0.25 -> 156.25 | G6: =H6+I6 -> 148.4375 | H6: =B6 -> 125 | I6: =F6*0.15 -> 23.4375 | J6: =400 -> 400 | K6: =R6/C6 -> 800 | N6: =R6/F6 -> 320 | O6: =R6/G6 -> 336.84211 | P6: =R6/H6 -> 400 | Q6: =R6/I6 -> 2133.3333 | R6: =50000 -> 50000 | S6: =T6+U6 -> 506250 | T6: =W6*H6 -> 37500 | U6: =X6*I6 -> 468750 | V6: =S6/G6 -> 3410.5263 | W6: 300 | X6: =20000 -> 20000 | Y6: =S6/R6 -> 10.125 | Z6: =T6/R6 -> 0.75 | AA6: =U6/R6 -> 9.375 | AC6: =B6/4 -> 31.25 | AD6: =C6/4 -> 15.625 | AG6: =F6/4 -> 39.0625 | AH6: =G6/4 -> 37.109375 | AI6: =H6/4 -> 31.25 | AJ6: =I6/4 -> 5.859375 | AK6: =R6/4 -> 12500 | AL6: =S6/4 -> 126562.5 | AM6: =T6/4 -> 9375 | AN6: =U6/4 -> 117187.5 | AO6: =AL6/AH6 -> 3410.5263 | AP6: 2500 | AQ6: =20000 -> 20000 | AR6: =AL6/AK6 -> 10.125 | AS6: =AM6/AK6 -> 0.75 | AT6: =AN6/AK6 -> 9.375
A7: maio | B7: =R7/J7 -> 125 | C7: =B7*0.5 -> 62.5 | F7: =B7+B7*0.25 -> 156.25 | G7: =H7+I7 -> 148.4375 | H7: =B7 -> 125 | I7: =F7*0.15 -> 23.4375 | J7: =400 -> 400 | K7: =R7/C7 -> 800 | N7: =R7/F7 -> 320 | O7: =R7/G7 -> 336.84211 | P7: =R7/H7 -> 400 | Q7: =R7/I7 -> 2133.3333 | R7: =50000 -> 50000 | S7: =T7+U7 -> 506250 | T7: =W7*H7 -> 37500 | U7: =X7*I7 -> 468750 | V7: =S7/G7 -> 3410.5263 | W7: 300 | X7: =20000 -> 20000 | Y7: =S7/R7 -> 10.125 | Z7: =T7/R7 -> 0.75 | AA7: =U7/R7 -> 9.375 | AC7: =B7/4 -> 31.25 | AD7: =C7/4 -> 15.625 | AG7: =F7/4 -> 39.0625 | AH7: =G7/4 -> 37.109375 | AI7: =H7/4 -> 31.25 | AJ7: =I7/4 -> 5.859375 | AK7: =R7/4 -> 12500 | AL7: =S7/4 -> 126562.5 | AM7: =T7/4 -> 9375 | AN7: =U7/4 -> 117187.5 | AO7: =AL7/AH7 -> 3410.5263 | AP7: 2500 | AQ7: =20000 -> 20000 | AR7: =AL7/AK7 -> 10.125 | AS7: =AM7/AK7 -> 0.75 | AT7: =AN7/AK7 -> 9.375
A8: junho | B8: =R8/J8 -> 0 | C8: =B8*0.5 -> 0 | F8: =B8+B8*0.25 -> 0 | G8: =H8+I8 -> 0 | H8: =B8 -> 0 | I8: =F8*0.15 -> 0 | J8: =400 -> 400 | K8: =R8/C8 -> #DIV/0! | N8: =R8/F8 -> #DIV/0! | O8: =R8/G8 -> #DIV/0! | P8: =R8/H8 -> #DIV/0! | Q8: =R8/I8 -> #DIV/0! | S8: =T8+U8 -> 0 | T8: =W8*H8 -> 0 | U8: =X8*I8 -> 0 | V8: =S8/G8 -> #DIV/0! | W8: 300 | X8: =20000 -> 20000 | Y8: =S8/R8 -> #DIV/0! | Z8: =T8/R8 -> #DIV/0! | AA8: =U8/R8 -> #DIV/0! | AC8: =B8/4 -> 0 | AD8: =C8/4 -> 0 | AG8: =F8/4 -> 0 | AH8: =G8/4 -> 0 | AI8: =H8/4 -> 0 | AJ8: =I8/4 -> 0 | AK8: =R8/4 -> 0 | AL8: =S8/4 -> 0 | AM8: =T8/4 -> 0 | AN8: =U8/4 -> 0 | AO8: =AL8/AH8 -> #DIV/0! | AP8: 2500 | AQ8: =20000 -> 20000 | AR8: =AL8/AK8 -> #DIV/0! | AS8: =AM8/AK8 -> #DIV/0! | AT8: =AN8/AK8 -> #DIV/0!
A9: julho | B9: =R9/J9 -> 0 | C9: =B9*0.5 -> 0 | F9: =B9+B9*0.25 -> 0 | G9: =H9+I9 -> 0 | H9: =B9 -> 0 | I9: =F9*0.15 -> 0 | J9: =400 -> 400 | K9: =R9/C9 -> #DIV/0! | N9: =R9/F9 -> #DIV/0! | O9: =R9/G9 -> #DIV/0! | P9: =R9/H9 -> #DIV/0! | Q9: =R9/I9 -> #DIV/0! | S9: =T9+U9 -> 0 | T9: =W9*H9 -> 0 | U9: =X9*I9 -> 0 | V9: =S9/G9 -> #DIV/0! | W9: 300 | X9: =20000 -> 20000 | Y9: =S9/R9 -> #DIV/0! | Z9: =T9/R9 -> #DIV/0! | AA9: =U9/R9 -> #DIV/0! | AC9: =B9/4 -> 0 | AD9: =C9/4 -> 0 | AG9: =F9/4 -> 0 | AH9: =G9/4 -> 0 | AI9: =H9/4 -> 0 | AJ9: =I9/4 -> 0 | AK9: =R9/4 -> 0 | AL9: =S9/4 -> 0 | AM9: =T9/4 -> 0 | AN9: =U9/4 -> 0 | AO9: =AL9/AH9 -> #DIV/0! | AP9: 2500 | AQ9: =20000 -> 20000 | AR9: =AL9/AK9 -> #DIV/0! | AS9: =AM9/AK9 -> #DIV/0! | AT9: =AN9/AK9 -> #DIV/0!
A10: agosto | B10: =R10/J10 -> 0 | C10: =B10*0.5 -> 0 | F10: =B10+B10*0.25 -> 0 | G10: =H10+I10 -> 0 | H10: =B10 -> 0 | I10: =F10*0.15 -> 0 | J10: =400 -> 400 | K10: =R10/C10 -> #DIV/0! | N10: =R10/F10 -> #DIV/0! | O10: =R10/G10 -> #DIV/0! | P10: =R10/H10 -> #DIV/0! | Q10: =R10/I10 -> #DIV/0! | S10: =T10+U10 -> 0 | T10: =W10*H10 -> 0 | U10: =X10*I10 -> 0 | V10: =S10/G10 -> #DIV/0! | W10: 300 | X10: =20000 -> 20000 | Y10: =S10/R10 -> #DIV/0! | Z10: =T10/R10 -> #DIV/0! | AA10: =U10/R10 -> #DIV/0! | AC10: =B10/4 -> 0 | AD10: =C10/4 -> 0 | AG10: =F10/4 -> 0 | AH10: =G10/4 -> 0 | AI10: =H10/4 -> 0 | AJ10: =I10/4 -> 0 | AK10: =R10/4 -> 0 | AL10: =S10/4 -> 0 | AM10: =T10/4 -> 0 | AN10: =U10/4 -> 0 | AO10: =AL10/AH10 -> #DIV/0! | AP10: 2500 | AQ10: =20000 -> 20000 | AR10: =AL10/AK10 -> #DIV/0! | AS10: =AM10/AK10 -> #DIV/0! | AT10: =AN10/AK10 -> #DIV/0!
A11: setembro | B11: =R11/J11 -> 0 | C11: =B11*0.5 -> 0 | F11: =B11+B11*0.25 -> 0 | G11: =H11+I11 -> 0 | H11: =B11 -> 0 | I11: =F11*0.15 -> 0 | J11: =400 -> 400 | K11: =R11/C11 -> #DIV/0! | N11: =R11/F11 -> #DIV/0! | O11: =R11/G11 -> #DIV/0! | P11: =R11/H11 -> #DIV/0! | Q11: =R11/I11 -> #DIV/0! | S11: =T11+U11 -> 0 | T11: =W11*H11 -> 0 | U11: =X11*I11 -> 0 | V11: =S11/G11 -> #DIV/0! | W11: 300 | X11: =20000 -> 20000 | Y11: =S11/R11 -> #DIV/0! | Z11: =T11/R11 -> #DIV/0! | AA11: =U11/R11 -> #DIV/0! | AC11: =B11/4 -> 0 | AD11: =C11/4 -> 0 | AG11: =F11/4 -> 0 | AH11: =G11/4 -> 0 | AI11: =H11/4 -> 0 | AJ11: =I11/4 -> 0 | AK11: =R11/4 -> 0 | AL11: =S11/4 -> 0 | AM11: =T11/4 -> 0 | AN11: =U11/4 -> 0 | AO11: =AL11/AH11 -> #DIV/0! | AP11: 2500 | AQ11: =20000 -> 20000 | AR11: =AL11/AK11 -> #DIV/0! | AS11: =AM11/AK11 -> #DIV/0! | AT11: =AN11/AK11 -> #DIV/0!
A12: outubro | B12: =R12/J12 -> 0 | C12: =B12*0.5 -> 0 | F12: =B12+B12*0.25 -> 0 | G12: =H12+I12 -> 0 | H12: =B12 -> 0 | I12: =F12*0.15 -> 0 | J12: =400 -> 400 | K12: =R12/C12 -> #DIV/0! | N12: =R12/F12 -> #DIV/0! | O12: =R12/G12 -> #DIV/0! | P12: =R12/H12 -> #DIV/0! | Q12: =R12/I12 -> #DIV/0! | S12: =T12+U12 -> 0 | T12: =W12*H12 -> 0 | U12: =X12*I12 -> 0 | V12: =S12/G12 -> #DIV/0! | W12: 300 | X12: =20000 -> 20000 | Y12: =S12/R12 -> #DIV/0! | Z12: =T12/R12 -> #DIV/0! | AA12: =U12/R12 -> #DIV/0! | AC12: =B12/4 -> 0 | AD12: =C12/4 -> 0 | AG12: =F12/4 -> 0 | AH12: =G12/4 -> 0 | AI12: =H12/4 -> 0 | AJ12: =I12/4 -> 0 | AK12: =R12/4 -> 0 | AL12: =S12/4 -> 0 | AM12: =T12/4 -> 0 | AN12: =U12/4 -> 0 | AO12: =AL12/AH12 -> #DIV/0! | AP12: 2500 | AQ12: =20000 -> 20000 | AR12: =AL12/AK12 -> #DIV/0! | AS12: =AM12/AK12 -> #DIV/0! | AT12: =AN12/AK12 -> #DIV/0!
A13: novembro | B13: =R13/J13 -> 0 | C13: =B13*0.5 -> 0 | F13: =B13+B13*0.25 -> 0 | G13: =H13+I13 -> 0 | H13: =B13 -> 0 | I13: =F13*0.15 -> 0 | J13: =400 -> 400 | K13: =R13/C13 -> #DIV/0! | N13: =R13/F13 -> #DIV/0! | O13: =R13/G13 -> #DIV/0! | P13: =R13/H13 -> #DIV/0! | Q13: =R13/I13 -> #DIV/0! | S13: =T13+U13 -> 0 | T13: =W13*H13 -> 0 | U13: =X13*I13 -> 0 | V13: =S13/G13 -> #DIV/0! | W13: 300 | X13: =20000 -> 20000 | Y13: =S13/R13 -> #DIV/0! | Z13: =T13/R13 -> #DIV/0! | AA13: =U13/R13 -> #DIV/0! | AC13: =B13/4 -> 0 | AD13: =C13/4 -> 0 | AG13: =F13/4 -> 0 | AH13: =G13/4 -> 0 | AI13: =H13/4 -> 0 | AJ13: =I13/4 -> 0 | AK13: =R13/4 -> 0 | AL13: =S13/4 -> 0 | AM13: =T13/4 -> 0 | AN13: =U13/4 -> 0 | AO13: =AL13/AH13 -> #DIV/0! | AP13: 2500 | AQ13: =20000 -> 20000 | AR13: =AL13/AK13 -> #DIV/0! | AS13: =AM13/AK13 -> #DIV/0! | AT13: =AN13/AK13 -> #DIV/0!
A14: dezembro | B14: =R14/J14 -> 0 | C14: =B14*0.5 -> 0 | F14: =B14+B14*0.25 -> 0 | G14: =H14+I14 -> 0 | H14: =B14 -> 0 | I14: =F14*0.15 -> 0 | J14: =400 -> 400 | K14: =R14/C14 -> #DIV/0! | N14: =R14/F14 -> #DIV/0! | O14: =R14/G14 -> #DIV/0! | P14: =R14/H14 -> #DIV/0! | Q14: =R14/I14 -> #DIV/0! | S14: =T14+U14 -> 0 | T14: =W14*H14 -> 0 | U14: =X14*I14 -> 0 | V14: =S14/G14 -> #DIV/0! | W14: 300 | X14: =20000 -> 20000 | Y14: =S14/R14 -> #DIV/0! | Z14: =T14/R14 -> #DIV/0! | AA14: =U14/R14 -> #DIV/0! | AC14: =B14/4 -> 0 | AD14: =C14/4 -> 0 | AG14: =F14/4 -> 0 | AH14: =G14/4 -> 0 | AI14: =H14/4 -> 0 | AJ14: =I14/4 -> 0 | AK14: =R14/4 -> 0 | AL14: =S14/4 -> 0 | AM14: =T14/4 -> 0 | AN14: =U14/4 -> 0 | AO14: =AL14/AH14 -> #DIV/0! | AP14: 2500 | AQ14: =20000 -> 20000 | AR14: =AL14/AK14 -> #DIV/0! | AS14: =AM14/AK14 -> #DIV/0! | AT14: =AN14/AK14 -> #DIV/0!
A16: TOTAL | B16: =SUM(B3:B14) -> 500 | C16: =SUM(C3:C14) -> 250 | D16: =SUM(D3:D14) -> 0 | E16: =SUM(E3:E14) -> 0 | F16: =SUM(F3:F14) -> 625 | G16: =SUM(G3:G14) -> 593.75 | H16: =SUM(H3:H14) -> 500 | I16: =SUM(I3:I14) -> 93.75 | R16: =SUM(R3:R14) -> 200000 | S16: =SUM(S3:S14) -> 2025000 | T16: =SUM(T3:T14) -> 150000 | U16: =SUM(U3:U14) -> 1875000

Sheet CAPTAÇÃO PRO COMERCIAL
A1: CAPTAÇÃO P/ COMERCIAL | B1: VOLUME | J1: CUSTOS | R1: NUM FINAIS | AC1: VOLUME SEMANAL | AK1: NÚMEROS FINAIS SEMANAL
B2: Leads | C2: Leads +MQL | D2: AGENDAMENTOS | E2: CALLS | G2: VENDAS | H2: V. MKT | I2: V. COM | J2: CPL | K2: CPL MQL | L2: CP AG | M2: CP. C.R | N2: C P/ PESSOA PITCH | O2: CAC GERAL | P2: CAC MKT | Q2: CAC COM | R2: INVESTIMENTO | S2: FATURAMENTO | T2: FAT MKT | U2: FAT COM | V2: Ticket médio | W2: T.M MKT | X2: T.M COM | Y2: ROAS | Z2: ROAS MKT | AA2: ROAS COM | AC2: Leads | AD2: Leads +MQL | AE2: AGENDAMENTOS | AF2: CALLS | AG2: PESSOAS NO PITCH | AH2: VENDAS | AI2: V. MKT | AJ2: V. COM | AK2: INVESTIMENTO | AL2: FATURAMENTO | AM2: FAT MKT | AN2: FAT COM | AO2: Ticket médio | AP2: T.M MKT | AQ2: T.M COM | AR2: ROAS | AS2: ROAS MKT | AT2: ROAS COM
A3: Janeiro | B3: =R3/J3 -> 500 | C3: =B3*0.25 -> 125 | D3: =B3*0.1 -> 50 | E3: =D3*0.7 -> 35 | G3: =H3+I3 -> 7 | H3: =F3*0.08 -> 0 | I3: =E3*0.2 -> 7 | J3: =20 -> 20 | K3: =R3/C3 -> 80 | L3: =R3/D3 -> 200 | M3: =R3/E3 -> 285.71429 | N3: =R3/F3 -> #DIV/0! | O3: =R3/G3 -> 1428.5714 | P3: =R3/H3 -> #DIV/0! | Q3: =R3/I3 -> 1428.5714 | R3: =10000 -> 10000 | S3: =T3+U3 -> 140000 | T3: =W3*H3 -> 0 | U3: =X3*I3 -> 140000 | V3: =S3/G3 -> 20000 | W3: 2500 | X3: =20000 -> 20000 | Y3: =S3/R3 -> 14 | Z3: =T3/R3 -> 0 | AA3: =U3/R3 -> 14 | AC3: =B3/4 -> 125 | AD3: =C3/4 -> 31.25 | AE3: =D3/4 -> 12.5 | AF3: =E3/4 -> 8.75 | AG3: =F3/4 -> 0 | AH3: =G3/4 -> 1.75 | AI3: =H3/4 -> 0 | AJ3: =I3/4 -> 1.75 | AK3: =R3/4 -> 2500 | AL3: =S3/4 -> 35000 | AM3: =T3/4 -> 0 | AN3: =U3/4 -> 35000 | AO3: =AL3/AH3 -> 20000 | AP3: 2500 | AQ3: =20000 -> 20000 | AR3: =AL3/AK3 -> 14 | AS3: =AM3/AK3 -> 0 | AT3: =AN3/AK3 -> 14
A4: fevereiro | B4: =R4/J4 -> 1000 | C4: =B4*0.25 -> 250 | D4: =B4*0.1 -> 100 | E4: =D4*0.7 -> 70 | G4: =H4+I4 -> 14 | H4: =F4*0.08 -> 0 | I4: =E4*0.2 -> 14 | J4: =20 -> 20 | K4: =R4/C4 -> 80 | L4: =R4/D4 -> 200 | M4: =R4/E4 -> 285.71429 | N4: =R4/F4 -> #DIV/0! | O4: =R4/G4 -> 1428.5714 | P4: =R4/H4 -> #DIV/0! | Q4: =R4/I4 -> 1428.5714 | R4: =20000 -> 20000 | S4: =T4+U4 -> 280000 | T4: =W4*H4 -> 0 | U4: =X4*I4 -> 280000 | V4: =S4/G4 -> 20000 | W4: 2500 | X4: =20000 -> 20000 | Y4: =S4/R4 -> 14 | Z4: =T4/R4 -> 0 | AA4: =U4/R4 -> 14 | AC4: =B4/4 -> 250 | AD4: =C4/4 -> 62.5 | AE4: =D4/4 -> 25 | AF4: =E4/4 -> 17.5 | AG4: =F4/4 -> 0 | AH4: =G4/4 -> 3.5 | AI4: =H4/4 -> 0 | AJ4: =I4/4 -> 3.5 | AK4: =R4/4 -> 5000 | AL4: =S4/4 -> 70000 | AM4: =T4/4 -> 0 | AN4: =U4/4 -> 70000 | AO4: =AL4/AH4 -> 20000 | AP4: 2500 | AQ4: =20000 -> 20000 | AR4: =AL4/AK4 -> 14 | AS4: =AM4/AK4 -> 0 | AT4: =AN4/AK4 -> 14
A5: março | B5: =R5/J5 -> 1500 | C5: =B5*0.25 -> 375 | D5: =B5*0.1 -> 150 | E5: =D5*0.7 -> 105 | G5: =H5+I5 -> 21 | H5: =F5*0.08 -> 0 | I5: =E5*0.2 -> 21 | J5: =20 -> 20 | K5: =R5/C5 -> 80 | L5: =R5/D5 -> 200 | M5: =R5/E5 -> 285.71429 | N5: =R5/F5 -> #DIV/0! | O5: =R5/G5 -> 1428.5714 | P5: =R5/H5 -> #DIV/0! | Q5: =R5/I5 -> 1428.5714 | R5: =30000 -> 30000 | S5: =T5+U5 -> 420000 | T5: =W5*H5 -> 0 | U5: =X5*I5 -> 420000 | V5: =S5/G5 -> 20000 | W5: 2500 | X5: =20000 -> 20000 | Y5: =S5/R5 -> 14 | Z5: =T5/R5 -> 0 | AA5: =U5/R5 -> 14 | AC5: =B5/4 -> 375 | AD5: =C5/4 -> 93.75 | AE5: =D5/4 -> 37.5 | AF5: =E5/4 -> 26.25 | AG5: =F5/4 -> 0 | AH5: =G5/4 -> 5.25 | AI5: =H5/4 -> 0 | AJ5: =I5/4 -> 5.25 | AK5: =R5/4 -> 7500 | AL5: =S5/4 -> 105000 | AM5: =T5/4 -> 0 | AN5: =U5/4 -> 105000 | AO5: =AL5/AH5 -> 20000 | AP5: 2500 | AQ5: =20000 -> 20000 | AR5: =AL5/AK5 -> 14 | AS5: =AM5/AK5 -> 0 | AT5: =AN5/AK5 -> 14
A6: abril | B6: =R6/J6 -> 2500 | C6: =B6*0.25 -> 625 | D6: =B6*0.1 -> 250 | E6: =D6*0.7 -> 175 | G6: =H6+I6 -> 35 | H6: =F6*0.08 -> 0 | I6: =E6*0.2 -> 35 | J6: =20 -> 20 | K6: =R6/C6 -> 80 | L6: =R6/D6 -> 200 | M6: =R6/E6 -> 285.71429 | N6: =R6/F6 -> #DIV/0! | O6: =R6/G6 -> 1428.5714 | P6: =R6/H6 -> #DIV/0! | Q6: =R6/I6 -> 1428.5714 | R6: =50000 -> 50000 | S6: =T6+U6 -> 700000 | T6: =W6*H6 -> 0 | U6: =X6*I6 -> 700000 | V6: =S6/G6 -> 20000 | W6: 2500 | X6: =20000 -> 20000 | Y6: =S6/R6 -> 14 | Z6: =T6/R6 -> 0 | AA6: =U6/R6 -> 14 | AC6: =B6/4 -> 625 | AD6: =C6/4 -> 156.25 | AE6: =D6/4 -> 62.5 | AF6: =E6/4 -> 43.75 | AG6: =F6/4 -> 0 | AH6: =G6/4 -> 8.75 | AI6: =H6/4 -> 0 | AJ6: =I6/4 -> 8.75 | AK6: =R6/4 -> 12500 | AL6: =S6/4 -> 175000 | AM6: =T6/4 -> 0 | AN6: =U6/4 -> 175000 | AO6: =AL6/AH6 -> 20000 | AP6: 2500 | AQ6: =20000 -> 20000 | AR6: =AL6/AK6 -> 14 | AS6: =AM6/AK6 -> 0 | AT6: =AN6/AK6 -> 14
A7: maio | B7: =R7/J7 -> 2500 | C7: =B7*0.25 -> 625 | D7: =B7*0.1 -> 250 | E7: =D7*0.7 -> 175 | G7: =H7+I7 -> 35 | H7: =F7*0.08 -> 0 | I7: =E7*0.2 -> 35 | J7: =20 -> 20 | K7: =R7/C7 -> 80 | L7: =R7/D7 -> 200 | M7: =R7/E7 -> 285.71429 | N7: =R7/F7 -> #DIV/0! | O7: =R7/G7 -> 1428.5714 | P7: =R7/H7 -> #DIV/0! | Q7: =R7/I7 -> 1428.5714 | R7: =50000 -> 50000 | S7: =T7+U7 -> 700000 | T7: =W7*H7 -> 0 | U7: =X7*I7 -> 700000 | V7: =S7/G7 -> 20000 | W7: 2500 | X7: =20000 -> 20000 | Y7: =S7/R7 -> 14 | Z7: =T7/R7 -> 0 | AA7: =U7/R7 -> 14 | AC7: =B7/4 -> 625 | AD7: =C7/4 -> 156.25 | AE7: =D7/4 -> 62.5 | AF7: =E7/4 -> 43.75 | AG7: =F7/4 -> 0 | AH7: =G7/4 -> 8.75 | AI7: =H7/4 -> 0 | AJ7: =I7/4 -> 8.75 | AK7: =R7/4 -> 12500 | AL7: =S7/4 -> 175000 | AM7: =T7/4 -> 0 | AN7: =U7/4 -> 175000 | AO7: =AL7/AH7 -> 20000 | AP7: 2500 | AQ7: =20000 -> 20000 | AR7: =AL7/AK7 -> 14 | AS7: =AM7/AK7 -> 0 | AT7: =AN7/AK7 -> 14
A8: junho | B8: =R8/J8 -> 500 | C8: =B8*0.25 -> 125 | D8: =B8*0.1 -> 50 | E8: =D8*0.7 -> 35 | G8: =H8+I8 -> 7 | H8: =F8*0.08 -> 0 | I8: =E8*0.2 -> 7 | J8: =20 -> 20 | K8: =R8/C8 -> 80 | L8: =R8/D8 -> 200 | M8: =R8/E8 -> 285.71429 | N8: =R8/F8 -> #DIV/0! | O8: =R8/G8 -> 1428.5714 | P8: =R8/H8 -> #DIV/0! | Q8: =R8/I8 -> 1428.5714 | R8: =10000 -> 10000 | S8: =T8+U8 -> 140000 | T8: =W8*H8 -> 0 | U8: =X8*I8 -> 140000 | V8: =S8/G8 -> 20000 | W8: 2500 | X8: =20000 -> 20000 | Y8: =S8/R8 -> 14 | Z8: =T8/R8 -> 0 | AA8: =U8/R8 -> 14 | AC8: =B8/4 -> 125 | AD8: =C8/4 -> 31.25 | AE8: =D8/4 -> 12.5 | AF8: =E8/4 -> 8.75 | AG8: =F8/4 -> 0 | AH8: =G8/4 -> 1.75 | AI8: =H8/4 -> 0 | AJ8: =I8/4 -> 1.75 | AK8: =R8/4 -> 2500 | AL8: =S8/4 -> 35000 | AM8: =T8/4 -> 0 | AN8: =U8/4 -> 35000 | AO8: =AL8/AH8 -> 20000 | AP8: 2500 | AQ8: =20000 -> 20000 | AR8: =AL8/AK8 -> 14 | AS8: =AM8/AK8 -> 0 | AT8: =AN8/AK8 -> 14
A9: julho | B9: =R9/J9 -> 1500 | C9: =B9*0.25 -> 375 | D9: =B9*0.1 -> 150 | E9: =D9*0.7 -> 105 | G9: =H9+I9 -> 21 | H9: =F9*0.08 -> 0 | I9: =E9*0.2 -> 21 | J9: =20 -> 20 | K9: =R9/C9 -> 80 | L9: =R9/D9 -> 200 | M9: =R9/E9 -> 285.71429 | N9: =R9/F9 -> #DIV/0! | O9: =R9/G9 -> 1428.5714 | P9: =R9/H9 -> #DIV/0! | Q9: =R9/I9 -> 1428.5714 | R9: 30000 | S9: =T9+U9 -> 420000 | T9: =W9*H9 -> 0 | U9: =X9*I9 -> 420000 | V9: =S9/G9 -> 20000 | W9: 2500 | X9: =20000 -> 20000 | Y9: =S9/R9 -> 14 | Z9: =T9/R9 -> 0 | AA9: =U9/R9 -> 14 | AC9: =B9/4 -> 375 | AD9: =C9/4 -> 93.75 | AE9: =D9/4 -> 37.5 | AF9: =E9/4 -> 26.25 | AG9: =F9/4 -> 0 | AH9: =G9/4 -> 5.25 | AI9: =H9/4 -> 0 | AJ9: =I9/4 -> 5.25 | AK9: =R9/4 -> 7500 | AL9: =S9/4 -> 105000 | AM9: =T9/4 -> 0 | AN9: =U9/4 -> 105000 | AO9: =AL9/AH9 -> 20000 | AP9: 2500 | AQ9: =20000 -> 20000 | AR9: =AL9/AK9 -> 14 | AS9: =AM9/AK9 -> 0 | AT9: =AN9/AK9 -> 14
A10: agosto | B10: =R10/J10 -> 1500 | C10: =B10*0.25 -> 375 | D10: =B10*0.1 -> 150 | E10: =D10*0.7 -> 105 | G10: =H10+I10 -> 21 | H10: =F10*0.08 -> 0 | I10: =E10*0.2 -> 21 | J10: =20 -> 20 | K10: =R10/C10 -> 80 | L10: =R10/D10 -> 200 | M10: =R10/E10 -> 285.71429 | N10: =R10/F10 -> #DIV/0! | O10: =R10/G10 -> 1428.5714 | P10: =R10/H10 -> #DIV/0! | Q10: =R10/I10 -> 1428.5714 | R10: =30000 -> 30000 | S10: =T10+U10 -> 420000 | T10: =W10*H10 -> 0 | U10: =X10*I10 -> 420000 | V10: =S10/G10 -> 20000 | W10: 2500 | X10: =20000 -> 20000 | Y10: =S10/R10 -> 14 | Z10: =T10/R10 -> 0 | AA10: =U10/R10 -> 14 | AC10: =B10/4 -> 375 | AD10: =C10/4 -> 93.75 | AE10: =D10/4 -> 37.5 | AF10: =E10/4 -> 26.25 | AG10: =F10/4 -> 0 | AH10: =G10/4 -> 5.25 | AI10: =H10/4 -> 0 | AJ10: =I10/4 -> 5.25 | AK10: =R10/4 -> 7500 | AL10: =S10/4 -> 105000 | AM10: =T10/4 -> 0 | AN10: =U10/4 -> 105000 | AO10: =AL10/AH10 -> 20000 | AP10: 2500 | AQ10: =20000 -> 20000 | AR10: =AL10/AK10 -> 14 | AS10: =AM10/AK10 -> 0 | AT10: =AN10/AK10 -> 14
A11: setembro | B11: =R11/J11 -> 1500 | C11: =B11*0.25 -> 375 | D11: =B11*0.1 -> 150 | E11: =D11*0.7 -> 105 | G11: =H11+I11 -> 21 | H11: =F11*0.08 -> 0 | I11: =E11*0.2 -> 21 | J11: =20 -> 20 | K11: =R11/C11 -> 80 | L11: =R11/D11 -> 200 | M11: =R11/E11 -> 285.71429 | N11: =R11/F11 -> #DIV/0! | O11: =R11/G11 -> 1428.5714 | P11: =R11/H11 -> #DIV/0! | Q11: =R11/I11 -> 1428.5714 | R11: =30000 -> 30000 | S11: =T11+U11 -> 420000 | T11: =W11*H11 -> 0 | U11: =X11*I11 -> 420000 | V11: =S11/G11 -> 20000 | W11: 2500 | X11: =20000 -> 20000 | Y11: =S11/R11 -> 14 | Z11: =T11/R11 -> 0 | AA11: =U11/R11 -> 14 | AC11: =B11/4 -> 375 | AD11: =C11/4 -> 93.75 | AE11: =D11/4 -> 37.5 | AF11: =E11/4 -> 26.25 | AG11: =F11/4 -> 0 | AH11: =G11/4 -> 5.25 | AI11: =H11/4 -> 0 | AJ11: =I11/4 -> 5.25 | AK11: =R11/4 -> 7500 | AL11: =S11/4 -> 105000 | AM11: =T11/4 -> 0 | AN11: =U11/4 -> 105000 | AO11: =AL11/AH11 -> 20000 | AP11: 2500 | AQ11: =20000 -> 20000 | AR11: =AL11/AK11 -> 14 | AS11: =AM11/AK11 -> 0 | AT11: =AN11/AK11 -> 14
A12: outubro | B12: =R12/J12 -> 2500 | C12: =B12*0.25 -> 625 | D12: =B12*0.1 -> 250 | E12: =D12*0.7 -> 175 | G12: =H12+I12 -> 35 | H12: =F12*0.08 -> 0 | I12: =E12*0.2 -> 35 | J12: =20 -> 20 | K12: =R12/C12 -> 80 | L12: =R12/D12 -> 200 | M12: =R12/E12 -> 285.71429 | N12: =R12/F12 -> #DIV/0! | O12: =R12/G12 -> 1428.5714 | P12: =R12/H12 -> #DIV/0! | Q12: =R12/I12 -> 1428.5714 | R12: =50000 -> 50000 | S12: =T12+U12 -> 700000 | T12: =W12*H12 -> 0 | U12: =X12*I12 -> 700000 | V12: =S12/G12 -> 20000 | W12: 2500 | X12: =20000 -> 20000 | Y12: =S12/R12 -> 14 | Z12: =T12/R12 -> 0 | AA12: =U12/R12 -> 14 | AC12: =B12/4 -> 625 | AD12: =C12/4 -> 156.25 | AE12: =D12/4 -> 62.5 | AF12: =E12/4 -> 43.75 | AG12: =F12/4 -> 0 | AH12: =G12/4 -> 8.75 | AI12: =H12/4 -> 0 | AJ12: =I12/4 -> 8.75 | AK12: =R12/4 -> 12500 | AL12: =S12/4 -> 175000 | AM12: =T12/4 -> 0 | AN12: =U12/4 -> 175000 | AO12: =AL12/AH12 -> 20000 | AP12: 2500 | AQ12: =20000 -> 20000 | AR12: =AL12/AK12 -> 14 | AS12: =AM12/AK12 -> 0 | AT12: =AN12/AK12 -> 14
A13: novembro | B13: =R13/J13 -> 2500 | C13: =B13*0.25 -> 625 | D13: =B13*0.1 -> 250 | E13: =D13*0.7 -> 175 | G13: =H13+I13 -> 35 | H13: =F13*0.08 -> 0 | I13: =E13*0.2 -> 35 | J13: =20 -> 20 | K13: =R13/C13 -> 80 | L13: =R13/D13 -> 200 | M13: =R13/E13 -> 285.71429 | N13: =R13/F13 -> #DIV/0! | O13: =R13/G13 -> 1428.5714 | P13: =R13/H13 -> #DIV/0! | Q13: =R13/I13 -> 1428.5714 | R13: =50000 -> 50000 | S13: =T13+U13 -> 700000 | T13: =W13*H13 -> 0 | U13: =X13*I13 -> 700000 | V13: =S13/G13 -> 20000 | W13: 2500 | X13: =20000 -> 20000 | Y13: =S13/R13 -> 14 | Z13: =T13/R13 -> 0 | AA13: =U13/R13 -> 14 | AC13: =B13/4 -> 625 | AD13: =C13/4 -> 156.25 | AE13: =D13/4 -> 62.5 | AF13: =E13/4 -> 43.75 | AG13: =F13/4 -> 0 | AH13: =G13/4 -> 8.75 | AI13: =H13/4 -> 0 | AJ13: =I13/4 -> 8.75 | AK13: =R13/4 -> 12500 | AL13: =S13/4 -> 175000 | AM13: =T13/4 -> 0 | AN13: =U13/4 -> 175000 | AO13: =AL13/AH13 -> 20000 | AP13: 2500 | AQ13: =20000 -> 20000 | AR13: =AL13/AK13 -> 14 | AS13: =AM13/AK13 -> 0 | AT13: =AN13/AK13 -> 14
A14: dezembro | B14: =R14/J14 -> 500 | C14: =B14*0.25 -> 125 | D14: =B14*0.1 -> 50 | E14: =D14*0.7 -> 35 | G14: =H14+I14 -> 7 | H14: =F14*0.08 -> 0 | I14: =E14*0.2 -> 7 | J14: =20 -> 20 | K14: =R14/C14 -> 80 | L14: =R14/D14 -> 200 | M14: =R14/E14 -> 285.71429 | N14: =R14/F14 -> #DIV/0! | O14: =R14/G14 -> 1428.5714 | P14: =R14/H14 -> #DIV/0! | Q14: =R14/I14 -> 1428.5714 | R14: =10000 -> 10000 | S14: =T14+U14 -> 140000 | T14: =W14*H14 -> 0 | U14: =X14*I14 -> 140000 | V14: =S14/G14 -> 20000 | W14: 2500 | X14: =20000 -> 20000 | Y14: =S14/R14 -> 14 | Z14: =T14/R14 -> 0 | AA14: =U14/R14 -> 14 | AC14: =B14/4 -> 125 | AD14: =C14/4 -> 31.25 | AE14: =D14/4 -> 12.5 | AF14: =E14/4 -> 8.75 | AG14: =F14/4 -> 0 | AH14: =G14/4 -> 1.75 | AI14: =H14/4 -> 0 | AJ14: =I14/4 -> 1.75 | AK14: =R14/4 -> 2500 | AL14: =S14/4 -> 35000 | AM14: =T14/4 -> 0 | AN14: =U14/4 -> 35000 | AO14: =AL14/AH14 -> 20000 | AP14: 2500 | AQ14: =20000 -> 20000 | AR14: =AL14/AK14 -> 14 | AS14: =AM14/AK14 -> 0 | AT14: =AN14/AK14 -> 14
A16: TOTAL | B16: =SUM(B3:B14) -> 18500 | C16: =SUM(C3:C14) -> 4625 | D16: =SUM(D3:D14) -> 1850 | E16: =SUM(E3:E14) -> 1295 | F16: =SUM(F3:F14) -> 0 | G16: =SUM(G3:G14) -> 259 | H16: =SUM(H3:H14) -> 0 | I16: =SUM(I3:I14) -> 259 | R16: =SUM(R3:R14) -> 370000 | S16: =SUM(S3:S14) -> 5180000 | T16: =SUM(T3:T14) -> 0 | U16: =SUM(U3:U14) -> 5180000

Sheet ✂️CORTE
K1: CAC DO TRAFEGO | O1: CAIXA DA VENDA MED | P1: CUSTO DA OFERTA (FORA TRÁFEGO)
B2: Lucro | D2: 0.01 | F2: =E2*30%+E2 -> 0 | G2: 0.05 | H2: =J2*I2 -> 1050 | I2: 0.75 | J2: =L2*K2 -> 1400 | K2: 0.2 | L2: 7000 | M2: 80000
B3: Lucro | D3: 0.01 | F3: =E3*30%+E3 -> 0 | G3: 0.05 | H3: =J3*I3 -> 525 | I3: 0.75 | J3: =L3*K3 -> 700 | K3: 0.2 | L3: 3500 | M3: 35000
B4: Lucro | D4: 0.02 | F4: =E4*30%+E4 -> 0 | G4: 0.05 | H4: =J4*I4 -> 375 | I4: 0.75 | J4: =L4*K4 -> 500 | K4: 0.2 | L4: 2500 | M4: 12000
B5: Lucro | D5: 0.01 | F5: =E5*30%+E5 -> 0 | G5: 0.05 | H5: =J5*I5 -> 0 | I5: 0.75 | J5: =L5*K5 -> 0 | K5: 0.2
B6: Lucro | D6: 0.01 | F6: =E6*30%+E6 -> 0 | G6: 0.05 | H6: =J6*I6 -> 150 | I6: 0.75 | J6: =L6*K6 -> 200 | K6: 0.2 | L6: 1000 | M6: 3000
B7: Cliente | D7: 0.01 | F7: =E7*30%+E7 -> 0 | G7: 0.05 | H7: =J7*I7 -> 150 | I7: 0.75 | J7: =L7*K7 -> 200 | K7: 0.2 | L7: 1000 | M7: 1500
B8: Cliente | D8: 0.01 | F8: =E8*30%+E8 -> 0 | G8: 0.05 | H8: =J8*I8 -> 60 | I8: 0.75 | J8: =L8*K8 -> 80 | K8: 0.2 | L8: 400 | M8: 300
B9: Cliente | D9: 0.01 | F9: =E9*30%+E9 -> 0 | G9: 0.05 | H9: =J9*I9 -> 30 | I9: 0.75 | J9: =L9*K9 -> 40 | K9: 0.2 | L9: 200 | M9: 100
B10: Cliente | D10: 0.01 | F10: =E10*30%+E10 -> 0 | G10: 0.05 | H10: =J10*I10 -> 0 | I10: 0.75 | J10: =L10*K10 -> 0 | K10: 0.2
B11: Cliente | D11: 0.01 | F11: =E11*30%+E11 -> 0 | G11: 0.05 | H11: =J11*I11 -> 0 | I11: 0.75 | J11: =L11*K11 -> 0 | K11: 0.2

Sheet 🗺️MICRO
A1: CONTA 2024
A2: JANEIRO | B2: LEADS | C2: VENDAS | D2: TICKET | E2: FATURAMENTO | F2: GATWAY | G2: IMPOSTOS | H2: LIQUIDO | I2: TRÁFEGO | K2: BRUTO | M2: Q1
E3: =C3*D3 -> 0 | F3: =(E3*2.9/100) -> 0 | G3: =E3*6% -> 0 | H3: =E3-F3-G3 -> 0
E4: =C4*D4 -> 0 | F4: =(E4*2.9/100) -> 0 | G4: =E4*6% -> 0 | H4: =E4-F4-G4 -> 0 | K4: =H4-I4 -> 0
E5: =C5*D5 -> 0 | F5: =(E5*2.9/100) -> 0 | G5: =E5*6% -> 0 | H5: =E5-F5-G5 -> 0 | K5: =H5-I5 -> 0 | N5: BRUTO
E6: =C6*D6 -> 0 | F6: =(E6*2.9/100) -> 0 | G6: =E6*6% -> 0 | H6: =E6-F6-G6 -> 0 | K6: =H6-I6 -> 0
E7: =C7*D7 -> 0 | F7: =(E7*2.9/100) -> 0 | G7: =E7*6% -> 0 | H7: =E7-F7-G7 -> 0 | K7: =H7-I7 -> 0 | N7: =K16+K33 -> 0
E8: =C8*D8 -> 0 | F8: =(E8*2.9/100) -> 0 | G8: =E8*6% -> 0 | H8: =E8-F8-G8 -> 0 | K8: =H8-I8 -> 0
E9: =C9*D9 -> 0 | F9: =(E9*2.9/100) -> 0 | G9: =E9*6% -> 0 | H9: =E9-F9-G9 -> 0 | K9: =H9-I9 -> 0
E10: =C10*D10 -> 0 | F10: =(E10*2.9/100) -> 0 | G10: =E10*6% -> 0 | H10: =E10-F10-G10 -> 0 | K10: =H10-I10 -> 0 | N10: OPERACIONAL
E11: =C11*D11 -> 0 | F11: =(E11*2.9/100) -> 0 | G11: =E11*6% -> 0 | H11: =E11-F11-G11 -> 0 | K11: =H11-I11 -> 0 | N11: 21500
E12: =C12*D12 -> 0 | F12: =(E12*2.9/100) -> 0 | G12: =E12*6% -> 0 | H12: =E12-F12-G12 -> 0 | K12: =H12-I12 -> 0
E13: =C13*D13 -> 0 | F13: =(E13*2.9/100) -> 0 | G13: =E13*6% -> 0 | H13: =E13-F13-G13 -> 0 | K13: =H13-I13 -> 0
E14: =C14*D14 -> 0 | F14: =(E14*2.9/100) -> 0 | G14: =E14*6% -> 0 | H14: =E14-F14-G14 -> 0 | K14: =H14-I14 -> 0
E16: =SUM(E3:E15) -> 0 | F16: =SUM(F3:F15) -> 0 | G16: =SUM(G3:G15) -> 0 | H16: =SUM(H3:H15) -> 0 | K16: =SUM(K3:K14)-I16 -> 0
N17: TRÁFEGO
A18: FEVEREIRO | B18: LEADS | C18: VENDAS | D18: TICKET | E18: FATURAMENTO | F18: GATWAY | G18: IMPOSTOS | H18: LIQUIDO | I18: TRÁFEGO | J18: EVENTO | K18: BRUTO | N18: =I14+I33 -> 0
E19: =C19*D19 -> 0 | F19: =(E19*3.24/100) -> 0 | G19: =E19*6% -> 0 | H19: =E19-F19-G19 -> 0 | K19: =I19-H19-H20-H21 -> 0
E20: =C20*D20 -> 0 | F20: =(E20*3.24/100) -> 0 | G20: =E20*6% -> 0 | H20: =E20-F20-G20 -> 0 | N20: ROAS
E21: =C21*D21 -> 0 | F21: =(E21*3.24/100) -> 0 | G21: =E21*6% -> 0 | H21: =E21-F21-G21 -> 0 | N21: =N7-N12-N18 -> 0
E22: =C22*D22 -> 0 | F22: =(E22*3.24/100) -> 0 | G22: =E22*6% -> 0 | H22: =E22-F22-G22 -> 0 | K22: =H22-I22 -> 0
E23: =C23*D23 -> 0 | F23: =(E23*3.24/100) -> 0 | G23: =E23*6% -> 0 | H23: =E23-F23-G23 -> 0 | K23: =H23-I23 -> 0
E24: =C24*D24 -> 0 | F24: =(E24*3.24/100) -> 0 | G24: =E24*6% -> 0 | H24: =E24-F24-G24 -> 0 | K24: =I24-H24-H25 -> 0
E25: =C25*D25 -> 0 | F25: =(E25*3.24/100) -> 0 | G25: =E25*6% -> 0 | H25: =E25-F25-G25 -> 0
E26: =C26*D26 -> 0 | F26: =(E26*3.24/100) -> 0 | G26: =E26*6% -> 0 | H26: =E26-F26-G26 -> 0 | K26: =H26-I26 -> 0
E27: =C27*D27 -> 0 | F27: =(E27*3.24/100) -> 0 | G27: =E27*6% -> 0 | H27: =E27-F27-G27 -> 0 | K27: =H27-I27 -> 0
E28: =C28*D28 -> 0 | F28: =(E28*3.24/100)+1 -> 1 | G28: =E28*6% -> 0 | H28: =E28-F28-G28 -> -1
E29: =C29*D29 -> 0 | F29: =(E29*3.24/100)+1 -> 1 | G29: =E29*6% -> 0 | H29: =E29-F29-G29 -> -1
E30: =C30*D30 -> 0 | F30: =(E30*3.24/100)+1 -> 1 | G30: =E30*6% -> 0 | H30: =E30-F30-G30 -> -1
E31: =C31*D31 -> 0 | F31: =(E31*3.24/100)+1 -> 1 | G31: =E31*6% -> 0 | H31: =E31-F31-G31 -> -1
E33: =SUM(E19:E31) -> 0 | F33: =SUM(F19:F31) -> 4 | G33: =SUM(G19:G31) -> 0 | I33: =SUM(I19:I31) -> 0 | K33: =SUM(K19:K31) -> 0
A36: MARÇO | C36: VENDAS | D36: TICKET | E36: FATURAMENTO | F36: GATWAY | G36: IMPOSTOS | H36: LIQUIDO | I36: TRÁFEGO | J36: EVENTO | K36: BRUTO
N38: BRUTO
N39: =K52+K64+K73 -> 0
N42: OPERACIONAL
N45: TRÁFEGO
N46: =I52+I64+I73 -> 0
N49: ROAS
N51: =N39-N43-N46 -> 0
E52: =SUM(E37:E51) -> 0 | F52: =SUM(F37:F51) -> 0 | G52: =SUM(G37:G51) -> 0 | I52: =SUM(I37:I51) -> 0 | K52: =SUM(K37:K51) -> 0
...

Sheet 🧮 CALCULADORA
B2: CALCULADORA DE PORCENTAGEM LIVRO | E2: CALCULADORA DE PORCENTAGEM CURSO | H2: CALCULADORA DE PORCENTAGEM CURSO | K2: CALCULADORA DE PORCENTAGEM CURSO
B3: Ticket | C3: 97 | E3: Ticket | F3: 197 | H3: Ticket | I3: 497 | K3: Ticket | L3: 5997
B4: Plataforma Gatway | C4: =(C3*9.9/100)+1 -> 10.603 | E4: Plataforma Gatway | F4: =(F3*9.9/100)+1+2.59 -> 23.093 | H4: Plataforma Gatway | I4: =(I3*9.9/100)+1+2.59 -> 52.793 | K4: Plataforma Gatway | L4: =(L3*9.9/100)+1+2.59 -> 597.293
B5: Agência % | C5: 100 | E5: Agência % | F5: 70 | H5: Agência % | I5: 70 | K5: Agência % | L5: 70
B6: Agência Investidora | C6: =(C3-C4)*C5/100 -> 86.397 | E6: Agência Investidora | F6: =(F3-F4)*F5/100 -> 121.7349 | H6: Agência Investidora | I6: =(I3-I4)*I5/100 -> 310.9449 | K6: Agência Investidora | L6: =(L3-L4)*L5/100 -> 3779.7949
B7: Produtor | C7: =C3-(C6+C4) -> 0 | E7: Produtor | F7: =F3-(F6+F4) -> 52.1721 | H7: Produtor | I7: =I3-(I6+I4) -> 133.2621 | K7: Produtor | L7: =L3-(L6+L4) -> 1619.9121
B9: CALCULADORA DE PORCENTAGEM LIVRO AFF | E9: CALCULADORA DE PORCENTAGEM CURSO AFF | H9: CALCULADORA DE PORCENTAGEM CURSO AFF | K9: CALCULADORA DE PORCENTAGEM CURSO AFF
B10: Ticket | C10: 2197 | E10: Ticket | F10: 2497 | H10: Ticket | I10: 5997 | K10: Ticket | L10: 5997
B11: Plataforma Gatway | C11: =(C10*9.9/100)+1 -> 218.503 | E11: Plataforma Gatway | F11: =(F10*9.9/100)+1+2.59 -> 250.793 | H11: Plataforma Gatway | I11: =(I10*9.9/100)+1+2.59 -> 597.293 | K11: Plataforma Gatway | L11: =(L10*9.9/100)+1+2.59 -> 597.293
B12: Agência % | C12: 50 | E12: Agência % | F12: 50 | H12: Agência % | I12: 50 | K12: Agência % | L12: 50
B13: Agência Investidora | C13: =(C10-C11)*C12/100 -> 989.2485 | E13: Agência Investidora | F13: =(F10-F11)*F12/100 -> 1123.1035 | H13: Agência Investidora | I13: =(I10-I11)*I12/100 -> 2699.8535 | K13: Agência Investidora | L13: =(L10-L11)*L12/100 -> 2699.8535
B14: Afiliado % | C14: 20 | E14: Afiliado % | F14: 20 | H14: Afiliado % | I14: 20 | K14: Afiliado % | L14: 20
B15: Afiliado Investidor | C15: =(C10-C11-C13)*C14/100 -> 197.8497 | E15: Afiliado Investidor | F15: =(F10-F11-F13)*F14/100 -> 224.6207 | H15: Afiliado Investidor | I15: =(I10-I11-I13)*I14/100 -> 539.9707 | K15: Afiliado Investidor | L15: =(L10-L11-L13)*L14/100 -> 539.9707
B16: Produtor | C16: =C10-(C13+C11+C15) -> 791.3988 | E16: Produtor | F16: =F10-(F13+F11+F15) -> 898.4828 | H16: Produtor | I16: =I10-(I13+I11+I15) -> 2159.8828 | K16: Produtor | L16: =L10-(L13+L11+L15) -> 2159.8828

Sheet 🌱 RECORRÊNCIA LIVRO FLUXO
B2: MÉTRICAS GERAIS
C4: janeiro | D4: fevereiro | E4: março | F4: abril | G4: maio | H4: junho | I4: julho | J4: agosto | K4: setembro | L4: outubro | M4: novembro | N4: dezembro
B5: INVESTIMENTO TOTAL | C5: =C6 -> 0 | D5: =D6 -> 0 | E5: =E6 -> 177.42 | F5: =F6 -> 1523.97 | G5: =G6 -> 0 | H5: =H6 -> 0 | I5: =I6 -> 0 | J5: =J6 -> 0 | ... N5: =N6 -> 0
B6: FACEBOOK | C6: 0 | D6: 0 | E6: =P26+AD26 -> 177.42 | F6: =P64 -> 1523.97 | G6: 0 | H6: 0 | I6: 0 | J6: 0 | K6: 0 | L6: 0 | M6: 0 | N6: 0
B8: CLIQUES ÚNICOS | C8: 0 | D8: 0 | E8: =W26 -> 143 | F8: =W64 -> 927 | G8: 0 | H8: 0 | I8: 0 | J8: 0 | K8: 0 | L8: 0 | M8: 0 | N8: 0
B9: CUSTO/CLIQUES ÚNICOS | C9: =C5/C8 -> #DIV/0! | D9: =D5/D8 -> #DIV/0! | E9: =E5/E8 -> 1.2406993 | F9: =F5/F8 -> 1.6439806 | G9: =G5/G8 -> #DIV/0! | H9: =H5/H8 -> #DIV/0! | I9: =I5/I8 -> #DIV/0! | J9: =J5/J8 -> #DIV/0! | ... N9: =N5/N8 -> #DIV/0!
B10: PÁGINA DE VENDAS | C10: 0 | D10: 0 | E10: =U26 -> 123 | F10: =U64 -> 690 | G10: 0 | H10: 0 | I10: 0 | J10: 0 | K10: 0 | L10: 0 | M10: 0 | N10: 0
B11: CUSTO/ PÁGINA DE VENDAS | C11: =C5/C10 -> #DIV/0! | D11: =D5/D10 -> #DIV/0! | E11: =E5/E10 -> 1.442439 | F11: =F5/F10 -> 2.2086522 | G11: =G5/G10 -> #DIV/0! | H11: =H5/H10 -> #DIV/0! | I11: =I5/I10 -> #DIV/0! | J11: =J5/J10 -> #DIV/0! | ... N11: =N5/N10 -> #DIV/0!
B12: CHECKOUT | C12: 0 | D12: 0 | E12: =S26 -> 186 | F12: =S64 -> 698 | G12: 0 | H12: 0 | I12: 0 | J12: 0 | K12: 0 | L12: 0 | M12: 0 | N12: 0
B13: CUSTO/CHECKOUT | C13: =C5/C12 -> #DIV/0! | D13: =D5/D12 -> #DIV/0! | E13: =E5/E12 -> 0.95387097 | F13: =F5/F12 -> 2.1833381 | G13: =G5/G12 -> #DIV/0! | H13: =H5/H12 -> #DIV/0! | I13: =I5/I12 -> #DIV/0! | J13: =J5/J12 -> #DIV/0! | ... N13: =N5/N12 -> #DIV/0!
B14: VENDAS | C14: 0 | D14: 0 | E14: =Q26 -> 22 | F14: =Q64 -> 104 | G14: 0 | H14: 0 | I14: 0 | J14: 0 | K14: 0 | L14: 0 | M14: 0 | N14: 0
B15: CUSTO/VENDAS | C15: =C5/C14 -> #DIV/0! | D15: =D5/D14 -> #DIV/0! | E15: =E5/E14 -> 8.0645455 | F15: =F5/F14 -> 14.653558 | G15: =G5/G14 -> #DIV/0! | H15: =H5/H14 -> #DIV/0! | I15: =I5/I14 -> #DIV/0! | J15: =J5/J14 -> #DIV/0! | ... N15: =N5/N14 -> #DIV/0!
B16: KPIS:
B17: _% Conversão Pg Vendas | C17: =C10/C8 -> #DIV/0! | D17: =D10/D8 -> #DIV/0! | E17: =E10/E8 -> 0.86013986 | F17: =F10/F8 -> 0.74433657 | G17: =G10/G8 -> #DIV/0! | H17: =H10/H8 -> #DIV/0! | I17: =I10/I8 -> #DIV/0! | J17: =J10/J8 -> #DIV/0! | ... N17: =N10/N8 -> #DIV/0!
B18: _% Conversão Checkout | C18: =C12/C10 -> #DIV/0! | D18: =D12/D10 -> #DIV/0! | E18: =E12/E10 -> 1.5121951 | F18: =F12/F10 -> 1.0115942 | G18: =G12/G10 -> #DIV/0! | H18: =H12/H10 -> #DIV/0! | I18: =I12/I10 -> #DIV/0! | J18: =J12/J10 -> #DIV/0! | ... N18: =N12/N10 -> #DIV/0!
B19: _% Conversão Vendas | C19: =C14/C12 -> #DIV/0! | D19: =D14/D12 -> #DIV/0! | E19: =E14/E12 -> 0.11827957 | F19: =F14/F12 -> 0.14899713 | G19: =G14/G12 -> #DIV/0! | H19: =H14/H12 -> #DIV/0! | I19: =I14/I12 -> #DIV/0! | J19: =J14/J12 -> #DIV/0! | ... N19: =N14/N12 -> #DIV/0!
B20: _% Order Bump | E20: =4/25 -> 0.16 | F20: =6/63 -> 0.095238095
B21: _% Upsell 1
B22: _% Upsell 2
O24: FACEBOOK ADS (OFERTA DIRETA) | AC24: FACEBOOK ADS (RMKT) | AQ24: GOOGLE ADS (OFERTA DIRETA) | BD24: GOOGLE ADS (RMKT)
B25: Março | O25: DATA | P25: Investimento | Q25: Compras | R25: Custo por Vendas | S25: Inicialização de Finalização de Compras | T25: Custo por Inicialização de Finalização de Compras | U25: Visualização Única de Página de destino | V25: Custo porVisualização Única de Página | W25: Cliques no link único | X25: Custo por Cliques no link único | Y25: % Conversão Visualização Pg Vendas | Z25: % Conversão de Compra | AA25: Diário de Bordo | AC25: DATA | AD25: Investimento | AE25: Compras | AF25: Custo por Vendas | AG25: Inicialização de Finalização de Compras | AH25: Custo por Inicialização de Finalização de Compras | AI25: Visualização Única de Página de destino | AJ25: Custo porVisualização Única de Página | AK25: Cliques no link único | AL25: Custo por Cliques no link único | AM25: % Conversão Pg Vendas | AN25: Diário de Bordo | AQ25: DATA | AR25: Investimento | AS25: Compras | AT25: Custo por Vendas | AU25: Inicialização de Finalização de Compras | AV25: Custo por Inicialização de Finalização de Compras | AW25: Visualização Única de Página de destino | AX25: Custo porVisualização Única de Página | AY25: Cliques no link único | AZ25: Custo por Cliques no link único | BA25: % Conversão Pg Vendas | BB25: Diário de Bordo | BD25: DATA | BE25: Investimento | BF25: Compras | BG25: Custo por Vendas | BH25: Inicialização de Finalização de Compras | BI25: Custo por Inicialização de Finalização de Compras | BJ25: Visualização Única de Página de destino | BK25: Custo porVisualização Única de Página | BL25: Cliques no link único | BM25: Custo por Cliques no link único | BN25: % Conversão Pg Vendas | BO25: Diário de Bordo
P26: =SUM(P27:P57) -> 177.42 | Q26: =SUM(Q27:Q57) -> 22 | R26: =P26/Q26 -> 8.0645455 | S26: =SUM(S27:S57) -> 186 | T26: =P26/S26 -> 0.95387097 | U26: =SUM(U27:U57) -> 123 | V26: =P26/U26 -> 1.442439 | W26: =SUM(W27:W57) -> 143 | X26: =P26/W26 -> 1.2406993 | Y26: =U26/W26 -> 0.86013986 | Z26: =Q26/S26 -> 0.11827957 | AD26: =SUM(AD27:AD57) -> 0 | AE26: =SUM(AE27:AE57) -> 0 | AF26: =AD26/AE26 -> #DIV/0! | AG26: =SUM(AG27:AG57) -> 0 | AH26: =AD26/AG26 -> #DIV/0! | AI26: =SUM(AI27:AI57) -> 0 | AJ26: =AD26/AI26 -> #DIV/0! | AK26: =SUM(AK27:AK57) -> 0 | AL26: =AD26/AK26 -> #DIV/0! | AM26: =AI26/AK26 -> #DIV/0! | AR26: =SUM(AR27:AR57) -> 0 | AS26: =SUM(AS27:AS57) -> 0 | AT26: =AR26/AS26 -> #DIV/0! | AU26: =SUM(AU27:AU57) -> 0 | AV26: =AR26/AU26 -> #DIV/0! | AW26: =SUM(AW27:AW57) -> 0 | AX26: =AR26/AW26 -> #DIV/0! | AY26: =SUM(AY27:AY57) -> 0 | AZ26: =AR26/AY26 -> #DIV/0! | BA26: =AW26/AY26 -> #DIV/0! | BE26: =SUM(BE27:BE57) -> 0 | BF26: =SUM(BF27:BF57) -> 0 | BG26: =BE26/BF26 -> #DIV/0! | BH26: =SUM(BH27:BH57) -> 0 | BI26: =BE26/BH26 -> #DIV/0! | BJ26: =SUM(BJ27:BJ57) -> 0 | BK26: =BE26/BJ26 -> #DIV/0! | BL26: =SUM(BL27:BL57) -> 0 | BM26: =BE26/BL26 -> #DIV/0! | BN26: =BJ26/BL26 -> #DIV/0!
N27: Sexta-feira | AB27: Sexta-feira | AC27: 44197 | AD27: 0 | AE27: 0 | AF27: =AD27/AE27 -> #DIV/0! | AG27: 0 | AH27: =AD27/AG27 -> #DIV/0! | AI27: 0 | AJ27: =AD27/AI27 -> #DIV/0! | AK27: 0 | AL27: =AD27/AK27 -> #DIV/0! | AM27: =AI27/AK27 -> #DIV/0! | AP27: Sexta-feira | AQ27: 44197 | AR27: 0 | AS27: 0 | AT27: =AR27/AS27 -> #DIV/0! | AU27: 0 | AV27: =AR27/AU27 -> #DIV/0! | AW27: 0 | AX27: =AR27/AW27 -> #DIV/0! | AY27: 0 | AZ27: =AR27/AY27 -> #DIV/0! | BA27: =AW27/AY27 -> #DIV/0! | BC27: Sexta-feira | BD27: 44197 | BE27: 0 | BF27: 0 | BG27: =BE27/BF27 -> #DIV/0! | BH27: 0 | BI27: =BE27/BH27 -> #DIV/0! | BJ27: 0 | BK27: =BE27/BJ27 -> #DIV/0! | BL27: 0 | BM27: =BE27/BL27 -> #DIV/0! | BN27: =BJ27/BL27 -> #DIV/0!
B28: Planejamento e Metas Esperadas | H28: Números Reais | N28: Sábado | AB28: Sábado | AC28: 44198 | AD28: 0 | AE28: 0 | AF28: =AD28/AE28 -> #DIV/0! | AG28: 0 | AH28: =AD28/AG28 -> #DIV/0! | AI28: 0 | AJ28: =AD28/AI28 -> #DIV/0! | AK28: 0 | AL28: =AD28/AK28 -> #DIV/0! | AM28: =AI28/AK28 -> #DIV/0! | AP28: Sábado | AQ28: 44198 | AR28: 0 | AS28: 0 | AT28: =AR28/AS28 -> #DIV/0! | AU28: 0 | AV28: =AR28/AU28 -> #DIV/0! | AW28: 0 | AX28: =AR28/AW28 -> #DIV/0! | AY28: 0 | AZ28: =AR28/AY28 -> #DIV/0! | BA28: =AW28/AY28 -> #DIV/0! | BC28: Sábado | BD28: 44198 | BE28: 0 | BF28: 0 | BG28: =BE28/BF28 -> #DIV/0! | BH28: 0 | BI28: =BE28/BH28 -> #DIV/0! | BJ28: 0 | BK28: =BE28/BJ28 -> #DIV/0! | BL28: 0 | BM28: =BE28/BL28 -> #DIV/0! | BN28: =BJ28/BL28 -> #DIV/0!
N29: Domingo | AB29: Domingo | AC29: 44199 | AD29: 0 | AE29: 0 | AF29: =AD29/AE29 -> #DIV/0! | AG29: 0 | AH29: =AD29/AG29 -> #DIV/0! | AI29: 0 | AJ29: =AD29/AI29 -> #DIV/0! | AK29: 0 | AL29: =AD29/AK29 -> #DIV/0! | AM29: =AI29/AK29 -> #DIV/0! | AP29: Domingo | AQ29: 44199 | AR29: 0 | AS29: 0 | AT29: =AR29/AS29 -> #DIV/0! | AU29: 0 | AV29: =AR29/AU29 -> #DIV/0! | AW29: 0 | AX29: =AR29/AW29 -> #DIV/0! | AY29: 0 | AZ29: =AR29/AY29 -> #DIV/0! | BA29: =AW29/AY29 -> #DIV/0! | BC29: Domingo | BD29: 44199 | BE29: 0 | BF29: 0 | BG29: =BE29/BF29 -> #DIV/0! | BH29: 0 | BI29: =BE29/BH29 -> #DIV/0! | BJ29: 0 | BK29: =BE29/BJ29 -> #DIV/0! | BL29: 0 | BM29: =BE29/BL29 -> #DIV/0! | BN29: =BJ29/BL29 -> #DIV/0!
B30: Meta de Faturamento | E30: 20160 | H30: Investimento Realizado | K30: 0 | N30: Segunda-feira | O30: 44200 | P30: 0 | Q30: 0 | R30: =P30/Q30 -> #DIV/0! | S30: 0 | T30: =P30/S30 -> #DIV/0! | U30: 0 | V30: =P30/U30 -> #DIV/0! | W30: 0 | X30: =P30/W30 -> #DIV/0! | Y30: =U30/W30 -> #DIV/0! | AB30: Segunda-feira | AC30: 44200 | AD30: 0 | AE30: 0 | AF30: =AD30/AE30 -> #DIV/0! | AG30: 0 | AH30: =AD30/AG30 -> #DIV/0! | AI30: 0 | AJ30: =AD30/AI30 -> #DIV/0! | AK30: 0 | AL30: =AD30/AK30 -> #DIV/0! | AM30: =AI30/AK30 -> #DIV/0! | AP30: Segunda-feira | AQ30: 44200 | AR30: 0 | AS30: 0 | AT30: =AR30/AS30 -> #DIV/0! | AU30: 0 | AV30: =AR30/AU30 -> #DIV/0! | AW30: 0 | AX30: =AR30/AW30 -> #DIV/0! | AY30: 0 | AZ30: =AR30/AY30 -> #DIV/0! | BA30: =AW30/AY30 -> #DIV/0! | BC30: Segunda-feira | BD30: 44200 | BE30: 0 | BF30: 0 | BG30: =BE30/BF30 -> #DIV/0! | BH30: 0 | BI30: =BE30/BH30 -> #DIV/0! | BJ30: 0 | BK30: =BE30/BJ30 -> #DIV/0! | BL30: 0 | BM30: =BE30/BL30 -> #DIV/0! | BN30: =BJ30/BL30 -> #DIV/0!
N31: Terça-feira | O31: 44201 | P31: 0 | Q31: 0 | R31: =P31/Q31 -> #DIV/0! | S31: 0 | T31: =P31/S31 -> #DIV/0! | U31: 0 | V31: =P31/U31 -> #DIV/0! | W31: 0 | X31: =P31/W31 -> #DIV/0! | Y31: =U31/W31 -> #DIV/0! | AB31: Terça-feira | AC31: 44201 | AD31: 0 | AE31: 0 | AF31: =AD31/AE31 -> #DIV/0! | AG31: 0 | AH31: =AD31/AG31 -> #DIV/0! | AI31: 0 | AJ31: =AD31/AI31 -> #DIV/0! | AK31: 0 | AL31: =AD31/AK31 -> #DIV/0! | AM31: =AI31/AK31 -> #DIV/0! | AP31: Terça-feira | AQ31: 44201 | AR31: 0 | AS31: 0 | AT31: =AR31/AS31 -> #DIV/0! | AU31: 0 | AV31: =AR31/AU31 -> #DIV/0! | AW31: 0 | AX31: =AR31/AW31 -> #DIV/0! | AY31: 0 | AZ31: =AR31/AY31 -> #DIV/0! | BA31: =AW31/AY31 -> #DIV/0! | BC31: Terça-feira | BD31: 44201 | BE31: 0 | BF31: 0 | BG31: =BE31/BF31 -> #DIV/0! | BH31: 0 | BI31: =BE31/BH31 -> #DIV/0! | BJ31: 0 | BK31: =BE31/BJ31 -> #DIV/0! | BL31: 0 | BM31: =BE31/BL31 -> #DIV/0! | BN31: =BJ31/BL31 -> #DIV/0!
B32: Ticket do Produto | E32: 97 | H32: Vendas Realizadas | K32: 0 | N32: Quarta-feira | O32: 44202 | P32: 0 | Q32: 0 | R32: =P32/Q32 -> #DIV/0! | S32: 0 | T32: =P32/S32 -> #DIV/0! | U32: 0 | V32: =P32/U32 -> #DIV/0! | W32: 0 | X32: =P32/W32 -> #DIV/0! | Y32: =U32/W32 -> #DIV/0! | AB32: Quarta-feira | AC32: 44202 | AD32: 0 | AE32: 0 | AF32: =AD32/AE32 -> #DIV/0! | AG32: 0 | AH32: =AD32/AG32 -> #DIV/0! | AI32: 0 | AJ32: =AD32/AI32 -> #DIV/0! | AK32: 0 | AL32: =AD32/AK32 -> #DIV/0! | AM32: =AI32/AK32 -> #DIV/0! | AP32: Quarta-feira | AQ32: 44202 | AR32: 0 | AS32: 0 | AT32: =AR32/AS32 -> #DIV/0! | AU32: 0 | AV32: =AR32/AU32 -> #DIV/0! | AW32: 0 | AX32: =AR32/AW32 -> #DIV/0! | AY32: 0 | AZ32: =AR32/AY32 -> #DIV/0! | BA32: =AW32/AY32 -> #DIV/0! | BC32: Quarta-feira | BD32: 44202 | BE32: 0 | BF32: 0 | BG32: =BE32/BF32 -> #DIV/0! | BH32: 0 | BI32: =BE32/BH32 -> #DIV/0! | BJ32: 0 | BK32: =BE32/BJ32 -> #DIV/0! | BL32: 0 | BM32: =BE32/BL32 -> #DIV/0! | BN32: =BJ32/BL32 -> #DIV/0!
N33: Quinta-feira | O33: 44203 | P33: 0 | Q33: 0 | R33: =P33/Q33 -> #DIV/0! | S33: 0 | T33: =P33/S33 -> #DIV/0! | U33: 0 | V33: =P33/U33 -> #DIV/0! | W33: 0 | X33: =P33/W33 -> #DIV/0! | Y33: =U33/W33 -> #DIV/0! | AB33: Quinta-feira | AC33: 44203 | AD33: 0 | AE33: 0 | AF33: =AD33/AE33 -> #DIV/0! | AG33: 0 | AH33: =AD33/AG33 -> #DIV/0! | AI33: 0 | AJ33: =AD33/AI33 -> #DIV/0! | AK33: 0 | AL33: =AD33/AK33 -> #DIV/0! | AM33: =AI33/AK33 -> #DIV/0! | AP33: Quinta-feira | AQ33: 44203 | AR33: 0 | AS33: 0 | AT33: =AR33/AS33 -> #DIV/0! | AU33: 0 | AV33: =AR33/AU33 -> #DIV/0! | AW33: 0 | AX33: =AR33/AW33 -> #DIV/0! | AY33: 0 | AZ33: =AR33/AY33 -> #DIV/0! | BA33: =AW33/AY33 -> #DIV/0! | BC33: Quinta-feira | BD33: 44203 | BE33: 0 | BF33: 0 | BG33: =BE33/BF33 -> #DIV/0! | BH33: 0 | BI33: =BE33/BH33 -> #DIV/0! | BJ33: 0 | BK33: =BE33/BJ33 -> #DIV/0! | BL33: 0 | BM33: =BE33/BL33 -> #DIV/0! | BN33: =BJ33/BL33 -> #DIV/0!
B34: Taxas da Plataforma | E34: 10.6 | H34: CPA Real | K34: =SUM(L30/L32) -> #DIV/0! | N34: Sexta-feira | O34: 44204 | P34: 0 | Q34: 0 | R34: =P34/Q34 -> #DIV/0! | S34: 0 | T34: =P34/S34 -> #DIV/0! | U34: 0 | V34: =P34/U34 -> #DIV/0! | W34: 0 | X34: =P34/W34 -> #DIV/0! | Y34: =U34/W34 -> #DIV/0! | AB34: Sexta-feira | AC34: 44204 | AD34: 0 | AE34: 0 | AF34: =AD34/AE34 -> #DIV/0! | AG34: 0 | AH34: =AD34/AG34 -> #DIV/0! | AI34: 0 | AJ34: =AD34/AI34 -> #DIV/0! | AK34: 0 | AL34: =AD34/AK34 -> #DIV/0! | AM34: =AI34/AK34 -> #DIV/0! | AP34: Sexta-feira | AQ34: 44204 | AR34: 0 | AS34: 0 | AT34: =AR34/AS34 -> #DIV/0! | AU34: 0 | AV34: =AR34/AU34 -> #DIV/0! | AW34: 0 | AX34: =AR34/AW34 -> #DIV/0! | AY34: 0 | AZ34: =AR34/AY34 -> #DIV/0! | BA34: =AW34/AY34 -> #DIV/0! | BC34: Sexta-feira | BD34: 44204 | BE34: 0 | BF34: 0 | BG34: =BE34/BF34 -> #DIV/0! | BH34: 0 | BI34: =BE34/BH34 -> #DIV/0! | BJ34: 0 | BK34: =BE34/BJ34 -> #DIV/0! | BL34: 0 | BM34: =BE34/BL34 -> #DIV/0! | BN34: =BJ34/BL34 -> #DIV/0!
N35: Sábado | O35: 44205 | P35: 0 | Q35: 0 | R35: =P35/Q35 -> #DIV/0! | S35: 0 | T35: =P35/S35 -> #DIV/0! | U35: 0 | V35: =P35/U35 -> #DIV/0! | W35: 0 | X35: =P35/W35 -> #DIV/0! | Y35: =U35/W35 -> #DIV/0! | AB35: Sábado | AC35: 44205 | AD35: 0 | AE35: 0 | AF35: =AD35/AE35 -> #DIV/0! | AG35: 0 | AH35: =AD35/AG35 -> #DIV/0! | AI35: 0 | AJ35: =AD35/AI35 -> #DIV/0! | AK35: 0 | AL35: =AD35/AK35 -> #DIV/0! | AM35: =AI35/AK35 -> #DIV/0! | AP35: Sábado | AQ35: 44205 | AR35: 0 | AS35: 0 | AT35: =AR35/AS35 -> #DIV/0! | AU35: 0 | AV35: =AR35/AU35 -> #DIV/0! | AW35: 0 | AX35: =AR35/AW35 -> #DIV/0! | AY35: 0 | AZ35: =AR35/AY35 -> #DIV/0! | BA35: =AW35/AY35 -> #DIV/0! | BC35: Sábado | BD35: 44205 | BE35: 0 | BF35: 0 | BG35: =BE35/BF35 -> #DIV/0! | BH35: 0 | BI35: =BE35/BH35 -> #DIV/0! | BJ35: 0 | BK35: =BE35/BJ35 -> #DIV/0! | BL35: 0 | BM35: =BE35/BL35 -> #DIV/0! | BN35: =BJ35/BL35 -> #DIV/0!
B36: Taxas de Coprodução | E36: 36.61 | H36: Faturamento Real | K36: =SUM(L32*F38) -> 0 | N36: Domingo | O36: 44206 | P36: 0 | Q36: 0 | R36: =P36/Q36 -> #DIV/0! | S36: 0 | T36: =P36/S36 -> #DIV/0! | U36: 0 | V36: =P36/U36 -> #DIV/0! | W36: 0 | X36: =P36/W36 -> #DIV/0! | Y36: =U36/W36 -> #DIV/0! | AB36: Domingo | AC36: 44206 | AD36: 0 | AE36: 0 | AF36: =AD36/AE36 -> #DIV/0! | AG36: 0 | AH36: =AD36/AG36 -> #DIV/0! | AI36: 0 | AJ36: =AD36/AI36 -> #DIV/0! | AK36: 0 | AL36: =AD36/AK36 -> #DIV/0! | AM36: =AI36/AK36 -> #DIV/0! | AP36: Domingo | AQ36: 44206 | AR36: 0 | AS36: 0 | AT36: =AR36/AS36 -> #DIV/0! | AU36: 0 | AV36: =AR36/AU36 -> #DIV/0! | AW36: 0 | AX36: =AR36/AW36 -> #DIV/0! | AY36: 0 | AZ36: =AR36/AY36 -> #DIV/0! | BA36: =AW36/AY36 -> #DIV/0! | BC36: Domingo | BD36: 44206 | BE36: 0 | BF36: 0 | BG36: =BE36/BF36 -> #DIV/0! | BH36: 0 | BI36: =BE36/BH36 -> #DIV/0! | BJ36: 0 | BK36: =BE36/BJ36 -> #DIV/0! | BL36: 0 | BM36: =BE36/BL36 -> #DIV/0! | BN36: =BJ36/BL36 -> #DIV/0!
